File: ElectricPoleSupport/ExptData/Raw/Heel_B1_cycle.raw.csv
"Test Type","Compression"
"Temperature:","20.5"
"Humidity:","57.5"
"Geometry:","Rectangular"
"Specimen",1
"Specimen name:","B1 "
"Width:",342.000000,"mm"
"Thickness:",448.000000,"mm"
"Anvil height:",90.000000,"mm"
"Diameter:",50.000000,"mm"
"Inner diameter:",0.500000,"mm"
"Outer diameter:",1.000000,"mm"
"Wall thickness:",0.500000,"mm"
"Area:",153216.000000,"mm*mm"
"Linear density:",1.000000,"den"
"Sled weight:",9.806650,"N"
"Loading span:",0.000000,"mm"
"Support span:",1.000000,"mm"
"Span ratio:","2"
"Fixture type:","3-point"
"Extensometer",-10.000000,"**mm"
"Included"
"Time sec","Extension mm","Strain 1 %","Load N","Comp. stress MPa","Cycle Count ","Total Cycle Count ","Comp. extension mm","Comp. strain %","True strain %","Comp. load N","True stress Pa"
0,-1.25264,-0.02133362,-67.21292,0.0004386808,0,0,0.002133362,0.02133362,0.0213359,67.21291,438.5872
1,-1.26676,-0.02133362,-87.93928,0.0005739562,0,0,0.002133362,0.02133362,0.0213359,87.93928,573.8338
2,-1.28576,-0.02142932,-124.0817,0.0008098479,0,0,0.002142932,0.02142932,0.02143162,124.0817,809.6743
3,-1.30256,-0.02141338,-151.3045,0.0009875244,0,0,0.002141338,0.02141338,0.02141567,151.3045,987.3129
4,-1.31916,-0.02125386,-178.0702,0.001162217,0,0,0.002125386,0.02125386,0.02125612,178.0703,1161.97
5,-1.33596,-0.02122197,-204.3556,0.001333774,0,0,0.002122197,0.02122197,0.02122422,204.3556,1333.491
6,-1.35248,-0.02163671,-230.003,0.001501168,0,0,0.002163671,0.02163671,0.02163905,230.003,1500.843
7,-1.36916,-0.02144527,-252.1112,0.001645462,0,0,0.002144527,0.02144527,0.02144757,252.1112,1645.109
8,-1.38584,-0.02130173,-273.0747,0.001782286,0,0,0.002130173,0.02130173,0.021304,273.0747,1781.906
9,-1.4024,-0.02139743,-291.8322,0.001904711,0,0,0.002139743,0.02139743,0.02139972,291.8322,1904.303
10,-1.4194,-0.02139743,-309.8365,0.00202222,0,0,0.002139743,0.02139743,0.02139972,309.8365,2021.788
11,-1.43596,-0.02112627,-310.1032,0.002023961,0,0,0.002112627,0.02112627,0.0211285,310.1032,2023.533
12,-1.45248,-0.02082318,-310.0075,0.002023336,0,0,0.002082318,0.02082318,0.02082535,310.0074,2022.915
13,-1.46928,-0.02130173,-310.3758,0.00202574,0,0,0.002130173,0.02130173,0.021304,310.3758,2025.308
14,-1.4858,-0.02170049,-310.739,0.002028111,0,0,0.002170049,0.02170049,0.02170284,310.739,2027.671
15,-1.50248,-0.0216686,-310.8794,0.002029027,0,0,0.00216686,0.0216686,0.02167095,310.8794,2028.588
16,-1.51932,-0.02144527,-311.0959,0.00203044,0,0,0.002144527,0.02144527,0.02144757,311.0959,2030.005
17,-1.53564,-0.02133362,-311.2891,0.002031701,0,0,0.002133362,0.02133362,0.0213359,311.2891,2031.267
18,-1.55248,-0.02112627,-312.3397,0.002038558,0,0,0.002112627,0.02112627,0.0211285,312.3397,2038.127
19,-1.5694,-0.02085511,-311.392,0.002032372,0,0,0.002085511,0.02085511,0.02085728,311.392,2031.949
20,-1.58592,-0.02077535,-312.0268,0.002036516,0,0,0.002077535,0.02077535,0.02077751,312.0268,2036.093
21,-1.60248,-0.0210784,-312.3762,0.002038796,0,0,0.00210784,0.0210784,0.02108062,312.3762,2038.366
22,-1.6192,-0.02114221,-312.2419,0.00203792,0,0,0.002114221,0.02114221,0.02114445,312.2419,2037.489
23,-1.63584,-0.02115816,-311.6998,0.002034381,0,0,0.002115816,0.02115816,0.0211604,311.6998,2033.951
24,-1.65264,-0.02126981,-312.6871,0.002040826,0,0,0.002126981,0.02126981,0.02127207,312.6871,2040.391
25,-1.66912,-0.02133362,-312.3051,0.002038332,0,0,0.002133362,0.02133362,0.0213359,312.3051,2037.897
26,-1.68596,-0.02088699,-313.1268,0.002043695,0,0,0.002088699,0.02088699,0.02088918,313.1268,2043.269
27,-1.70272,-0.02119008,-316.6828,0.002066904,0,0,0.002119008,0.02119008,0.02119233,316.6828,2066.466
28,-1.719,-0.02125386,-328.7246,0.002145498,0,0,0.002125386,0.02125386,0.02125612,328.7246,2145.042
29,-1.73576,-0.02104651,-353.1218,0.002304732,0,0,0.002104651,0.02104651,0.02104873,353.1218,2304.247
30,-1.75256,-0.02095081,-378.2368,0.002468651,0,0,0.002095081,0.02095081,0.020953,378.2368,2468.134
31,-1.76912,-0.02130173,-402.5016,0.00262702,0,0,0.002130173,0.02130173,0.021304,402.5016,2626.461
32,-1.78592,-0.02090294,-428.3967,0.002796031,0,0,0.002090294,0.02090294,0.02090512,428.3967,2795.447
33,-1.80248,-0.02126981,-454.1168,0.002963899,0,0,0.002126981,0.02126981,0.02127207,454.1168,2963.269
34,-1.81904,-0.02125386,-479.1975,0.003127594,0,0,0.002125386,0.02125386,0.02125612,479.1975,3126.93
35,-1.83604,-0.02139743,-506.8289,0.003307937,0,0,0.002139743,0.02139743,0.02139972,506.8289,3307.229
36,-1.85244,-0.02142932,-532.379,0.003474696,0,0,0.002142932,0.02142932,0.02143162,532.379,3473.952
37,-1.86924,-0.02114221,-558.9002,0.003647793,0,0,0.002114221,0.02114221,0.02114445,558.9002,3647.022
38,-1.88596,-0.0209827,-586.5958,0.003828554,0,0,0.00209827,0.0209827,0.0209849,586.5958,3827.751
39,-1.90232,-0.02104651,-612.5004,0.003997627,0,0,0.002104651,0.02104651,0.02104873,612.5004,3996.786
40,-1.91932,-0.02114221,-639.1017,0.004171246,0,0,0.002114221,0.02114221,0.02114445,639.1017,4170.364
41,-1.93584,-0.02111033,-665.9466,0.004346456,0,0,0.002111033,0.02111033,0.02111255,665.9467,4345.539
42,-1.95216,-0.02104651,-691.7787,0.004515056,0,0,0.002104651,0.02104651,0.02104873,691.7787,4514.105
43,-1.96928,-0.0211741,-718.4933,0.004689415,0,0,0.00211741,0.0211741,0.02117634,718.4933,4688.422
44,-1.98572,-0.0215729,-743.6069,0.004853324,0,0,0.00215729,0.0215729,0.02157522,743.6069,4852.277
45,-2.00252,-0.0209827,-770.312,0.005027621,0,0,0.00209827,0.0209827,0.0209849,770.312,5026.566
46,-2.0192,-0.02125386,-797.4559,0.005204782,0,0,0.002125386,0.02125386,0.02125612,797.4559,5203.676
47,-2.0356,-0.02133362,-822.9416,0.00537112,0,0,0.002133362,0.02133362,0.0213359,822.9416,5369.975
48,-2.05248,-0.02088699,-851.8738,0.005559953,0,0,0.002088699,0.02088699,0.02088918,851.8738,5558.792
49,-2.06932,-0.02088699,-878.8558,0.005736057,0,0,0.002088699,0.02088699,0.02088918,878.8558,5734.859
50,-2.08588,-0.02122197,-907.0681,0.005920192,0,0,0.002122197,0.02122197,0.02122422,907.0681,5918.936
51,-2.10248,-0.02088699,-935.2702,0.006104259,0,0,0.002088699,0.02088699,0.02088918,935.2701,6102.984
52,-2.11888,-0.02120603,-962.3207,0.006280811,0,0,0.002120603,0.02120603,0.02120828,962.3207,6279.479
53,-2.13564,-0.0211741,-990.727,0.006466211,0,0,0.00211741,0.0211741,0.02117634,990.727,6464.842
54,-2.15276,-0.02119008,-1019.883,0.006656505,0,0,0.002119008,0.02119008,0.02119233,1019.883,6655.094
55,-2.16932,-0.02099864,-1048.199,0.006841313,0,0,0.002099864,0.02099864,0.02100085,1048.198,6839.876
56,-2.186,-0.02114221,-1077.075,0.007029781,0,0,0.002114221,0.02114221,0.02114445,1077.075,7028.295
57,-2.20268,-0.02130173,-1106.178,0.007219727,0,0,0.002130173,0.02130173,0.021304,1106.178,7218.189
58,-2.21908,-0.02122197,-1134.338,0.007403519,0,0,0.002122197,0.02122197,0.02122422,1134.338,7401.949
59,-2.23608,-0.02123792,-1165.161,0.007604694,0,0,0.002123792,0.02123792,0.02124017,1165.161,7603.078
60,-2.2526,-0.02106246,-1193.038,0.007786641,0,0,0.002106246,0.02106246,0.02106467,1193.038,7785.001
61,-2.26932,-0.02090294,-1222.098,0.007976305,0,0,0.002090294,0.02090294,0.02090512,1222.098,7974.637
62,-2.286199,-0.02120603,-1252.561,0.008175131,0,0,0.002120603,0.02120603,0.02120828,1252.561,8173.397
63,-2.30248,-0.02109434,-1279.47,0.008350758,0,0,0.002109434,0.02109434,0.02109657,1279.47,8348.997
64,-2.31924,-0.02099864,-1309.109,0.008544203,0,0,0.002099864,0.02099864,0.02100085,1309.109,8542.409
65,-2.3362,-0.02106246,-1338.97,0.008739099,0,0,0.002106246,0.02106246,0.02106467,1338.97,8737.258
66,-2.35252,-0.02085511,-1365.76,0.008913948,0,0,0.002085511,0.02085511,0.02085728,1365.76,8912.089
67,-2.3692,-0.02133362,-1396.097,0.009111953,0,0,0.002133362,0.02133362,0.0213359,1396.097,9110.009
68,-2.38604,-0.02128579,-1426.781,0.009312223,0,0,0.002128579,0.02128579,0.02128805,1426.781,9310.241
69,-2.40244,-0.02109434,-1454.898,0.009495732,0,0,0.002109434,0.02109434,0.02109657,1454.898,9493.729
70,-2.41936,-0.02099864,-1485.063,0.009692611,0,0,0.002099864,0.02099864,0.02100085,1485.063,9690.576
71,-2.43604,-0.02133362,-1514.059,0.009881859,0,0,0.002133362,0.02133362,0.0213359,1514.059,9879.751
72,-2.45252,-0.02099864,-1543.094,0.01007136,0,0,0.002099864,0.02099864,0.02100085,1543.094,10069.25
73,-2.46936,-0.02080724,-1573.051,0.01026688,0,0,0.002080724,0.02080724,0.0208094,1573.051,10264.75
74,-2.48576,-0.02133362,-1601.059,0.01044969,0,0,0.002133362,0.02133362,0.0213359,1601.059,10447.46
75,-2.50256,-0.02131768,-1630.601,0.0106425,0,0,0.002131768,0.02131768,0.02131995,1630.601,10640.23
76,-2.5196,-0.02163671,-1661.162,0.01084196,0,0,0.002163671,0.02163671,0.02163905,1661.162,10839.62
77,-2.535959,-0.02147719,-1690.475,0.01103328,0,0,0.002147719,0.02147719,0.0214795,1690.474,11030.91
78,-2.55256,-0.02125386,-1720.505,0.01122928,0,0,0.002125386,0.02125386,0.02125612,1720.505,11226.89
79,-2.56944,-0.02122197,-1750.724,0.01142651,0,0,0.002122197,0.02122197,0.02122422,1750.724,11424.08
80,-2.5858,-0.02126981,-1780.299,0.01161954,0,0,0.002126981,0.02126981,0.02127207,1780.299,11617.07
81,-2.6026,-0.02112627,-1810.173,0.01181452,0,0,0.002112627,0.02112627,0.0211285,1810.173,11812.02
82,-2.619319,-0.02130173,-1839.35,0.01200495,0,0,0.002130173,0.02130173,0.021304,1839.35,12002.39
83,-2.635919,-0.02126981,-1870.331,0.01220715,0,0,0.002126981,0.02126981,0.02127207,1870.331,12204.55
84,-2.652839,-0.02133362,-1900.393,0.01240336,0,0,0.002133362,0.02133362,0.0213359,1900.393,12400.71
85,-2.669279,-0.02123792,-1928.768,0.01258855,0,0,0.002123792,0.02123792,0.02124017,1928.768,12585.88
86,-2.68612,-0.02111033,-1959.76,0.01279083,0,0,0.002111033,0.02111033,0.02111255,1959.76,12788.13
87,-2.702959,-0.02114221,-1991.654,0.012999,0,0,0.002114221,0.02114221,0.02114445,1991.654,12996.25
88,-2.719079,-0.02128579,-2021.028,0.01319071,0,0,0.002128579,0.02128579,0.02128805,2021.028,13187.9
89,-2.735959,-0.02123792,-2053.634,0.01340352,0,0,0.002123792,0.02123792,0.02124017,2053.635,13400.68
90,-2.752759,-0.02119008,-2085.542,0.01361177,0,0,0.002119008,0.02119008,0.02119233,2085.542,13608.89
91,-2.76908,-0.02093486,-2115.692,0.01380856,0,0,0.002093486,0.02093486,0.02093706,2115.692,13805.67
92,-2.78596,-0.0209827,-2147.751,0.0140178,0,0,0.00209827,0.0209827,0.0209849,2147.75,14014.85
93,-2.802559,-0.02093486,-2179.093,0.01422236,0,0,0.002093486,0.02093486,0.02093706,2179.093,14219.38
94,-2.819239,-0.02120603,-2210.471,0.01442716,0,0,0.002120603,0.02120603,0.02120828,2210.471,14424.1
95,-2.83624,-0.02120603,-2243.465,0.0146425,0,0,0.002120603,0.02120603,0.02120828,2243.465,14639.39
96,-2.852599,-0.02077535,-2273.981,0.01484167,0,0,0.002077535,0.02077535,0.02077751,2273.981,14838.59
97,-2.86936,-0.0210784,-2306.779,0.01505573,0,0,0.00210784,0.0210784,0.02108062,2306.779,15052.56
98,-2.886319,-0.02138149,-2340.491,0.01527576,0,0,0.002138149,0.02138149,0.02138378,2340.49,15272.49
99,-2.9026,-0.02106246,-2371.061,0.01547528,0,0,0.002106246,0.02106246,0.02106467,2371.061,15472.02
100,-2.919479,-0.02106246,-2405.041,0.01569706,0,0,0.002106246,0.02106246,0.02106467,2405.041,15693.76
101,-2.93604,-0.02147719,-2436.887,0.01590491,0,0,0.002147719,0.02147719,0.0214795,2436.887,15901.5
102,-2.95252,-0.02123792,-2468.343,0.01611022,0,0,0.002123792,0.02123792,0.02124017,2468.344,16106.8
103,-2.96948,-0.02150908,-2502.174,0.01633102,0,0,0.002150908,0.02150908,0.0215114,2502.174,16327.51
104,-2.986119,-0.02087105,-2532.887,0.01653148,0,0,0.002087105,0.02087105,0.02087323,2532.887,16528.03
105,-3.00284,-0.02109434,-2565.009,0.01674113,0,0,0.002109434,0.02109434,0.02109657,2565.009,16737.6
106,-3.01956,-0.02096675,-2597.619,0.01695397,0,0,0.002096675,0.02096675,0.02096895,2597.619,16950.41
107,-3.035879,-0.02115816,-2628.618,0.01715629,0,0,0.002115816,0.02115816,0.0211604,2628.618,17152.66
108,-3.052719,-0.02141338,-2662.533,0.01737764,0,0,0.002141338,0.02141338,0.02141567,2662.532,17373.92
109,-3.06924,-0.02158884,-2694.401,0.01758564,0,0,0.002158884,0.02158884,0.02159117,2694.401,17581.84
110,-3.085879,-0.02122197,-2727.812,0.0178037,0,0,0.002122197,0.02122197,0.02122422,2727.812,17799.93
111,-3.102719,-0.02122197,-2760.108,0.01801449,0,0,0.002122197,0.02122197,0.02122422,2760.108,18010.67
112,-3.119319,-0.02109434,-2790.906,0.0182155,0,0,0.002109434,0.02109434,0.02109657,2790.906,18211.66
113,-3.135999,-0.02104651,-2823.663,0.01842929,0,0,0.002104651,0.02104651,0.02104873,2823.663,18425.42
114,-3.152839,-0.02122197,-2856.341,0.01864258,0,0,0.002122197,0.02122197,0.02122422,2856.341,18638.62
115,-3.1692,-0.02093486,-2887.282,0.01884452,0,0,0.002093486,0.02093486,0.02093706,2887.282,18840.58
116,-3.186119,-0.02103057,-2921.864,0.01907023,0,0,0.002103057,0.02103057,0.02103278,2921.864,19066.22
117,-3.202799,-0.02115816,-2953.523,0.01927686,0,0,0.002115816,0.02115816,0.0211604,2953.523,19272.78
118,-3.219199,-0.02095081,-2984.693,0.0194803,0,0,0.002095081,0.02095081,0.020953,2984.693,19476.22
119,-3.235959,-0.02082318,-3017.182,0.01969235,0,0,0.002082318,0.02082318,0.02082535,3017.182,19688.25
120,-3.252639,-0.02123792,-3050.156,0.01990756,0,0,0.002123792,0.02123792,0.02124017,3050.156,19903.33
121,-3.26928,-0.02082318,-3081.018,0.02010898,0,0,0.002082318,0.02082318,0.02082535,3081.018,20104.79
122,-3.285999,-0.02085511,-3113.758,0.02032267,0,0,0.002085511,0.02085511,0.02085728,3113.758,20318.43
123,-3.30244,-0.02085511,-3141.42,0.02050321,0,0,0.002085511,0.02085511,0.02085728,3141.42,20498.94
124,-3.319079,-0.02104651,-3167.587,0.020674,0,0,0.002104651,0.02104651,0.02104873,3167.587,20669.65
125,-3.33588,-0.02087105,-3195.044,0.0208532,0,0,0.002087105,0.02087105,0.02087323,3195.044,20848.85
126,-3.35256,-0.02083912,-3221.209,0.02102397,0,0,0.002083912,0.02083912,0.0208413,3221.209,21019.59
127,-3.369279,-0.02074342,-3249.592,0.02120922,0,0,0.002074342,0.02074342,0.02074557,3249.592,21204.82
128,-3.386119,-0.02101459,-3280.067,0.02140813,0,0,0.002101459,0.02101459,0.02101679,3280.067,21403.63
129,-3.40252,-0.02104651,-3309.009,0.02159702,0,0,0.002104651,0.02104651,0.02104873,3309.009,21592.47
130,-3.41936,-0.0211741,-3340.87,0.02180497,0,0,0.00211741,0.0211741,0.02117634,3340.87,21800.35
131,-3.435879,-0.02103057,-3369.856,0.02199415,0,0,0.002103057,0.02103057,0.02103278,3369.856,21989.53
132,-3.452559,-0.02085511,-3401.492,0.02220063,0,0,0.002085511,0.02085511,0.02085728,3401.492,22196
133,-3.469319,-0.02128579,-3432.281,0.02240158,0,0,0.002128579,0.02128579,0.02128805,3432.281,22396.81
134,-3.485759,-0.02115816,-3460.779,0.02258758,0,0,0.002115816,0.02115816,0.0211604,3460.779,22582.8
135,-3.502439,-0.02111033,-3491.555,0.02278845,0,0,0.002111033,0.02111033,0.02111255,3491.555,22783.64
136,-3.519519,-0.02109434,-3524.619,0.02300425,0,0,0.002109434,0.02109434,0.02109657,3524.619,22999.39
137,-3.536039,-0.02115816,-3554.998,0.02320253,0,0,0.002115816,0.02115816,0.0211604,3554.998,23197.62
138,-3.55284,-0.02134956,-3588.751,0.02342282,0,0,0.002134956,0.02134956,0.02135184,3588.751,23417.82
139,-3.569439,-0.02106246,-3620.049,0.0236271,0,0,0.002106246,0.02106246,0.02106467,3620.049,23622.12
140,-3.585959,-0.02136555,-3650.786,0.02382771,0,0,0.002136555,0.02136555,0.02136783,3650.786,23822.62
141,-3.602799,-0.02119008,-3683.059,0.02403834,0,0,0.002119008,0.02119008,0.02119233,3683.059,24033.25
142,-3.6194,-0.02125386,-3714.076,0.02424078,0,0,0.002125386,0.02125386,0.02125612,3714.076,24235.63
143,-3.6358,-0.02109434,-3744.098,0.02443673,0,0,0.002109434,0.02109434,0.02109657,3744.098,24431.57
144,-3.652759,-0.02126981,-3775.258,0.0246401,0,0,0.002126981,0.02126981,0.02127207,3775.258,24634.86
145,-3.669199,-0.02126981,-3805.111,0.02483495,0,0,0.002126981,0.02126981,0.02127207,3805.111,24829.66
146,-3.685879,-0.02109434,-3837.232,0.02504459,0,0,0.002109434,0.02109434,0.02109657,3837.231,25039.3
147,-3.70268,-0.02091888,-3867.726,0.02524362,0,0,0.002091888,0.02091888,0.02092107,3867.726,25238.34
148,-3.719039,-0.02128579,-3899.703,0.02545232,0,0,0.002128579,0.02128579,0.02128805,3899.703,25446.9
149,-3.735799,-0.02131768,-3934.648,0.02568039,0,0,0.002131768,0.02131768,0.02131995,3934.647,25674.92
150,-3.752719,-0.02120603,-3969.227,0.02590609,0,0,0.002120603,0.02120603,0.02120828,3969.227,25900.59
151,-3.769039,-0.02119008,-4003.05,0.02612684,0,0,0.002119008,0.02119008,0.02119233,4003.05,26121.3
152,-3.786039,-0.02150908,-4039.728,0.02636622,0,0,0.002150908,0.02150908,0.0215114,4039.728,26360.55
153,-3.80256,-0.0210784,-4073.181,0.02658457,0,0,0.00210784,0.0210784,0.02108062,4073.181,26578.97
154,-3.81924,-0.02130173,-4108.112,0.02681255,0,0,0.002130173,0.02130173,0.021304,4108.111,26806.84
155,-3.836119,-0.0210784,-4143.61,0.02704424,0,0,0.00210784,0.0210784,0.02108062,4143.61,27038.54
156,-3.852519,-0.02119008,-4176.594,0.02725951,0,0,0.002119008,0.02119008,0.02119233,4176.594,27253.74
157,-3.86896,-0.02106246,-4211.621,0.02748813,0,0,0.002106246,0.02106246,0.02106467,4211.622,27482.34
158,-3.885719,-0.02077535,-4247.612,0.02772303,0,0,0.002077535,0.02077535,0.02077751,4247.612,27717.27
159,-3.902079,-0.02115816,-4282.222,0.02794892,0,0,0.002115816,0.02115816,0.0211604,4282.222,27943.01
160,-3.919039,-0.0211741,-4319.254,0.02819062,0,0,0.00211741,0.0211741,0.02117634,4319.254,28184.65
161,-3.935959,-0.02080724,-4355.641,0.02842811,0,0,0.002080724,0.02080724,0.0208094,4355.641,28422.19
162,-3.952399,-0.02130173,-4392.843,0.02867092,0,0,0.002130173,0.02130173,0.021304,4392.843,28664.81
163,-3.969279,-0.02111033,-4430.644,0.02891763,0,0,0.002111033,0.02111033,0.02111255,4430.644,28911.53
164,-3.985839,-0.02146125,-4467.127,0.02915575,0,0,0.002146125,0.02146125,0.02146355,4467.127,29149.49
165,-4.002599,-0.02106246,-4505.849,0.02940848,0,0,0.002106246,0.02106246,0.02106467,4505.849,29402.28
166,-4.0196,-0.0210784,-4544.671,0.02966186,0,0,0.00210784,0.0210784,0.02108062,4544.671,29655.61
167,-4.035879,-0.02115816,-4580.839,0.02989791,0,0,0.002115816,0.02115816,0.0211604,4580.838,29891.58
168,-4.052399,-0.02091888,-4619.399,0.03014959,0,0,0.002091888,0.02091888,0.02092107,4619.399,30143.28
169,-4.069239,-0.02147719,-4658.278,0.03040334,0,0,0.002147719,0.02147719,0.0214795,4658.278,30396.81
170,-4.085639,-0.02082318,-4695.326,0.03064514,0,0,0.002082318,0.02082318,0.02082535,4695.326,30638.76
171,-4.102799,-0.02096675,-4736.41,0.03091329,0,0,0.002096675,0.02096675,0.02096895,4736.41,30906.8
172,-4.119359,-0.02090294,-4773.315,0.03115416,0,0,0.002090294,0.02090294,0.02090512,4773.315,31147.64
173,-4.135919,-0.02111033,-4810.495,0.03139682,0,0,0.002111033,0.02111033,0.02111255,4810.495,31390.19
174,-4.15276,-0.02160478,-4849.722,0.03165284,0,0,0.002160478,0.02160478,0.02160712,4849.722,31646
175,-4.169159,-0.02090294,-4885.648,0.03188732,0,0,0.002090294,0.02090294,0.02090512,4885.648,31880.66
176,-4.185879,-0.0209827,-4922.782,0.03212969,0,0,0.00209827,0.0209827,0.0209849,4922.782,32122.95
177,-4.202679,-0.02106246,-4961.647,0.03238335,0,0,0.002106246,0.02106246,0.02106467,4961.647,32376.53
178,-4.219199,-0.02085511,-4998.334,0.0326228,0,0,0.002085511,0.02085511,0.02085728,4998.334,32615.99
179,-4.236079,-0.02080724,-5037.376,0.03287761,0,0,0.002080724,0.02080724,0.0208094,5037.376,32870.77
180,-4.252679,-0.02122197,-5074.417,0.03311937,0,0,0.002122197,0.02122197,0.02122422,5074.417,33112.34
180.294,-4.257399,-0.0211741,-5085,0.03318844,0,0,0.00211741,0.0211741,0.02117634,5085,33181.41
"Specimen",2
"Specimen name:","B1 Cycle"
"Width:",342.000000,"mm"
"Thickness:",448.000000,"mm"
"Anvil height:",90.000000,"mm"
"Diameter:",50.000000,"mm"
"Inner diameter:",0.500000,"mm"
"Outer diameter:",1.000000,"mm"
"Wall thickness:",0.500000,"mm"
"Area:",153216.000000,"mm*mm"
"Linear density:",1.000000,"den"
"Sled weight:",9.806650,"N"
"Loading span:",0.000000,"mm"
"Support span:",1.000000,"mm"
"Span ratio:","2"
"Fixture type:","3-point"
"Extensometer",-10.000000,"**mm"
"Included"
"Time sec","Extension mm","Strain 1 %","Load N","Comp. stress MPa","Cycle Count ","Total Cycle Count ","Comp. extension mm","Comp. strain %","True strain %","Comp. load N","True stress Pa"
0,-3.999999e-005,-0.02077535,-248.729,0.001623388,0,0,0.002077535,0.02077535,0.02077751,248.729,1623.05
3,-0.05003999,-0.02055202,-307.1245,0.00200452,0,0,0.002055202,0.02055202,0.02055413,307.1245,2004.108
6,-0.09999999,-0.02074342,-309.8311,0.002022185,0,0,0.002074342,0.02074342,0.02074557,309.8311,2021.766
9,-0.15,-0.02093486,-310.4926,0.002026502,0,0,0.002093486,0.02093486,0.02093706,310.4926,2026.078
12,-0.2,-0.02139743,-311.5054,0.002033112,0,0,0.002139743,0.02139743,0.02139972,311.5053,2032.677
15,-0.2500399,-0.02150908,-311.4885,0.002033002,0,0,0.002150908,0.02150908,0.0215114,311.4885,2032.565
18,-0.29996,-0.02095081,-311.3901,0.002032361,0,0,0.002095081,0.02095081,0.020953,311.3901,2031.935
21,-0.35008,-0.02111033,-371.1359,0.002422305,0,0,0.002111033,0.02111033,0.02111255,371.1359,2421.794
24,-0.3999599,-0.02083912,-460.0805,0.003002823,0,0,0.002083912,0.02083912,0.0208413,460.0805,3002.197
27,-0.4499999,-0.02099864,-545.3948,0.003559647,0,0,0.002099864,0.02099864,0.02100085,545.3948,3558.899
30,-0.5000399,-0.02099864,-631.3419,0.0041206,0,0,0.002099864,0.02099864,0.02100085,631.3419,4119.735
33,-0.5499999,-0.02047226,-717.1278,0.004680502,0,0,0.002047226,0.02047226,0.02047435,717.1278,4679.544
36,-0.6000399,-0.02069559,-806.4897,0.005263743,0,0,0.002069559,0.02069559,0.02069773,806.4897,5262.654
39,-0.6499999,-0.02095081,-897.5031,0.005857763,0,0,0.002095081,0.02095081,0.020953,897.5031,5856.536
42,-0.6999999,-0.02082318,-989.9834,0.006461358,0,0,0.002082318,0.02082318,0.02082535,989.9834,6460.012
45,-0.7500399,-0.02106246,-1083.898,0.007074316,0,0,0.002106246,0.02106246,0.02106467,1083.898,7072.826
48,-0.7999999,-0.02126981,-1179.177,0.007696177,0,0,0.002126981,0.02126981,0.02127207,1179.177,7694.54
51,-0.8500399,-0.02120603,-1274.151,0.008316043,0,0,0.002120603,0.02120603,0.02120828,1274.151,8314.279
54,-0.9000399,-0.02131768,-1369.434,0.00893793,0,0,0.002131768,0.02131768,0.02131995,1369.434,8936.024
57,-0.9499999,-0.02101459,-1466.078,0.009568697,0,0,0.002101459,0.02101459,0.02101679,1466.078,9566.686
60,-1.00004,-0.02063178,-1561.904,0.01019413,0,0,0.002063178,0.02063178,0.0206339,1561.904,10192.03
63,-1.05004,-0.02099864,-1658.892,0.01082715,0,0,0.002099864,0.02099864,0.02100085,1658.892,10824.87
66,-1.10004,-0.02112627,-1759.15,0.01148151,0,0,0.002112627,0.02112627,0.0211285,1759.15,11479.08
69,-1.15008,-0.02131768,-1858.386,0.01212919,0,0,0.002131768,0.02131768,0.02131995,1858.386,12126.61
72,-1.2,-0.02085511,-1957.978,0.0127792,0,0,0.002085511,0.02085511,0.02085728,1957.978,12776.54
75,-1.25,-0.02087105,-2060.816,0.01345039,0,0,0.002087105,0.02087105,0.02087323,2060.816,13447.59
78,-1.30008,-0.02075937,-2163.605,0.01412127,0,0,0.002075937,0.02075937,0.02076152,2163.605,14118.34
81,-1.35,-0.02066366,-2267.174,0.01479724,0,0,0.002066366,0.02066366,0.0206658,2267.174,14794.18
84,-1.40008,-0.0209827,-2373.11,0.01548865,0,0,0.00209827,0.0209827,0.0209849,2373.11,15485.4
87,-1.45,-0.02109434,-2479.222,0.01618122,0,0,0.002109434,0.02109434,0.02109657,2479.222,16177.81
90,-1.5,-0.02083912,-2584.235,0.01686662,0,0,0.002083912,0.02083912,0.0208413,2584.235,16863.1
93,-1.55004,-0.02087105,-2690.873,0.01756261,0,0,0.002087105,0.02087105,0.02087323,2690.873,17558.94
96,-1.60004,-0.02079129,-2797.423,0.01825803,0,0,0.002079129,0.02079129,0.02079345,2797.423,18254.24
99,-1.64996,-0.02080724,-2902.617,0.01894461,0,0,0.002080724,0.02080724,0.0208094,2902.617,18940.67
102,-1.70004,-0.02104651,-3004.89,0.01961212,0,0,0.002104651,0.02104651,0.02104873,3004.89,19607.99
105,-1.75004,-0.02079129,-3111.105,0.02030535,0,0,0.002079129,0.02079129,0.02079345,3111.105,20301.13
108,-1.80008,-0.02075937,-3216.087,0.02099054,0,0,0.002075937,0.02075937,0.02076152,3216.087,20986.19
111,-1.85,-0.02093486,-3318.888,0.02166149,0,0,0.002093486,0.02093486,0.02093706,3318.888,21656.96
114,-1.9,-0.02138149,-3422.34,0.0223367,0,0,0.002138149,0.02138149,0.02138378,3422.34,22331.92
117,-1.95004,-0.02112627,-3529.48,0.02303598,0,0,0.002112627,0.02112627,0.0211285,3529.48,23031.11
120,-2.00004,-0.02103057,-3643.055,0.02377725,0,0,0.002103057,0.02103057,0.02103278,3643.055,23772.25
123,-2.05,-0.0209827,-3756.4,0.02451702,0,0,0.00209827,0.0209827,0.0209849,3756.4,24511.88
126,-2.1,-0.02077535,-3873.625,0.02528212,0,0,0.002077535,0.02077535,0.02077751,3873.625,25276.87
129,-2.15,-0.02096675,-3989.545,0.02603869,0,0,0.002096675,0.02096675,0.02096895,3989.544,26033.23
132,-2.20004,-0.02106246,-4106.22,0.02680021,0,0,0.002106246,0.02106246,0.02106467,4106.22,26794.56
135,-2.25004,-0.02074342,-4232.924,0.02762716,0,0,0.002074342,0.02074342,0.02074557,4232.924,27621.43
138,-2.3,-0.02122197,-4360.484,0.02845972,0,0,0.002122197,0.02122197,0.02122422,4360.484,28453.68
141,-2.35004,-0.02106246,-4487.052,0.02928579,0,0,0.002106246,0.02106246,0.02106467,4487.052,29279.63
144,-2.40004,-0.02111033,-4613.418,0.03011055,0,0,0.002111033,0.02111033,0.02111255,4613.418,30104.19
147,-2.449999,-0.02080724,-4740.077,0.03093722,0,0,0.002080724,0.02080724,0.0208094,4740.077,30930.78
150,-2.5,-0.02087105,-4863.551,0.0317431,0,0,0.002087105,0.02087105,0.02087323,4863.551,31736.48
153,-2.55,-0.02079129,-4985.894,0.0325416,0,0,0.002079129,0.02079129,0.02079345,4985.894,32534.83
154.36,-2.54024,-0.02085511,-4960.011,0.03237267,0,0,0.002085511,0.02085511,0.02085728,4960.011,32365.92
157.36,-2.489359,-0.02095081,-4697.091,0.03065666,0,0,0.002095081,0.02095081,0.020953,4697.091,30650.24
160.36,-2.43932,-0.02112627,-4458.332,0.02909834,0,0,0.002112627,0.02112627,0.0211285,4458.332,29092.2
163.36,-2.38932,-0.02058391,-4239.346,0.02766909,0,0,0.002058391,0.02058391,0.02058602,4239.347,27663.39
166.36,-2.33936,-0.0209827,-4035.849,0.02634091,0,0,0.00209827,0.0209827,0.0209849,4035.849,26335.38
169.36,-2.28936,-0.02106246,-3840.157,0.02506368,0,0,0.002106246,0.02106246,0.02106467,3840.157,25058.4
172.36,-2.23936,-0.02091888,-3663.293,0.02390934,0,0,0.002091888,0.02091888,0.02092107,3663.293,23904.33
175.36,-2.18928,-0.02119008,-3496.948,0.02282364,0,0,0.002119008,0.02119008,0.02119233,3496.948,22818.81
178.36,-2.13936,-0.02122197,-3340.951,0.0218055,0,0,0.002122197,0.02122197,0.02122422,3340.951,21800.87
181.36,-2.08932,-0.02087105,-3192.709,0.02083796,0,0,0.002087105,0.02087105,0.02087323,3192.709,20833.61
184.36,-2.03932,-0.02085511,-3058.841,0.01996424,0,0,0.002085511,0.02085511,0.02085728,3058.841,19960.07
187.36,-1.98932,-0.02103057,-2930.473,0.01912642,0,0,0.002103057,0.02103057,0.02103278,2930.473,19122.39
190.36,-1.93932,-0.02067965,-2805.114,0.01830823,0,0,0.002067965,0.02067965,0.02068178,2805.114,18304.44
193.36,-1.88932,-0.02069559,-2684.972,0.0175241,0,0,0.002069559,0.02069559,0.02069773,2684.972,17520.47
196.36,-1.83936,-0.02103057,-2570.65,0.01677795,0,0,0.002103057,0.02103057,0.02103278,2570.65,16774.42
199.36,-1.78936,-0.02087105,-2459.944,0.0160554,0,0,0.002087105,0.02087105,0.02087323,2459.944,16052.05
202.36,-1.73936,-0.02079129,-2353.478,0.01536052,0,0,0.002079129,0.02079129,0.02079345,2353.478,15357.33
205.36,-1.68928,-0.02106246,-2249.037,0.01467886,0,0,0.002106246,0.02106246,0.02106467,2249.037,14675.77
208.36,-1.63936,-0.02099864,-2148.547,0.01402299,0,0,0.002099864,0.02099864,0.02100085,2148.547,14020.05
211.36,-1.58932,-0.02111033,-2048.429,0.01336955,0,0,0.002111033,0.02111033,0.02111255,2048.429,13366.73
214.36,-1.53928,-0.02115816,-1952.346,0.01274244,0,0,0.002115816,0.02115816,0.0211604,1952.346,12739.75
217.36,-1.48932,-0.02146125,-1857.651,0.01212439,0,0,0.002146125,0.02146125,0.02146355,1857.651,12121.79
220.36,-1.43936,-0.02104651,-1763.948,0.01151282,0,0,0.002104651,0.02104651,0.02104873,1763.948,11510.4
223.36,-1.38932,-0.02088699,-1672.52,0.0109161,0,0,0.002088699,0.02088699,0.02088918,1672.521,10913.82
226.36,-1.33932,-0.02091888,-1582.148,0.01032626,0,0,0.002091888,0.02091888,0.02092107,1582.148,10324.1
229.36,-1.28932,-0.02122197,-1492.171,0.009738999,0,0,0.002122197,0.02122197,0.02122422,1492.171,9736.933
232.36,-1.23936,-0.02106246,-1405.953,0.009176283,0,0,0.002106246,0.02106246,0.02106467,1405.953,9174.35
235.36,-1.18936,-0.02128579,-1321.132,0.008622673,0,0,0.002128579,0.02128579,0.02128805,1321.132,8620.838
238.36,-1.13932,-0.02099864,-1237.23,0.008075069,0,0,0.002099864,0.02099864,0.02100085,1237.23,8073.373
241.36,-1.08928,-0.02111033,-1155.769,0.007543393,0,0,0.002111033,0.02111033,0.02111255,1155.769,7541.801
244.36,-1.03928,-0.02111033,-1077.33,0.007031444,0,0,0.002111033,0.02111033,0.02111255,1077.33,7029.96
247.36,-0.9893598,-0.02091888,-1001.321,0.006535358,0,0,0.002091888,0.02091888,0.02092107,1001.321,6533.991
250.36,-0.9393199,-0.02091888,-927.03,0.006050478,0,0,0.002091888,0.02091888,0.02092107,927.03,6049.212
253.36,-0.8893599,-0.02091888,-854.9804,0.005580229,0,0,0.002091888,0.02091888,0.02092107,854.9804,5579.062
256.36,-0.8392799,-0.02050415,-783.8697,0.005116109,0,0,0.002050415,0.02050415,0.02050625,783.8697,5115.06
259.36,-0.7893599,-0.02071153,-714.3529,0.004662391,0,0,0.002071153,0.02071153,0.02071368,714.3528,4661.425
262.36,-0.7392799,-0.02082318,-646.9261,0.004222314,0,0,0.002082318,0.02082318,0.02082535,646.9261,4221.435
265.36,-0.6893199,-0.02088699,-582.0882,0.003799135,0,0,0.002088699,0.02088699,0.02088918,582.0882,3798.341
268.36,-0.6392799,-0.02083912,-517.2701,0.003376084,0,0,0.002083912,0.02083912,0.0208413,517.2701,3375.38
271.36,-0.5893199,-0.02103057,-453.8374,0.002962075,0,0,0.002103057,0.02103057,0.02103278,453.8373,2961.453
273.968,-0.5458399,-0.02047226,-399.9741,0.002610525,0,0,0.002047226,0.02047226,0.02047435,399.9741,2609.99
275.97,-0.5790799,-0.02079129,-455.5095,0.002972989,1,1,0.002079129,0.02079129,0.02079345,455.5095,2972.371
278.97,-0.6291999,-0.02096675,-555.8881,0.003628134,1,1,0.002096675,0.02096675,0.02096895,555.8881,3627.373
281.97,-0.6791599,-0.02088699,-661.7866,0.004319305,1,1,0.002088699,0.02088699,0.02088918,661.7866,4318.402
284.97,-0.7291999,-0.0209827,-761.529,0.004970297,1,1,0.00209827,0.0209827,0.0209849,761.529,4969.254
287.97,-0.7791599,-0.02111033,-862.3102,0.005628069,1,1,0.002111033,0.02111033,0.02111255,862.3102,5626.881
290.97,-0.8291599,-0.0211741,-961.4086,0.006274858,1,1,0.00211741,0.0211741,0.02117634,961.4086,6273.529
293.97,-0.8791599,-0.0209827,-1061.841,0.006930352,1,1,0.00209827,0.0209827,0.0209849,1061.841,6928.898
296.97,-0.9291599,-0.02095081,-1167.928,0.007622757,1,1,0.002095081,0.02095081,0.020953,1167.928,7621.16
299.97,-0.9791599,-0.02069559,-1271.657,0.008299766,1,1,0.002069559,0.02069559,0.02069773,1271.657,8298.048
302.97,-1.02924,-0.02104651,-1374.556,0.008971364,1,1,0.002104651,0.02104651,0.02104873,1374.557,8969.476
305.97,-1.07916,-0.02082318,-1478.862,0.009652141,1,1,0.002082318,0.02082318,0.02082535,1478.862,9650.131
308.97,-1.12924,-0.02080724,-1584.369,0.01034076,1,1,0.002080724,0.02080724,0.0208094,1584.369,10338.6
311.97,-1.17916,-0.02114221,-1688.344,0.01101937,1,1,0.002114221,0.02114221,0.02114445,1688.344,11017.04
314.97,-1.2292,-0.02106246,-1792.894,0.01170174,1,1,0.002106246,0.02106246,0.02106467,1792.894,11699.28
317.97,-1.2792,-0.02083912,-1898.028,0.01238792,1,1,0.002083912,0.02083912,0.0208413,1898.028,12385.34
320.97,-1.32916,-0.02061583,-2002.598,0.01307042,1,1,0.002061583,0.02061583,0.02061796,2002.598,13067.73
323.97,-1.37916,-0.02072748,-2107.917,0.01375781,1,1,0.002072748,0.02072748,0.02072963,2107.917,13754.96
326.97,-1.42924,-0.02066366,-2215.591,0.01446057,1,1,0.002066366,0.02066366,0.0206658,2215.591,14457.59
329.97,-1.47916,-0.02056796,-2324.606,0.01517208,1,1,0.002056796,0.02056796,0.02057008,2324.606,15168.96
332.97,-1.5292,-0.02109434,-2432.445,0.01587592,1,1,0.002109434,0.02109434,0.02109657,2432.445,15872.57
335.97,-1.5792,-0.02071153,-2542.703,0.01659554,1,1,0.002071153,0.02071153,0.02071368,2542.703,16592.11
338.97,-1.62916,-0.02111033,-2654.924,0.01732798,1,1,0.002111033,0.02111033,0.02111255,2654.924,17324.32
341.97,-1.6792,-0.02079129,-2764.272,0.01804167,1,1,0.002079129,0.02079129,0.02079345,2764.272,18037.92
344.97,-1.72924,-0.02085511,-2876.505,0.01877418,1,1,0.002085511,0.02085511,0.02085728,2876.504,18770.26
347.97,-1.77916,-0.02106246,-2990.075,0.01951542,1,1,0.002106246,0.02106246,0.02106467,2990.075,19511.31
350.97,-1.8292,-0.0211741,-3103.437,0.0202553,1,1,0.00211741,0.0211741,0.02117634,3103.437,20251.02
353.97,-1.87916,-0.02099864,-3216.125,0.02099079,1,1,0.002099864,0.02099864,0.02100085,3216.125,20986.38
356.97,-1.9292,-0.02077535,-3334.909,0.02176606,1,1,0.002077535,0.02077535,0.02077751,3334.908,21761.54
359.97,-1.9792,-0.02120603,-3456.192,0.02255764,1,1,0.002120603,0.02120603,0.02120828,3456.192,22552.86
362.97,-2.02916,-0.02112627,-3575.412,0.02333576,1,1,0.002112627,0.02112627,0.0211285,3575.412,23330.83
365.97,-2.07924,-0.02082318,-3696.804,0.02412806,1,1,0.002082318,0.02082318,0.02082535,3696.804,24123.03
368.97,-2.1292,-0.02109434,-3819.056,0.02492596,1,1,0.002109434,0.02109434,0.02109657,3819.056,24920.7
371.97,-2.17916,-0.02082318,-3942.308,0.0257304,1,1,0.002082318,0.02082318,0.02082535,3942.308,25725.04
374.97,-2.2292,-0.02106246,-4069.645,0.02656149,1,1,0.002106246,0.02106246,0.02106467,4069.645,26555.89
377.97,-2.27916,-0.02091888,-4203.676,0.02743627,1,1,0.002091888,0.02091888,0.02092107,4203.676,27430.53
380.97,-2.3292,-0.02080724,-4335.503,0.02829667,1,1,0.002080724,0.02080724,0.0208094,4335.502,28290.78
383.97,-2.3792,-0.02064772,-4465.271,0.02914364,1,1,0.002064772,0.02064772,0.02064985,4465.271,29137.62
386.97,-2.42916,-0.02091888,-4595.864,0.02999598,1,1,0.002091888,0.02091888,0.02092107,4595.864,29989.7
389.97,-2.479239,-0.02071153,-4726.726,0.03085008,1,1,0.002071153,0.02071153,0.02071368,4726.726,30843.69
392.97,-2.5292,-0.02075937,-4852.328,0.03166986,1,1,0.002075937,0.02075937,0.02076152,4852.329,31663.28
395.97,-2.579199,-0.02064772,-4978.301,0.03249205,1,1,0.002064772,0.02064772,0.02064985,4978.301,32485.34
397.506,-2.57232,-0.02080724,-4959.41,0.03236875,1,1,0.002080724,0.02080724,0.0208094,4959.41,32362.01
400.506,-2.5214,-0.02074342,-4691.564,0.03062059,1,1,0.002074342,0.02074342,0.02074557,4691.564,30614.24
403.506,-2.47148,-0.02088699,-4454.2,0.02907137,1,1,0.002088699,0.02088699,0.02088918,4454.2,29065.3
406.506,-2.4214,-0.02096675,-4234.306,0.02763619,1,1,0.002096675,0.02096675,0.02096895,4234.306,27630.39
409.506,-2.37144,-0.02075937,-4028.256,0.02629136,1,1,0.002075937,0.02075937,0.02076152,4028.256,26285.9
412.506,-2.3214,-0.02123792,-3834.508,0.02502681,1,1,0.002123792,0.02123792,0.02124017,3834.508,25021.5
415.506,-2.27148,-0.02061583,-3655.107,0.02385591,1,1,0.002061583,0.02061583,0.02061796,3655.107,23850.99
418.506,-2.2214,-0.02088699,-3489.432,0.02277459,1,1,0.002088699,0.02088699,0.02088918,3489.432,22769.83
421.506,-2.17144,-0.02090294,-3336.564,0.02177686,1,1,0.002090294,0.02090294,0.02090512,3336.564,21772.31
424.506,-2.12144,-0.02072748,-3194.766,0.02085139,1,1,0.002072748,0.02072748,0.02072963,3194.767,20847.07
427.506,-2.07144,-0.02083912,-3060.612,0.0199758,1,1,0.002083912,0.02083912,0.0208413,3060.612,19971.64
430.506,-2.0214,-0.02066366,-2930.791,0.01912849,1,1,0.002066366,0.02066366,0.0206658,2930.791,19124.54
433.506,-1.97144,-0.02058391,-2805.494,0.01831071,1,1,0.002058391,0.02058391,0.02058602,2805.494,18306.94
436.506,-1.92144,-0.02090294,-2682.977,0.01751108,1,1,0.002090294,0.02090294,0.02090512,2682.977,17507.41
439.506,-1.87144,-0.02099864,-2567.457,0.01675711,1,1,0.002099864,0.02099864,0.02100085,2567.458,16753.59
442.506,-1.82144,-0.02109434,-2455.54,0.01602666,1,1,0.002109434,0.02109434,0.02109657,2455.54,16023.28
445.506,-1.77144,-0.02106246,-2345.916,0.01531117,1,1,0.002106246,0.02106246,0.02106467,2345.916,15307.94
448.506,-1.7214,-0.02096675,-2242.223,0.01463439,1,1,0.002096675,0.02096675,0.02096895,2242.223,14631.33
451.506,-1.6714,-0.02088699,-2139.333,0.01396286,1,1,0.002088699,0.02088699,0.02088918,2139.333,13959.94
454.506,-1.6214,-0.02085511,-2039.574,0.01331175,1,1,0.002085511,0.02085511,0.02085728,2039.573,13308.98
457.506,-1.57144,-0.02082318,-1942.937,0.01268104,1,1,0.002082318,0.02082318,0.02082535,1942.938,12678.39
460.506,-1.5214,-0.02085511,-1847.746,0.01205974,1,1,0.002085511,0.02085511,0.02085728,1847.746,12057.23
463.506,-1.47148,-0.02134956,-1753.344,0.01144361,1,1,0.002134956,0.02134956,0.02135184,1753.344,11441.17
466.506,-1.4214,-0.02101459,-1660.409,0.01083705,1,1,0.002101459,0.02101459,0.02101679,1660.409,10834.77
469.506,-1.37144,-0.02109434,-1570.566,0.01025066,1,1,0.002109434,0.02109434,0.02109657,1570.566,10248.5
472.506,-1.3214,-0.02082318,-1480.632,0.009663687,1,1,0.002082318,0.02082318,0.02082535,1480.631,9661.675
475.506,-1.2714,-0.02091888,-1391.639,0.009082855,1,1,0.002091888,0.02091888,0.02092107,1391.639,9080.954
478.506,-1.2214,-0.02096675,-1306.529,0.008527366,1,1,0.002096675,0.02096675,0.02096895,1306.529,8525.578
481.506,-1.17144,-0.02122197,-1224.025,0.007988881,1,1,0.002122197,0.02122197,0.02122422,1224.025,7987.186
484.506,-1.1214,-0.02091888,-1141.608,0.007450974,1,1,0.002091888,0.02091888,0.02092107,1141.608,7449.415
487.506,-1.07144,-0.02104651,-1063.079,0.006938433,1,1,0.002104651,0.02104651,0.02104873,1063.079,6936.973
490.506,-1.02144,-0.02061583,-987.0984,0.006442528,1,1,0.002061583,0.02061583,0.02061796,987.0984,6441.2
493.506,-0.9713999,-0.02099864,-912.5768,0.005956146,1,1,0.002099864,0.02099864,0.02100085,912.5768,5954.895
496.506,-0.9214399,-0.02066366,-839.904,0.00548183,1,1,0.002066366,0.02066366,0.0206658,839.9041,5480.697
499.506,-0.8713998,-0.02085511,-769.1907,0.005020303,1,1,0.002085511,0.02085511,0.02085728,769.1907,5019.256
502.506,-0.8214399,-0.02082318,-699.3191,0.004564269,1,1,0.002082318,0.02082318,0.02082535,699.3191,4563.319
505.506,-0.7713999,-0.02142932,-632.3164,0.00412696,1,1,0.002142932,0.02142932,0.02143162,632.3164,4126.076
508.506,-0.7213999,-0.02064772,-567.3934,0.003703226,1,1,0.002064772,0.02064772,0.02064985,567.3934,3702.461
511.506,-0.6713999,-0.02095081,-502.2461,0.003278026,1,1,0.002095081,0.02095081,0.020953,502.2461,3277.339
514.506,-0.6214399,-0.02066366,-438.8344,0.002864155,1,1,0.002066366,0.02066366,0.0206658,438.8344,2863.563
516.366,-0.5904399,-0.02016921,-399.9088,0.002610098,2,2,0.002016921,0.02016921,0.02017124,399.9088,2609.572
519.366,-0.6403999,-0.02091888,-490.8745,0.003203807,2,2,0.002091888,0.02091888,0.02092107,490.8745,3203.137
522.366,-0.6904398,-0.02120603,-593.1512,0.00387134,2,2,0.002120603,0.02120603,0.02120828,593.1512,3870.519
525.366,-0.7404399,-0.02104651,-695.8819,0.004541836,2,2,0.002104651,0.02104651,0.02104873,695.8819,4540.88
528.366,-0.7903999,-0.02090294,-795.5164,0.005192123,2,2,0.002090294,0.02090294,0.02090512,795.5164,5191.038
531.366,-0.8404399,-0.02096675,-895.4288,0.005844226,2,2,0.002096675,0.02096675,0.02096895,895.4288,5843
534.366,-0.8905199,-0.02091888,-996.4287,0.006503425,2,2,0.002091888,0.02091888,0.02092107,996.4287,6502.064
537.366,-0.9403998,-0.02090294,-1100.151,0.007180389,2,2,0.002090294,0.02090294,0.02090512,1100.151,7178.889
540.366,-0.9904798,-0.02058391,-1205.981,0.007871116,2,2,0.002058391,0.02058391,0.02058602,1205.981,7869.496
543.366,-1.04048,-0.02112627,-1309.789,0.00854864,2,2,0.002112627,0.02112627,0.0211285,1309.788,8546.834
546.366,-1.09044,-0.02072748,-1415.074,0.00923581,2,2,0.002072748,0.02072748,0.02072963,1415.074,9233.896
549.366,-1.14048,-0.02067965,-1521.51,0.009930494,2,2,0.002067965,0.02067965,0.02068178,1521.51,9928.44
552.366,-1.1904,-0.02045631,-1625.685,0.01061041,2,2,0.002045631,0.02045631,0.02045841,1625.685,10608.24
555.366,-1.24044,-0.02058391,-1731.358,0.01130011,2,2,0.002058391,0.02058391,0.02058602,1731.358,11297.79
558.366,-1.29048,-0.02059989,-1837.665,0.01199395,2,2,0.002059989,0.02059989,0.02060201,1837.665,11991.48
561.366,-1.34044,-0.02059989,-1942.661,0.01267923,2,2,0.002059989,0.02059989,0.02060201,1942.661,12676.62
564.366,-1.39048,-0.02040844,-2048.45,0.01336969,2,2,0.002040844,0.02040844,0.02041053,2048.45,13366.96
567.366,-1.44048,-0.02066366,-2155.038,0.01406536,2,2,0.002066366,0.02066366,0.0206658,2155.038,14062.45
570.366,-1.49044,-0.02096675,-2263.164,0.01477107,2,2,0.002096675,0.02096675,0.02096895,2263.164,14767.97
[...]
652.546,-2.36008,-0.0202968,-3893.59,0.02541242,2,2,0.00202968,0.0202968,0.02029886,3893.59,25407.27
655.546,-2.31012,-0.02045631,-3707.388,0.02419714,2,2,0.002045631,0.02045631,0.02045841,3707.388,24192.19
658.546,-2.26012,-0.02069559,-3537.972,0.0230914,2,2,0.002069559,0.02069559,0.02069773,3537.971,23086.62
661.546,-2.21004,-0.02088699,-3381.735,0.02207169,2,2,0.002088699,0.02088699,0.02088918,3381.735,22067.08
664.546,-2.16008,-0.02101459,-3238.526,0.021137,2,2,0.002101459,0.02101459,0.02101679,3238.526,21132.55
667.546,-2.11012,-0.02083912,-3101.153,0.0202404,2,2,0.002083912,0.02083912,0.0208413,3101.153,20236.18
670.546,-2.06008,-0.0210784,-2968.745,0.01937621,2,2,0.00210784,0.0210784,0.02108062,2968.745,19372.12
673.546,-2.01016,-0.02066366,-2842.861,0.0185546,2,2,0.002066366,0.02066366,0.0206658,2842.861,18550.76
676.546,-1.96008,-0.02085511,-2719.724,0.01775091,2,2,0.002085511,0.02085511,0.02085728,2719.724,17747.21
679.546,-1.91012,-0.02061583,-2600.558,0.01697315,2,2,0.002061583,0.02061583,0.02061796,2600.558,16969.65
682.546,-1.86012,-0.02080724,-2486.748,0.01623034,2,2,0.002080724,0.02080724,0.0208094,2486.748,16226.96
685.546,-1.81012,-0.02056796,-2375.758,0.01550594,2,2,0.002056796,0.02056796,0.02057008,2375.758,15502.75
688.546,-1.76008,-0.02072748,-2269.369,0.01481157,2,2,0.002072748,0.02072748,0.02072963,2269.369,14808.5
691.546,-1.71008,-0.02087105,-2164.784,0.01412897,2,2,0.002087105,0.02087105,0.02087323,2164.784,14126.02
694.546,-1.66012,-0.02071153,-2063.447,0.01346757,2,2,0.002071153,0.02071153,0.02071368,2063.447,13464.78
697.546,-1.61008,-0.02083912,-1965.38,0.01282751,2,2,0.002083912,0.02083912,0.0208413,1965.38,12824.84
700.546,-1.56012,-0.0209827,-1869.745,0.01220333,2,2,0.00209827,0.0209827,0.0209849,1869.745,12200.77
703.546,-1.51004,-0.02111033,-1774.131,0.01157928,2,2,0.002111033,0.02111033,0.02111255,1774.131,11576.84
706.546,-1.46012,-0.02088699,-1681.102,0.0109721,2,2,0.002088699,0.02088699,0.02088918,1681.102,10969.81
709.546,-1.41008,-0.02090294,-1589.772,0.01037601,2,2,0.002090294,0.02090294,0.02090512,1589.772,10373.85
712.546,-1.36008,-0.02074342,-1500.578,0.009793872,2,2,0.002074342,0.02074342,0.02074557,1500.578,9791.84
715.546,-1.31008,-0.02067965,-1410.603,0.009206633,2,2,0.002067965,0.02067965,0.02068178,1410.603,9204.729
718.546,-1.26008,-0.02095081,-1324.152,0.008642385,2,2,0.002095081,0.02095081,0.020953,1324.152,8640.574
721.546,-1.21008,-0.02099864,-1240.317,0.008095219,2,2,0.002099864,0.02099864,0.02100085,1240.317,8093.519
724.546,-1.16012,-0.02067965,-1158.114,0.007558702,2,2,0.002067965,0.02067965,0.02068178,1158.114,7557.139
727.546,-1.11008,-0.02080724,-1076.853,0.007028332,2,2,0.002080724,0.02080724,0.0208094,1076.853,7026.87
730.546,-1.06012,-0.02071153,-1000.43,0.006529542,2,2,0.002071153,0.02071153,0.02071368,1000.43,6528.19
733.546,-1.01004,-0.02069559,-924.9013,0.006036584,2,2,0.002069559,0.02069559,0.02069773,924.9013,6035.335
736.546,-0.9601199,-0.02088699,-852.718,0.005565463,2,2,0.002088699,0.02088699,0.02088918,852.718,5564.301
739.546,-0.9100799,-0.02085511,-779.1251,0.005085142,2,2,0.002085511,0.02085511,0.02085728,779.1251,5084.082
742.546,-0.8600399,-0.0204882,-709.9688,0.004633777,2,2,0.00204882,0.0204882,0.0204903,709.9688,4632.828
745.546,-0.8100799,-0.02079129,-641.8889,0.004189438,2,2,0.002079129,0.02079129,0.02079345,641.8889,4188.567
748.546,-0.7600799,-0.02090294,-576.608,0.003763367,2,2,0.002090294,0.02090294,0.02090512,576.608,3762.58
751.546,-0.7100799,-0.02069559,-511.0946,0.003335778,2,2,0.002069559,0.02069559,0.02069773,511.0946,3335.088
754.546,-0.6600799,-0.02072748,-448.011,0.002924048,2,2,0.002072748,0.02072748,0.02072963,448.011,2923.442
756.826,-0.6221199,-0.02024896,-399.9949,0.00261066,2,2,0.002024896,0.02024896,0.02025102,399.9949,2610.131
757.83,-0.6379999,-0.02085511,-417.0703,0.002722107,0,3,0.002085511,0.02085511,0.02085728,417.0703,2721.539
760.83,-0.6887599,-0.02042443,-522.0552,0.003407315,0,3,0.002042443,0.02042443,0.02042651,522.0552,3406.619
763.83,-0.7387198,-0.02079129,-628.1447,0.004099733,0,3,0.002079129,0.02079129,0.02079345,628.1447,4098.881
766.83,-0.7887199,-0.02037656,-727.9144,0.004750903,0,3,0.002037656,0.02037656,0.02037863,727.9144,4749.935
769.83,-0.8387199,-0.02099864,-827.7412,0.005402446,0,3,0.002099864,0.02099864,0.02100085,827.7411,5401.312
772.83,-0.8887998,-0.02087105,-927.7321,0.00605506,0,3,0.002087105,0.02087105,0.02087323,927.7321,6053.797
775.83,-0.9387199,-0.02085511,-1030.71,0.006727173,0,3,0.002085511,0.02085511,0.02085728,1030.71,6725.769
778.83,-0.9887999,-0.02066366,-1136.615,0.007418382,0,3,0.002066366,0.02066366,0.0206658,1136.615,7416.849
781.83,-1.03876,-0.02074342,-1241.053,0.008100023,0,3,0.002074342,0.02074342,0.02074557,1241.053,8098.343
784.83,-1.08876,-0.02083912,-1346.938,0.008791104,0,3,0.002083912,0.02083912,0.0208413,1346.938,8789.272
787.83,-1.13876,-0.02045631,-1453.556,0.00948697,0,3,0.002045631,0.02045631,0.02045841,1453.556,9485.029
790.83,-1.18868,-0.02080724,-1557.876,0.01016784,0,3,0.002080724,0.02080724,0.0208094,1557.876,10165.73
793.83,-1.23872,-0.02075937,-1665.427,0.0108698,0,3,0.002075937,0.02075937,0.02076152,1665.427,10867.54
796.83,-1.28876,-0.02066366,-1771.49,0.01156204,0,3,0.002066366,0.02066366,0.0206658,1771.49,11559.65
799.83,-1.33872,-0.02052013,-1877.071,0.01225114,0,3,0.002052013,0.02052013,0.02052223,1877.071,12248.63
802.83,-1.3888,-0.02088699,-1983.585,0.01294633,0,3,0.002088699,0.02088699,0.02088918,1983.585,12943.63
805.83,-1.43876,-0.02045631,-2089.854,0.01363992,0,3,0.002045631,0.02045631,0.02045841,2089.854,13637.13
808.83,-1.48872,-0.02061583,-2197.011,0.0143393,0,3,0.002061583,0.02061583,0.02061796,2197.011,14336.35
811.83,-1.53876,-0.02091888,-2306.354,0.01505296,0,3,0.002091888,0.02091888,0.02092107,2306.354,15049.81
814.83,-1.58876,-0.02075937,-2417.019,0.01577524,0,3,0.002075937,0.02075937,0.02076152,2417.019,15771.97
817.83,-1.63872,-0.02063178,-2529.297,0.01650805,0,3,0.002063178,0.02063178,0.0206339,2529.297,16504.64
820.83,-1.68876,-0.02047226,-2640.611,0.01723456,0,3,0.002047226,0.02047226,0.02047435,2640.611,17231.03
823.83,-1.73876,-0.02082318,-2754.388,0.01797716,0,3,0.002082318,0.02082318,0.02082535,2754.388,17973.41
826.83,-1.78876,-0.02056796,-2870.342,0.01873396,0,3,0.002056796,0.02056796,0.02057008,2870.342,18730.1
829.83,-1.83876,-0.02080724,-2983.959,0.01947551,0,3,0.002080724,0.02080724,0.0208094,2983.959,19471.45
832.83,-1.88872,-0.02064772,-3101.2,0.0202407,0,3,0.002064772,0.02064772,0.02064985,3101.2,20236.52
835.83,-1.9388,-0.02059989,-3222.513,0.02103248,0,3,0.002059989,0.02059989,0.02060201,3222.513,21028.15
838.83,-1.9888,-0.02067965,-3343.993,0.02182535,0,3,0.002067965,0.02067965,0.02068178,3343.993,21820.84
841.83,-2.03876,-0.02059989,-3465.637,0.02261929,0,3,0.002059989,0.02059989,0.02060201,3465.637,22614.63
844.83,-2.08876,-0.02066366,-3588.222,0.02341937,0,3,0.002066366,0.02066366,0.0206658,3588.222,23414.53
847.83,-2.13872,-0.02044037,-3712.13,0.02422808,0,3,0.002044037,0.02044037,0.02044246,3712.13,24223.13
850.83,-2.18872,-0.02016921,-3836.498,0.0250398,0,3,0.002016921,0.02016921,0.02017124,3836.498,25034.75
853.83,-2.2388,-0.02066366,-3970.048,0.02591145,0,3,0.002066366,0.02066366,0.0206658,3970.048,25906.09
856.83,-2.28872,-0.02056796,-4105.236,0.02679378,0,3,0.002056796,0.02056796,0.02057008,4105.236,26788.27
859.83,-2.3388,-0.02047226,-4239.082,0.02766736,0,3,0.002047226,0.02047226,0.02047435,4239.083,27661.7
862.83,-2.38876,-0.02052013,-4370.163,0.02852289,0,3,0.002052013,0.02052013,0.02052223,4370.163,28517.03
865.83,-2.4388,-0.02032869,-4502.212,0.02938474,0,3,0.002032869,0.02032869,0.02033075,4502.212,29378.77
868.83,-2.488719,-0.02045631,-4633.185,0.03023956,0,3,0.002045631,0.02045631,0.02045841,4633.185,30233.38
871.83,-2.53876,-0.02056796,-4764.705,0.03109796,0,3,0.002056796,0.02056796,0.02057008,4764.705,31091.56
874.83,-2.58872,-0.02047226,-4894.331,0.031944,0,3,0.002047226,0.02047226,0.02047435,4894.332,31937.46
877.83,-2.638799,-0.02045631,-5025.648,0.03280107,0,3,0.002045631,0.02045631,0.02045841,5025.648,32794.35
880.83,-2.68872,-0.02061583,-5152.104,0.03362641,0,3,0.002061583,0.02061583,0.02061796,5152.104,33619.48
883.83,-2.7388,-0.02099864,-5280.296,0.03446308,0,3,0.002099864,0.02099864,0.02100085,5280.296,34455.85
886.83,-2.78872,-0.02074342,-5404.979,0.03527686,0,3,0.002074342,0.02074342,0.02074557,5404.979,35269.54
889.83,-2.83872,-0.02064772,-5527.98,0.03607966,0,3,0.002064772,0.02064772,0.02064985,5527.98,36072.21
892.83,-2.888759,-0.02104651,-5650.25,0.03687768,0,3,0.002104651,0.02104651,0.02104873,5650.25,36869.91
895.83,-2.938799,-0.02099864,-5773.221,0.03768028,0,3,0.002099864,0.02099864,0.02100085,5773.221,37672.36
898.83,-2.988719,-0.02101459,-5892.676,0.03845992,0,3,0.002101459,0.02101459,0.02101679,5892.676,38451.84
901.83,-3.0388,-0.02064772,-6011.324,0.03923431,0,3,0.002064772,0.02064772,0.02064985,6011.324,39226.21
904.83,-3.08872,-0.02056796,-6130.48,0.04001201,0,3,0.002056796,0.02056796,0.02057008,6130.479,40003.78
907.83,-3.13876,-0.02083912,-6250.361,0.04079444,0,3,0.002083912,0.02083912,0.0208413,6250.361,40785.94
910.83,-3.188759,-0.02085511,-6367.301,0.04155768,0,3,0.002085511,0.02085511,0.02085728,6367.301,41549.01
913.83,-3.23872,-0.02080724,-6485.735,0.04233066,0,3,0.002080724,0.02080724,0.0208094,6485.735,42321.86
916.83,-3.288799,-0.02099864,-6603.924,0.04310205,0,3,0.002099864,0.02099864,0.02100085,6603.924,43093
919.83,-3.338759,-0.02055202,-6796.961,0.04436196,0,3,0.002055202,0.02055202,0.02055413,6796.961,44352.84
922.83,-3.38876,-0.02055202,-7037.889,0.04593443,0,3,0.002055202,0.02055202,0.02055413,7037.889,45924.99
925.83,-3.43876,-0.02058391,-7296.909,0.04762498,0,3,0.002058391,0.02058391,0.02058602,7296.909,47615.18
928.83,-3.4888,-0.02042443,-7549.112,0.04927104,0,3,0.002042443,0.02042443,0.02042651,7549.111,49260.98
931.83,-3.538759,-0.02079129,-7804.982,0.05094104,0,3,0.002079129,0.02079129,0.02079345,7804.982,50930.45
934.83,-3.588799,-0.02056796,-8060.263,0.05260719,0,3,0.002056796,0.02056796,0.02057008,8060.263,52596.37
937.83,-3.638719,-0.02069559,-8308.634,0.05422824,0,3,0.002069559,0.02069559,0.02069773,8308.634,54217.01
940.83,-3.688759,-0.02072748,-8557.298,0.0558512,0,3,0.002072748,0.02072748,0.02072963,8557.298,55839.63
943.83,-3.73876,-0.02042443,-8887.316,0.05800514,0,3,0.002042443,0.02042443,0.02042651,8887.315,57993.29
946.83,-3.788719,-0.02085511,-9274.895,0.06053477,0,3,0.002085511,0.02085511,0.02085728,9274.895,60522.14
949.83,-3.8388,-0.02050415,-9676.999,0.06315919,0,3,0.002050415,0.02050415,0.02050625,9676.999,63146.24
952.83,-3.88872,-0.02074342,-10091.5,0.06586453,0,3,0.002074342,0.02074342,0.02074557,10091.5,65850.87
955.83,-3.938719,-0.02072748,-10529.2,0.06872129,0,3,0.002072748,0.02072748,0.02072963,10529.2,68707.05
958.83,-3.988799,-0.02079129,-10988.11,0.07171647,0,3,0.002079129,0.02079129,0.02079345,10988.11,71701.55
961.83,-4.03872,-0.02032869,-11456.42,0.07477299,0,3,0.002032869,0.02032869,0.02033075,11456.42,74757.79
964.83,-4.088799,-0.02045631,-11946.62,0.07797237,0,3,0.002045631,0.02045631,0.02045841,11946.62,77956.43
967.83,-4.138719,-0.02064772,-12458.56,0.08131367,0,3,0.002064772,0.02064772,0.02064985,12458.56,81296.88
970.83,-4.188759,-0.0202968,-12986.38,0.08475864,0,3,0.00202968,0.0202968,0.02029886,12986.38,84741.44
973.83,-4.238759,-0.02036061,-13532.52,0.08832318,0,3,0.002036061,0.02036061,0.02036268,13532.52,88305.19
976.83,-4.28872,-0.02021704,-14100.44,0.0920298,0,3,0.002021704,0.02021704,0.02021908,14100.44,92011.2
979.83,-4.33872,-0.02044037,-14701.32,0.09595158,0,3,0.002044037,0.02044037,0.02044246,14701.32,95931.97
982.83,-4.388799,-0.02010539,-15317.86,0.09997562,0,3,0.002010539,0.02010539,0.02010741,15317.86,99955.52
985.83,-4.438719,-0.02053607,-15937.19,0.1040178,0,3,0.002053607,0.02053607,0.02053818,15937.19,103996.4
988.83,-4.488799,-0.02020109,-16565.4,0.108118,0,3,0.002020109,0.02020109,0.02020314,16565.4,108096.1
991.83,-4.538719,-0.02047226,-17195.91,0.1122331,0,3,0.002047226,0.02047226,0.02047435,17195.91,112210.2
994.83,-4.58876,-0.02024896,-17869.19,0.1166274,0,3,0.002024896,0.02024896,0.02025102,17869.19,116603.8
997.83,-4.638759,-0.02058391,-18581.74,0.121278,0,3,0.002058391,0.02058391,0.02058602,18581.74,121253.1
1000.83,-4.688719,-0.02066366,-19285,0.1258681,0,3,0.002066366,0.02066366,0.0206658,19285,125842
1003.83,-4.738719,-0.02047226,-20002.68,0.1305521,0,3,0.002047226,0.02047226,0.02047435,20002.68,130525.4
1006.83,-4.788759,-0.02066366,-20725.03,0.1352668,0,3,0.002066366,0.02066366,0.0206658,20725.03,135238.8
1009.83,-4.83872,-0.02034467,-21446.18,0.1399735,0,3,0.002034467,0.02034467,0.02034674,21446.18,139945
1012.83,-4.888799,-0.02055202,-22176.26,0.1447385,0,3,0.002055202,0.02055202,0.02055413,22176.26,144708.8
1015.83,-4.938759,-0.02101459,-22916.25,0.1495682,0,3,0.002101459,0.02101459,0.02101679,22916.25,149536.8
1018.83,-4.988759,-0.02072748,-23651.5,0.154367,0,3,0.002072748,0.02072748,0.02072963,23651.5,154335
1021.83,-5.038799,-0.02093486,-24396.55,0.1592298,0,3,0.002093486,0.02093486,0.02093706,24396.55,159196.4
1024.83,-5.088759,-0.02056796,-25144.31,0.1641102,0,3,0.002056796,0.02056796,0.02057008,25144.31,164076.4
1027.804,-5.138319,-0.02075937,-25895.04,0.16901,0,3,0.002075937,0.02075937,0.02076152,25895.04,168974.9
1030.788,-5.188039,-0.02080724,-26644.65,0.1739025,0,3,0.002080724,0.02080724,0.0208094,26644.65,173866.3
1033.738,-5.237199,-0.02096675,-27395.56,0.1788035,0,3,0.002096675,0.02096675,0.02096895,27395.55,178766
1036.728,-5.287039,-0.02050415,-28146.16,0.1837025,0,3,0.002050415,0.02050415,0.02050625,28146.16,183664.8
1039.698,-5.336599,-0.02047226,-28897.1,0.1886037,0,3,0.002047226,0.02047226,0.02047435,28897.1,188565.1
1042.698,-5.386519,-0.02052013,-29640.76,0.1934573,0,3,0.002052013,0.02052013,0.02052223,29640.76,193417.6
1045.63,-5.435439,-0.02064772,-30391.63,0.1983581,0,3,0.002064772,0.02064772,0.02064985,30391.63,198317.1
1048.616,-5.485239,-0.02021704,-31139.29,0.2032378,0,3,0.002021704,0.02021704,0.02021908,31139.29,203196.8
1051.614,-5.535159,-0.02080724,-31887.36,0.2081203,0,3,0.002080724,0.02080724,0.0208094,31887.37,208077
1054.598,-5.584879,-0.02085511,-32637.45,0.2130159,0,3,0.002085511,0.02085511,0.02085728,32637.45,212971.5
1057.534,-5.633839,-0.02063178,-33388.12,0.2179154,0,3,0.002063178,0.02063178,0.0206339,33388.12,217870.4
1060.518,-5.683519,-0.02012134,-34138.07,0.2228101,0,3,0.002012134,0.02012134,0.02012336,34138.07,222765.3
1063.434,-5.732199,-0.02047226,-34888.75,0.2277096,0,3,0.002047226,0.02047226,0.02047435,34888.75,227663
1066.342,-5.780559,-0.02053607,-35639.95,0.2326125,0,3,0.002053607,0.02053607,0.02053818,35639.95,232564.7
1069.218,-5.828599,-0.02040844,-36391.05,0.2375147,0,3,0.002040844,0.02040844,0.02041053,36391.05,237466.2
1072.128,-5.876999,-0.02064772,-37141.66,0.2424137,0,3,0.002064772,0.02064772,0.02064985,37141.66,242363.7
1075.022,-5.925239,-0.02042443,-37892.55,0.2473146,0,3,0.002042443,0.02042443,0.02042651,37892.55,247264
1077.872,-5.972839,-0.02047226,-38643.19,0.2522138,0,3,0.002047226,0.02047226,0.02047435,38643.19,252162.2
1080.724,-6.020279,-0.02042443,-39393.45,0.2571106,0,3,0.002042443,0.02042443,0.02042651,39393.45,257058
1083.584,-6.068039,-0.02023298,-40144.14,0.2620101,0,3,0.002023298,0.02023298,0.02023503,40144.14,261957.1
1086.426,-6.115319,-0.02050415,-40894.93,0.2669103,0,3,0.002050415,0.02050415,0.02050625,40894.93,266855.6
1089.268,-6.162759,-0.02074342,-41645.96,0.2718121,0,3,0.002074342,0.02074342,0.02074557,41645.96,271755.7
1092.132,-6.210439,-0.02072748,-42396.22,0.2767088,0,3,0.002072748,0.02072748,0.02072963,42396.22,276651.5
1094.98,-6.257959,-0.02067965,-43147.15,0.28161,0,3,0.002067965,0.02067965,0.02068178,43147.15,281551.7
1097.866,-6.306039,-0.02075937,-43898.28,0.2865124,0,3,0.002075937,0.02075937,0.02076152,43898.29,286452.9
1100.728,-6.353719,-0.02036061,-44649,0.2914121,0,3,0.002036061,0.02036061,0.02036268,44649,291352.8
1103.626,-6.401999,-0.02045631,-45399.8,0.2963124,0,3,0.002045631,0.02045631,0.02045841,45399.8,296251.8
1106.564,-6.450919,-0.02087105,-46150.57,0.3012124,0,3,0.002087105,0.02087105,0.02087323,46150.57,301149.6
1109.502,-6.499919,-0.0203925,-46901.37,0.3061128,0,3,0.00203925,0.0203925,0.02039458,46901.37,306050.3
1112.498,-6.549839,-0.02024896,-47648.1,0.3109865,0,3,0.002024896,0.02024896,0.02025102,47648.1,310923.5
1115.474,-6.599479,-0.02032869,-48397.33,0.3158765,0,3,0.002032869,0.02032869,0.02033075,48397.33,315812.3
1118.366,-6.647679,-0.02023298,-49147.9,0.3207752,0,3,0.002023298,0.02023298,0.02023503,49147.9,320710.3
1121.322,-6.696959,-0.02080724,-49898.92,0.3256769,0,3,0.002080724,0.02080724,0.0208094,49898.92,325609.2
1124.276,-6.746159,-0.02052013,-50649.61,0.3305765,0,3,0.002052013,0.02052013,0.02052223,50649.61,330508.7
1127.248,-6.795719,-0.02024896,-51400.29,0.335476,0,3,0.002024896,0.02024896,0.02025102,51400.29,335408.1
1130.168,-6.844399,-0.02066366,-52151.22,0.3403771,0,3,0.002066366,0.02066366,0.0206658,52151.22,340306.8
1133.152,-6.894119,-0.02021704,-52902.13,0.3452781,0,3,0.002021704,0.02021704,0.02021908,52902.13,345208.3
1136.112,-6.943479,-0.02024896,-53651.35,0.3501681,0,3,0.002024896,0.02024896,0.02025102,53651.35,350097.2
1139.06,-6.992559,-0.02040844,-54401.73,0.3550656,0,3,0.002040844,0.02040844,0.02041053,54401.73,354993.1
1141.986,-7.041359,-0.02040844,-55152.6,0.3599663,0,3,0.002040844,0.02040844,0.02041053,55152.59,359892.8
1144.966,-7.090999,-0.02031274,-55902.92,0.3648635,0,3,0.002031274,0.02031274,0.02031481,55902.92,364789.4
1147.928,-7.140359,-0.0202968,-56653.52,0.3697625,0,3,0.00202968,0.0202968,0.02029886,56653.52,369687.4
1150.922,-7.190279,-0.02044037,-57392.75,0.3745872,0,3,0.002044037,0.02044037,0.02044246,57392.75,374510.6
1153.89,-7.239719,-0.02028085,-58143.56,0.3794875,0,3,0.002028085,0.02028085,0.02028291,58143.55,379410.5
1156.89,-7.289759,-0.02032869,-58884.32,0.3843223,0,3,0.002032869,0.02032869,0.02033075,58884.32,384244.1
1159.872,-7.339479,-0.02045631,-59633.42,0.3892114,0,3,0.002045631,0.02045631,0.02045841,59633.42,389131.8
1162.872,-7.389399,-0.02061583,-60349.93,0.3938879,0,3,0.002061583,0.02061583,0.02061796,60349.93,393806.7
1165.872,-7.439479,-0.02074342,-61087.73,0.3987034,0,3,0.002074342,0.02074342,0.02074557,61087.73,398620.7
1168.872,-7.489439,-0.0203925,-61809.03,0.4034111,0,3,0.00203925,0.0203925,0.02039458,61809.03,403328.8
1171.872,-7.539479,-0.02082318,-62536.98,0.4081622,0,3,0.002082318,0.02082318,0.02082535,62536.98,408077.2
1174.872,-7.589439,-0.02028085,-63246.94,0.4127959,0,3,0.002028085,0.02028085,0.02028291,63246.94,412712.2
1177.872,-7.639439,-0.02026491,-63959.37,0.4174458,0,3,0.002026491,0.02026491,0.02026696,63959.37,417361.2
1180.872,-7.689439,-0.02023298,-64669.08,0.4220778,0,3,0.002023298,0.02023298,0.02023503,64669.08,421992.4
1183.872,-7.739519,-0.02010539,-65373.49,0.4266753,0,3,0.002010539,0.02010539,0.02010741,65373.49,426589.6
1186.872,-7.789399,-0.02020109,-66058.64,0.4311471,0,3,0.002020109,0.02020109,0.02020314,66058.63,431060
1189.872,-7.839519,-0.01988206,-66769.7,0.435788,0,3,0.001988206,0.01988206,0.01988404,66769.7,435701.4
1192.872,-7.889479,-0.02034467,-67453.29,0.4402497,0,3,0.002034467,0.02034467,0.02034674,67453.3,440160.1
1195.872,-7.939478,-0.02044037,-68140.81,0.4447369,0,3,0.002044037,0.02044037,0.02044246,68140.81,444646
1198.872,-7.989398,-0.02069559,-68817.83,0.4491556,0,3,0.002069559,0.02069559,0.02069773,68817.83,449062.7
1201.872,-8.039479,-0.02026491,-69502.19,0.4536223,0,3,0.002026491,0.02026491,0.02026696,69502.19,453530.3
1204.872,-8.089439,-0.02056796,-70172.32,0.457996,0,3,0.002056796,0.02056796,0.02057008,70172.31,457901.8
1207.872,-8.139479,-0.02023298,-70848.85,0.4624116,0,3,0.002023298,0.02023298,0.02023503,70848.85,462318
1210.716,-8.186799,-0.0204882,-71482.12,0.4665448,0,3,0.00204882,0.0204882,0.0204903,71482.13,466449.2