File: ElectricPoleSupport/ExptData/Raw/Heel_C1_cycle.raw.csv
"Test Type","Compression"
"Method Name:","C:\INSTRON\USER\TEMPLATE\Andyscomp.mtB"
"Name:","Transnet Compression Tests"
"Operator ID:","AndyS"
"Company:","IRL"
"Lab name:","Rm 3.09"
"Test date:","26/08/08"
"Temperature:","20.5"
"Humidity:","57.5"
"Note 1:","Plastic Telegraph Pole Breast and Heel Plate Tests"
"Note 2:",""
"Note 3:",""
"Geometry:","Rectangular"
"Specimen",1
"Specimen name:","C1"
"Width:",341.000000,"mm"
"Thickness:",886.000000,"mm"
"Anvil height:",90.000000,"mm"
"Diameter:",50.000000,"mm"
"Inner diameter:",0.500000,"mm"
"Outer diameter:",1.000000,"mm"
"Wall thickness:",0.500000,"mm"
"Area:",302126.000000,"mm*mm"
"Linear density:",1.000000,"den"
"Sled weight:",9.806650,"N"
"Loading span:",0.000000,"mm"
"Support span:",1.000000,"mm"
"Span ratio:","2"
"Fixture type:","3-point"
"Comment:","Transnet Large Rectangular Sample"
"Extensometer",-10.000000,"**mm"
"Included"
"Time sec","Extension mm","Strain 1 %","Load N","Comp. stress MPa","Cycle Count ","Total Cycle Count ","Comp. extension mm","Comp. strain %","True strain %","Comp. load N","True stress Pa"
0,-3.999999e-005,-0.005637668,-10.63455,3.519907e-005,0,0,0.0005637669,0.005637668,0.005637827,10.63455,35.19709
1,-0.01632,-0.006036423,-17.69626,5.857245e-005,0,0,0.0006036423,0.006036423,0.006036605,17.69626,58.56892
2,-0.03331999,-0.006052405,-34.84541,0.000115334,0,0,0.0006052405,0.006052405,0.006052588,34.84541,115.3271
3,-0.04999999,-0.005813129,-51.97249,0.0001720226,0,0,0.0005813129,0.005813129,0.005813298,51.97248,172.0126
4,-0.06671999,-0.005621687,-69.57173,0.0002302739,0,0,0.0005621687,0.005621687,0.005621845,69.57173,230.2609
5,-0.08331998,-0.005924776,-87.68724,0.000290234,0,0,0.0005924776,0.005924776,0.005924952,87.68724,290.2168
6,-0.10008,-0.006036423,-105.2786,0.0003484594,0,0,0.0006036423,0.006036423,0.006036605,105.2786,348.4384
7,-0.11668,-0.006100237,-122.2113,0.0004045043,0,0,0.0006100237,0.006100237,0.006100423,122.2113,404.4797
8,-0.13336,-0.005781204,-140.0466,0.000463537,0,0,0.0005781204,0.005781204,0.005781371,140.0466,463.5102
9,-0.15,-0.005876906,-157.3353,0.0005207605,0,0,0.0005876906,0.005876906,0.005877079,157.3353,520.7299
10,-0.16668,-0.005876906,-176.0695,0.0005827683,0,0,0.0005876906,0.005876906,0.005877079,176.0695,582.734
11,-0.18332,-0.005541965,-194.1609,0.0006426487,0,0,0.0005541965,0.005541965,0.005542119,194.1609,642.6131
12,-0.2,-0.006084293,-213.4055,0.0007063461,0,0,0.0006084293,0.006084293,0.006084478,213.4055,706.3032
13,-0.21668,-0.005876906,-232.8641,0.0007707517,0,0,0.0005876906,0.005876906,0.005877079,232.8641,770.7064
14,-0.2334,-0.005781204,-252.5399,0.0008358762,0,0,0.0005781204,0.005781204,0.005781371,252.5399,835.8278
15,-0.2500399,-0.005605742,-271.4868,0.000898588,0,0,0.0005605742,0.005605742,0.0056059,271.4868,898.5376
16,-0.26672,-0.00594072,-291.5903,0.0009651279,0,0,0.000594072,0.00594072,0.005940897,291.5902,965.0706
17,-0.28336,-0.00598859,-305.0753,0.001009762,0,0,0.000598859,0.00598859,0.00598877,305.0753,1009.701
18,-0.30004,-0.005446225,-307.1782,0.001016722,0,0,0.0005446225,0.005446225,0.005446374,307.1782,1016.667
19,-0.3166799,-0.005621687,-310.3336,0.001027166,0,0,0.0005621687,0.005621687,0.005621845,310.3336,1027.108
20,-0.33336,-0.006275699,-310.449,0.001027548,0,0,0.0006275699,0.006275699,0.006275895,310.449,1027.484
21,-0.3499599,-0.006179996,-310.5492,0.00102788,0,0,0.0006179996,0.006179996,0.006180187,310.5492,1027.816
22,-0.3667199,-0.005605742,-310.6582,0.001028241,0,0,0.0005605742,0.005605742,0.0056059,310.6582,1028.183
23,-0.3833999,-0.006164052,-310.6553,0.001028231,0,0,0.0006164052,0.006164052,0.006164242,310.6553,1028.167
24,-0.40008,-0.005685501,-311.1472,0.001029859,0,0,0.0005685501,0.005685501,0.005685662,311.1472,1029.801
25,-0.4166799,-0.005956665,-311.8019,0.001032026,0,0,0.0005956665,0.005956665,0.005956842,311.8018,1031.964
26,-0.43336,-0.005845018,-311.6525,0.001031532,0,0,0.0005845018,0.005845018,0.005845189,311.6526,1031.471
27,-0.4499999,-0.00598859,-311.8645,0.001032233,0,0,0.000598859,0.00598859,0.00598877,311.8645,1032.171
28,-0.4667199,-0.006004535,-312.0272,0.001032772,0,0,0.0006004535,0.006004535,0.006004715,312.0272,1032.71
29,-0.4833199,-0.006211884,-312.0182,0.001032742,0,0,0.0006211884,0.006211884,0.006212077,312.0182,1032.678
30,-0.5000799,-0.005860962,-312.2882,0.001033636,0,0,0.0005860962,0.005860962,0.005861134,312.2882,1033.575
31,-0.5167199,-0.00598859,-312.4413,0.001034142,0,0,0.000598859,0.00598859,0.00598877,312.4413,1034.08
32,-0.5333999,-0.005876906,-312.4549,0.001034188,0,0,0.0005876906,0.005876906,0.005877079,312.4549,1034.127
33,-0.5500399,-0.006307624,-312.2238,0.001033422,0,0,0.0006307624,0.006307624,0.006307823,312.2238,1033.357
34,-0.5667199,-0.005924776,-313.6327,0.001038086,0,0,0.0005924776,0.005924776,0.005924952,313.6327,1038.024
35,-0.5833599,-0.006546862,-316.8439,0.001048715,0,0,0.0006546862,0.006546862,0.006547077,316.8439,1048.646
36,-0.6000399,-0.006275699,-329.6526,0.00109111,0,0,0.0006275699,0.006275699,0.006275895,329.6526,1091.041
37,-0.6166399,-0.005908832,-351.6165,0.001163807,0,0,0.0005908832,0.005908832,0.005909006,351.6165,1163.739
38,-0.6333999,-0.006275699,-373.5557,0.001236424,0,0,0.0006275699,0.006275699,0.006275895,373.5557,1236.346
39,-0.6500399,-0.005956665,-396.9559,0.001313875,0,0,0.0005956665,0.005956665,0.005956842,396.9559,1313.797
40,-0.6667199,-0.006307624,-420.1843,0.001390758,0,0,0.0006307624,0.006307624,0.006307823,420.1843,1390.671
41,-0.6833199,-0.006068349,-444.3909,0.001470879,0,0,0.0006068349,0.006068349,0.006068533,444.3909,1470.79
42,-0.7000399,-0.006084293,-468.8447,0.001551819,0,0,0.0006084293,0.006084293,0.006084478,468.8447,1551.724
43,-0.7167199,-0.006483085,-493.5783,0.001633684,0,0,0.0006483085,0.006483085,0.006483296,493.5783,1633.578
44,-0.7333999,-0.006307624,-518.593,0.001716479,0,0,0.0006307624,0.006307624,0.006307823,518.593,1716.371
45,-0.7499999,-0.006148107,-544.3297,0.001801665,0,0,0.0006148107,0.006148107,0.006148296,544.3297,1801.554
46,-0.7667199,-0.006052405,-570.2948,0.001887606,0,0,0.0006052405,0.006052405,0.006052588,570.2948,1887.492
47,-0.7833999,-0.006355457,-596.2066,0.001973371,0,0,0.0006355457,0.006355457,0.006355659,596.2066,1973.245
48,-0.8000399,-0.006148107,-622.4516,0.002060239,0,0,0.0006148107,0.006148107,0.006148296,622.4517,2060.112
49,-0.8167198,-0.006148107,-652.2075,0.002158727,0,0,0.0006148107,0.006148107,0.006148296,652.2075,2158.594
50,-0.8333998,-0.006387345,-680.0384,0.002250844,0,0,0.0006387345,0.006387345,0.006387549,680.0385,2250.7
51,-0.8499999,-0.006084293,-708.6209,0.002345448,0,0,0.0006084293,0.006084293,0.006084478,708.6209,2345.306
52,-0.8666798,-0.006004535,-738.2168,0.002443407,0,0,0.0006004535,0.006004535,0.006004715,738.2168,2443.26
53,-0.8833199,-0.006435215,-769.0944,0.002545608,0,0,0.0006435215,0.006435215,0.006435423,769.0944,2545.444
54,-0.9000399,-0.006179996,-799.724,0.002646988,0,0,0.0006179996,0.006179996,0.006180187,799.724,2646.825
55,-0.9167599,-0.006068349,-831.4353,0.002751949,0,0,0.0006068349,0.006068349,0.006068533,831.4354,2751.782
56,-0.9333999,-0.006211884,-862.2155,0.002853827,0,0,0.0006211884,0.006211884,0.006212077,862.2155,2853.65
57,-0.9500398,-0.006371401,-892.3364,0.002953524,0,0,0.0006371401,0.006371401,0.006371604,892.3364,2953.336
58,-0.9666399,-0.006164052,-922.9154,0.003054737,0,0,0.0006164052,0.006164052,0.006164242,922.9154,3054.549
59,-0.9833198,-0.006068349,-953.9855,0.003157575,0,0,0.0006068349,0.006068349,0.006068533,953.9855,3157.383
60,-1.00004,-0.005908832,-985.6855,0.003262498,0,0,0.0005908832,0.005908832,0.005909006,985.6855,3262.305
61,-1.01672,-0.006179996,-1017.326,0.003367223,0,0,0.0006179996,0.006179996,0.006180187,1017.326,3367.015
62,-1.0334,-0.006164052,-1048.469,0.003470304,0,0,0.0006164052,0.006164052,0.006164242,1048.469,3470.09
63,-1.05004,-0.006227866,-1079.959,0.003574533,0,0,0.0006227866,0.006227866,0.00622806,1079.959,3574.31
64,-1.06672,-0.006371401,-1112.656,0.003682755,0,0,0.0006371401,0.006371401,0.006371604,1112.656,3682.521
65,-1.0834,-0.005892888,-1144.345,0.003787642,0,0,0.0005892888,0.005892888,0.005893061,1144.345,3787.418
66,-1.10008,-0.006148107,-1179.341,0.003903475,0,0,0.0006148107,0.006148107,0.006148296,1179.341,3903.235
67,-1.11672,-0.00619594,-1219.974,0.004037966,0,0,0.000619594,0.00619594,0.006196132,1219.974,4037.716
68,-1.13336,-0.005956665,-1260.682,0.004172704,0,0,0.0005956665,0.005956665,0.005956842,1260.682,4172.456
69,-1.15,-0.006100237,-1303.223,0.004313508,0,0,0.0006100237,0.006100237,0.006100423,1303.223,4313.245
70,-1.16668,-0.006084293,-1346.095,0.00445541,0,0,0.0006084293,0.006084293,0.006084478,1346.095,4455.139
71,-1.1834,-0.006068349,-1389.041,0.004597554,0,0,0.0006068349,0.006068349,0.006068533,1389.041,4597.275
72,-1.20008,-0.00645116,-1434.075,0.004746612,0,0,0.000645116,0.00645116,0.006451368,1434.075,4746.306
73,-1.21672,-0.006227866,-1482.38,0.004906495,0,0,0.0006227866,0.006227866,0.00622806,1482.38,4906.189
74,-1.2334,-0.006403327,-1530.933,0.005067201,0,0,0.0006403327,0.006403327,0.006403532,1530.933,5066.877
75,-1.25,-0.005972646,-1579.841,0.005229079,0,0,0.0005972646,0.005972646,0.005972824,1579.841,5228.767
76,-1.26664,-0.006036423,-1630.465,0.005396639,0,0,0.0006036423,0.006036423,0.006036605,1630.465,5396.314
77,-1.28336,-0.00624381,-1681.585,0.005565841,0,0,0.000624381,0.00624381,0.006244005,1681.585,5565.493
78,-1.3,-0.006371401,-1733.739,0.005738465,0,0,0.0006371401,0.006371401,0.006371604,1733.739,5738.099
79,-1.31672,-0.006403327,-1787.644,0.005916883,0,0,0.0006403327,0.006403327,0.006403532,1787.644,5916.504
80,-1.3334,-0.006355457,-1842.62,0.006098846,0,0,0.0006355457,0.006355457,0.006355659,1842.62,6098.458
81,-1.35004,-0.006323569,-1897.684,0.006281102,0,0,0.0006323569,0.006323569,0.006323768,1897.684,6280.705
82,-1.36668,-0.006211884,-1954.121,0.0064679,0,0,0.0006211884,0.006211884,0.006212077,1954.121,6467.498
83,-1.38336,-0.006259754,-2011.355,0.006657338,0,0,0.0006259754,0.006259754,0.00625995,2011.355,6656.921
84,-1.39996,-0.006100237,-2069.125,0.006848551,0,0,0.0006100237,0.006100237,0.006100423,2069.125,6848.133
85,-1.41672,-0.006467104,-2126.775,0.007039365,0,0,0.0006467104,0.006467104,0.006467313,2126.775,7038.91
86,-1.43332,-0.005781204,-2186.649,0.00723754,0,0,0.0005781204,0.005781204,0.005781371,2186.649,7237.122
87,-1.45008,-0.00649903,-2246.551,0.007435807,0,0,0.000649903,0.00649903,0.006499241,2246.551,7435.324
88,-1.46672,-0.00645116,-2305.273,0.007630173,0,0,0.000645116,0.00645116,0.006451368,2305.273,7629.68
89,-1.4834,-0.006578788,-2365.797,0.007830497,0,0,0.0006578788,0.006578788,0.006579005,2365.797,7829.982
90,-1.5,-0.006275699,-2425.75,0.008028935,0,0,0.0006275699,0.006275699,0.006275895,2425.75,8028.431
91,-1.51672,-0.006259754,-2486.315,0.008229396,0,0,0.0006259754,0.006259754,0.00625995,2486.315,8228.881
92,-1.53332,-0.006642565,-2547.848,0.008433064,0,0,0.0006642565,0.006642565,0.006642786,2547.848,8432.503
93,-1.55004,-0.006291643,-2610.608,0.008640793,0,0,0.0006291643,0.006291643,0.006291841,2610.608,8640.249
94,-1.56668,-0.006419271,-2674.089,0.008850907,0,0,0.0006419271,0.006419271,0.006419477,2674.089,8850.339
95,-1.58336,-0.006259754,-2737.433,0.009060568,0,0,0.0006259754,0.006259754,0.00625995,2737.433,9060.001
96,-1.60004,-0.006259754,-2800.593,0.009269617,0,0,0.0006259754,0.006259754,0.00625995,2800.593,9269.038
97,-1.61676,-0.006323569,-2862.897,0.009475836,0,0,0.0006323569,0.006323569,0.006323768,2862.896,9475.237
98,-1.6334,-0.006435215,-2924.159,0.009678606,0,0,0.0006435215,0.006435215,0.006435423,2924.159,9677.983
99,-1.65004,-0.006578788,-2983.574,0.009875264,0,0,0.0006578788,0.006578788,0.006579005,2983.574,9874.614
100,-1.66664,-0.006036423,-3045.812,0.01008126,0,0,0.0006036423,0.006036423,0.006036605,3045.812,10080.65
101,-1.6834,-0.006610677,-3111.682,0.01029928,0,0,0.0006610677,0.006610677,0.006610895,3111.682,10298.6
102,-1.7,-0.006483085,-3174.79,0.01050817,0,0,0.0006483085,0.006483085,0.006483296,3174.79,10507.49
103,-1.71672,-0.006626621,-3240.268,0.01072489,0,0,0.0006626621,0.006626621,0.00662684,3240.268,10724.18
104,-1.7334,-0.006514974,-3304.296,0.01093682,0,0,0.0006514974,0.006514974,0.006515186,3304.296,10936.1
105,-1.75008,-0.006594732,-3370.61,0.01115631,0,0,0.0006594732,0.006594732,0.00659495,3370.61,11155.57
106,-1.76672,-0.006259754,-3436.438,0.01137419,0,0,0.0006259754,0.006259754,0.00625995,3436.438,11373.48
107,-1.7834,-0.006323569,-3501.328,0.01158897,0,0,0.0006323569,0.006323569,0.006323768,3501.328,11588.23
108,-1.8,-0.006562807,-3566.641,0.01180515,0,0,0.0006562807,0.006562807,0.006563022,3566.641,11804.37
109,-1.81672,-0.006291643,-3633.776,0.01202735,0,0,0.0006291643,0.006291643,0.006291841,3633.776,12026.6
110,-1.83336,-0.006323569,-3700.141,0.01224701,0,0,0.0006323569,0.006323569,0.006323768,3700.141,12246.24
111,-1.85004,-0.006259754,-3767.346,0.01246945,0,0,0.0006259754,0.006259754,0.00625995,3767.346,12468.67
112,-1.86672,-0.00624381,-3834.748,0.01269255,0,0,0.000624381,0.00624381,0.006244005,3834.748,12691.75
113,-1.8834,-0.006754249,-3903.522,0.01292018,0,0,0.0006754249,0.006754249,0.006754477,3903.522,12919.31
114,-1.9,-0.006674491,-3972.013,0.01314688,0,0,0.0006674491,0.006674491,0.006674714,3972.013,13146
115,-1.91672,-0.006435215,-4039.981,0.01337184,0,0,0.0006435215,0.006435215,0.006435423,4039.981,13370.98
116,-1.93332,-0.006578788,-4108.126,0.01359739,0,0,0.0006578788,0.006578788,0.006579005,4108.126,13596.5
117,-1.95004,-0.006435215,-4176.928,0.01382512,0,0,0.0006435215,0.006435215,0.006435423,4176.929,13824.23
118,-1.96668,-0.006387345,-4243.468,0.01404536,0,0,0.0006387345,0.006387345,0.006387549,4243.468,14044.46
119,-1.98336,-0.006562807,-4310.075,0.01426582,0,0,0.0006562807,0.006562807,0.006563022,4310.075,14264.88
120,-2.00004,-0.006849952,-4377.848,0.01449014,0,0,0.0006849952,0.006849952,0.006850187,4377.848,14489.15
121,-2.01672,-0.00619594,-4444.157,0.01470962,0,0,0.000619594,0.00619594,0.006196132,4444.157,14708.7
122,-2.03336,-0.006578788,-4511.652,0.01493301,0,0,0.0006578788,0.006578788,0.006579005,4511.652,14932.03
123,-2.05004,-0.006658547,-4579.21,0.01515662,0,0,0.0006658547,0.006658547,0.006658768,4579.21,15155.61
124,-2.06668,-0.006483085,-4647.207,0.01538168,0,0,0.0006483085,0.006483085,0.006483296,4647.207,15380.69
125,-2.08336,-0.006642565,-4714.879,0.01560567,0,0,0.0006642565,0.006642565,0.006642786,4714.879,15604.64
126,-2.1,-0.006227866,-4780.995,0.01582451,0,0,0.0006227866,0.006227866,0.00622806,4780.995,15823.52
127,-2.11672,-0.006674491,-4850.363,0.01605411,0,0,0.0006674491,0.006674491,0.006674714,4850.363,16053.03
128,-2.1334,-0.006435215,-4918.541,0.01627977,0,0,0.0006435215,0.006435215,0.006435423,4918.541,16278.72
129,-2.15008,-0.006562807,-4987.112,0.01650673,0,0,0.0006562807,0.006562807,0.006563022,4987.112,16505.64
130,-2.16668,-0.006610677,-5055.972,0.01673465,0,0,0.0006610677,0.006610677,0.006610895,5055.972,16733.54
131,-2.18336,-0.006307624,-5124.051,0.01695998,0,0,0.0006307624,0.006307624,0.006307823,5124.051,16958.91
132,-2.2,-0.006275699,-5191.722,0.01718396,0,0,0.0006275699,0.006275699,0.006275895,5191.722,17182.88
133,-2.21672,-0.006387345,-5259.782,0.01740923,0,0,0.0006387345,0.006387345,0.006387549,5259.782,17408.12
134,-2.2334,-0.006578788,-5327.05,0.01763188,0,0,0.0006578788,0.006578788,0.006579005,5327.05,17630.72
135,-2.25004,-0.006802082,-5391.177,0.01784413,0,0,0.0006802082,0.006802082,0.006802313,5391.177,17842.92
136,-2.26664,-0.006068349,-5444.474,0.01802054,0,0,0.0006068349,0.006068349,0.006068533,5444.474,18019.45
137,-2.28336,-0.006259754,-5446.322,0.01802666,0,0,0.0006259754,0.006259754,0.00625995,5446.322,18025.53
138,-2.30004,-0.006722324,-5486.977,0.01816122,0,0,0.0006722324,0.006722324,0.00672255,5486.978,18160
139,-2.31676,-0.006514974,-5552.56,0.01837829,0,0,0.0006514974,0.006514974,0.006515186,5552.56,18377.09
140,-2.3334,-0.006722324,-5617.325,0.01859266,0,0,0.0006722324,0.006722324,0.00672255,5617.325,18591.41
141,-2.35,-0.006307624,-5685.16,0.01881718,0,0,0.0006307624,0.006307624,0.006307823,5685.16,18816
142,-2.36668,-0.006355457,-5755.493,0.01904998,0,0,0.0006355457,0.006355457,0.006355659,5755.494,19048.77
143,-2.38336,-0.006722324,-5824.354,0.0192779,0,0,0.0006722324,0.006722324,0.00672255,5824.354,19276.6
144,-2.40004,-0.006722324,-5894.189,0.01950904,0,0,0.0006722324,0.006722324,0.00672255,5894.189,19507.73
145,-2.41676,-0.006658547,-5964.939,0.01974322,0,0,0.0006658547,0.006658547,0.006658768,5964.938,19741.9
146,-2.43336,-0.006530918,-6034.428,0.01997322,0,0,0.0006530918,0.006530918,0.006531131,6034.428,19971.91
147,-2.449999,-0.006610677,-6103.98,0.02020342,0,0,0.0006610677,0.006610677,0.006610895,6103.98,20202.09
148,-2.466679,-0.006435215,-6173.748,0.02043435,0,0,0.0006435215,0.006435215,0.006435423,6173.748,20433.03
149,-2.483359,-0.006802082,-6244.755,0.02066937,0,0,0.0006802082,0.006802082,0.006802313,6244.755,20667.97
150,-2.500039,-0.006355457,-6314.772,0.02090112,0,0,0.0006355457,0.006355457,0.006355659,6314.771,20899.79
151,-2.51672,-0.006834008,-6383.642,0.02112907,0,0,0.0006834008,0.006834008,0.006834241,6383.642,21127.63
152,-2.5334,-0.006658547,-6454.398,0.02136326,0,0,0.0006658547,0.006658547,0.006658768,6454.398,21361.84
153,-2.550039,-0.006467104,-6522.21,0.02158771,0,0,0.0006467104,0.006467104,0.006467313,6522.21,21586.32
154,-2.566719,-0.006562807,-6591.581,0.02181732,0,0,0.0006562807,0.006562807,0.006563022,6591.581,21815.89
155,-2.58336,-0.006275699,-6662.324,0.02205148,0,0,0.0006275699,0.006275699,0.006275895,6662.324,22050.09
156,-2.599999,-0.006818026,-6731.22,0.02227951,0,0,0.0006818026,0.006818026,0.006818259,6731.22,22277.99
157,-2.616679,-0.006642565,-6802.8,0.02251643,0,0,0.0006642565,0.006642565,0.006642786,6802.799,22514.94
158,-2.6334,-0.006802082,-6872.835,0.02274824,0,0,0.0006802082,0.006802082,0.006802313,6872.835,22746.69
159,-2.65008,-0.006674491,-6943.276,0.02298139,0,0,0.0006674491,0.006674491,0.006674714,6943.276,22979.86
160,-2.66672,-0.006419271,-7012.029,0.02320896,0,0,0.0006419271,0.006419271,0.006419477,7012.029,23207.47
161,-2.6834,-0.00649903,-7081.351,0.0234384,0,0,0.000649903,0.00649903,0.006499241,7081.351,23436.88
162,-2.70008,-0.006514974,-7150.067,0.02366584,0,0,0.0006514974,0.006514974,0.006515186,7150.066,23664.3
163,-2.71668,-0.006897785,-7220.739,0.02389976,0,0,0.0006897785,0.006897785,0.006898023,7220.739,23898.11
164,-2.73336,-0.006802082,-7290.483,0.02413061,0,0,0.0006802082,0.006802082,0.006802313,7290.483,24128.96
165,-2.749999,-0.006834008,-7358.741,0.02435653,0,0,0.0006834008,0.006834008,0.006834241,7358.741,24354.87
166,-2.76668,-0.006578788,-7429.508,0.02459076,0,0,0.0006578788,0.006578788,0.006579005,7429.508,24589.14
167,-2.7834,-0.006754249,-7497.872,0.02481704,0,0,0.0006754249,0.006754249,0.006754477,7497.873,24815.36
168,-2.80004,-0.006961599,-7566.487,0.02504414,0,0,0.0006961599,0.006961599,0.006961841,7566.487,25042.4
169,-2.81672,-0.006786138,-7634.776,0.02527017,0,0,0.0006786138,0.006786138,0.006786368,7634.776,25268.46
170,-2.8334,-0.007041357,-7698.453,0.02548094,0,0,0.0007041357,0.007041357,0.007041605,7698.453,25479.14
170.946,-2.84912,-0.006802082,-7446.218,0.02464607,0,0,0.0006802082,0.006802082,0.006802313,7446.218,24644.39
171.946,-2.86584,-0.007153004,-7357.126,0.02435119,0,0,0.0007153004,0.007153004,0.007153261,7357.126,24349.44
172.946,-2.88244,-0.006722324,-7431.976,0.02459893,0,0,0.0006722324,0.006722324,0.00672255,7431.976,24597.27
173.946,-2.89912,-0.006802082,-7506.742,0.02484639,0,0,0.0006802082,0.006802082,0.006802313,7506.742,24844.7
174.946,-2.9158,-0.006945655,-7579.656,0.02508773,0,0,0.0006945655,0.006945655,0.006945896,7579.656,25085.99
175.946,-2.932519,-0.006913766,-7654.11,0.02533417,0,0,0.0006913766,0.006913766,0.006914006,7654.11,25332.41
176.946,-2.949119,-0.006802082,-7728.033,0.02557884,0,0,0.0006802082,0.006802082,0.006802313,7728.033,25577.1
177.946,-2.96584,-0.006403327,-7801.967,0.02582355,0,0,0.0006403327,0.006403327,0.006403532,7801.967,25821.9
178.946,-2.982479,-0.006483085,-7871.782,0.02605463,0,0,0.0006483085,0.006483085,0.006483296,7871.782,26052.94
179.946,-2.99916,-0.006897785,-7941.84,0.02628652,0,0,0.0006897785,0.006897785,0.006898023,7941.84,26284.7
180.946,-3.01576,-0.006514974,-8013.259,0.0265229,0,0,0.0006514974,0.006514974,0.006515186,8013.259,26521.18
181.946,-3.032479,-0.006722324,-8085.414,0.02676173,0,0,0.0006722324,0.006722324,0.00672255,8085.414,26759.93
182.946,-3.04912,-0.006897785,-8156.946,0.02699849,0,0,0.0006897785,0.006897785,0.006898023,8156.946,26996.63
183.946,-3.065839,-0.006897785,-8227.963,0.02723355,0,0,0.0006897785,0.006897785,0.006898023,8227.963,27231.67
184.946,-3.08248,-0.006530918,-8297.54,0.02746383,0,0,0.0006530918,0.006530918,0.006531131,8297.539,27462.04
185.946,-3.099199,-0.006594732,-8367.18,0.02769434,0,0,0.0006594732,0.006594732,0.00659495,8367.18,27692.51
186.946,-3.115759,-0.006834008,-8435.394,0.02792012,0,0,0.0006834008,0.006834008,0.006834241,8435.394,27918.21
187.946,-3.132439,-0.006674491,-8502.252,0.02814141,0,0,0.0006674491,0.006674491,0.006674714,8502.252,28139.53
188.946,-3.14908,-0.006626621,-8567.701,0.02835804,0,0,0.0006626621,0.006626621,0.00662684,8567.701,28356.16
189.946,-3.165799,-0.006419271,-8634.402,0.02857881,0,0,0.0006419271,0.006419271,0.006419477,8634.402,28576.98
190.946,-3.18244,-0.00718493,-8702.691,0.02880484,0,0,0.0007184931,0.00718493,0.007185189,8702.69,28802.77
191.946,-3.199159,-0.006786138,-8770.494,0.02902926,0,0,0.0006786138,0.006786138,0.006786368,8770.494,29027.29
192.946,-3.2158,-0.006834008,-8839.485,0.02925761,0,0,0.0006834008,0.006834008,0.006834241,8839.485,29255.61
193.946,-3.232519,-0.006929711,-8908.562,0.02948625,0,0,0.0006929711,0.006929711,0.006929951,8908.563,29484.21
194.946,-3.249159,-0.006786138,-8974.791,0.02970546,0,0,0.0006786138,0.006786138,0.006786368,8974.791,29703.44
195.946,-3.2658,-0.006881841,-9044.17,0.02993509,0,0,0.0006881841,0.006881841,0.006882078,9044.17,29933.03
196.946,-3.282439,-0.006977543,-9110.694,0.03015528,0,0,0.0006977543,0.006977543,0.006977786,9110.693,30153.17
197.946,-3.299119,-0.006738305,-9177.145,0.03037522,0,0,0.0006738306,0.006738305,0.006738532,9177.145,30373.18
198.946,-3.315799,-0.006834008,-9245.335,0.03060093,0,0,0.0006834008,0.006834008,0.006834241,9245.335,30598.83
199.946,-3.33252,-0.006786138,-9310.335,0.03081607,0,0,0.0006786138,0.006786138,0.006786368,9310.335,30813.98
200.946,-3.34912,-0.006690435,-9374.688,0.03102907,0,0,0.0006690435,0.006690435,0.006690659,9374.688,31026.99
201.946,-3.365839,-0.006786138,-9431.865,0.03121832,0,0,0.0006786138,0.006786138,0.006786368,9431.865,31216.2
202.946,-3.38244,-0.006770194,-9491.584,0.03141598,0,0,0.0006770194,0.006770194,0.006770422,9491.584,31413.85
203.946,-3.39912,-0.006610677,-9554.779,0.03162514,0,0,0.0006610677,0.006610677,0.006610895,9554.778,31623.05
204.946,-3.415759,-0.006818026,-9618.298,0.03183538,0,0,0.0006818026,0.006818026,0.006818259,9618.298,31833.22
205.946,-3.43248,-0.006594732,-9681.243,0.03204373,0,0,0.0006594732,0.006594732,0.00659495,9681.243,32041.62
206.946,-3.44908,-0.006594732,-9745.599,0.03225674,0,0,0.0006594732,0.006594732,0.00659495,9745.599,32254.61
207.946,-3.46584,-0.007041357,-9810.046,0.03247005,0,0,0.0007041357,0.007041357,0.007041605,9810.046,32467.76
208.946,-3.482479,-0.006435215,-9874.777,0.0326843,0,0,0.0006435215,0.006435215,0.006435423,9874.776,32682.19
209.946,-3.499159,-0.006818026,-9940.141,0.03290065,0,0,0.0006818026,0.006818026,0.006818259,9940.141,32898.4
210.946,-3.515839,-0.007089227,-10004.38,0.03311329,0,0,0.0007089227,0.007089227,0.007089479,10004.38,33110.94
211.946,-3.532519,-0.006913766,-10070.05,0.03333062,0,0,0.0006913766,0.006913766,0.006914006,10070.05,33328.32
212.946,-3.54912,-0.006849952,-10134.85,0.03354512,0,0,0.0006849952,0.006849952,0.006850187,10134.85,33542.82
213.946,-3.56572,-0.006977543,-10199.83,0.0337602,0,0,0.0006977543,0.006977543,0.006977786,10199.83,33757.84
214.946,-3.5824,-0.006802082,-10265.86,0.03397874,0,0,0.0006802082,0.006802082,0.006802313,10265.86,33976.43
215.946,-3.59916,-0.006722324,-10331.15,0.03419485,0,0,0.0006722324,0.006722324,0.00672255,10331.15,34192.56
216.946,-3.61584,-0.006834008,-10396.7,0.03441182,0,0,0.0006834008,0.006834008,0.006834241,10396.71,34409.47
217.946,-3.63252,-0.007105172,-10462.66,0.03463014,0,0,0.0007105172,0.007105172,0.007105424,10462.67,34627.68
218.946,-3.649159,-0.006706379,-10525.15,0.03483697,0,0,0.0006706379,0.006706379,0.006706604,10525.15,34834.63
219.946,-3.665839,-0.007089227,-10582.81,0.03502781,0,0,0.0007089227,0.007089227,0.007089479,10582.81,35025.32
220.946,-3.68244,-0.007041357,-10638.35,0.03521163,0,0,0.0007041357,0.007041357,0.007041605,10638.35,35209.15
221.946,-3.69912,-0.006993525,-10697.59,0.0354077,0,0,0.0006993525,0.006993525,0.006993769,10697.59,35405.22
222.946,-3.715759,-0.006849952,-10762.09,0.03562121,0,0,0.0006849952,0.006849952,0.006850187,10762.09,35618.77
223.946,-3.73252,-0.006977543,-10828.78,0.03584195,0,0,0.0006977543,0.006977543,0.006977786,10828.78,35839.44
224.946,-3.749119,-0.006865896,-10893.8,0.03605714,0,0,0.0006865896,0.006865896,0.006866132,10893.8,36054.67
225.946,-3.765799,-0.007041357,-10959.97,0.03627615,0,0,0.0007041357,0.007041357,0.007041605,10959.97,36273.6
226.946,-3.782479,-0.007009469,-11026.05,0.03649488,0,0,0.0007009469,0.007009469,0.007009714,11026.05,36492.32
227.946,-3.799159,-0.006977543,-11091.31,0.03671088,0,0,0.0006977543,0.006977543,0.006977786,11091.31,36708.32
228.946,-3.8158,-0.006977543,-11157.84,0.03693108,0,0,0.0006977543,0.006977543,0.006977786,11157.84,36928.5
229.946,-3.83244,-0.007105172,-11222.45,0.03714494,0,0,0.0007105172,0.007105172,0.007105424,11222.45,37142.31
230.946,-3.849079,-0.006610677,-11287.38,0.03735983,0,0,0.0006610677,0.006610677,0.006610895,11287.38,37357.36
231.946,-3.86584,-0.006849952,-11355.14,0.03758411,0,0,0.0006849952,0.006849952,0.006850187,11355.14,37581.54
232.946,-3.88248,-0.006977543,-11420.94,0.03780193,0,0,0.0006977543,0.006977543,0.006977786,11420.94,37799.29
233.946,-3.899159,-0.007089227,-11487.54,0.03802235,0,0,0.0007089227,0.007089227,0.007089479,11487.54,38019.66
234.946,-3.915799,-0.006993525,-11552.13,0.03823613,0,0,0.0006993525,0.006993525,0.006993769,11552.13,38233.45
235.946,-3.932439,-0.006849952,-11616.95,0.03845069,0,0,0.0006849952,0.006849952,0.006850187,11616.95,38448.06
236.946,-3.949119,-0.006897785,-11683.21,0.03867,0,0,0.0006897785,0.006897785,0.006898023,11683.21,38667.33
237.946,-3.965799,-0.007200874,-11748.3,0.03888543,0,0,0.0007200874,0.007200874,0.007201134,11748.3,38882.63
238.946,-3.982439,-0.00713706,-11813.75,0.03910208,0,0,0.000713706,0.00713706,0.007137315,11813.75,39099.29
239.946,-3.999159,-0.007009469,-11879.08,0.03931829,0,0,0.0007009469,0.007009469,0.007009714,11879.08,39315.54
240.946,-4.015799,-0.006897785,-11945.19,0.03953712,0,0,0.0006897785,0.006897785,0.006898023,11945.19,39534.4
241.946,-4.032439,-0.007408224,-12011.47,0.0397565,0,0,0.0007408224,0.007408224,0.007408498,12011.47,39753.56
242.946,-4.049159,-0.007121116,-12079.05,0.03998018,0,0,0.0007121116,0.007121116,0.00712137,12079.05,39977.34
243.946,-4.065839,-0.006993525,-12144.88,0.04019806,0,0,0.0006993525,0.006993525,0.006993769,12144.88,40195.25
244.946,-4.082479,-0.006977543,-12210.84,0.04041637,0,0,0.0006977543,0.006977543,0.006977786,12210.84,40413.55
245.946,-4.099119,-0.007089227,-12273.5,0.04062377,0,0,0.0007089227,0.007089227,0.007089479,12273.5,40620.89
246.946,-4.11576,-0.007025413,-12338.41,0.04083861,0,0,0.0007025413,0.007025413,0.00702566,12338.41,40835.74
247.946,-4.132479,-0.007216819,-12404.59,0.04105768,0,0,0.0007216819,0.007216819,0.007217079,12404.59,41054.72
248.946,-4.149159,-0.007248744,-12468.21,0.04126823,0,0,0.0007248744,0.007248744,0.007249007,12468.21,41265.24
249.946,-4.165799,-0.006961599,-12531.96,0.04147924,0,0,0.0006961599,0.006961599,0.006961841,12531.96,41476.35
250.946,-4.182479,-0.006945655,-12596.57,0.04169309,0,0,0.0006945655,0.006945655,0.006945896,12596.57,41690.19
251.946,-4.199159,-0.007041357,-12661.3,0.04190736,0,0,0.0007041357,0.007041357,0.007041605,12661.3,41904.41
252.946,-4.215799,-0.006770194,-12729.75,0.04213392,0,0,0.0006770194,0.006770194,0.006770422,12729.75,42131.07
253.946,-4.232439,-0.007248744,-12796.52,0.0423549,0,0,0.0007248744,0.007248744,0.007249007,12796.52,42351.83
254.946,-4.249119,-0.007328466,-12860.99,0.04256828,0,0,0.0007328466,0.007328466,0.007328734,12860.99,42565.16
255.946,-4.265799,-0.006913766,-12928.69,0.04279236,0,0,0.0006913766,0.006913766,0.006914006,12928.69,42789.4
256.946,-4.282519,-0.00713706,-12993.17,0.04300581,0,0,0.000713706,0.00713706,0.007137315,12993.17,43002.74
257.946,-4.299119,-0.007264689,-13058.18,0.04322096,0,0,0.0007264689,0.007264689,0.007264953,13058.17,43217.82
258.946,-4.315839,-0.007248744,-13123.21,0.04343622,0,0,0.0007248744,0.007248744,0.007249007,13123.21,43433.07
259.946,-4.332479,-0.007264689,-13184.78,0.04364002,0,0,0.0007264689,0.007264689,0.007264953,13184.78,43636.85
260.946,-4.34912,-0.007408224,-13248.5,0.04385091,0,0,0.0007408224,0.007408224,0.007408498,13248.5,43847.66
261.946,-4.3658,-0.00718493,-13313.03,0.04406451,0,0,0.0007184931,0.00718493,0.007185189,13313.03,44061.34
262.946,-4.38248,-0.007216819,-13378.25,0.04428038,0,0,0.0007216819,0.007216819,0.007217079,13378.25,44277.18
263.946,-4.399119,-0.007089227,-13441.01,0.0444881,0,0,0.0007089227,0.007089227,0.007089479,13441.01,44484.94
264.946,-4.41584,-0.006977543,-13505.44,0.04470134,0,0,0.0006977543,0.006977543,0.006977786,13505.44,44698.22
265.946,-4.432479,-0.006945655,-13567.66,0.04490729,0,0,0.0006945655,0.006945655,0.006945896,13567.66,44904.17
266.946,-4.449199,-0.006881841,-13625.26,0.04509794,0,0,0.0006881841,0.006881841,0.006882078,13625.26,45094.84
267.946,-4.465839,-0.00718493,-13672.19,0.04525328,0,0,0.0007184931,0.00718493,0.007185189,13672.19,45250.03
268.946,-4.482439,-0.006961599,-13731.97,0.04545113,0,0,0.0006961599,0.006961599,0.006961841,13731.97,45447.96
269.946,-4.499079,-0.007232763,-13795.13,0.0456602,0,0,0.0007232763,0.007232763,0.007233025,13795.13,45656.9
270.946,-4.515799,-0.007089227,-13861.24,0.04587901,0,0,0.0007089227,0.007089227,0.007089479,13861.24,45875.76
271.946,-4.532439,-0.006834008,-13931.27,0.04611079,0,0,0.0006834008,0.006834008,0.006834241,13931.27,46107.64
272.946,-4.549199,-0.007280633,-14001.11,0.04634196,0,0,0.0007280633,0.007280633,0.007280898,14001.11,46338.58
273.946,-4.565839,-0.007121116,-14070.76,0.0465725,0,0,0.0007121116,0.007121116,0.00712137,14070.76,46569.19
274.946,-4.582479,-0.007009469,-14139.85,0.04680116,0,0,0.0007009469,0.007009469,0.007009714,14139.85,46797.89
275.946,-4.599119,-0.006929711,-14208.49,0.04702836,0,0,0.0006929711,0.006929711,0.006929951,14208.49,47025.1
276.946,-4.61576,-0.007264689,-14276.88,0.04725474,0,0,0.0007264689,0.007264689,0.007264953,14276.88,47251.3
277.946,-4.63244,-0.006961599,-14344.59,0.04747883,0,0,0.0006961599,0.006961599,0.006961841,14344.59,47475.53
278.946,-4.64912,-0.007009469,-14413.86,0.04770812,0,0,0.0007009469,0.007009469,0.007009714,14413.86,47704.78
279.946,-4.665799,-0.006929711,-14483.07,0.04793719,0,0,0.0006929711,0.006929711,0.006929951,14483.07,47933.87
280.946,-4.682479,-0.007121116,-14554.04,0.04817207,0,0,0.0007121116,0.007121116,0.00712137,14554.04,48168.64
281.946,-4.699119,-0.006977543,-14625.07,0.04840717,0,0,0.0006977543,0.006977543,0.006977786,14625.07,48403.79
282.946,-4.715799,-0.006929711,-14699.54,0.04865368,0,0,0.0006929711,0.006929711,0.006929951,14699.54,48650.31
283.946,-4.732479,-0.007456094,-14776.51,0.04890843,0,0,0.0007456094,0.007456094,0.007456372,14776.51,48904.78
284.946,-4.749159,-0.007216819,-14851.57,0.04915687,0,0,0.0007216819,0.007216819,0.007217079,14851.57,49153.32
285.946,-4.765759,-0.007280633,-14805.9,0.04900571,0,0,0.0007280633,0.007280633,0.007280898,14805.9,49002.14
286.946,-4.782479,-0.007232763,-14843.84,0.04913128,0,0,0.0007232763,0.007232763,0.007233025,14843.84,49127.73
287.946,-4.799119,-0.00713706,-14926.6,0.04940521,0,0,0.000713706,0.00713706,0.007137315,14926.6,49401.68
288.946,-4.815879,-0.007503927,-15015.48,0.04969938,0,0,0.0007503927,0.007503927,0.007504208,15015.48,49695.65
289.946,-4.832519,-0.007041357,-15097.19,0.04996986,0,0,0.0007041357,0.007041357,0.007041605,15097.19,49966.34
290.946,-4.849199,-0.007153004,-15171.45,0.05021564,0,0,0.0007153004,0.007153004,0.007153261,15171.45,50212.05
291.946,-4.86572,-0.007312521,-15247.58,0.05046761,0,0,0.0007312521,0.007312521,0.007312789,15247.58,50463.93
292.946,-4.882439,-0.006897785,-15327.66,0.05073267,0,0,0.0006897785,0.006897785,0.006898023,15327.66,50729.17
293.946,-4.899079,-0.007487983,-15406.04,0.0509921,0,0,0.0007487983,0.007487983,0.007488263,15406.04,50988.28
294.946,-4.915839,-0.007424206,-15487.1,0.05126041,0,0,0.0007424206,0.007424206,0.007424481,15487.1,51256.6
295.946,-4.932399,-0.006881841,-15566.22,0.05152229,0,0,0.0006881841,0.006881841,0.006882078,15566.22,51518.75
296.946,-4.9492,-0.007360391,-15647.14,0.05179013,0,0,0.0007360391,0.007360391,0.007360662,15647.14,51786.31
297.946,-4.965839,-0.007344447,-15724.77,0.05204706,0,0,0.0007344447,0.007344447,0.007344717,15724.77,52043.23
298.946,-4.982519,-0.007567741,-15798.18,0.05229004,0,0,0.0007567741,0.007567741,0.007568028,15798.18,52286.08
299.946,-4.999119,-0.007328466,-15869.93,0.05252753,0,0,0.0007328466,0.007328466,0.007328734,15869.93,52523.68
300.946,-5.015839,-0.007376336,-15946.48,0.05278089,0,0,0.0007376336,0.007376336,0.007376608,15946.48,52777
301.946,-5.032439,-0.007456094,-16027.72,0.05304979,0,0,0.0007456094,0.007456094,0.007456372,16027.72,53045.83
302.946,-5.049119,-0.007153004,-16108.73,0.05331793,0,0,0.0007153004,0.007153004,0.007153261,16108.73,53314.11
303.946,-5.065759,-0.007312521,-16190.49,0.05358855,0,0,0.0007312521,0.007312521,0.007312789,16190.49,53584.63
304.946,-5.082479,-0.006802082,-16276.15,0.05387207,0,0,0.0006802082,0.006802082,0.006802313,16276.15,53868.41
305.946,-5.099159,-0.007121116,-16361.42,0.05415429,0,0,0.0007121116,0.007121116,0.00712137,16361.42,54150.43
306.946,-5.115839,-0.007487983,-16448.38,0.05444212,0,0,0.0007487983,0.007487983,0.007488263,16448.38,54438.04
307.946,-5.132479,-0.007408224,-16534.45,0.054727,0,0,0.0007408224,0.007408224,0.007408498,16534.45,54722.94
308.946,-5.149159,-0.007264689,-16624.11,0.05502378,0,0,0.0007264689,0.007264689,0.007264953,16624.11,55019.78
309.946,-5.165759,-0.007153004,-16714.24,0.05532208,0,0,0.0007153004,0.007153004,0.007153261,16714.24,55318.12
310.946,-5.182479,-0.007408224,-16804.81,0.05562186,0,0,0.0007408224,0.007408224,0.007408498,16804.81,55617.74
311.946,-5.199119,-0.007456094,-16895.07,0.05592061,0,0,0.0007456094,0.007456094,0.007456372,16895.07,55916.44
312.946,-5.215839,-0.007408224,-16989.82,0.05623422,0,0,0.0007408224,0.007408224,0.007408498,16989.82,56230.05
313.946,-5.232519,-0.007376336,-17082.47,0.05654088,0,0,0.0007376336,0.007376336,0.007376608,17082.47,56536.71
314.946,-5.249159,-0.007248744,-17178,0.05685706,0,0,0.0007248744,0.007248744,0.007249007,17178,56852.94
315.946,-5.265799,-0.007424206,-17273.32,0.05717259,0,0,0.0007424206,0.007424206,0.007424481,17273.32,57168.34
316.946,-5.282479,-0.007472038,-17367.34,0.05748376,0,0,0.0007472038,0.007472038,0.007472318,17367.34,57479.47
317.946,-5.299119,-0.007168986,-17462.16,0.05779762,0,0,0.0007168986,0.007168986,0.007169243,17462.16,57793.48
318.946,-5.315799,-0.007743202,-17557.96,0.05811469,0,0,0.0007743202,0.007743202,0.007743502,17557.96,58110.19
319.946,-5.332439,-0.007487983,-17653.04,0.05842941,0,0,0.0007487983,0.007487983,0.007488263,17653.04,58425.03
320.946,-5.349119,-0.007503927,-17751.1,0.05875396,0,0,0.0007503927,0.007503927,0.007504208,17751.1,58749.55
321.946,-5.365839,-0.007535852,-17851.01,0.05908465,0,0,0.0007535852,0.007535852,0.007536137,17851.01,59080.2
322.946,-5.382479,-0.007472038,-17949.08,0.05940924,0,0,0.0007472038,0.007472038,0.007472318,17949.08,59404.8
323.946,-5.399119,-0.007519908,-18049.17,0.05974053,0,0,0.0007519908,0.007519908,0.007520191,18049.17,59736.04
324.946,-5.415799,-0.007360391,-18150.36,0.06007546,0,0,0.0007360391,0.007360391,0.007360662,18150.36,60071.04
325.946,-5.432439,-0.007200874,-18250.02,0.06040531,0,0,0.0007200874,0.007200874,0.007201134,18250.02,60400.96
326.946,-5.449119,-0.007248744,-18352.85,0.0607457,0,0,0.0007248744,0.007248744,0.007249007,18352.85,60741.29
327.946,-5.465759,-0.007312521,-18452.15,0.06107435,0,0,0.0007312521,0.007312521,0.007312789,18452.15,61069.88
328.946,-5.482479,-0.007121116,-18554.38,0.06141272,0,0,0.0007121116,0.007121116,0.00712137,18554.38,61408.35
329.946,-5.499159,-0.006897785,-18657.21,0.06175307,0,0,0.0006897785,0.006897785,0.006898023,18657.21,61748.81
330.946,-5.515839,-0.007328466,-18758.63,0.06208875,0,0,0.0007328466,0.007328466,0.007328734,18758.63,62084.2
331.946,-5.532439,-0.007264689,-18863.04,0.06243435,0,0,0.0007264689,0.007264689,0.007264953,18863.04,62429.82
332.946,-5.549159,-0.007408224,-18966.53,0.06277689,0,0,0.0007408224,0.007408224,0.007408498,18966.53,62772.24
333.946,-5.565759,-0.007408224,-19068.83,0.0631155,0,0,0.0007408224,0.007408224,0.007408498,19068.83,63110.82
334.946,-5.582479,-0.007631555,-19175.45,0.0634684,0,0,0.0007631555,0.007631555,0.007631846,19175.46,63463.56
335.946,-5.599119,-0.00718493,-19281.04,0.06381789,0,0,0.0007184931,0.00718493,0.007185189,19281.04,63813.3
336.946,-5.615799,-0.007775128,-19387.41,0.06416994,0,0,0.0007775128,0.007775128,0.00777543,19387.41,64164.95
337.946,-5.632519,-0.007248744,-19488.32,0.06450395,0,0,0.0007248744,0.007248744,0.007249007,19488.32,64499.27
338.946,-5.649199,-0.007328466,-19593.61,0.06485245,0,0,0.0007328466,0.007328466,0.007328734,19593.61,64847.7
339.946,-5.665799,-0.007647499,-19698.7,0.06520029,0,0,0.0007647499,0.007647499,0.007647792,19698.7,65195.31
340.946,-5.682519,-0.007519908,-19807.28,0.06555967,0,0,0.0007519908,0.007519908,0.007520191,19807.28,65554.74
341.946,-5.699119,-0.007583685,-19917.68,0.06592509,0,0,0.0007583685,0.007583685,0.007583973,19917.68,65920.09
342.946,-5.715799,-0.007663444,-20035.36,0.06631456,0,0,0.0007663444,0.007663444,0.007663737,20035.36,66309.48
343.946,-5.732479,-0.007041357,-20152.68,0.06670289,0,0,0.0007041357,0.007041357,0.007041605,20152.68,66698.19
344.946,-5.74916,-0.007535852,-20269.77,0.06709047,0,0,0.0007535852,0.007535852,0.007536137,20269.77,67085.41
345.946,-5.76584,-0.007535852,-20388.94,0.06748488,0,0,0.0007535852,0.007535852,0.007536137,20388.94,67479.79
346.946,-5.78252,-0.007599667,-20507.53,0.06787741,0,0,0.0007599667,0.007599667,0.007599956,20507.53,67872.25
347.946,-5.799119,-0.007200874,-20629.58,0.06828138,0,0,0.0007200874,0.007200874,0.007201134,20629.58,68276.46
348.946,-5.815839,-0.007695369,-20755.73,0.06869892,0,0,0.0007695369,0.007695369,0.007695665,20755.73,68693.63
349.946,-5.832479,-0.007424206,-20880.63,0.06911232,0,0,0.0007424206,0.007424206,0.007424481,20880.63,69107.19
350.946,-5.849119,-0.007599667,-21014.07,0.06955399,0,0,0.0007599667,0.007599667,0.007599956,21014.07,69548.7
351.946,-5.865799,-0.007934645,-21149.53,0.07000235,0,0,0.0007934645,0.007934645,0.007934959,21149.53,69996.8
352.946,-5.882479,-0.007551797,-21289.31,0.07046499,0,0,0.0007551797,0.007551797,0.007552082,21289.31,70459.67
353.946,-5.899119,-0.007503927,-21427.72,0.07092313,0,0,0.0007503927,0.007503927,0.007504208,21427.72,70917.81
354.946,-5.915799,-0.007248744,-21566.35,0.07138198,0,0,0.0007248744,0.007248744,0.007249007,21566.35,71376.81
355.946,-5.932479,-0.007775128,-21703.38,0.07183554,0,0,0.0007775128,0.007775128,0.00777543,21703.38,71829.95
356.946,-5.949159,-0.007759146,-21842.69,0.07229663,0,0,0.0007759146,0.007759146,0.007759447,21842.69,72291.02
357.946,-5.965839,-0.007791072,-21980.26,0.07275197,0,0,0.0007791072,0.007791072,0.007791376,21980.26,72746.3
358.946,-5.982439,-0.007663444,-22119.34,0.07321231,0,0,0.0007663444,0.007663444,0.007663737,22119.34,73206.7
[...]
1324.65,-4.389119,-0.01265619,-10369.42,0.0343215,2,2,0.001265619,0.01265619,0.01265699,10369.42,34317.16
1329.65,-4.472399,-0.01238503,-10737.09,0.03553847,2,2,0.001238503,0.01238503,0.01238579,10737.09,35534.07
1334.65,-4.55576,-0.01295924,-11109.16,0.03676996,2,2,0.001295924,0.01295924,0.01296008,11109.16,36765.19
1339.65,-4.639119,-0.01260832,-11486.71,0.03801961,2,2,0.001260832,0.01260832,0.01260911,11486.71,38014.82
1344.65,-4.722399,-0.01240097,-11859.35,0.03925299,2,2,0.001240097,0.01240097,0.01240174,11859.35,39248.12
1349.65,-4.80572,-0.0122574,-12237.03,0.04050307,2,2,0.00122574,0.0122574,0.01225815,12237.03,40498.1
1354.65,-4.889079,-0.01273595,-12626.91,0.04179352,2,2,0.001273595,0.01273595,0.01273676,12626.91,41788.2
1359.65,-4.972399,-0.01256049,-13050.89,0.04319685,2,2,0.001256049,0.01256049,0.01256128,13050.89,43191.42
1364.65,-5.055759,-0.0122574,-13495.7,0.04466911,2,2,0.00122574,0.0122574,0.01225815,13495.7,44663.64
1369.65,-5.139079,-0.01216169,-13947.6,0.04616484,2,2,0.001216169,0.01216169,0.01216243,13947.6,46159.23
1374.65,-5.222439,-0.01248073,-14418.38,0.04772308,2,2,0.001248073,0.01248073,0.01248151,14418.38,47717.13
1379.65,-5.305759,-0.01267213,-14913.31,0.04936123,2,2,0.001267213,0.01267213,0.01267294,14913.31,49354.98
1384.65,-5.389079,-0.01283165,-15436.56,0.05109312,2,2,0.001283165,0.01283165,0.01283247,15436.56,51086.56
1389.65,-5.472399,-0.01276784,-15985.57,0.05291026,2,2,0.001276784,0.01276784,0.01276865,15985.57,52903.51
1394.65,-5.555799,-0.01248073,-16549.25,0.05477598,2,2,0.001248073,0.01248073,0.01248151,16549.25,54769.14
1399.65,-5.63908,-0.01264025,-17120.34,0.05666625,2,2,0.001264025,0.01264025,0.01264104,17120.35,56659.08
1404.65,-5.72248,-0.01259238,-17713.81,0.05863056,2,2,0.001259238,0.01259238,0.01259317,17713.81,58623.17
1409.65,-5.805679,-0.01212981,-18327.66,0.06066232,2,2,0.001212981,0.01212981,0.01213054,18327.66,60654.96
1414.65,-5.889079,-0.01281571,-18990.26,0.06285544,2,2,0.001281571,0.01281571,0.01281653,18990.26,62847.38
1419.65,-5.972439,-0.01273595,-19723.88,0.06528363,2,2,0.001273595,0.01273595,0.01273676,19723.88,65275.32
1424.65,-6.055759,-0.01335803,-20486.23,0.06780691,2,2,0.001335803,0.01335803,0.01335893,20486.23,67797.86
1429.65,-6.139119,-0.01256049,-21282.31,0.07044183,2,2,0.001256049,0.01256049,0.01256128,21282.31,70432.99
1434.65,-6.222439,-0.01265619,-22093.71,0.07312745,2,2,0.001265619,0.01265619,0.01265699,22093.71,73118.2
1439.65,-6.305719,-0.01281571,-22934.04,0.07590885,2,2,0.001281571,0.01281571,0.01281653,22934.04,75899.13
1444.65,-6.389079,-0.01284759,-23800.42,0.07877649,2,2,0.001284759,0.01284759,0.01284842,23800.42,78766.36
1449.65,-6.472399,-0.01275189,-24684.11,0.08170138,2,2,0.001275189,0.01275189,0.01275271,24684.11,81690.95
1453.136,-6.472399,-0.01262426,-24596.58,0.08141165,2,2,0.001262426,0.01262426,0.01262506,24596.58,81401.38
1456.954,-6.408559,-0.01254451,-23345.84,0.07727185,2,2,0.001254451,0.01254451,0.01254529,23345.84,77262.16
1461.242,-6.337079,-0.01302306,-22094.43,0.07312984,2,2,0.001302306,0.01302306,0.0130239,22094.43,73120.32
1465.92,-6.259119,-0.01287948,-20843.49,0.06898941,2,2,0.001287948,0.01287948,0.01288031,20843.49,68980.52
1470.888,-6.176319,-0.01283165,-19620.45,0.06494129,2,2,0.001283165,0.01283165,0.01283247,19620.45,64932.96
1475.888,-6.092959,-0.01289546,-18481.07,0.06117005,2,2,0.001289546,0.01289546,0.0128963,18481.06,61162.17
1480.888,-6.009599,-0.01284759,-17421.19,0.05766201,2,2,0.001284759,0.01284759,0.01284842,17421.19,57654.6
1485.888,-5.926319,-0.01299117,-16469.66,0.05451256,2,2,0.001299117,0.01299117,0.01299201,16469.66,54505.48
1490.888,-5.842959,-0.01299117,-15626.83,0.05172288,2,2,0.001299117,0.01299117,0.01299201,15626.83,51716.16
1495.888,-5.759679,-0.01297519,-14884.58,0.04926613,2,2,0.001297519,0.01297519,0.01297603,14884.58,49259.74
1500.888,-5.676279,-0.01307093,-14187.29,0.04695819,2,2,0.001307093,0.01307093,0.01307178,14187.29,46952.06
1505.888,-5.592999,-0.01315068,-13531.91,0.04478898,2,2,0.001315068,0.01315068,0.01315155,13531.91,44783.09
1510.888,-5.509639,-0.01260832,-12913.6,0.04274242,2,2,0.001260832,0.01260832,0.01260911,12913.6,42737.03
1515.888,-5.426279,-0.01286354,-12333.34,0.04082184,2,2,0.001286354,0.01286354,0.01286437,12333.34,40816.59
1520.888,-5.342959,-0.01276784,-11803.16,0.039067,2,2,0.001276784,0.01276784,0.01276865,11803.16,39062.01
1525.888,-5.259639,-0.01291141,-11309.42,0.03743279,2,2,0.001291141,0.01291141,0.01291224,11309.42,37427.96
1530.888,-5.176279,-0.01315068,-10842.07,0.03588593,2,2,0.001315068,0.01315068,0.01315155,10842.07,35881.21
1535.888,-5.092959,-0.01310281,-10392.41,0.03439761,2,2,0.001310281,0.01310281,0.01310367,10392.41,34393.11
1540.888,-5.009639,-0.01273595,-9979.811,0.03303195,2,2,0.001273595,0.01273595,0.01273676,9979.812,33027.74
1545.888,-4.926279,-0.01299117,-9592.269,0.03174923,2,2,0.001299117,0.01299117,0.01299201,9592.269,31745.11
1550.888,-4.842959,-0.01310281,-9218.71,0.0305128,2,2,0.001310281,0.01310281,0.01310367,9218.71,30508.8
1555.888,-4.759599,-0.01271997,-8857.22,0.02931631,2,2,0.001271997,0.01271997,0.01272078,8857.22,29312.58
1560.888,-4.676319,-0.01271997,-8508.107,0.02816079,2,2,0.001271997,0.01271997,0.01272078,8508.107,28157.21
1565.888,-4.592959,-0.01318257,-8166.117,0.02702885,2,2,0.001318257,0.01318257,0.01318344,8166.117,27025.28
1570.888,-4.509639,-0.0129433,-7831.085,0.02591993,2,2,0.00129433,0.0129433,0.01294413,7831.085,25916.58
1575.888,-4.426279,-0.0131347,-7504.008,0.02483735,2,2,0.00131347,0.0131347,0.01313557,7504.008,24834.08
1580.888,-4.342959,-0.013039,-7181.218,0.02376895,2,2,0.0013039,0.013039,0.01303985,7181.217,23765.85
1585.888,-4.259599,-0.01319852,-6864.963,0.02272218,2,2,0.001319852,0.01319852,0.01319939,6864.963,22719.19
1590.888,-4.176279,-0.01332615,-6556.405,0.0217009,2,2,0.001332615,0.01332615,0.01332703,6556.405,21698
1595.888,-4.092959,-0.01334209,-6254.793,0.0207026,2,2,0.001334209,0.01334209,0.01334298,6254.793,20699.84
1600.888,-4.009639,-0.01315068,-5959.344,0.0197247,2,2,0.001315068,0.01315068,0.01315155,5959.344,19722.1
1605.888,-3.926319,-0.01335803,-5666.818,0.01875647,2,2,0.001335803,0.01335803,0.01335893,5666.818,18753.97
1610.888,-3.842959,-0.01316663,-5382.689,0.01781604,2,2,0.001316663,0.01316663,0.0131675,5382.689,17813.69
1615.888,-3.75964,-0.01329422,-5101.509,0.01688537,2,2,0.001329422,0.01329422,0.0132951,5101.509,16883.12
1620.888,-3.676279,-0.01295924,-4824.841,0.01596963,2,2,0.001295924,0.01295924,0.01296008,4824.841,15967.56
1625.888,-3.59296,-0.0129433,-4552.32,0.01506762,2,2,0.00129433,0.0129433,0.01294413,4552.32,15065.67
1630.888,-3.50956,-0.013039,-4285.424,0.01418423,2,2,0.0013039,0.013039,0.01303985,4285.424,14182.38
1635.888,-3.426319,-0.01289546,-4019.38,0.01330366,2,2,0.001289546,0.01289546,0.0128963,4019.38,13301.94
1640.888,-3.342959,-0.01284759,-3761.597,0.01245042,2,2,0.001284759,0.01284759,0.01284842,3761.597,12448.83
1645.888,-3.259639,-0.01302306,-3507.021,0.01160781,2,2,0.001302306,0.01302306,0.0130239,3507.021,11606.3
1650.888,-3.176279,-0.0131347,-3257.151,0.01078077,2,2,0.00131347,0.0131347,0.01313557,3257.151,10779.36
1655.888,-3.092999,-0.01311876,-3011.233,0.009966812,2,2,0.001311876,0.01311876,0.01311962,3011.233,9965.504
1660.888,-3.009599,-0.01297519,-2774.101,0.009181934,2,2,0.001297519,0.01297519,0.01297603,2774.101,9180.743
1665.888,-2.926319,-0.01297519,-2536.695,0.00839615,2,2,0.001297519,0.01297519,0.01297603,2536.695,8395.06
1670.888,-2.842919,-0.01291141,-2305.221,0.007629998,2,2,0.001291141,0.01291141,0.01291224,2305.221,7629.012
1675.888,-2.7596,-0.01332615,-2077.565,0.006876486,2,2,0.001332615,0.01332615,0.01332703,2077.565,6875.57
1680.888,-2.67628,-0.01286354,-1859.44,0.006154518,2,2,0.001286354,0.01286354,0.01286437,1859.44,6153.726
1685.888,-2.592959,-0.01295924,-1645.388,0.005446032,2,2,0.001295924,0.01295924,0.01296008,1645.388,5445.326
1690.888,-2.50964,-0.01356538,-1445.914,0.004785797,2,2,0.001356538,0.01356538,0.0135663,1445.914,4785.148
1695.888,-2.42628,-0.0135335,-1256.913,0.004160229,2,2,0.00135335,0.0135335,0.01353441,1256.913,4159.666
1700.888,-2.34296,-0.01342185,-1092.247,0.003615202,2,2,0.001342185,0.01342185,0.01342275,1092.247,3614.717
1705.888,-2.25968,-0.01340587,-938.3518,0.003105829,2,2,0.001340587,0.01340587,0.01340677,938.3518,3105.413
1710.888,-2.17628,-0.01307093,-791.2444,0.002618922,2,2,0.001307093,0.01307093,0.01307178,791.2444,2618.58
1715.888,-2.09296,-0.01358137,-655.1099,0.002168334,2,2,0.001358137,0.01358137,0.01358229,655.1099,2168.039
1720.888,-2.00964,-0.01332615,-532.2589,0.001761712,2,2,0.001332615,0.01332615,0.01332703,532.2589,1761.477
1725.888,-1.92628,-0.01318257,-422.761,0.001399287,2,2,0.001318257,0.01318257,0.01318344,422.761,1399.103
1728.14,-1.9214,-0.01278378,-412.9069,0.001366671,0,3,0.001278378,0.01278378,0.0127846,412.9069,1366.496
1733.14,-2.00548,-0.01315068,-615.4082,0.002036926,0,3,0.001315068,0.01315068,0.01315155,615.4082,2036.658
1738.14,-2.0888,-0.01332615,-844.4487,0.002795022,0,3,0.001332615,0.01332615,0.01332703,844.4487,2794.649
1743.14,-2.17212,-0.01354944,-1087.457,0.00359935,0,3,0.001354944,0.01354944,0.01355036,1087.457,3598.863
1748.14,-2.25544,-0.01329422,-1343.341,0.004446294,0,3,0.001329422,0.01329422,0.0132951,1343.341,4445.703
1753.14,-2.33884,-0.01331016,-1636.224,0.005415701,0,3,0.001331016,0.01331016,0.01331105,1636.224,5414.98
1758.14,-2.42216,-0.0135335,-1952.986,0.006464143,0,3,0.00135335,0.0135335,0.01353441,1952.986,6463.268
1763.14,-2.50552,-0.01351755,-2275.166,0.007530519,0,3,0.001351755,0.01351755,0.01351846,2275.166,7529.502
1768.14,-2.58884,-0.0131347,-2602.253,0.008613138,0,3,0.00131347,0.0131347,0.01313557,2602.253,8612.006
1773.14,-2.67212,-0.0135335,-2932.112,0.00970493,0,3,0.00135335,0.0135335,0.01353441,2932.112,9703.617
1778.14,-2.75552,-0.01324639,-3265.028,0.01080684,0,3,0.001324639,0.01324639,0.01324726,3265.029,10805.41
1783.14,-2.8388,-0.01338992,-3597.709,0.01190798,0,3,0.001338992,0.01338992,0.01339082,3597.709,11906.38
1788.14,-2.92216,-0.01307093,-3936.089,0.01302797,0,3,0.001307093,0.01307093,0.01307178,3936.089,13026.27
1793.14,-3.00552,-0.01335803,-4273.408,0.01414446,0,3,0.001335803,0.01335803,0.01335893,4273.408,14142.57
1798.14,-3.08884,-0.01346968,-4611.469,0.0152634,0,3,0.001346968,0.01346968,0.01347059,4611.469,15261.34
1803.14,-3.17212,-0.01337398,-4951.769,0.01638975,0,3,0.001337398,0.01337398,0.01337487,4951.769,16387.56
1808.14,-3.25552,-0.01310281,-5298.935,0.01753883,0,3,0.001310281,0.01310281,0.01310367,5298.935,17536.53
1813.14,-3.3388,-0.01331016,-5642.189,0.01867495,0,3,0.001331016,0.01331016,0.01331105,5642.189,18672.47
1818.14,-3.4222,-0.01361325,-5990.539,0.01982795,0,3,0.001361325,0.01361325,0.01361418,5990.54,19825.25
1823.14,-3.50544,-0.01370896,-6337.041,0.02097483,0,3,0.001370896,0.01370896,0.0137099,6337.041,20971.95
1828.14,-3.588799,-0.01316663,-6688.131,0.02213689,0,3,0.001316663,0.01316663,0.0131675,6688.131,22133.98
1833.14,-3.672199,-0.0129433,-7035.481,0.02328658,0,3,0.00129433,0.0129433,0.01294413,7035.481,23283.57
1838.14,-3.75544,-0.01308687,-7383.779,0.0244394,0,3,0.001308687,0.01308687,0.01308773,7383.779,24436.21
1843.14,-3.8388,-0.01334209,-7733.8,0.02559793,0,3,0.001334209,0.01334209,0.01334298,7733.799,25594.51
1848.14,-3.922159,-0.01319852,-8091.605,0.02678222,0,3,0.001319852,0.01319852,0.01319939,8091.604,26778.68
1853.14,-4.005519,-0.01390036,-8450.273,0.02796937,0,3,0.001390036,0.01390036,0.01390133,8450.272,27965.48
1858.14,-4.088839,-0.01354944,-8812.228,0.02916739,0,3,0.001354944,0.01354944,0.01355036,8812.228,29163.44
1863.14,-4.172119,-0.01366109,-9170.509,0.03035326,0,3,0.001366109,0.01366109,0.01366202,9170.509,30349.11
1868.14,-4.255479,-0.01323041,-9535.348,0.03156083,0,3,0.001323041,0.01323041,0.01323128,9535.348,31556.66
1873.14,-4.338839,-0.01327828,-9900.278,0.03276871,0,3,0.001327828,0.01327828,0.01327916,9900.278,32764.36
1878.14,-4.42212,-0.01326233,-10267.7,0.03398483,0,3,0.001326233,0.01326233,0.01326321,10267.7,33980.32
1883.14,-4.505519,-0.01326233,-10633.78,0.03519651,0,3,0.001326233,0.01326233,0.01326321,10633.78,35191.84
1888.14,-4.588799,-0.01326233,-11013.1,0.03645202,0,3,0.001326233,0.01326233,0.01326321,11013.1,36447.18
1893.14,-4.672119,-0.01354944,-11385.99,0.03768622,0,3,0.001354944,0.01354944,0.01355036,11385.99,37681.11
1898.14,-4.755479,-0.01342185,-11764.48,0.038939,0,3,0.001342185,0.01342185,0.01342275,11764.48,38933.77
1903.14,-4.838839,-0.01340587,-12143.69,0.04019412,0,3,0.001340587,0.01340587,0.01340677,12143.69,40188.74
1908.14,-4.922159,-0.01337398,-12541.14,0.04150963,0,3,0.001337398,0.01337398,0.01337487,12541.14,41504.08
1913.14,-5.005559,-0.0136292,-12978.75,0.04295807,0,3,0.00136292,0.0136292,0.01363013,12978.75,42952.22
1918.14,-5.088799,-0.013039,-13426.63,0.04444049,0,3,0.0013039,0.013039,0.01303985,13426.63,44434.7
1923.14,-5.172159,-0.01315068,-13882.01,0.04594773,0,3,0.001315068,0.01315068,0.01315155,13882,45941.69
1928.14,-5.255439,-0.01351755,-14362.84,0.04753923,0,3,0.001351755,0.01351755,0.01351846,14362.84,47532.8
1933.14,-5.338839,-0.01385253,-14867.2,0.0492086,0,3,0.001385253,0.01385253,0.01385349,14867.2,49201.79
1938.14,-5.422199,-0.01319852,-15408.1,0.05099892,0,3,0.001319852,0.01319852,0.01319939,15408.1,50992.19
1943.14,-5.505479,-0.01350161,-15960.62,0.0528277,0,3,0.001350161,0.01350161,0.01350252,15960.62,52820.57
1948.14,-5.588839,-0.01340587,-16530.17,0.05471284,0,3,0.001340587,0.01340587,0.01340677,16530.17,54705.51
1953.14,-5.672159,-0.01340587,-17109.45,0.05663016,0,3,0.001340587,0.01340587,0.01340677,17109.45,56622.57
1958.14,-5.755479,-0.01350161,-17711.02,0.05862132,0,3,0.001350161,0.01350161,0.01350252,17711.02,58613.4
1963.14,-5.838839,-0.01319852,-18344.69,0.06071869,0,3,0.001319852,0.01319852,0.01319939,18344.7,60710.68
1968.14,-5.922159,-0.01316663,-19035.2,0.06300417,0,3,0.001316663,0.01316663,0.0131675,19035.2,62995.87
1973.14,-6.005479,-0.01342185,-19789.38,0.06550041,0,3,0.001342185,0.01342185,0.01342275,19789.38,65491.62
1978.14,-6.088839,-0.01354944,-20567.26,0.06807511,0,3,0.001354944,0.01354944,0.01355036,20567.26,68065.88
1983.14,-6.172079,-0.01348563,-21366.04,0.07071899,0,3,0.001348563,0.01348563,0.01348653,21366.04,70709.45
1988.14,-6.255519,-0.01375683,-22193.22,0.07345682,0,3,0.001375683,0.01375683,0.01375777,22193.22,73446.72
1993.14,-6.338799,-0.01315068,-23049.71,0.07629171,0,3,0.001315068,0.01315068,0.01315155,23049.71,76281.68
1998.14,-6.422159,-0.01334209,-23926.91,0.07919513,0,3,0.001334209,0.01334209,0.01334298,23926.91,79184.56
2003.14,-6.505479,-0.0136292,-24838.52,0.08221246,0,3,0.00136292,0.0136292,0.01363013,24838.52,82201.26
2008.14,-6.588799,-0.01356538,-25754.35,0.08524374,0,3,0.001356538,0.01356538,0.0135663,25754.35,85232.18
2013.14,-6.672119,-0.01343779,-26654.4,0.08822278,0,3,0.001343779,0.01343779,0.0134387,26654.39,88210.92
2018.14,-6.755519,-0.01359731,-27573.34,0.09126439,0,3,0.001359731,0.01359731,0.01359823,27573.34,91251.98
2023.14,-6.838759,-0.01367707,-28482.59,0.09427387,0,3,0.001367707,0.01367707,0.013678,28482.59,94260.98
2028.14,-6.922159,-0.01369301,-29407.16,0.09733408,0,3,0.001369301,0.01369301,0.01369395,29407.16,97320.75
2033.14,-7.005479,-0.01331016,-30330.93,0.1003917,0,3,0.001331016,0.01331016,0.01331105,30330.93,100378.3
2038.14,-7.088839,-0.01334209,-31263.3,0.1034777,0,3,0.001334209,0.01334209,0.01334298,31263.3,103463.9
2043.14,-7.172159,-0.01350161,-32207.44,0.1066027,0,3,0.001350161,0.01350161,0.01350252,32207.44,106588.3
2048.14,-7.255439,-0.01350161,-33162.8,0.1097648,0,3,0.001350161,0.01350161,0.01350252,33162.8,109750
2053.14,-7.338759,-0.0136292,-34125.99,0.1129528,0,3,0.00136292,0.0136292,0.01363013,34125.99,112937.4
2058.14,-7.422199,-0.01396418,-35103.34,0.1161877,0,3,0.001396418,0.01396418,0.01396515,35103.34,116171.5
2063.14,-7.505479,-0.01340587,-36085.78,0.1194395,0,3,0.001340587,0.01340587,0.01340677,36085.78,119423.5
2068.14,-7.588879,-0.01354944,-37067.38,0.1226885,0,3,0.001354944,0.01354944,0.01355036,37067.38,122671.8
2073.14,-7.672079,-0.01358137,-38067.79,0.1259997,0,3,0.001358137,0.01358137,0.01358229,38067.79,125982.6
2078.14,-7.755479,-0.01337398,-39091.21,0.1293871,0,3,0.001337398,0.01337398,0.01337487,39091.21,129369.8
2083.14,-7.838839,-0.0135335,-40124.04,0.1328056,0,3,0.00135335,0.0135335,0.01353441,40124.04,132787.7
2088.14,-7.922119,-0.01340587,-41178.1,0.1362945,0,3,0.001340587,0.01340587,0.01340677,41178.11,136276.2
2093.14,-8.005478,-0.01337398,-42245.02,0.1398258,0,3,0.001337398,0.01337398,0.01337487,42245.02,139807.1
2098.14,-8.088839,-0.01348563,-43336.51,0.1434385,0,3,0.001348563,0.01348563,0.01348653,43336.51,143419.2
2103.14,-8.172118,-0.01369301,-44447.97,0.1471173,0,3,0.001369301,0.01369301,0.01369395,44447.97,147097.2
2108.14,-8.255479,-0.01388442,-45588.02,0.1508908,0,3,0.001388442,0.01388442,0.01388538,45588.02,150869.8
2113.14,-8.338799,-0.01380466,-46757.17,0.1547605,0,3,0.001380466,0.01380466,0.01380561,46757.17,154739.1
2118.14,-8.422159,-0.01375683,-47936.79,0.1586649,0,3,0.001375683,0.01375683,0.01375777,47936.79,158643.1
2123.13,-8.505359,-0.01359731,-49176.19,0.1627671,0,3,0.001359731,0.01359731,0.01359823,49176.19,162745
2128.13,-8.588598,-0.01386847,-50391.6,0.16679,0,3,0.001386847,0.01386847,0.01386943,50391.6,166766.9
2133.022,-8.670199,-0.01407582,-51642.75,0.1709312,0,3,0.001407582,0.01407582,0.01407681,51642.75,170907.1
2137.796,-8.749719,-0.01326233,-52893.27,0.1750702,0,3,0.001326233,0.01326233,0.01326321,52893.27,175047
2142.42,-8.826879,-0.01350161,-54144.63,0.1792121,0,3,0.001350161,0.01350161,0.01350252,54144.63,179187.9
2146.652,-8.897359,-0.0135335,-55396.16,0.1833545,0,3,0.00135335,0.0135335,0.01353441,55396.16,183329.7
2150.698,-8.964759,-0.01377277,-56647.35,0.1874958,0,3,0.001377277,0.01377277,0.01377372,56647.35,187470
2154.742,-9.032199,-0.01364514,-57899.07,0.1916388,0,3,0.001364514,0.01364514,0.01364607,57899.07,191612.7
2158.732,-9.098679,-0.0137249,-59150.88,0.1957822,0,3,0.00137249,0.0137249,0.01372584,59150.88,195755.3
2162.61,-9.163318,-0.01364514,-60401.83,0.1999227,0,3,0.001364514,0.01364514,0.01364607,60401.83,199895.4
2166.498,-9.228159,-0.01359731,-61653.56,0.2040657,0,3,0.001359731,0.01359731,0.01359823,61653.56,204038
2170.254,-9.290719,-0.01375683,-62905.38,0.2082091,0,3,0.001375683,0.01375683,0.01375777,62905.38,208180.5
2174.014,-9.353358,-0.01361325,-64156.69,0.2123508,0,3,0.001361325,0.01361325,0.01361418,64156.69,212321.9
2177.73,-9.415318,-0.01378872,-65408.34,0.2164936,0,3,0.001378872,0.01378872,0.01378967,65408.34,216463.7
2181.388,-9.476239,-0.01370896,-66660,0.2206364,0,3,0.001370896,0.01370896,0.0137099,66660.01,220606.2
2185.048,-9.537279,-0.01346968,-67911.19,0.2247777,0,3,0.001346968,0.01346968,0.01347059,67911.19,224747.4
2188.664,-9.597599,-0.01380466,-69162.68,0.22892,0,3,0.001380466,0.01380466,0.01380561,69162.69,228888.4
2192.256,-9.657399,-0.01380466,-70415.06,0.2330652,0,3,0.001380466,0.01380466,0.01380561,70415.05,233033
2195.876,-9.717719,-0.01369301,-71666.95,0.2372088,0,3,0.001369301,0.01369301,0.01369395,71666.95,237176.4
2199.46,-9.777478,-0.01343779,-72918.48,0.2413512,0,3,0.001343779,0.01343779,0.0134387,72918.48,241318.8
2202.958,-9.835839,-0.01375683,-74170.42,0.245495,0,3,0.001375683,0.01375683,0.01375777,74170.41,245461.2
2206.564,-9.895879,-0.01361325,-75421.91,0.2496373,0,3,0.001361325,0.01361325,0.01361418,75421.91,249603.3
2210.092,-9.954718,-0.01374085,-76673.31,0.2537792,0,3,0.001374085,0.01374085,0.01374179,76673.3,253744.4
2213.68,-10.01444,-0.01374085,-77924.54,0.2579207,0,3,0.001374085,0.01374085,0.01374179,77924.54,257885.2
2217.26,-10.07408,-0.01393229,-79176.19,0.2620635,0,3,0.001393229,0.01393229,0.01393326,79176.2,262027
2220.72,-10.13188,-0.01378872,-80428.33,0.2662079,0,3,0.001378872,0.01378872,0.01378967,80428.33,266171.2
2224.068,-10.1876,-0.01359731,-81602.44,0.2700941,0,3,0.001359731,0.01359731,0.01359823,81602.45,270057.4