File: ElectricPoleSupport/ExptData/Raw/Heel_E1_cycle.raw.csv
"Test Type","Compression"
"Temperature:","20.5"
"Humidity:","57.5"
"Geometry:","Rectangular"
"Specimen",1
"Specimen name:","E1"
"Width:",333.000000,"mm"
"Thickness:",452.000000,"mm"
"Anvil height:",90.000000,"mm"
"Diameter:",50.000000,"mm"
"Inner diameter:",0.500000,"mm"
"Outer diameter:",1.000000,"mm"
"Wall thickness:",0.500000,"mm"
"Area:",150516.000000,"mm*mm"
"Linear density:",1.000000,"den"
"Sled weight:",9.806650,"N"
"Loading span:",0.000000,"mm"
"Support span:",1.000000,"mm"
"Span ratio:","2"
"Fixture type:","3-point"
"Extensometer",-10.000000,"**mm"
"Included"
"Time sec","Extension mm","Strain 1 %","Load N","Comp. stress MPa","Cycle Count ","Total Cycle Count ","Comp. extension mm","Comp. strain %","True strain %","Comp. load N","True stress Pa"
0,-0.4688,-0.02594352,-301.7175,0.002004554,0,0,0.002594352,0.02594352,0.02594688,301.7175,2004.034
1,-0.4851599,-0.02583187,-304.3174,0.002021827,0,0,0.002583187,0.02583187,0.02583521,304.3174,2021.305
2,-0.5020399,-0.02564047,-306.547,0.00203664,0,0,0.002564047,0.02564047,0.02564375,306.547,2036.118
3,-0.5188399,-0.02570424,-308.887,0.002052187,0,0,0.002570424,0.02570424,0.02570755,308.887,2051.66
4,-0.5354799,-0.02564047,-313.0493,0.002079841,0,0,0.002564047,0.02564047,0.02564375,313.0493,2079.307
5,-0.5521199,-0.02579994,-315.046,0.002093106,0,0,0.002579994,0.02579994,0.02580327,315.046,2092.566
6,-0.5687599,-0.02557665,-317.9113,0.002112143,0,0,0.002557665,0.02557665,0.02557992,317.9113,2111.603
7,-0.5853999,-0.02597541,-322.0008,0.002139312,0,0,0.002597541,0.02597541,0.02597878,322.0008,2138.757
8,-0.6020799,-0.0258797,-323.6609,0.002150342,0,0,0.00258797,0.0258797,0.02588305,323.6609,2149.786
9,-0.6187599,-0.02562448,-329.9854,0.002192361,0,0,0.002562448,0.02562448,0.02562777,329.9854,2191.799
10,-0.6353998,-0.02562448,-335.0023,0.002225692,0,0,0.002562448,0.02562448,0.02562777,335.0023,2225.122
11,-0.6521599,-0.02576806,-345.7857,0.002297335,0,0,0.002576806,0.02576806,0.02577138,345.7857,2296.743
12,-0.6688399,-0.025784,-366.1938,0.002432923,0,0,0.0025784,0.025784,0.02578733,366.1938,2432.295
13,-0.6855198,-0.02572019,-392.2219,0.002605848,0,0,0.002572019,0.02572019,0.02572349,392.2219,2605.178
14,-0.7021199,-0.02556071,-424.5135,0.002820387,0,0,0.002556071,0.02556071,0.02556397,424.5135,2819.667
15,-0.7187999,-0.02594352,-462.0117,0.003069519,0,0,0.002594352,0.02594352,0.02594688,462.0117,3068.723
16,-0.7354398,-0.02584781,-507.7932,0.003373682,0,0,0.002584781,0.02584781,0.02585116,507.7932,3372.811
17,-0.7521199,-0.02589568,-555.1294,0.003688175,0,0,0.002589568,0.02589568,0.02589904,555.1294,3687.22
18,-0.7687198,-0.0262785,-604.4734,0.004016008,0,0,0.00262785,0.0262785,0.02628195,604.4734,4014.952
19,-0.7854799,-0.02635825,-656.584,0.004362221,0,0,0.002635826,0.02635825,0.02636173,656.584,4361.071
20,-0.8021199,-0.02595946,-707.2184,0.004698626,0,0,0.002595946,0.02595946,0.02596283,707.2184,4697.406
21,-0.8187999,-0.02611898,-759.815,0.005048068,0,0,0.002611898,0.02611898,0.02612239,759.815,5046.75
22,-0.8354799,-0.02597541,-810.8438,0.005387094,0,0,0.002597541,0.02597541,0.02597878,810.8438,5385.694
23,-0.8521199,-0.02591163,-862.6396,0.005731215,0,0,0.002591163,0.02591163,0.02591499,862.6396,5729.73
24,-0.8687999,-0.02592757,-915.2765,0.006080925,0,0,0.002592757,0.02592757,0.02593094,915.2766,6079.349
25,-0.8854399,-0.02608709,-966.6518,0.006422253,0,0,0.002608709,0.02608709,0.02609049,966.6519,6420.578
26,-0.9020799,-0.0261509,-1020.49,0.006779946,0,0,0.002615091,0.0261509,0.02615433,1020.49,6778.173
27,-0.9187599,-0.02607115,-1073.845,0.007134427,0,0,0.002607115,0.02607115,0.02607454,1073.845,7132.567
28,-0.9354798,-0.02576806,-1127.669,0.007492018,0,0,0.002576806,0.02576806,0.02577138,1127.669,7490.087
29,-0.9521599,-0.02592757,-1182.062,0.007853396,0,0,0.002592757,0.02592757,0.02593094,1182.062,7851.36
30,-0.9688399,-0.02600733,-1237.101,0.008219067,0,0,0.002600733,0.02600733,0.02601071,1237.101,8216.93
31,-0.9854798,-0.02548095,-1292.198,0.008585118,0,0,0.002548095,0.02548095,0.0254842,1292.198,8582.93
32,-1.00212,-0.02613492,-1347.316,0.008951314,0,0,0.002613492,0.02613492,0.02613834,1347.316,8948.974
33,-1.0188,-0.02597541,-1403.255,0.009322965,0,0,0.002597541,0.02597541,0.02597878,1403.255,9320.543
34,-1.03544,-0.02573617,-1459.367,0.009695761,0,0,0.002573617,0.02573617,0.02573948,1459.367,9693.265
35,-1.05216,-0.0256883,-1517.621,0.01008279,0,0,0.00256883,0.0256883,0.0256916,1517.621,10080.2
36,-1.06884,-0.02586376,-1576.504,0.010474,0,0,0.002586376,0.02586376,0.0258671,1576.504,10471.29
37,-1.08544,-0.02557665,-1635.918,0.01086873,0,0,0.002557665,0.02557665,0.02557992,1635.918,10865.95
38,-1.10212,-0.02591163,-1698.771,0.01128632,0,0,0.002591163,0.02591163,0.02591499,1698.771,11283.39
39,-1.11876,-0.02556071,-1761.002,0.01169976,0,0,0.002556071,0.02556071,0.02556397,1761.002,11696.77
40,-1.13544,-0.02573617,-1827.296,0.01214021,0,0,0.002573617,0.02573617,0.02573948,1827.296,12137.09
41,-1.15212,-0.02592757,-1893.683,0.01258128,0,0,0.002592757,0.02592757,0.02593094,1893.683,12578.01
42,-1.16876,-0.02541713,-1962.91,0.01304121,0,0,0.002541713,0.02541713,0.02542036,1962.91,13037.89
43,-1.18544,-0.02564047,-2033.421,0.01350966,0,0,0.002564047,0.02564047,0.02564375,2033.421,13506.2
44,-1.20216,-0.02564047,-2104.948,0.01398488,0,0,0.002564047,0.02564047,0.02564375,2104.948,13981.29
45,-1.2188,-0.02579994,-2179.037,0.01447711,0,0,0.002579994,0.02579994,0.02580327,2179.037,14473.38
46,-1.23548,-0.0258797,-2256.315,0.01499053,0,0,0.00258797,0.0258797,0.02588305,2256.315,14986.65
47,-1.25216,-0.0256883,-2334.476,0.01550982,0,0,0.00256883,0.0256883,0.0256916,2334.477,15505.84
48,-1.2688,-0.0256883,-2414.494,0.01604144,0,0,0.00256883,0.0256883,0.0256916,2414.494,16037.32
49,-1.28544,-0.02579994,-2496.734,0.01658783,0,0,0.002579994,0.02579994,0.02580327,2496.734,16583.55
50,-1.30208,-0.0256883,-2579.817,0.01713982,0,0,0.00256883,0.0256883,0.0256916,2579.817,17135.41
51,-1.31876,-0.02552878,-2664.97,0.01770556,0,0,0.002552878,0.02552878,0.02553204,2664.97,17701.04
52,-1.33548,-0.02567235,-2749.714,0.01826858,0,0,0.002567235,0.02567235,0.02567565,2749.714,18263.89
53,-1.35216,-0.02556071,-2834.983,0.01883509,0,0,0.002556071,0.02556071,0.02556397,2834.983,18830.28
54,-1.36884,-0.02586376,-2922.869,0.01941899,0,0,0.002586376,0.02586376,0.0258671,2922.869,19413.97
55,-1.38544,-0.02556071,-3012.369,0.02001361,0,0,0.002556071,0.02556071,0.02556397,3012.369,20008.5
56,-1.40208,-0.02552878,-3104.272,0.0206242,0,0,0.002552878,0.02552878,0.02553204,3104.272,20618.94
57,-1.41876,-0.02554473,-3201.376,0.02126934,0,0,0.002554473,0.02554473,0.02554799,3201.376,21263.91
58,-1.43544,-0.02567235,-3298.624,0.02191544,0,0,0.002567235,0.02567235,0.02567565,3298.624,21909.81
59,-1.45208,-0.02607115,-3401.496,0.0225989,0,0,0.002607115,0.02607115,0.02607454,3401.496,22593
60,-1.46884,-0.02595946,-3508.446,0.02330945,0,0,0.002595946,0.02595946,0.02596283,3508.446,23303.4
61,-1.48548,-0.02541713,-3615.622,0.02402151,0,0,0.002541713,0.02541713,0.02542036,3615.622,24015.41
62,-1.50216,-0.0258797,-3724.927,0.02474771,0,0,0.00258797,0.0258797,0.02588305,3724.927,24741.31
63,-1.5188,-0.02549689,-3834.993,0.02547898,0,0,0.002549689,0.02549689,0.02550014,3834.993,25472.48
64,-1.53544,-0.02572019,-3946.29,0.02621841,0,0,0.002572019,0.02572019,0.02572349,3946.29,26211.67
65,-1.55208,-0.02541713,-4061.647,0.02698482,0,0,0.002541713,0.02541713,0.02542036,4061.647,26977.96
66,-1.5688,-0.02557665,-4180.096,0.02777177,0,0,0.002557665,0.02557665,0.02557992,4180.096,27764.67
67,-1.58544,-0.02530549,-4300.294,0.02857034,0,0,0.002530549,0.02530549,0.02530869,4300.293,28563.11
68,-1.60216,-0.02556071,-4423.326,0.02938775,0,0,0.002556071,0.02556071,0.02556397,4423.326,29380.24
69,-1.61876,-0.02548095,-4545.173,0.03019727,0,0,0.002548095,0.02548095,0.0254842,4545.173,30189.58
70,-1.63548,-0.02551284,-4669.262,0.0310217,0,0,0.002551284,0.02551284,0.02551609,4669.263,31013.79
71,-1.65212,-0.02592757,-4795.383,0.03185963,0,0,0.002592757,0.02592757,0.02593094,4795.383,31851.36
72,-1.6688,-0.02602328,-4920.3,0.03268955,0,0,0.002602328,0.02602328,0.02602666,4920.3,32681.04
73,-1.6854,-0.0258797,-5048.398,0.0335406,0,0,0.00258797,0.0258797,0.02588305,5048.397,33531.92
74,-1.70216,-0.0261509,-5176.86,0.03439409,0,0,0.002615091,0.0261509,0.02615433,5176.86,34385.09
75,-1.71876,-0.02575211,-5306.511,0.03525546,0,0,0.002575211,0.02575211,0.02575543,5306.511,35246.38
76,-1.73548,-0.02611898,-5440.987,0.03614889,0,0,0.002611898,0.02611898,0.02612239,5440.987,36139.45
77,-1.75212,-0.02608709,-5573.716,0.03703072,0,0,0.002608709,0.02608709,0.02609049,5573.716,37021.06
78,-1.7688,-0.02600733,-5708.098,0.03792353,0,0,0.002600733,0.02600733,0.02601071,5708.098,37913.66
79,-1.78544,-0.025784,-5843.665,0.03882421,0,0,0.0025784,0.025784,0.02578733,5843.665,38814.2
80,-1.80212,-0.02552878,-5978.628,0.03972088,0,0,0.002552878,0.02552878,0.02553204,5978.627,39710.74
81,-1.81872,-0.02592757,-6115.093,0.04062753,0,0,0.002592757,0.02592757,0.02593094,6115.093,40616.99
82,-1.83548,-0.02599139,-6251.046,0.04153077,0,0,0.002599139,0.02599139,0.02599477,6251.046,41519.98
83,-1.85208,-0.02586376,-6387.601,0.04243802,0,0,0.002586376,0.02586376,0.0258671,6387.601,42427.04
84,-1.86884,-0.02616685,-6528.062,0.04337122,0,0,0.002616685,0.02616685,0.02617027,6528.062,43359.86
85,-1.88544,-0.02581593,-6667.048,0.04429461,0,0,0.002581593,0.02581593,0.02581926,6667.048,44283.18
86,-1.90216,-0.02570424,-6809.948,0.04524401,0,0,0.002570424,0.02570424,0.02570755,6809.948,45232.38
87,-1.91876,-0.02584781,-6954.402,0.04620374,0,0,0.002584781,0.02584781,0.02585116,6954.402,46191.79
88,-1.9354,-0.02565641,-7098.726,0.0471626,0,0,0.002565641,0.02565641,0.0256597,7098.726,47150.5
89,-1.95208,-0.02535332,-7245.126,0.04813525,0,0,0.002535332,0.02535332,0.02535653,7245.125,48123.05
90,-1.9688,-0.02575211,-7395.808,0.04913636,0,0,0.002575211,0.02575211,0.02575543,7395.808,49123.7
91,-1.98544,-0.02552878,-7546.863,0.05013994,0,0,0.002552878,0.02552878,0.02553204,7546.863,50127.14
92,-2.00216,-0.02579994,-7702.275,0.05117247,0,0,0.002579994,0.02579994,0.02580327,7702.275,51159.27
93,-2.0188,-0.02575211,-7861.022,0.05222715,0,0,0.002575211,0.02575211,0.02575543,7861.022,52213.7
94,-2.03548,-0.02592757,-8023.212,0.05330471,0,0,0.002592757,0.02592757,0.02593094,8023.212,53290.89
95,-2.05208,-0.02600733,-8189.447,0.05440915,0,0,0.002600733,0.02600733,0.02601071,8189.447,54395
96,-2.0688,-0.02575211,-8360.165,0.05554337,0,0,0.002575211,0.02575211,0.02575543,8360.165,55529.06
97,-2.0854,-0.02544902,-8532.868,0.05669076,0,0,0.002544902,0.02544902,0.02545226,8532.867,56676.34
98,-2.10212,-0.02538525,-8713.175,0.05788871,0,0,0.002538525,0.02538525,0.02538847,8713.176,57874.01
99,-2.11872,-0.0256883,-8890.437,0.05906639,0,0,0.00256883,0.0256883,0.0256916,8890.438,59051.22
100,-2.13548,-0.02536926,-9078.803,0.06031786,0,0,0.002536926,0.02536926,0.02537248,9078.803,60302.56
101,-2.15212,-0.025784,-9269.194,0.06158279,0,0,0.0025784,0.025784,0.02578733,9269.194,61566.91
102,-2.1688,-0.02572019,-9460.524,0.06285394,0,0,0.002572019,0.02572019,0.02572349,9460.523,62837.77
103,-2.18544,-0.02527356,-9656.577,0.06415648,0,0,0.002527356,0.02527356,0.02527676,9656.577,64140.27
104,-2.20216,-0.02552878,-9849.674,0.06543938,0,0,0.002552878,0.02552878,0.02553204,9849.674,65422.67
105,-2.21876,-0.02554473,-10045.67,0.06674153,0,0,0.002554473,0.02554473,0.02554799,10045.67,66724.49
106,-2.23544,-0.02570424,-10249.22,0.06809389,0,0,0.002570424,0.02570424,0.02570755,10249.22,68076.39
107,-2.25208,-0.0258797,-10457.45,0.06947736,0,0,0.00258797,0.0258797,0.02588305,10457.45,69459.38
108,-2.2688,-0.0256883,-10672.62,0.07090689,0,0,0.00256883,0.0256883,0.0256916,10672.62,70888.68
109,-2.28548,-0.02554473,-10886.91,0.07233057,0,0,0.002554473,0.02554473,0.02554799,10886.91,72312.1
110,-2.30216,-0.02532143,-11102.39,0.07376218,0,0,0.002532143,0.02532143,0.02532464,11102.39,73743.5
111,-2.31876,-0.02552878,-11319.66,0.07520568,0,0,0.002552878,0.02552878,0.02553204,11319.66,75186.48
112,-2.33548,-0.02570424,-11536.62,0.07664715,0,0,0.002570424,0.02570424,0.02570755,11536.62,76627.45
113,-2.35208,-0.02556071,-11739.98,0.07799824,0,0,0.002556071,0.02556071,0.02556397,11739.98,77978.3
114,-2.3688,-0.02562448,-11941.65,0.0793381,0,0,0.002562448,0.02562448,0.02562777,11941.65,79317.78
115,-2.38544,-0.02536926,-12114.74,0.08048808,0,0,0.002536926,0.02536926,0.02537248,12114.74,80467.66
116,-2.40208,-0.0256883,-12317.4,0.08183447,0,0,0.00256883,0.0256883,0.0256916,12317.4,81813.45
117,-2.41876,-0.02557665,-12531.4,0.08325627,0,0,0.002557665,0.02557665,0.02557992,12531.4,83234.98
118,-2.43548,-0.02595946,-12741.88,0.08465466,0,0,0.002595946,0.02595946,0.02596283,12741.88,84632.68
119,-2.45212,-0.02605516,-12952.76,0.08605567,0,0,0.002605516,0.02605516,0.02605856,12952.76,86033.25
120,-2.4688,-0.02591163,-13181.36,0.0875745,0,0,0.002591163,0.02591163,0.02591499,13181.36,87551.82
121,-2.485439,-0.02573617,-13389.02,0.08895414,0,0,0.002573617,0.02573617,0.02573948,13389.02,88931.25
122,-2.50208,-0.02589568,-13521.96,0.08983735,0,0,0.002589568,0.02589568,0.02589904,13521.96,89814.09
123,-2.51876,-0.02572019,-13725.67,0.0911908,0,0,0.002572019,0.02572019,0.02572349,13725.67,91167.34
124,-2.535479,-0.02584781,-13934.83,0.09258036,0,0,0.002584781,0.02584781,0.02585116,13934.83,92556.43
125,-2.552159,-0.02546497,-14169.61,0.09414023,0,0,0.002546497,0.02546497,0.02546821,14169.61,94116.26
126,-2.568839,-0.02595946,-14381.3,0.09554666,0,0,0.002595946,0.02595946,0.02596283,14381.3,95521.85
126.98,-2.58512,-0.0255926,-14631.44,0.09720854,0,0,0.00255926,0.0255926,0.02559587,14631.44,97183.66
127.892,-2.60032,-0.02586376,-14881.83,0.09887211,0,0,0.002586376,0.02586376,0.0258671,14881.83,98846.54
128.754,-2.61464,-0.02576806,-15132.28,0.100536,0,0,0.002576806,0.02576806,0.02577138,15132.28,100510.1
129.566,-2.62816,-0.02565641,-15382.93,0.1022013,0,0,0.002565641,0.02565641,0.0256597,15382.93,102175.1
130.35,-2.64128,-0.02536926,-15633.42,0.1038655,0,0,0.002536926,0.02536926,0.02537248,15633.42,103839.1
131.124,-2.65416,-0.02541713,-15883.97,0.1055301,0,0,0.002541713,0.02541713,0.02542036,15883.97,105503.3
131.86,-2.66644,-0.02556071,-16134.25,0.1071929,0,0,0.002556071,0.02556071,0.02556397,16134.25,107165.5
132.582,-2.67852,-0.0256883,-16384.68,0.1088567,0,0,0.00256883,0.0256883,0.0256916,16384.68,108828.8
133.298,-2.69044,-0.025784,-16635.04,0.1105201,0,0,0.0025784,0.025784,0.02578733,16635.04,110491.6
134.02,-2.70248,-0.02564047,-16885.68,0.1121853,0,0,0.002564047,0.02564047,0.02564375,16885.68,112156.5
134.738,-2.714439,-0.02579994,-17135.75,0.1138467,0,0,0.002579994,0.02579994,0.02580327,17135.75,113817.3
135.43,-2.72592,-0.02623063,-17386.26,0.115511,0,0,0.002623063,0.02623063,0.02623407,17386.26,115480.7
136.124,-2.737519,-0.02575211,-17636.68,0.1171748,0,0,0.002575211,0.02575211,0.02575543,17636.68,117144.6
136.886,-2.750199,-0.02594352,-17887.25,0.1188395,0,0,0.002594352,0.02594352,0.02594688,17887.25,118808.7
137.684,-2.76348,-0.02594352,-18137.52,0.1205023,0,0,0.002594352,0.02594352,0.02594688,18137.52,120471
138.432,-2.776,-0.02613492,-18387.8,0.1221651,0,0,0.002613492,0.02613492,0.02613834,18387.8,122133.2
139.162,-2.78812,-0.0258797,-18637.83,0.1238263,0,0,0.00258797,0.0258797,0.02588305,18637.83,123794.2
139.91,-2.8006,-0.02610303,-18888.54,0.1254919,0,0,0.002610303,0.02610303,0.02610644,18888.54,125459.2
140.634,-2.81272,-0.02621468,-19139.16,0.127157,0,0,0.002621468,0.02621468,0.02621812,19139.16,127123.6
141.46,-2.82648,-0.02594352,-19389.23,0.1288184,0,0,0.002594352,0.02594352,0.02594688,19389.23,128785
142.298,-2.840479,-0.0258797,-19639.45,0.1304808,0,0,0.00258797,0.0258797,0.02588305,19639.45,130447
142.916,-2.85072,-0.02595946,-19369.76,0.1286891,0,0,0.002595946,0.02595946,0.02596283,19369.76,128655.6
142.93,-2.850959,-0.02584781,-19111.81,0.1269753,0,0,0.002584781,0.02584781,0.02585116,19111.81,126942.4
142.95,-2.85132,-0.02605516,-18843.56,0.1251931,0,0,0.002605516,0.02605516,0.02605856,18843.56,125160.5
142.99,-2.852,-0.0261509,-18585.69,0.1234798,0,0,0.002615091,0.0261509,0.02615433,18585.69,123447.5
143.11,-2.854,-0.0262785,-18335.36,0.1218167,0,0,0.00262785,0.0262785,0.02628195,18335.36,121784.7
144.11,-2.87068,-0.0262785,-18413.75,0.1223375,0,0,0.00262785,0.0262785,0.02628195,18413.75,122305.3
144.708,-2.8806,-0.02575211,-18663.96,0.1239999,0,0,0.002575211,0.02575211,0.02575543,18663.96,123967.9
145.278,-2.89008,-0.02613492,-18914.66,0.1256655,0,0,0.002613492,0.02613492,0.02613834,18914.66,125632.6
145.794,-2.898639,-0.02560854,-19165.55,0.1273323,0,0,0.002560854,0.02560854,0.02561182,19165.55,127299.7
146.288,-2.90692,-0.02583187,-19415.86,0.1289953,0,0,0.002583187,0.02583187,0.02583521,19415.86,128962
146.802,-2.91544,-0.02552878,-19666.18,0.1306584,0,0,0.002552878,0.02552878,0.02553204,19666.18,130625
147.324,-2.92416,-0.02562448,-19916.64,0.1323224,0,0,0.002562448,0.02562448,0.02562777,19916.64,132288.5
147.85,-2.932959,-0.02581593,-20167.38,0.1339883,0,0,0.002581593,0.02581593,0.02581926,20167.38,133953.7
148.382,-2.94184,-0.02573617,-20417.69,0.1356513,0,0,0.002573617,0.02573617,0.02573948,20417.69,135616.4
148.914,-2.950719,-0.02573617,-20668.51,0.1373177,0,0,0.002573617,0.02573617,0.02573948,20668.51,137282.3
149.45,-2.95964,-0.02589568,-20918.69,0.1389798,0,0,0.002589568,0.02589568,0.02589904,20918.69,138943.8
150,-2.968799,-0.02579994,-21168.84,0.1406418,0,0,0.002579994,0.02579994,0.02580327,21168.84,140605.5
150.558,-2.978119,-0.02564047,-21418.98,0.1423037,0,0,0.002564047,0.02564047,0.02564375,21418.98,142267.2
151.094,-2.98704,-0.0256883,-21669.28,0.1439666,0,0,0.00256883,0.0256883,0.0256916,21669.28,143929.7
151.622,-2.995799,-0.02581593,-21920.14,0.1456333,0,0,0.002581593,0.02581593,0.02581926,21920.14,145595.7
152.126,-3.0042,-0.02560854,-22170.23,0.1472948,0,0,0.002560854,0.02560854,0.02561182,22170.23,147257.1
152.63,-3.012599,-0.02572019,-22420.26,0.148956,0,0,0.002572019,0.02572019,0.02572349,22420.26,148917.7
153.136,-3.021079,-0.02570424,-22670.31,0.1506173,0,0,0.002570424,0.02570424,0.02570755,22670.31,150578.6
153.636,-3.02932,-0.02594352,-22921.02,0.1522829,0,0,0.002594352,0.02594352,0.02594688,22921.02,152243.4
154.124,-3.037479,-0.02552878,-23171.08,0.1539443,0,0,0.002552878,0.02552878,0.02553204,23171.08,153905
154.62,-3.04576,-0.025784,-23421.66,0.1556091,0,0,0.0025784,0.025784,0.02578733,23421.66,155569
155.106,-3.053839,-0.02586376,-23672.3,0.1572743,0,0,0.002586376,0.02586376,0.0258671,23672.3,157233.6
155.58,-3.0618,-0.02597541,-23922.68,0.1589378,0,0,0.002597541,0.02597541,0.02597878,23922.68,158896.5
156.05,-3.069639,-0.02570424,-24172.89,0.1606002,0,0,0.002570424,0.02570424,0.02570755,24172.89,160558.9
156.508,-3.07724,-0.02557665,-24423.68,0.1622663,0,0,0.002557665,0.02557665,0.02557992,24423.68,162224.8
156.966,-3.084879,-0.02557665,-24674,0.1639294,0,0,0.002557665,0.02557665,0.02557992,24674,163887.5
157.412,-3.09232,-0.02586376,-24924.06,0.1655907,0,0,0.002586376,0.02586376,0.0258671,24924.06,165547.9
157.854,-3.09968,-0.02621468,-25175.06,0.1672584,0,0,0.002621468,0.02621468,0.02621812,25175.06,167214.6
158.29,-3.107,-0.02595946,-25426.21,0.168927,0,0,0.002595946,0.02595946,0.02596283,25426.21,168883.1
158.732,-3.11436,-0.02618279,-25677.05,0.1705935,0,0,0.002618279,0.02618279,0.02618622,25677.05,170548.8
159.172,-3.12164,-0.02594352,-25927.36,0.1722565,0,0,0.002594352,0.02594352,0.02594688,25927.37,172211.8
159.598,-3.128719,-0.0256883,-26178.21,0.1739231,0,0,0.00256883,0.0256883,0.0256916,26178.21,173878.4
160.014,-3.13564,-0.02581593,-26428.71,0.1755874,0,0,0.002581593,0.02581593,0.02581926,26428.71,175542
160.426,-3.142559,-0.02594352,-26679.52,0.1772538,0,0,0.002594352,0.02594352,0.02594688,26679.53,177207.8
160.842,-3.149479,-0.0256883,-26929.85,0.1789169,0,0,0.00256883,0.0256883,0.0256916,26929.85,178870.9
161.254,-3.15632,-0.02602328,-27180.17,0.18058,0,0,0.002602328,0.02602328,0.02602666,27180.17,180533
161.672,-3.163239,-0.02564047,-27431.15,0.1822474,0,0,0.002564047,0.02564047,0.02564375,27431.15,182200.7
162.082,-3.170079,-0.02573617,-27681.16,0.1839084,0,0,0.002573617,0.02573617,0.02573948,27681.16,183861.1
162.482,-3.1768,-0.02589568,-27931.91,0.1855743,0,0,0.002589568,0.02589568,0.02589904,27931.91,185526.3
162.894,-3.18368,-0.0258797,-28182.22,0.1872374,0,0,0.00258797,0.0258797,0.02588305,28182.22,187188.9
163.316,-3.19068,-0.02629444,-28433.42,0.1889063,0,0,0.002629444,0.02629444,0.0262979,28433.42,188856.6
163.72,-3.19744,-0.02624661,-28683.86,0.1905701,0,0,0.002624661,0.02624661,0.02625005,28683.86,190520.1
164.12,-3.20412,-0.02567235,-28935.05,0.192239,0,0,0.002567235,0.02567235,0.02567565,28935.04,192189.6
164.514,-3.210719,-0.0258797,-29186.03,0.1939065,0,0,0.00258797,0.0258797,0.02588305,29186.03,193856.3
164.918,-3.21744,-0.02591163,-29437.06,0.1955743,0,0,0.002591163,0.02591163,0.02591499,29437.06,195523.6
165.342,-3.22448,-0.02597541,-29687.65,0.1972392,0,0,0.002597541,0.02597541,0.02597878,29687.65,197187.9
165.766,-3.231519,-0.02619874,-29938.43,0.1989053,0,0,0.002619874,0.02619874,0.02620217,29938.43,198853.2
166.18,-3.238439,-0.02583187,-30189.24,0.2005716,0,0,0.002583187,0.02583187,0.02583521,30189.24,200519.8
166.582,-3.245159,-0.025784,-30440.32,0.2022397,0,0,0.0025784,0.025784,0.02578733,30440.32,202187.6
166.982,-3.25184,-0.02592757,-30690.91,0.2039046,0,0,0.002592757,0.02592757,0.02593094,30690.91,203851.8
167.398,-3.25872,-0.02570424,-30941.78,0.2055714,0,0,0.002570424,0.02570424,0.02570755,30941.78,205518.5
167.788,-3.265239,-0.02602328,-31192.29,0.2072357,0,0,0.002602328,0.02602328,0.02602666,31192.29,207181.8
168.174,-3.271679,-0.02570424,-31442.64,0.208899,0,0,0.002570424,0.02570424,0.02570755,31442.64,208845.3
168.568,-3.27828,-0.02573617,-31693.24,0.2105639,0,0,0.002573617,0.02573617,0.02573948,31693.24,210509.7
168.966,-3.284879,-0.0256883,-31944.45,0.2122329,0,0,0.00256883,0.0256883,0.0256916,31944.45,212178.4
169.358,-3.291439,-0.02595946,-32194.78,0.2138961,0,0,0.002595946,0.02595946,0.02596283,32194.78,213840.5
169.75,-3.29788,-0.02595946,-32444.97,0.2155583,0,0,0.002595946,0.02595946,0.02596283,32444.97,215502.4
170.136,-3.30432,-0.02589568,-32696.07,0.2172266,0,0,0.002589568,0.02589568,0.02589904,32696.07,217170.3
170.514,-3.310679,-0.02602328,-32946.6,0.218891,0,0,0.002602328,0.02602328,0.02602666,32946.59,218834
170.89,-3.316959,-0.02610303,-33196.96,0.2205544,0,0,0.002610303,0.02610303,0.02610644,33196.96,220496.8
171.278,-3.323359,-0.02594352,-33447.79,0.2222209,0,0,0.002594352,0.02594352,0.02594688,33447.79,222163.2
171.658,-3.329719,-0.02610303,-33698.34,0.2238854,0,0,0.002610303,0.02610303,0.02610644,33698.34,223827
172.052,-3.33632,-0.02621468,-33949.23,0.2255523,0,0,0.002621468,0.02621468,0.02621812,33949.23,225493.1
172.438,-3.342759,-0.02616685,-34199.58,0.2272156,0,0,0.002616685,0.02616685,0.02617027,34199.58,227156.1
172.812,-3.348959,-0.02586376,-34450.01,0.2288794,0,0,0.002586376,0.02586376,0.0258671,34450.01,228820.2
173.182,-3.35512,-0.02635825,-34700.36,0.2305427,0,0,0.002635826,0.02635825,0.02636173,34700.36,230481.9
173.558,-3.36136,-0.02595946,-34950.44,0.2322041,0,0,0.002595946,0.02595946,0.02596283,34950.44,232143.9
173.924,-3.36748,-0.02567235,-35200.49,0.2338655,0,0,0.002567235,0.02567235,0.02567565,35200.5,233805.4
174.296,-3.37372,-0.02605516,-35451.56,0.2355335,0,0,0.002605516,0.02605516,0.02605856,35451.56,235472.1
174.664,-3.379879,-0.02605516,-35701.72,0.2371955,0,0,0.002605516,0.02605516,0.02605856,35701.72,237133.7
175.04,-3.38616,-0.02565641,-35952.49,0.2388616,0,0,0.002565641,0.02565641,0.0256597,35952.49,238800.3
175.422,-3.392439,-0.02573617,-36203.15,0.2405269,0,0,0.002573617,0.02573617,0.02573948,36203.14,240465
175.792,-3.398639,-0.02610303,-36453.18,0.2421881,0,0,0.002610303,0.02610303,0.02610644,36453.18,242124.8
176.158,-3.404719,-0.02595946,-36703.4,0.2438505,0,0,0.002595946,0.02595946,0.02596283,36703.39,243787.2
176.524,-3.4108,-0.02605516,-36954.37,0.2455179,0,0,0.002605516,0.02605516,0.02605856,36954.37,245453.9
176.894,-3.417,-0.02567235,-37204.66,0.2471808,0,0,0.002567235,0.02567235,0.02567565,37204.66,247117.3
177.27,-3.423239,-0.02611898,-37455.11,0.2488447,0,0,0.002611898,0.02611898,0.02612239,37455.11,248779.7
177.648,-3.42952,-0.02586376,-37705.32,0.2505071,0,0,0.002586376,0.02586376,0.0258671,37705.32,250442.3
178.022,-3.43576,-0.02548095,-37955.68,0.2521704,0,0,0.002548095,0.02548095,0.0254842,37955.68,252106.2
178.398,-3.442079,-0.02605516,-38206.16,0.2538345,0,0,0.002605516,0.02605516,0.02605856,38206.16,253768.4
178.768,-3.448239,-0.02584781,-38456.37,0.2554969,0,0,0.002584781,0.02584781,0.02585116,38456.38,255430.9
179.154,-3.45464,-0.02608709,-38707.41,0.2571648,0,0,0.002608709,0.02608709,0.02609049,38707.41,257097.7
179.534,-3.460959,-0.02621468,-38958.68,0.2588342,0,0,0.002621468,0.02621468,0.02621812,38958.68,258766.3
179.906,-3.4672,-0.02567235,-39209.01,0.2604973,0,0,0.002567235,0.02567235,0.02567565,39209.01,260430.4
180.278,-3.47344,-0.02581593,-39460.06,0.2621652,0,0,0.002581593,0.02581593,0.02581926,39460.06,262097.5
180.654,-3.479719,-0.02567235,-39710.79,0.263831,0,0,0.002567235,0.02567235,0.02567565,39710.79,263763.2
181.022,-3.485839,-0.02576806,-39961.17,0.2654945,0,0,0.002576806,0.02576806,0.02577138,39961.16,265426.1
181.394,-3.492,-0.02621468,-40212.11,0.2671617,0,0,0.002621468,0.02621468,0.02621812,40212.11,267091.6
181.772,-3.49828,-0.0258797,-40462.76,0.268827,0,0,0.00258797,0.0258797,0.02588305,40462.76,268757.4
182.14,-3.50444,-0.02619874,-40713.28,0.2704914,0,0,0.002619874,0.02619874,0.02620217,40713.28,270420.5
182.51,-3.510639,-0.02592757,-40963.36,0.2721529,0,0,0.002592757,0.02592757,0.02593094,40963.36,272082.3
182.884,-3.51688,-0.02581593,-41213.87,0.2738172,0,0,0.002581593,0.02581593,0.02581926,41213.87,273746.5
183.252,-3.52292,-0.02584781,-41464.52,0.2754824,0,0,0.002584781,0.02584781,0.02585116,41464.52,275411.2
183.61,-3.528919,-0.02581593,-41714.83,0.2771455,0,0,0.002581593,0.02581593,0.02581926,41714.83,277074
183.966,-3.534879,-0.02629444,-41965.83,0.2788131,0,0,0.002629444,0.02629444,0.0262979,41965.83,278739.8
184.326,-3.540879,-0.02599139,-42216.48,0.2804784,0,0,0.002599139,0.02599139,0.02599477,42216.48,280405.5
184.676,-3.54672,-0.0258797,-42467.28,0.2821446,0,0,0.00258797,0.0258797,0.02588305,42467.28,282071.6
185.032,-3.552639,-0.0258797,-42718.29,0.2838123,0,0,0.00258797,0.0258797,0.02588305,42718.29,283738.9
185.382,-3.55848,-0.02595946,-42968.6,0.2854753,0,0,0.002595946,0.02595946,0.02596283,42968.61,285401.2
185.73,-3.56424,-0.02589568,-43219.02,0.2871391,0,0,0.002589568,0.02589568,0.02589904,43219.02,287064.7
186.074,-3.56996,-0.02602328,-43470.13,0.2888074,0,0,0.002602328,0.02602328,0.02602666,43470.13,288732.2
186.416,-3.575679,-0.02619874,-43720.67,0.2904719,0,0,0.002619874,0.02619874,0.02620217,43720.68,290395.8
186.76,-3.581439,-0.02594352,-43971.17,0.2921362,0,0,0.002594352,0.02594352,0.02594688,43971.18,292060.4
187.116,-3.58732,-0.02594352,-44221.57,0.2937998,0,0,0.002594352,0.02594352,0.02594688,44221.57,293723.5
187.47,-3.59324,-0.02581593,-44472.07,0.2954641,0,0,0.002581593,0.02581593,0.02581926,44472.07,295387.8
187.822,-3.599119,-0.02600733,-44722.54,0.2971282,0,0,0.002600733,0.02600733,0.02601071,44722.54,297050.9
188.174,-3.605039,-0.02586376,-44973.86,0.2987978,0,0,0.002586376,0.02586376,0.0258671,44973.86,298720.6
188.53,-3.61096,-0.02594352,-45224.23,0.3004613,0,0,0.002594352,0.02594352,0.02594688,45224.23,300383.3
188.886,-3.61692,-0.02567235,-45475.53,0.3021308,0,0,0.002567235,0.02567235,0.02567565,45475.53,302053.3
189.25,-3.622959,-0.02603922,-45726.8,0.3038003,0,0,0.002603922,0.02603922,0.02604261,45726.8,303721.1
189.608,-3.628879,-0.02589568,-45977.53,0.3054661,0,0,0.002589568,0.02589568,0.02589904,45977.53,305386.9
189.972,-3.63496,-0.02602328,-46228.18,0.3071313,0,0,0.002602328,0.02602328,0.02602666,46228.18,307051.4
190.334,-3.640999,-0.02591163,-46478.74,0.308796,0,0,0.002591163,0.02591163,0.02591499,46478.74,308716
190.696,-3.64708,-0.02589568,-46729.65,0.310463,0,0,0.002589568,0.02589568,0.02589904,46729.64,310382.6
191.07,-3.653319,-0.02602328,-46979.98,0.3121262,0,0,0.002602328,0.02602328,0.02602666,46979.98,312044.9
191.444,-3.65948,-0.02576806,-47230.9,0.3137932,0,0,0.002576806,0.02576806,0.02577138,47230.89,313712.3
191.808,-3.66556,-0.02595946,-47481.11,0.3154556,0,0,0.002595946,0.02595946,0.02596283,47481.11,315373.7
192.176,-3.67168,-0.02597541,-47732.41,0.3171251,0,0,0.002597541,0.02597541,0.02597878,47732.41,317042.8
192.548,-3.67792,-0.0258797,-47982.59,0.3187873,0,0,0.00258797,0.0258797,0.02588305,47982.59,318704.8
192.916,-3.68404,-0.02573617,-48233.04,0.3204513,0,0,0.002573617,0.02573617,0.02573948,48233.04,320368.8
193.304,-3.690519,-0.02619874,-48483.56,0.3221157,0,0,0.002619874,0.02619874,0.02620217,48483.56,322031.3
193.702,-3.69712,-0.02579994,-48734,0.3237796,0,0,0.002579994,0.02579994,0.02580327,48734,323696
194.1,-3.70372,-0.02597541,-48984.18,0.3254417,0,0,0.002597541,0.02597541,0.02597878,48984.18,325357.1
194.488,-3.710199,-0.02548095,-49234.6,0.3271054,0,0,0.002548095,0.02548095,0.0254842,49234.6,327022.1
194.882,-3.7168,-0.02589568,-49484.86,0.3287681,0,0,0.002589568,0.02589568,0.02589904,49484.86,328683
195.266,-3.72316,-0.02591163,-49736.12,0.3304374,0,0,0.002591163,0.02591163,0.02591499,49736.12,330351.8
195.634,-3.729319,-0.02557665,-49986.93,0.3321037,0,0,0.002557665,0.02557665,0.02557992,49986.93,332018.8
196.008,-3.735599,-0.02595946,-50237.98,0.3337717,0,0,0.002595946,0.02595946,0.02596283,50237.98,333685.1
196.388,-3.74196,-0.02594352,-50489.12,0.3354402,0,0,0.002594352,0.02594352,0.02594688,50489.12,335353.2
196.764,-3.74824,-0.02600733,-50739.85,0.337106,0,0,0.002600733,0.02600733,0.02601071,50739.86,337018.4
197.142,-3.75452,-0.02586376,-50990.66,0.3387724,0,0,0.002586376,0.02586376,0.0258671,50990.66,338684.8
197.52,-3.760799,-0.02597541,-51240.81,0.3404343,0,0,0.002597541,0.02597541,0.02597878,51240.81,340345.9
197.902,-3.767159,-0.02589568,-51491.93,0.3421027,0,0,0.002589568,0.02589568,0.02589904,51491.93,342014.1
198.284,-3.773519,-0.02565641,-51742.15,0.3437651,0,0,0.002565641,0.02565641,0.0256597,51742.16,343676.9
198.666,-3.779919,-0.02586376,-51992.28,0.3454269,0,0,0.002586376,0.02586376,0.0258671,51992.28,345337.6
199.052,-3.786359,-0.02554473,-52243.49,0.347096,0,0,0.002554473,0.02554473,0.02554799,52243.5,347007.3
199.452,-3.79296,-0.02602328,-52493.7,0.3487583,0,0,0.002602328,0.02602328,0.02602666,52493.7,348667.5
199.472,-3.793279,-0.0258797,-52506.66,0.3488443,0,0,0.00258797,0.0258797,0.02588305,52506.66,348754.1
"Specimen",2
"Specimen name:","E1 cycle"
"Width:",333.000000,"mm"
"Thickness:",452.000000,"mm"
"Anvil height:",90.000000,"mm"
"Diameter:",50.000000,"mm"
"Inner diameter:",0.500000,"mm"
"Outer diameter:",1.000000,"mm"
"Wall thickness:",0.500000,"mm"
"Area:",150516.000000,"mm*mm"
"Linear density:",1.000000,"den"
"Sled weight:",9.806650,"N"
"Loading span:",0.000000,"mm"
"Support span:",1.000000,"mm"
"Span ratio:","2"
"Fixture type:","3-point"
"Extensometer",-10.000000,"**mm"
"Included"
"Time sec","Extension mm","Strain 1 %","Load N","Comp. stress MPa","Cycle Count ","Total Cycle Count ","Comp. extension mm","Comp. strain %","True strain %","Comp. load N","True stress Pa"
0,-1.55588,-0.02613492,-811.0488,0.005388455,0,0,0.002613492,0.02613492,0.02613834,811.0488,5387.047
4,-1.62248,-0.02591163,-1039.762,0.006907984,0,0,0.002591163,0.02591163,0.02591499,1039.762,6906.194
8,-1.68916,-0.02591163,-1287.746,0.008555545,0,0,0.002591163,0.02591163,0.02591499,1287.746,8553.328
12,-1.75584,-0.02564047,-1538.934,0.01022439,0,0,0.002564047,0.02564047,0.02564375,1538.934,10221.77
16,-1.82252,-0.02605516,-1799.786,0.01195744,0,0,0.002605516,0.02605516,0.02605856,1799.786,11954.32
20,-1.88924,-0.02583187,-2088.866,0.01387803,0,0,0.002583187,0.02583187,0.02583521,2088.866,13874.45
24,-1.95584,-0.02594352,-2435.489,0.01618093,0,0,0.002594352,0.02594352,0.02594688,2435.489,16176.73
28,-2.02256,-0.0258797,-2824.61,0.01876617,0,0,0.00258797,0.0258797,0.02588305,2824.61,18761.32
32,-2.0892,-0.02613492,-3249.725,0.02159056,0,0,0.002613492,0.02613492,0.02613834,3249.725,21584.92
36,-2.15592,-0.02621468,-3714.448,0.0246781,0,0,0.002621468,0.02621468,0.02621812,3714.448,24671.63
40,-2.22248,-0.02616685,-4199.962,0.02790375,0,0,0.002616685,0.02616685,0.02617027,4199.961,27896.45
44,-2.28924,-0.02634231,-4725.208,0.03139339,0,0,0.002634231,0.02634231,0.02634578,4725.208,31385.12
48,-2.35584,-0.02597541,-5270.743,0.03501783,0,0,0.002597541,0.02597541,0.02597878,5270.743,35008.73
52,-2.42252,-0.02621468,-5852.462,0.03888266,0,0,0.002621468,0.02621468,0.02621812,5852.462,38872.46
56,-2.48916,-0.02584781,-6452.403,0.04286855,0,0,0.002584781,0.02584781,0.02585116,6452.403,42857.47
60,-2.55592,-0.02631038,-7069.734,0.04696999,0,0,0.002631038,0.02631038,0.02631384,7069.734,46957.63
64,-2.62252,-0.02616685,-7707.05,0.05120419,0,0,0.002616685,0.02616685,0.02617027,7707.05,51190.8
68,-2.689199,-0.02610303,-8411.491,0.05588436,0,0,0.002610303,0.02610303,0.02610644,8411.491,55869.78
72,-2.75584,-0.025784,-9201.382,0.06113225,0,0,0.0025784,0.025784,0.02578733,9201.382,61116.49
76,-2.82256,-0.02581593,-10087.2,0.06701746,0,0,0.002581593,0.02581593,0.02581926,10087.2,67000.16
80,-2.88916,-0.02592757,-11036.02,0.07332126,0,0,0.002592757,0.02592757,0.02593094,11036.02,73302.25
83.834,-2.95308,-0.02600733,-12037.27,0.07997334,0,0,0.002600733,0.02600733,0.02601071,12037.27,79952.54
87.466,-3.013599,-0.02621468,-13037.92,0.08662152,0,0,0.002621468,0.02621468,0.02621812,13037.92,86598.81
90.734,-3.068119,-0.02602328,-14039.13,0.09327336,0,0,0.002602328,0.02602328,0.02602666,14039.13,93249.08
93.298,-3.110839,-0.02623063,-15040.95,0.09992921,0,0,0.002623063,0.02623063,0.02623407,15040.95,99903
95.654,-3.150039,-0.02621468,-16042.36,0.1065824,0,0,0.002621468,0.02621468,0.02621812,16042.36,106554.5
97.858,-3.186839,-0.02618279,-17043.57,0.1132343,0,0,0.002618279,0.02618279,0.02618622,17043.57,113204.6
99.908,-3.220999,-0.02654966,-18045.83,0.1198931,0,0,0.002654966,0.02654966,0.02655318,18045.83,119861.3
101.788,-3.252319,-0.02579994,-19048.58,0.1265552,0,0,0.002579994,0.02579994,0.02580327,19048.58,126522.5
103.492,-3.28068,-0.02626255,-20050.76,0.1332134,0,0,0.002626255,0.02626255,0.026266,20050.76,133178.5
105.048,-3.306599,-0.02597541,-21054.02,0.1398789,0,0,0.002597541,0.02597541,0.02597878,21054.02,139842.6
106.464,-3.330279,-0.02624661,-22055.6,0.1465332,0,0,0.002624661,0.02624661,0.02625005,22055.6,146494.8
107.824,-3.352879,-0.02608709,-23058.4,0.1531956,0,0,0.002608709,0.02608709,0.02609049,23058.39,153155.7
109.116,-3.374399,-0.02645396,-24062.8,0.1598687,0,0,0.002645396,0.02645396,0.02645746,24062.8,159826.4
110.37,-3.39532,-0.02607115,-25065.29,0.1665291,0,0,0.002607115,0.02607115,0.02607454,25065.29,166485.7
111.572,-3.415319,-0.02629444,-26068.22,0.1731923,0,0,0.002629444,0.02629444,0.0262979,26068.22,173146.8
112.742,-3.434879,-0.02592757,-27073,0.1798679,0,0,0.002592757,0.02592757,0.02593094,27073,179821.3
113.878,-3.453799,-0.02616685,-28075.99,0.1865316,0,0,0.002616685,0.02616685,0.02617027,28075.99,186482.8
114.988,-3.472359,-0.02589568,-29079.58,0.1931992,0,0,0.002589568,0.02589568,0.02589904,29079.58,193149.2
116.086,-3.490599,-0.02589568,-30083.11,0.1998665,0,0,0.002589568,0.02589568,0.02589904,30083.11,199814.8
117.162,-3.508519,-0.02592757,-31088.35,0.2065452,0,0,0.002592757,0.02592757,0.02593094,31088.35,206491.6
118.222,-3.526199,-0.02626255,-32091.34,0.2132088,0,0,0.002626255,0.02626255,0.026266,32091.34,213152.8
119.27,-3.543679,-0.02595946,-33096.64,0.2198879,0,0,0.002595946,0.02595946,0.02596283,33096.64,219830.8
120.308,-3.560999,-0.02619874,-34098.99,0.2265473,0,0,0.002619874,0.02619874,0.02620217,34098.99,226487.9
121.34,-3.57812,-0.02595946,-35102.46,0.2332141,0,0,0.002595946,0.02595946,0.02596283,35102.46,233153.6
122.36,-3.5952,-0.02605516,-36107.18,0.2398893,0,0,0.002605516,0.02605516,0.02605856,36107.18,239826.8
123.392,-3.612359,-0.02581593,-37111.47,0.2465616,0,0,0.002581593,0.02581593,0.02581926,37111.47,246498
124.412,-3.6294,-0.02642207,-38114.46,0.2532253,0,0,0.002642207,0.02642207,0.02642556,38114.46,253158.4
125.42,-3.646159,-0.02592757,-39116.3,0.2598813,0,0,0.002592757,0.02592757,0.02593094,39116.3,259814
126.422,-3.662839,-0.02639014,-40121.47,0.2665595,0,0,0.002639014,0.02639014,0.02639363,40121.47,266489.2
127.422,-3.679519,-0.02583187,-41127.7,0.2732447,0,0,0.002583187,0.02583187,0.02583521,41127.7,273174.1
128.424,-3.69628,-0.02605516,-42132.32,0.2799192,0,0,0.002605516,0.02605516,0.02605856,42132.32,279846.2
129.47,-3.713639,-0.02605516,-43135.12,0.2865816,0,0,0.002605516,0.02605516,0.02605856,43135.12,286507
130.478,-3.73048,-0.02594352,-44138.91,0.2932506,0,0,0.002594352,0.02594352,0.02594688,44138.91,293174.5
131.366,-3.74528,-0.02602328,-45001.44,0.2989811,0,0,0.002602328,0.02602328,0.02602666,45001.44,298903.3
132.602,-3.72528,-0.02626255,-44248.05,0.2939757,0,0,0.002626255,0.02626255,0.026266,44248.05,293898.5
133.348,-3.71248,-0.02589568,-43242.13,0.2872926,0,0,0.002589568,0.02589568,0.02589904,43242.13,287218.2
134.048,-3.70072,-0.02631038,-42238.32,0.2806234,0,0,0.002631038,0.02631038,0.02631384,42238.32,280549.6
134.78,-3.688479,-0.02616685,-41232.67,0.2739421,0,0,0.002616685,0.02616685,0.02617027,41232.67,273870.4
135.518,-3.67616,-0.02631038,-40226.41,0.2672567,0,0,0.002631038,0.02631038,0.02631384,40226.41,267186.4
136.28,-3.66348,-0.02595946,-39222.15,0.2605846,0,0,0.002595946,0.02595946,0.02596283,39222.15,260516.9
137.064,-3.650399,-0.02610303,-38218.27,0.253915,0,0,0.002610303,0.02610303,0.02610644,38218.27,253848.7
137.858,-3.63716,-0.02626255,-37211.47,0.247226,0,0,0.002626255,0.02626255,0.026266,37211.47,247161.1
138.668,-3.62368,-0.02611898,-36209.76,0.2405708,0,0,0.002611898,0.02611898,0.02612239,36209.76,240508
139.502,-3.60976,-0.0263742,-35205.95,0.2339017,0,0,0.00263742,0.0263742,0.02637768,35205.95,233840
140.344,-3.595719,-0.02634231,-34201.31,0.2272271,0,0,0.002634231,0.02634231,0.02634578,34201.31,227167.2
141.196,-3.58152,-0.02600733,-33196.4,0.2205506,0,0,0.002600733,0.02600733,0.02601071,33196.39,220493.3
142.07,-3.56696,-0.02632637,-32191.74,0.2138759,0,0,0.002632637,0.02632637,0.02632983,32191.74,213819.6
142.964,-3.55204,-0.02626255,-31187.33,0.2072028,0,0,0.002626255,0.02626255,0.026266,31187.33,207148.4
143.87,-3.536959,-0.02623063,-30182.61,0.2005276,0,0,0.002623063,0.02623063,0.02623407,30182.61,200475
144.812,-3.521279,-0.02629444,-29177.57,0.1938503,0,0,0.002629444,0.02629444,0.0262979,29177.57,193799.3
145.774,-3.50524,-0.0262785,-28173.78,0.1871813,0,0,0.00262785,0.0262785,0.02628195,28173.78,187132.1
146.744,-3.489039,-0.0264699,-27168.66,0.1805035,0,0,0.00264699,0.0264699,0.0264734,27168.66,180455.7
147.744,-3.472359,-0.02639014,-26164.11,0.1738294,0,0,0.002639014,0.02639014,0.02639363,26164.11,173783.5
148.766,-3.45536,-0.02626255,-25159.25,0.1671533,0,0,0.002626255,0.02626255,0.026266,25159.25,167109.4
149.824,-3.437719,-0.02648585,-24157.31,0.1604966,0,0,0.002648585,0.02648585,0.02648935,24157.31,160454.1
150.944,-3.41908,-0.02608709,-23154.46,0.1538339,0,0,0.002608709,0.02608709,0.02609049,23154.46,153793.7
152.118,-3.399519,-0.02619874,-22151.07,0.1471676,0,0,0.002619874,0.02619874,0.02620217,22151.07,147129
153.39,-3.37828,-0.02613492,-21147.12,0.1404975,0,0,0.002613492,0.02613492,0.02613834,21147.12,140460.8
154.738,-3.355839,-0.02599139,-20145.19,0.1338408,0,0,0.002599139,0.02599139,0.02599477,20145.19,133806
156.26,-3.330479,-0.02621468,-19142.34,0.1271781,0,0,0.002621468,0.02621468,0.02621812,19142.34,127144.8
157.934,-3.302559,-0.02643801,-18138.78,0.1205106,0,0,0.002643801,0.02643801,0.02644151,18138.78,120478.8
159.784,-3.27172,-0.02635825,-17136.28,0.1138502,0,0,0.002635826,0.02635825,0.02636173,17136.28,113820.2
161.858,-3.23716,-0.02648585,-16134,0.1071913,0,0,0.002648585,0.02648585,0.02648935,16134,107162.9
[...]
599.2,-3.225759,-0.02634231,-16494.48,0.1095862,2,2,0.002634231,0.02634231,0.02634578,16494.48,109557.4
601.25,-3.259919,-0.02631038,-17496.66,0.1162445,2,2,0.002631038,0.02631038,0.02631384,17496.66,116213.9
603.092,-3.290679,-0.02629444,-18498.64,0.1229015,2,2,0.002629444,0.02629444,0.0262979,18498.64,122869.2
604.786,-3.318919,-0.02599139,-19501.96,0.1295674,2,2,0.002599139,0.02599139,0.02599477,19501.96,129533.7
606.34,-3.344759,-0.02621468,-20505.03,0.1362316,2,2,0.002621468,0.02621468,0.02621812,20505.03,136195.9
607.718,-3.367719,-0.02631038,-21507.75,0.1428934,2,2,0.002631038,0.02631038,0.02631384,21507.75,142855.8
609.028,-3.3896,-0.02642207,-22510.92,0.1495583,2,2,0.002642207,0.02642207,0.02642556,22510.92,149518.8
610.274,-3.410319,-0.02632637,-23514.67,0.1562271,2,2,0.002632637,0.02632637,0.02632983,23514.67,156185.9
611.478,-3.4304,-0.02631038,-24519.87,0.1629054,2,2,0.002631038,0.02631038,0.02631384,24519.87,162862.6
612.632,-3.449639,-0.02624661,-25523.56,0.1695737,2,2,0.002624661,0.02624661,0.02625005,25523.55,169529.2
613.758,-3.4684,-0.0261509,-26525.95,0.1762334,2,2,0.002615091,0.0261509,0.02615433,26525.95,176187.4
614.858,-3.48676,-0.02605516,-27529.9,0.1829035,2,2,0.002605516,0.02605516,0.02605856,27529.9,182855.8
615.93,-3.504599,-0.02632637,-28534.01,0.1895746,2,2,0.002632637,0.02632637,0.02632983,28534.01,189524.7
616.986,-3.52216,-0.02597541,-29536.81,0.196237,2,2,0.002597541,0.02597541,0.02597878,29536.81,196186
618.014,-3.539319,-0.02602328,-30538.56,0.2028925,2,2,0.002602328,0.02602328,0.02602666,30538.56,202839.7
619.03,-3.55628,-0.02586376,-31544.07,0.2095729,2,2,0.002586376,0.02586376,0.0258671,31544.07,209518.7
620.036,-3.573039,-0.02603922,-32546.79,0.2162347,2,2,0.002603922,0.02603922,0.02604261,32546.79,216178.4
621.032,-3.58964,-0.02618279,-33551.44,0.2229095,2,2,0.002618279,0.02618279,0.02618622,33551.44,222851.1
622.03,-3.606239,-0.02597541,-34556.56,0.2295873,2,2,0.002597541,0.02597541,0.02597878,34556.56,229527.6
623.018,-3.622719,-0.02618279,-35560.94,0.2362602,2,2,0.002618279,0.02618279,0.02618622,35560.94,236198.3
623.992,-3.63896,-0.02599139,-36565.37,0.2429334,2,2,0.002599139,0.02599139,0.02599477,36565.37,242870.3
624.958,-3.655039,-0.02619874,-37568.88,0.2496005,2,2,0.002619874,0.02619874,0.02620217,37568.88,249535.2
625.918,-3.67104,-0.02626255,-38572.19,0.2562664,2,2,0.002626255,0.02626255,0.026266,38572.19,256199
626.868,-3.68692,-0.02603922,-39574.91,0.2629282,2,2,0.002603922,0.02603922,0.02604261,39574.91,262859.8
627.844,-3.70312,-0.02597541,-40578.39,0.2695952,2,2,0.002597541,0.02597541,0.02597878,40578.39,269525.1
628.812,-3.719279,-0.02640609,-41581.43,0.2762592,2,2,0.002640609,0.02640609,0.02640957,41581.43,276186.3
629.79,-3.735599,-0.02624661,-42582.66,0.2829112,2,2,0.002624661,0.02624661,0.02625005,42582.66,282836.9
630.778,-3.752119,-0.02632637,-43584.78,0.2895691,2,2,0.002632637,0.02632637,0.02632983,43584.78,289492.8
631.782,-3.768799,-0.02610303,-44589.31,0.296243,2,2,0.002610303,0.02610303,0.02610644,44589.31,296165.6
632.948,-3.764119,-0.02613492,-44751.54,0.2973208,2,2,0.002613492,0.02613492,0.02613834,44751.54,297243.1
633.818,-3.74884,-0.0264699,-43745.41,0.2906363,2,2,0.00264699,0.0264699,0.0264734,43745.41,290559.3
634.506,-3.737159,-0.02619874,-42740.65,0.2839608,2,2,0.002619874,0.02619874,0.02620217,42740.65,283886.4
635.218,-3.725239,-0.02589568,-41734.53,0.2772764,2,2,0.002589568,0.02589568,0.02589904,41734.54,277204.6
635.942,-3.71316,-0.02631038,-40730.86,0.2706082,2,2,0.002631038,0.02631038,0.02631384,40730.86,270537
636.686,-3.700799,-0.02645396,-39726.16,0.2639332,2,2,0.002645396,0.02645396,0.02645746,39726.16,263863.3
637.45,-3.68804,-0.02642207,-38721.11,0.2572558,2,2,0.002642207,0.02642207,0.02642556,38721.11,257187.8
638.22,-3.675199,-0.02624661,-37717.34,0.2505869,2,2,0.002624661,0.02624661,0.02625005,37717.34,250521.1
639.012,-3.662,-0.02623063,-36716,0.2439342,2,2,0.002623063,0.02623063,0.02623407,36716,243870.2
639.828,-3.648399,-0.02564047,-35711.35,0.2372595,2,2,0.002564047,0.02564047,0.02564375,35711.35,237198.6
640.652,-3.63468,-0.02631038,-34704.38,0.2305693,2,2,0.002631038,0.02631038,0.02631384,34704.38,230508.7
641.488,-3.620719,-0.0261509,-33700.45,0.2238994,2,2,0.002615091,0.0261509,0.02615433,33700.45,223840.9
642.352,-3.60632,-0.02635825,-32694.63,0.217217,2,2,0.002635826,0.02635825,0.02636173,32694.63,217159.7
643.226,-3.59176,-0.02586376,-31690.61,0.2105464,2,2,0.002586376,0.02586376,0.0258671,31690.61,210492
644.112,-3.576999,-0.02632637,-30687.4,0.2038813,2,2,0.002632637,0.02632637,0.02632983,30687.4,203827.6
645.022,-3.56184,-0.02579994,-29682.37,0.1972041,2,2,0.002579994,0.02579994,0.02580327,29682.37,197153.2
645.962,-3.54616,-0.02605516,-28677.2,0.1905259,2,2,0.002605516,0.02605516,0.02605856,28677.21,190476.3
646.922,-3.53016,-0.02640609,-27673.48,0.1838574,2,2,0.002640609,0.02640609,0.02640957,27673.48,183808.8
647.914,-3.513639,-0.02573617,-26669.78,0.177189,2,2,0.002573617,0.02573617,0.02573948,26669.78,177143.4
648.912,-3.496959,-0.02624661,-25667.23,0.1705283,2,2,0.002624661,0.02624661,0.02625005,25667.23,170483.5
649.95,-3.479719,-0.02616685,-24662.84,0.1638553,2,2,0.002616685,0.02616685,0.02617027,24662.84,163812.4
651.026,-3.46172,-0.0264699,-23657.24,0.1571742,2,2,0.00264699,0.0264699,0.0264734,23657.24,157132.6
652.148,-3.443079,-0.02624661,-22653.11,0.150503,2,2,0.002624661,0.02624661,0.02625005,22653.11,150463.5
653.338,-3.4232,-0.02631038,-21649.05,0.1438322,2,2,0.002631038,0.02631038,0.02631384,21649.05,143794.3
654.592,-3.40232,-0.02594352,-20646.46,0.1371712,2,2,0.002594352,0.02594352,0.02594688,20646.46,137135.6
655.976,-3.37928,-0.02613492,-19644.18,0.1305123,2,2,0.002613492,0.02613492,0.02613834,19644.18,130478.1
657.526,-3.35344,-0.02629444,-18642.29,0.1238559,2,2,0.002629444,0.02629444,0.0262979,18642.29,123823.3
659.264,-3.324479,-0.02635825,-17639.87,0.117196,2,2,0.002635826,0.02635825,0.02636173,17639.87,117165.1
661.194,-3.292279,-0.02640609,-16638.21,0.1105411,2,2,0.002640609,0.02640609,0.02640957,16638.21,110512
663.3,-3.25716,-0.02642207,-15636.62,0.1038867,2,2,0.002642207,0.02642207,0.02642556,15636.62,103859.3
665.632,-3.21832,-0.02631038,-14634.97,0.09723198,2,2,0.002631038,0.02631038,0.02631384,14634.97,97206.4
668.208,-3.1754,-0.02594352,-13633.45,0.09057807,2,2,0.002594352,0.02594352,0.02594688,13633.45,90554.57
671.566,-3.119439,-0.02600733,-12631.95,0.08392433,2,2,0.002600733,0.02600733,0.02601071,12631.95,83902.5
675.208,-3.05868,-0.02616685,-11630.26,0.07726929,2,2,0.002616685,0.02616685,0.02617027,11630.26,77249.07
679.154,-2.992919,-0.02651777,-10633.53,0.07064718,2,2,0.002651777,0.02651777,0.02652129,10633.53,70628.44
683.154,-2.92628,-0.02658159,-9717.412,0.06456065,2,2,0.002658159,0.02658159,0.02658512,9717.411,64543.49
687.154,-2.85956,-0.025784,-8865.967,0.05890382,2,2,0.0025784,0.025784,0.02578733,8865.968,58888.64
691.154,-2.792919,-0.02608709,-8119.877,0.05394693,2,2,0.002608709,0.02608709,0.02609049,8119.876,53932.86
695.154,-2.726279,-0.02650183,-7479.204,0.04969043,2,2,0.002650183,0.02650183,0.02650534,7479.204,49677.26
699.154,-2.659599,-0.0262785,-6864.443,0.04560607,2,2,0.00262785,0.0262785,0.02628195,6864.443,45594.08
703.154,-2.59292,-0.02658159,-6263.729,0.04161504,2,2,0.002658159,0.02658159,0.02658512,6263.729,41603.98
707.154,-2.52624,-0.02634231,-5685.716,0.03777483,2,2,0.002634231,0.02634231,0.02634578,5685.716,37764.88
711.154,-2.4596,-0.02575211,-5121.312,0.03402503,2,2,0.002575211,0.02575211,0.02575543,5121.312,34016.27
715.154,-2.39296,-0.02642207,-4599.148,0.03055587,2,2,0.002642207,0.02642207,0.02642556,4599.147,30547.8
719.154,-2.32628,-0.02629444,-4105.84,0.02727843,2,2,0.002629444,0.02629444,0.0262979,4105.839,27271.25
723.154,-2.2596,-0.02634231,-3633.272,0.02413877,2,2,0.002634231,0.02634231,0.02634578,3633.272,24132.42
727.154,-2.19296,-0.02650183,-3195.254,0.02122867,2,2,0.002650183,0.02650183,0.02650534,3195.254,21223.04
731.154,-2.12628,-0.02610303,-2790.154,0.01853726,2,2,0.002610303,0.02610303,0.02610644,2790.154,18532.42
735.154,-2.0596,-0.02602328,-2423.412,0.01610069,2,2,0.002602328,0.02602328,0.02602666,2423.412,16096.5
739.154,-1.99296,-0.02645396,-2103.333,0.01397415,2,2,0.002645396,0.02645396,0.02645746,2103.333,13970.45
743.154,-1.92628,-0.02639014,-1813.11,0.01204596,2,2,0.002639014,0.02639014,0.02639363,1813.11,12042.79
747.154,-1.85964,-0.02653372,-1560.745,0.0103693,2,2,0.002653372,0.02653372,0.02653724,1560.745,10366.55
751.154,-1.79296,-0.02631038,-1317.805,0.008755252,2,2,0.002631038,0.02631038,0.02631384,1317.805,8752.948
755.154,-1.72628,-0.02623063,-1079.423,0.00717148,2,2,0.002623063,0.02623063,0.02623407,1079.422,7169.599
756.542,-1.70312,-0.02650183,-999.6215,0.006641297,0,3,0.002650183,0.02650183,0.02650534,999.6215,6639.537
760.542,-1.76984,-0.02608709,-1207.889,0.008024989,0,3,0.002608709,0.02608709,0.02609049,1207.889,8022.895
764.542,-1.83656,-0.02618279,-1471.235,0.009774609,0,3,0.002618279,0.02618279,0.02618622,1471.235,9772.05
768.542,-1.90316,-0.02634231,-1735.492,0.01153028,0,3,0.002634231,0.02634231,0.02634578,1735.492,11527.24
772.542,-1.96992,-0.02650183,-2030.264,0.01348869,0,3,0.002650183,0.02650183,0.02650534,2030.264,13485.12
776.542,-2.03652,-0.02650183,-2362.544,0.0156963,0,3,0.002650183,0.02650183,0.02650534,2362.544,15692.14
780.542,-2.1032,-0.02640609,-2742.449,0.01822031,0,3,0.002640609,0.02640609,0.02640957,2742.449,18215.5
784.542,-2.16984,-0.02645396,-3162.877,0.02101356,0,3,0.002645396,0.02645396,0.02645746,3162.877,21008
788.542,-2.23652,-0.02635825,-3621.358,0.02405962,0,3,0.002635826,0.02635825,0.02636173,3621.358,24053.28
792.542,-2.30316,-0.02613492,-4113.614,0.02733008,0,3,0.002613492,0.02613492,0.02613834,4113.614,27322.93
796.542,-2.36988,-0.02631038,-4633.827,0.03078627,0,3,0.002631038,0.02631038,0.02631384,4633.827,30778.17
800.542,-2.43652,-0.02629444,-5185.08,0.03444869,0,3,0.002629444,0.02629444,0.0262979,5185.08,34439.64
804.542,-2.50316,-0.02640609,-5777.54,0.03838489,0,3,0.002640609,0.02640609,0.02640957,5777.54,38374.75
808.542,-2.569839,-0.02623063,-6380.989,0.04239409,0,3,0.002623063,0.02623063,0.02623407,6380.989,42382.97
812.542,-2.636559,-0.02602328,-7008.202,0.04656117,0,3,0.002602328,0.02602328,0.02602666,7008.202,46549.06
816.542,-2.703159,-0.02626255,-7649.22,0.05081998,0,3,0.002626255,0.02626255,0.026266,7649.22,50806.63
820.542,-2.76992,-0.02623063,-8335.239,0.05537776,0,3,0.002623063,0.02623063,0.02623407,8335.238,55363.23
824.542,-2.83652,-0.02629444,-9120.945,0.06059785,0,3,0.002629444,0.02629444,0.0262979,9120.945,60581.91
828.542,-2.903199,-0.0261509,-10009.48,0.06650112,0,3,0.002615091,0.0261509,0.02615433,10009.48,66483.73
832.522,-2.96952,-0.02589568,-10984.29,0.07297755,0,3,0.002589568,0.02589568,0.02589904,10984.29,72958.65
836.294,-3.032399,-0.02635825,-11985.12,0.07962685,0,3,0.002635826,0.02635825,0.02636173,11985.12,79605.86
839.838,-3.091439,-0.02600733,-12986.29,0.0862785,0,3,0.002600733,0.02600733,0.02601071,12986.29,86256.06
843.054,-3.145039,-0.02639014,-13988.11,0.09293436,0,3,0.002639014,0.02639014,0.02639363,13988.11,92909.84
845.57,-3.186959,-0.02624661,-14989.66,0.09958848,0,3,0.002624661,0.02624661,0.02625005,14989.66,99562.35
847.886,-3.225559,-0.02635825,-15991.77,0.1062463,0,3,0.002635826,0.02635825,0.02636173,15991.77,106218.3
850.018,-3.26108,-0.0264699,-16993.08,0.1128988,0,3,0.00264699,0.0264699,0.0264734,16993.08,112868.9
851.936,-3.293119,-0.0261509,-17995.21,0.1195568,0,3,0.002615091,0.0261509,0.02615433,17995.21,119525.5
853.7,-3.322479,-0.02591163,-18997.36,0.1262149,0,3,0.002591163,0.02591163,0.02591499,18997.36,126182.2
855.304,-3.349159,-0.02632637,-20000.28,0.1328781,0,3,0.002632637,0.02632637,0.02632983,20000.29,132843.1
856.712,-3.37268,-0.02626255,-21001.64,0.1395309,0,3,0.002626255,0.02626255,0.026266,21001.64,139494.3
858.05,-3.394959,-0.02642207,-22005.75,0.1462021,0,3,0.002642207,0.02642207,0.02642556,22005.75,146163.4
859.306,-3.415879,-0.02632637,-23008.85,0.1528665,0,3,0.002632637,0.02632637,0.02632983,23008.85,152826.2
860.518,-3.436119,-0.02629444,-24011.91,0.1595306,0,3,0.002629444,0.02629444,0.0262979,24011.91,159488.6
861.694,-3.455679,-0.02635825,-25014.29,0.1661902,0,3,0.002635826,0.02635825,0.02636173,25014.29,166146.4
862.826,-3.47464,-0.02619874,-26019.46,0.1728684,0,3,0.002619874,0.02619874,0.02620217,26019.46,172823.1
863.938,-3.49308,-0.02634231,-27024.86,0.1795481,0,3,0.002634231,0.02634231,0.02634578,27024.86,179500.8
865.01,-3.51096,-0.02600733,-28027.56,0.1862098,0,3,0.002600733,0.02600733,0.02601071,28027.56,186161.4
866.072,-3.528639,-0.02613492,-29033.83,0.1928953,0,3,0.002613492,0.02613492,0.02613834,29033.83,192844.9
867.1,-3.545799,-0.02639014,-30037.78,0.1995654,0,3,0.002639014,0.02639014,0.02639363,30037.79,199512.7
868.128,-3.56296,-0.02600733,-31043.34,0.2062461,0,3,0.002600733,0.02600733,0.02601071,31043.35,206192.5
869.132,-3.579679,-0.02640609,-32047.32,0.2129164,0,3,0.002640609,0.02640609,0.02640957,32047.32,212860.2
870.132,-3.596359,-0.02635825,-33051.23,0.2195861,0,3,0.002635826,0.02635825,0.02636173,33051.23,219528.2
871.122,-3.61288,-0.0264699,-34054.45,0.2262513,0,3,0.00264699,0.0264699,0.0264734,34054.45,226191.4
872.108,-3.62924,-0.02621468,-35060.09,0.2329326,0,3,0.002621468,0.02621468,0.02621812,35060.09,232871.6
873.072,-3.64532,-0.02653372,-36062.73,0.239594,0,3,0.002653372,0.02653372,0.02653724,36062.73,239530.4
874.038,-3.6614,-0.02645396,-37069,0.2462794,0,3,0.002645396,0.02645396,0.02645746,37069,246214.3
874.98,-3.67716,-0.02634231,-38072.79,0.2529485,0,3,0.002634231,0.02634231,0.02634578,38072.79,252881.8
875.93,-3.692959,-0.0263742,-39078.83,0.2596323,0,3,0.00263742,0.0263742,0.02637768,39078.82,259563.9
876.884,-3.70884,-0.02632637,-40082.28,0.2662991,0,3,0.002632637,0.02632637,0.02632983,40082.28,266229
877.84,-3.724759,-0.02616685,-41086.58,0.2729716,0,3,0.002616685,0.02616685,0.02617027,41086.59,272900.1
878.806,-3.74096,-0.02639014,-42091.22,0.2796461,0,3,0.002639014,0.02639014,0.02639363,42091.22,279572.3
879.784,-3.7572,-0.02659753,-43095.94,0.2863213,0,3,0.002659753,0.02659753,0.02660107,43095.94,286245.2
880.764,-3.773519,-0.02573617,-44099.07,0.2929859,0,3,0.002573617,0.02573617,0.02573948,44099.07,292910.5
881.758,-3.790079,-0.02643801,-45103.1,0.2996565,0,3,0.002643801,0.02643801,0.02644151,45103.1,299577.3
882.75,-3.80664,-0.02642207,-46108.42,0.3063356,0,3,0.002642207,0.02642207,0.02642556,46108.41,306254.7
883.758,-3.823399,-0.02610303,-47112.41,0.313006,0,3,0.002610303,0.02610303,0.02610644,47112.41,312924.3
884.774,-3.84036,-0.02635825,-48117.44,0.3196832,0,3,0.002635826,0.02635825,0.02636173,48117.44,319598.9
885.8,-3.857439,-0.02613492,-49122.03,0.3263575,0,3,0.002613492,0.02613492,0.02613834,49122.03,326272.3
886.854,-3.87508,-0.02629444,-50126.91,0.3330338,0,3,0.002629444,0.02629444,0.0262979,50126.91,332946.2
887.952,-3.89332,-0.02613492,-51131.68,0.3397093,0,3,0.002613492,0.02613492,0.02613834,51131.68,339620.5
889.068,-3.911919,-0.02592757,-52137.02,0.3463885,0,3,0.002592757,0.02592757,0.02593094,52137.02,346298.7
890.22,-3.931119,-0.02618279,-53142.65,0.3530698,0,3,0.002618279,0.02618279,0.02618622,53142.66,352977.4
891.4,-3.950759,-0.02650183,-54146.55,0.3597395,0,3,0.002650183,0.02650183,0.02650534,54146.55,359644.1
892.594,-3.970719,-0.02629444,-55149.98,0.3664061,0,3,0.002629444,0.02629444,0.0262979,55149.98,366309.7
895.094,-4.012439,-0.02623063,-56099.77,0.3727163,0,3,0.002623063,0.02623063,0.02623407,56099.77,372618.6
896.976,-4.043719,-0.02653372,-57102.18,0.3793761,0,3,0.002653372,0.02653372,0.02653724,57102.18,379275.5
898.416,-4.06772,-0.02594352,-58105.32,0.3860408,0,3,0.002594352,0.02594352,0.02594688,58105.32,385940.7
899.578,-4.087079,-0.02659753,-59107.95,0.3927021,0,3,0.002659753,0.02659753,0.02660107,59107.95,392597.7
900.666,-4.105279,-0.02654966,-60111.76,0.3993712,0,3,0.002654966,0.02654966,0.02655318,60111.76,399265.2
901.768,-4.123599,-0.02624661,-61116.62,0.4060473,0,3,0.002624661,0.02624661,0.02625005,61116.62,405940.7
902.862,-4.141879,-0.02619874,-62120.15,0.4127146,0,3,0.002619874,0.02619874,0.02620217,62120.14,412606.4
903.984,-4.160519,-0.0261509,-63122.11,0.4193714,0,3,0.002615091,0.0261509,0.02615433,63122.11,419261.7
905.1,-4.179119,-0.02650183,-64124.72,0.4260326,0,3,0.002650183,0.02650183,0.02650534,64124.72,425919.7
906.24,-4.198119,-0.02618279,-65127.04,0.4326918,0,3,0.002618279,0.02618279,0.02618622,65127.04,432578.5
907.426,-4.217839,-0.02607115,-66130.72,0.4393601,0,3,0.002607115,0.02607115,0.02607454,66130.72,439245.5
908.612,-4.237719,-0.02659753,-67135.04,0.4460326,0,3,0.002659753,0.02659753,0.02660107,67135.04,445914
909.892,-4.258959,-0.02616685,-68137.87,0.4526952,0,3,0.002616685,0.02616685,0.02617027,68137.87,452576.7
911.406,-4.28424,-0.02643801,-69140.57,0.459357,0,3,0.002643801,0.02643801,0.02644151,69140.57,459235.5
913.746,-4.32324,-0.02631038,-68902.25,0.4577737,0,3,0.002631038,0.02631038,0.02631384,68902.26,457653.2
916.08,-4.36216,-0.02634231,-67900.16,0.4511159,0,3,0.002634231,0.02634231,0.02634578,67900.16,450997
916.526,-4.369679,-0.02595946,-66874.96,0.4443047,0,3,0.002595946,0.02595946,0.02596283,66874.96,444189.3
916.578,-4.370559,-0.0261509,-65816.95,0.4372754,0,3,0.002615091,0.0261509,0.02615433,65816.95,437161.1
916.604,-4.371039,-0.02616685,-64680.14,0.4297227,0,3,0.002616685,0.02616685,0.02617027,64680.14,429610.3
916.624,-4.371439,-0.02639014,-63469.06,0.4216765,0,3,0.002639014,0.02639014,0.02639363,63469.06,421565.2
916.64,-4.37172,-0.02659753,-62245.57,0.4135478,0,3,0.002659753,0.02659753,0.02660107,62245.57,413437.8
916.656,-4.372039,-0.02645396,-60795.3,0.4039125,0,3,0.002645396,0.02645396,0.02645746,60795.3,403805.7
916.672,-4.372359,-0.02618279,-59498.95,0.3952999,0,3,0.002618279,0.02618279,0.02618622,59498.95,395196.4
916.696,-4.372799,-0.02611898,-58307.03,0.387381,0,3,0.002611898,0.02611898,0.02612239,58307.04,387279.8
916.77,-4.37408,-0.02600733,-57237.31,0.3802739,0,3,0.002600733,0.02600733,0.02601071,57237.31,380175
917.06,-4.378799,-0.02605516,-56223.05,0.3735354,0,3,0.002605516,0.02605516,0.02605856,56223.05,373438
919.44,-4.4182,-0.02584781,-55384.28,0.3679627,0,3,0.002584781,0.02584781,0.02585116,55384.28,367867.6
919.756,-4.42344,-0.02607115,-54345.61,0.361062,0,3,0.002607115,0.02607115,0.02607454,54345.61,360967.9
919.786,-4.424039,-0.02613492,-53051.21,0.3524623,0,3,0.002613492,0.02613492,0.02613834,53051.21,352370.1
919.794,-4.424359,-0.02597541,-50798.25,0.337494,0,3,0.002597541,0.02597541,0.02597878,50798.25,337406.4
919.802,-4.424519,-0.0258797,-47836.09,0.317814,0,3,0.00258797,0.0258797,0.02588305,47836.09,317731.8
919.81,-4.424719,-0.02584781,-44991.4,0.2989144,0,3,0.002584781,0.02584781,0.02585116,44991.4,298837.2
919.818,-4.424959,-0.02584781,-42662.91,0.2834443,0,3,0.002584781,0.02584781,0.02585116,42662.91,283371.1
919.826,-4.425119,-0.0258797,-40968.19,0.272185,0,3,0.00258797,0.0258797,0.02588305,40968.19,272114.5
919.836,-4.425319,-0.02599139,-39664.32,0.2635223,0,3,0.002599139,0.02599139,0.02599477,39664.32,263453.8
920.042,-4.428719,-0.02613492,-38530.31,0.2559881,0,3,0.002613492,0.02613492,0.02613834,38530.3,255921.2
922.14,-4.463079,-0.02576806,-38683.05,0.2570029,0,3,0.002576806,0.02576806,0.02577138,38683.05,256936.7
923.766,-4.49016,-0.02654966,-39686.76,0.2636714,0,3,0.002654966,0.02654966,0.02655318,39686.76,263601.4
925.322,-4.516199,-0.02599139,-40688.42,0.2703262,0,3,0.002599139,0.02599139,0.02599477,40688.42,270256
926.776,-4.540399,-0.02624661,-41691.27,0.2769889,0,3,0.002624661,0.02624661,0.02625005,41691.27,276916.2
928.262,-4.565159,-0.02592757,-42694.55,0.2836545,0,3,0.002592757,0.02592757,0.02593094,42694.55,283581
929.748,-4.589919,-0.02589568,-43695.83,0.2903069,0,3,0.002589568,0.02589568,0.02589904,43695.83,290231.7
929.982,-4.5938,-0.02616685,-43870.57,0.2914678,0,3,0.002616685,0.02616685,0.02617027,43870.57,291391.5