File: ElectricPoleSupport/ExptData/Raw/Heel_A1_cycle.raw.csv
"Test Type","Compression"
"Method Name:","C:\INSTRON\USER\TEMPLATE\Andyscomp.mtB"
"Name:","Transnet Compression Tests"
"Operator ID:","AndyS"
"Company:","IRL"
"Lab name:","Rm 3.09"
"Test date:","25/08/08"
"Temperature:","20.5"
"Humidity:","57.5"
"Note 1:","Plastic Telegraph Pole Breast and Heel Plate Tests"
"Note 2:",""
"Note 3:",""
"Geometry:","Rectangular"
"Specimen",1
"Specimen name:","A1Cycle"
"Width:",342.000000,"mm"
"Thickness:",446.000000,"mm"
"Anvil height:",90.000000,"mm"
"Diameter:",50.000000,"mm"
"Inner diameter:",0.500000,"mm"
"Outer diameter:",1.000000,"mm"
"Wall thickness:",0.500000,"mm"
"Area:",152532.000000,"mm*mm"
"Linear density:",1.000000,"den"
"Sled weight:",9.806650,"N"
"Loading span:",0.000000,"mm"
"Support span:",1.000000,"mm"
"Span ratio:","2"
"Fixture type:","3-point"
"Comment:","Transnet Small Rectangular Sample"
"Extensometer",-10.000000,"**mm"
"Included"
"Time sec","Extension mm","Strain 1 %","Load N","Comp. stress MPa","Cycle Count ","Total Cycle Count ","Comp. extension mm","Comp. strain %","True strain %","Comp. load N","True stress Pa"
0,0,-0.01661208,-311.3174,0.002040997,0,0,0.001661208,0.01661208,0.01661345,311.3174,2040.658
3,-0.04995999,-0.01662802,-312.482,0.002048632,0,0,0.001662802,0.01662802,0.0166294,312.482,2048.292
6,-0.09995998,-0.01678754,-312.8672,0.002051158,0,0,0.001678754,0.01678754,0.01678895,312.8672,2050.813
9,-0.15,-0.01699489,-318.2556,0.002086484,0,0,0.001699489,0.01699489,0.01699633,318.2556,2086.13
12,-0.20008,-0.01640473,-364.9242,0.002392443,0,0,0.001640473,0.01640473,0.01640607,364.9242,2392.051
15,-0.25,-0.01669183,-416.4163,0.002730026,0,0,0.001669183,0.01669183,0.01669323,416.4164,2729.57
18,-0.30008,-0.01701087,-469.2952,0.0030767,0,0,0.001701087,0.01701087,0.01701232,469.2952,3076.176
21,-0.3499999,-0.01691516,-521.4279,0.003418482,0,0,0.001691516,0.01691516,0.0169166,521.4279,3417.904
24,-0.4,-0.01683541,-576.1932,0.003777524,0,0,0.001683541,0.01683541,0.01683682,576.1932,3776.888
27,-0.45004,-0.01681942,-637.2563,0.004177853,0,0,0.001681942,0.01681942,0.01682084,637.2563,4177.151
30,-0.5000399,-0.01723416,-705.6495,0.004626239,0,0,0.001723416,0.01723416,0.01723565,705.6495,4625.442
33,-0.5499999,-0.01688324,-782.7153,0.005131483,0,0,0.001688324,0.01688324,0.01688466,782.7153,5130.616
36,-0.6000399,-0.01691516,-865.7332,0.005675748,0,0,0.001691516,0.01691516,0.0169166,865.7332,5674.788
39,-0.6500399,-0.01667589,-951.0237,0.006234913,0,0,0.001667589,0.01667589,0.01667728,951.0237,6233.873
42,-0.7000799,-0.01662802,-1042.337,0.006833563,0,0,0.001662802,0.01662802,0.0166294,1042.337,6832.427
45,-0.7499999,-0.01664396,-1137.135,0.007455058,0,0,0.001664396,0.01664396,0.01664535,1137.135,7453.817
48,-0.7999999,-0.01701087,-1234.345,0.008092367,0,0,0.001701087,0.01701087,0.01701232,1234.345,8090.991
51,-0.8500799,-0.01686729,-1335.156,0.008753287,0,0,0.001686729,0.01686729,0.01686872,1335.156,8751.81
54,-0.9000399,-0.01659613,-1436.608,0.009418407,0,0,0.001659613,0.01659613,0.01659751,1436.609,9416.845
57,-0.9499999,-0.01701087,-1541.316,0.01010487,0,0,0.001701087,0.01701087,0.01701232,1541.316,10103.15
60,-1.00004,-0.01658019,-1651.663,0.01082831,0,0,0.001658019,0.01658019,0.01658156,1651.663,10826.51
63,-1.05,-0.016963,-1766.196,0.01157918,0,0,0.0016963,0.016963,0.01696444,1766.196,11577.22
66,-1.1,-0.01667589,-1881.92,0.01233787,0,0,0.001667589,0.01667589,0.01667728,1881.92,12335.81
69,-1.15008,-0.01678754,-1998.763,0.01310389,0,0,0.001678754,0.01678754,0.01678895,1998.763,13101.7
72,-1.2,-0.01680348,-2115.571,0.01386969,0,0,0.001680348,0.01680348,0.01680489,2115.571,13867.36
75,-1.25008,-0.01704276,-2237.217,0.0146672,0,0,0.001704276,0.01704276,0.01704421,2237.217,14664.7
78,-1.30004,-0.01699489,-2358.304,0.01546104,0,0,0.001699489,0.01699489,0.01699633,2358.304,15458.42
81,-1.35,-0.01701087,-2478.415,0.01624849,0,0,0.001701087,0.01701087,0.01701232,2478.415,16245.73
84,-1.4,-0.01713846,-2601.023,0.01705231,0,0,0.001713846,0.01713846,0.01713993,2601.023,17049.39
87,-1.45004,-0.01689918,-2726.632,0.0178758,0,0,0.001689918,0.01689918,0.01690061,2726.632,17872.78
90,-1.5,-0.01680348,-2852.345,0.01869998,0,0,0.001680348,0.01680348,0.01680489,2852.345,18696.84
93,-1.55008,-0.01713846,-2980.657,0.01954119,0,0,0.001713846,0.01713846,0.01713993,2980.657,19537.84
96,-1.6,-0.01689918,-3111.647,0.02039996,0,0,0.001689918,0.01689918,0.01690061,3111.647,20396.52
99,-1.65004,-0.01694705,-3243.784,0.02126625,0,0,0.001694705,0.01694705,0.01694849,3243.784,21262.65
102,-1.70004,-0.0170587,-3376.412,0.02213576,0,0,0.00170587,0.0170587,0.01706016,3376.412,22131.99
105,-1.75004,-0.01720227,-3511.003,0.02301814,0,0,0.001720227,0.01720227,0.01720375,3511.003,23014.18
108,-1.80004,-0.01726609,-3647.358,0.02391208,0,0,0.001726609,0.01726609,0.01726758,3647.358,23907.96
111,-1.85004,-0.01683541,-3784.232,0.02480943,0,0,0.001683541,0.01683541,0.01683682,3784.232,24805.25
114,-1.89996,-0.01702681,-3926.324,0.02574099,0,0,0.001702681,0.01702681,0.01702826,3926.324,25736.61
117,-1.95004,-0.01701087,-4077.251,0.02673046,0,0,0.001701087,0.01701087,0.01701232,4077.251,26725.92
120,-2,-0.01707464,-4227.149,0.02771319,0,0,0.001707464,0.01707464,0.0170761,4227.149,27708.46
123,-2.05,-0.01723416,-4383.135,0.02873584,0,0,0.001723416,0.01723416,0.01723565,4383.135,28730.89
126,-2.1,-0.01731392,-4540.784,0.02976938,0,0,0.001731392,0.01731392,0.01731542,4540.784,29764.23
129,-2.15,-0.01721822,-4702.317,0.03082839,0,0,0.001721822,0.01721822,0.0172197,4702.316,30823.08
132,-2.20008,-0.01702681,-4875.163,0.03196158,0,0,0.001702681,0.01702681,0.01702826,4875.164,31956.14
134.158,-2.23596,-0.01721822,-5000.008,0.03278006,0,0,0.001721822,0.01721822,0.0172197,5000.008,32774.41
136.16,-2.20288,-0.01740962,-4868.548,0.03191821,0,0,0.001740962,0.01740962,0.01741114,4868.548,31912.65
139.16,-2.15268,-0.01718633,-4568.874,0.02995354,0,0,0.001718633,0.01718633,0.01718781,4568.874,29948.39
142.16,-2.10264,-0.01729798,-4297.22,0.02817258,0,0,0.001729798,0.01729798,0.01729947,4297.22,28167.71
145.16,-2.05264,-0.0171544,-4050.675,0.02655623,0,0,0.00171544,0.0171544,0.01715587,4050.675,26551.67
148.16,-2.00264,-0.01737773,-3839.721,0.02517322,0,0,0.001737773,0.01737773,0.01737924,3839.721,25168.84
151.16,-1.95268,-0.01750533,-3645.852,0.02390221,0,0,0.001750533,0.01750533,0.01750686,3645.852,23898.03
154.16,-1.90264,-0.01740962,-3457.183,0.0226653,0,0,0.001740962,0.01740962,0.01741114,3457.183,22661.35
157.16,-1.85268,-0.01720227,-3280.229,0.02150519,0,0,0.001720227,0.01720227,0.01720375,3280.229,21501.49
160.16,-1.80264,-0.01704276,-3119.372,0.02045061,0,0,0.001704276,0.01704276,0.01704421,3119.372,20447.12
163.16,-1.75268,-0.01744155,-2963.586,0.01942927,0,0,0.001744155,0.01744155,0.01744307,2963.586,19425.88
166.16,-1.70264,-0.01723416,-2815.925,0.01846121,0,0,0.001723416,0.01723416,0.01723565,2815.925,18458.03
169.16,-1.65268,-0.01737773,-2673.41,0.01752688,0,0,0.001737773,0.01737773,0.01737924,2673.409,17523.83
172.16,-1.60268,-0.01779247,-2531.214,0.01659464,0,0,0.001779247,0.01779247,0.01779405,2531.214,16591.69
175.16,-1.55268,-0.01768079,-2394.886,0.01570088,0,0,0.001768079,0.01768079,0.01768235,2394.886,15698.1
178.16,-1.50268,-0.01777653,-2262.742,0.01483454,0,0,0.001777653,0.01777653,0.01777811,2262.742,14831.9
181.16,-1.45268,-0.01768079,-2134.263,0.01399223,0,0,0.001768079,0.01768079,0.01768235,2134.263,13989.76
184.16,-1.40268,-0.01728203,-2007.495,0.01316114,0,0,0.001728203,0.01728203,0.01728352,2007.495,13158.86
187.16,-1.35264,-0.01729798,-1886.31,0.01236665,0,0,0.001729798,0.01729798,0.01729947,1886.31,12364.51
190.16,-1.30268,-0.01772866,-1769.564,0.01160126,0,0,0.001772866,0.01772866,0.01773023,1769.564,11599.21
193.16,-1.25264,-0.01771271,-1653.487,0.01084027,0,0,0.001771271,0.01771271,0.01771428,1653.487,10838.35
196.16,-1.20264,-0.01750533,-1542.074,0.01010984,0,0,0.001750533,0.01750533,0.01750686,1542.074,10108.07
199.16,-1.15264,-0.01787223,-1433.641,0.00939895,0,0,0.001787223,0.01787223,0.01787383,1433.641,9397.27
202.16,-1.10264,-0.01785628,-1330.551,0.008723096,0,0,0.001785628,0.01785628,0.01785788,1330.551,8721.538
205.16,-1.05268,-0.01780841,-1233.392,0.008086123,0,0,0.001780841,0.01780841,0.01781,1233.392,8084.683
208.16,-1.00268,-0.01752131,-1140.848,0.007479402,0,0,0.001752131,0.01752131,0.01752284,1140.848,7478.092
211.16,-0.9526399,-0.01780841,-1046.992,0.006864083,0,0,0.001780841,0.01780841,0.01781,1046.992,6862.86
214.16,-0.9027199,-0.01750533,-955.5937,0.006264873,0,0,0.001750533,0.01750533,0.01750686,955.5937,6263.777
217.16,-0.8526399,-0.01760107,-868.2799,0.005692444,0,0,0.001760107,0.01760107,0.01760261,868.2798,5691.442
220.16,-0.8026799,-0.01756914,-783.2032,0.005134681,0,0,0.001756914,0.01756914,0.01757068,783.2032,5133.779
223.16,-0.7526399,-0.01737773,-703.7291,0.004613649,0,0,0.001737773,0.01737773,0.01737924,703.7291,4612.847
226.16,-0.7026799,-0.01752131,-632.8313,0.004148842,0,0,0.001752131,0.01752131,0.01752284,632.8312,4148.115
229.16,-0.6526799,-0.01815934,-574.3023,0.003765126,0,0,0.001815934,0.01815934,0.01816099,574.3022,3764.443
232.16,-0.6026799,-0.01807958,-520.1233,0.003409929,0,0,0.001807958,0.01807958,0.01808121,520.1233,3409.313
235.16,-0.5526399,-0.01796793,-466.6962,0.003059661,0,0,0.001796793,0.01796793,0.01796955,466.6962,3059.111
238.16,-0.5027199,-0.01819123,-415.7018,0.002725342,0,0,0.001819123,0.01819123,0.01819288,415.7018,2724.846
241.16,-0.4526399,-0.01785628,-364.8752,0.002392122,0,0,0.001785628,0.01785628,0.01785788,364.8752,2391.695
244.16,-0.4026799,-0.01763295,-318.1243,0.002085624,0,0,0.001763295,0.01763295,0.01763451,318.1243,2085.256
247.16,-0.3526399,-0.01771271,-311.1433,0.002039856,0,0,0.001771271,0.01771271,0.01771428,311.1433,2039.495
250.16,-0.30264,-0.01771271,-311.6091,0.00204291,0,0,0.001771271,0.01771271,0.01771428,311.6092,2042.548
253.16,-0.25264,-0.01766484,-311.3605,0.00204128,0,0,0.001766484,0.01766484,0.0176664,311.3605,2040.919
256.16,-0.20268,-0.01792006,-310.9597,0.002038652,0,0,0.001792006,0.01792006,0.01792167,310.9597,2038.287
259.16,-0.1526,-0.01792006,-309.8274,0.002031229,0,0,0.001792006,0.01792006,0.01792167,309.8274,2030.865
262.16,-0.10268,-0.01776055,-310.1376,0.002033262,0,0,0.001776055,0.01776055,0.01776212,310.1376,2032.901
265.16,-0.05263999,-0.01807958,-292.2596,0.001916055,0,0,0.001807958,0.01807958,0.01808121,292.2596,1915.708
268.16,-0.00268,-0.0175532,-243.3702,0.001595535,0,0,0.00175532,0.0175532,0.01755474,243.3702,1595.255
271.16,0.04732,-0.01804769,-197.8986,0.001297423,0,0,0.001804769,0.01804769,0.01804932,197.8986,1297.189
274.16,0.09732,-0.01801576,-154.5403,0.001013166,0,0,0.001801576,0.01801576,0.01801739,154.5403,1012.984
277.16,0.14736,-0.01761701,-113.7957,0.0007460447,0,0,0.001761701,0.01761701,0.01761856,113.7957,745.9133
278.23,0.16516,-0.0176489,-99.96949,0.0006554001,1,1,0.00176489,0.0176489,0.01765046,99.96949,655.2845
281.23,0.11516,-0.01804769,-154.432,0.001012456,1,1,0.001804769,0.01804769,0.01804932,154.432,1012.274
284.23,0.06512,-0.01793601,-219.998,0.001442307,1,1,0.001793601,0.01793601,0.01793761,219.998,1442.048
287.23,0.01516,-0.01788817,-280.4893,0.001838888,1,1,0.001788817,0.01788817,0.01788977,280.4893,1838.559
290.23,-0.03487999,-0.01827098,-310.7176,0.002037065,1,1,0.001827098,0.01827098,0.01827265,310.7176,2036.693
293.23,-0.08487998,-0.0184305,-310.9128,0.002038345,1,1,0.00184305,0.0184305,0.0184322,310.9128,2037.969
296.23,-0.13484,-0.01804769,-311.7656,0.002043936,1,1,0.001804769,0.01804769,0.01804932,311.7656,2043.567
299.23,-0.18488,-0.01846243,-312.8519,0.002051058,1,1,0.001846243,0.01846243,0.01846413,312.8519,2050.679
302.23,-0.23484,-0.01847837,-312.9988,0.00205202,1,1,0.001847837,0.01847837,0.01848008,312.9988,2051.641
305.23,-0.28484,-0.0181115,-312.8044,0.002050746,1,1,0.00181115,0.0181115,0.01811314,312.8044,2050.375
308.23,-0.3349199,-0.0184305,-345.2964,0.002263764,1,1,0.00184305,0.0184305,0.0184322,345.2964,2263.346
311.23,-0.3847999,-0.01815934,-404.3723,0.002651065,1,1,0.001815934,0.01815934,0.01816099,404.3723,2650.584
314.23,-0.4348799,-0.01803175,-463.2498,0.003037066,1,1,0.001803174,0.01803175,0.01803337,463.2498,3036.518
317.23,-0.4848799,-0.01854219,-521.958,0.003421957,1,1,0.001854219,0.01854219,0.0185439,521.958,3421.323
320.23,-0.5348799,-0.01846243,-582.383,0.003818104,1,1,0.001846243,0.01846243,0.01846413,582.383,3817.399
323.23,-0.5848399,-0.01855813,-647.9989,0.004248281,1,1,0.001855813,0.01855813,0.01855985,647.9989,4247.493
326.23,-0.6348399,-0.01860596,-726.8482,0.004765218,1,1,0.001860596,0.01860596,0.01860769,726.8482,4764.331
329.23,-0.6847999,-0.0182391,-816.7496,0.005354612,1,1,0.00182391,0.0182391,0.01824076,816.7496,5353.635
332.23,-0.7348799,-0.01825504,-912.5092,0.005982412,1,1,0.001825504,0.01825504,0.01825671,912.5092,5981.32
335.23,-0.7848399,-0.01817528,-1011.136,0.00662901,1,1,0.001817528,0.01817528,0.01817693,1011.136,6627.805
338.23,-0.8349199,-0.01825504,-1113.512,0.007300189,1,1,0.001825504,0.01825504,0.01825671,1113.512,7298.856
341.23,-0.8848798,-0.01819123,-1217.103,0.007979329,1,1,0.001819123,0.01819123,0.01819288,1217.103,7977.877
344.23,-0.9348398,-0.0183348,-1323.991,0.008680089,1,1,0.00183348,0.0183348,0.01833648,1323.991,8678.498
347.23,-0.9848798,-0.01835074,-1431.471,0.009384722,1,1,0.001835074,0.01835074,0.01835243,1431.471,9383.001
350.23,-1.03488,-0.01827098,-1542.834,0.01011482,1,1,0.001827098,0.01827098,0.01827265,1542.834,10112.97
353.23,-1.08484,-0.01868572,-1656.893,0.01086259,1,1,0.001868572,0.01868572,0.01868747,1656.893,10860.56
356.23,-1.13488,-0.01836669,-1778.837,0.01166206,1,1,0.001836669,0.01836669,0.01836837,1778.838,11659.92
359.23,-1.18484,-0.01870167,-1901.538,0.01246649,1,1,0.001870167,0.01870167,0.01870341,1901.538,12464.16
362.23,-1.23488,-0.01836669,-2026.747,0.01328736,1,1,0.001836669,0.01836669,0.01836837,2026.747,13284.92
365.23,-1.28492,-0.01851026,-2151.982,0.01410839,1,1,0.001851026,0.01851026,0.01851197,2151.981,14105.78
368.23,-1.33484,-0.01866978,-2277.019,0.01492814,1,1,0.001866978,0.01866978,0.01867152,2277.019,14925.35
371.23,-1.38492,-0.01882929,-2403.888,0.01575989,1,1,0.001882929,0.01882929,0.01883107,2403.887,15756.92
374.23,-1.43484,-0.0184305,-2534.013,0.016613,1,1,0.00184305,0.0184305,0.0184322,2534.013,16609.93
377.23,-1.48484,-0.0184305,-2664.22,0.01746663,1,1,0.00184305,0.0184305,0.0184322,2664.22,17463.41
380.23,-1.53488,-0.0185262,-2795.865,0.01832969,1,1,0.00185262,0.0185262,0.01852792,2795.865,18326.3
383.23,-1.58484,-0.01844645,-2932.052,0.01922254,1,1,0.001844645,0.01844645,0.01844815,2932.052,19218.99
386.23,-1.63484,-0.01862191,-3068.432,0.02011664,1,1,0.001862191,0.01862191,0.01862364,3068.432,20112.9
389.23,-1.68492,-0.01874954,-3206.805,0.02102382,1,1,0.001874954,0.01874954,0.01875129,3206.805,21019.87
392.23,-1.7348,-0.01910046,-3345.897,0.0219357,1,1,0.001910046,0.01910046,0.01910228,3345.897,21931.51
395.23,-1.78492,-0.01854219,-3489.497,0.02287715,1,1,0.001854219,0.01854219,0.0185439,3489.497,22872.9
398.23,-1.83488,-0.01876548,-3632.342,0.02381364,1,1,0.001876548,0.01876548,0.01876724,3632.343,23809.17
401.23,-1.88484,-0.01862191,-3778.046,0.02476887,1,1,0.001862191,0.01862191,0.01862364,3778.046,24764.26
404.23,-1.93488,-0.01873359,-3925.721,0.02573703,1,1,0.001873359,0.01873359,0.01873535,3925.721,25732.21
407.23,-1.98484,-0.0185262,-4076.97,0.02672862,1,1,0.00185262,0.0185262,0.01852792,4076.97,26723.67
410.23,-2.03484,-0.01859002,-4232.069,0.02774545,1,1,0.001859002,0.01859002,0.01859175,4232.069,27740.29
413.23,-2.08492,-0.0191164,-4398.628,0.02883741,1,1,0.00191164,0.0191164,0.01911823,4398.628,28831.9
416.23,-2.1348,-0.01839861,-4570.369,0.02996335,1,1,0.001839861,0.01839861,0.01840031,4570.369,29957.83
419.23,-2.18492,-0.01860596,-4745.647,0.03111247,1,1,0.001860596,0.01860596,0.01860769,4745.647,31106.68
422.23,-2.2348,-0.01859002,-4920.558,0.03225918,1,1,0.001859002,0.01859002,0.01859175,4920.558,32253.19
423.598,-2.25764,-0.01879741,-5000.197,0.0327813,1,1,0.001879741,0.01879741,0.01879917,5000.197,32775.14
426.598,-2.20768,-0.01854219,-4750.448,0.03114394,1,1,0.001854219,0.01854219,0.0185439,4750.448,31138.17
429.598,-2.15768,-0.01851026,-4460.251,0.02924141,1,1,0.001851026,0.01851026,0.01851197,4460.251,29236
432.598,-2.1076,-0.01868572,-4192.404,0.0274854,1,1,0.001868572,0.01868572,0.01868747,4192.404,27480.27
435.598,-2.0576,-0.01874954,-3956.008,0.02593559,1,1,0.001874954,0.01874954,0.01875129,3956.008,25930.73
438.598,-2.0076,-0.01865383,-3750.22,0.02458645,1,1,0.001865383,0.01865383,0.01865557,3750.22,24581.86
441.598,-1.95764,-0.01860596,-3558.202,0.02332758,1,1,0.001860596,0.01860596,0.01860769,3558.202,23323.24
444.598,-1.9076,-0.01895688,-3372.365,0.02210923,1,1,0.001895688,0.01895688,0.01895868,3372.365,22105.04
447.598,-1.85768,-0.01882929,-3199.206,0.020974,1,1,0.001882929,0.01882929,0.01883107,3199.206,20970.05
450.598,-1.80764,-0.01884524,-3044.509,0.01995981,1,1,0.001884524,0.01884524,0.01884701,3044.509,19956.05
453.598,-1.75764,-0.01873359,-2891.167,0.01895449,1,1,0.001873359,0.01873359,0.01873535,2891.167,18950.94
456.598,-1.70764,-0.01862191,-2745.31,0.01799826,1,1,0.001862191,0.01862191,0.01862364,2745.31,17994.9
459.598,-1.65764,-0.01898881,-2603.528,0.01706873,1,1,0.001898881,0.01898881,0.01899061,2603.528,17065.49
462.598,-1.60764,-0.01862191,-2464.412,0.01615669,1,1,0.001862191,0.01862191,0.01862364,2464.412,16153.68
465.598,-1.55764,-0.01882929,-2328.257,0.01526406,1,1,0.001882929,0.01882929,0.01883107,2328.257,15261.18
468.598,-1.50764,-0.01894094,-2197.74,0.01440838,1,1,0.001894094,0.01894094,0.01894273,2197.74,14405.66
471.598,-1.45764,-0.01862191,-2070.429,0.01357373,1,1,0.001862191,0.01862191,0.01862364,2070.429,13571.21
474.598,-1.40768,-0.01870167,-1946.087,0.01275855,1,1,0.001870167,0.01870167,0.01870341,1946.087,12756.16
477.598,-1.3576,-0.01846243,-1826.411,0.01197396,1,1,0.001846243,0.01846243,0.01846413,1826.411,11971.75
480.598,-1.30768,-0.01868572,-1709.572,0.01120796,1,1,0.001868572,0.01868572,0.01868747,1709.572,11205.86
483.598,-1.2576,-0.01863789,-1595.563,0.01046051,1,1,0.001863789,0.01863789,0.01863963,1595.563,10458.56
486.598,-1.20764,-0.01873359,-1483.706,0.009727179,1,1,0.001873359,0.01873359,0.01873535,1483.706,9725.356
489.598,-1.15764,-0.01887713,-1377.27,0.009029386,1,1,0.001887713,0.01887713,0.01887891,1377.27,9027.681
492.598,-1.10764,-0.01886118,-1275.604,0.008362864,1,1,0.001886118,0.01886118,0.01886296,1275.604,8361.287
495.598,-1.05764,-0.01884524,-1179.87,0.007735226,1,1,0.001884524,0.01884524,0.01884701,1179.87,7733.768
498.598,-1.00768,-0.01855813,-1086.948,0.007126034,1,1,0.001855813,0.01855813,0.01855985,1086.948,7124.711
501.598,-0.9575599,-0.01908451,-994.0833,0.006517211,1,1,0.001908451,0.01908451,0.01908633,994.0833,6515.968
504.598,-0.9077199,-0.01922809,-903.2222,0.005921526,1,1,0.001922809,0.01922809,0.01922993,903.2222,5920.387
507.598,-0.8575999,-0.01895688,-817.3698,0.005358677,1,1,0.001895688,0.01895688,0.01895868,817.3698,5357.661
510.598,-0.8076399,-0.01882929,-733.1059,0.004806244,1,1,0.001882929,0.01882929,0.01883107,733.106,4805.339
513.598,-0.7576399,-0.01916427,-658.343,0.004316098,1,1,0.001916427,0.01916427,0.01916611,658.343,4315.271
516.598,-0.7076399,-0.01903664,-594.9151,0.003900264,1,1,0.001903664,0.01903664,0.01903846,594.9151,3899.522
519.598,-0.6575999,-0.01914833,-540.0147,0.003540337,1,1,0.001914833,0.01914833,0.01915016,540.0147,3539.659
522.598,-0.6076399,-0.018925,-486.0369,0.003186458,1,1,0.0018925,0.018925,0.01892679,486.0369,3185.855
525.598,-0.5576399,-0.01897287,-433.4079,0.002841423,1,1,0.001897287,0.01897287,0.01897467,433.4079,2840.884
528.598,-0.5076399,-0.01876548,-382.233,0.00250592,1,1,0.001876548,0.01876548,0.01876724,382.233,2505.45
531.598,-0.4576,-0.01863789,-333.5726,0.002186902,1,1,0.001863789,0.01863789,0.01863963,333.5725,2186.495
534.598,-0.4076399,-0.01903664,-311.4665,0.002041975,1,1,0.001903664,0.01903664,0.01903846,311.4665,2041.586
537.598,-0.3576399,-0.01897287,-311.8324,0.002044374,1,1,0.001897287,0.01897287,0.01897467,311.8324,2043.986
540.598,-0.3075999,-0.018925,-312.2316,0.002046991,1,1,0.0018925,0.018925,0.01892679,312.2317,2046.604
543.598,-0.2575999,-0.01870167,-311.7585,0.002043889,1,1,0.001870167,0.01870167,0.01870341,311.7585,2043.507
546.598,-0.2076,-0.01903664,-311.4587,0.002041923,1,1,0.001903664,0.01903664,0.01903846,311.4587,2041.535
549.598,-0.1576,-0.01879741,-310.0608,0.002032759,1,1,0.001879741,0.01879741,0.01879917,310.0608,2032.377
552.598,-0.1076,-0.01953114,-306.3936,0.002008717,1,1,0.001953114,0.01953114,0.01953305,306.3936,2008.325
555.598,-0.05763999,-0.01918022,-261.6215,0.001715191,1,1,0.001918022,0.01918022,0.01918206,261.6215,1714.862
558.598,-0.007599999,-0.01924403,-217.3029,0.001424638,1,1,0.001924403,0.01924403,0.01924588,217.3029,1424.364
561.598,0.04232,-0.01948331,-171.9622,0.001127384,1,1,0.001948331,0.01948331,0.0194852,171.9622,1127.165
564.598,0.09236,-0.01918022,-129.6385,0.0008499101,1,1,0.001918022,0.01918022,0.01918206,129.6385,849.7471
566.846,0.12984,-0.01906857,-99.96993,0.000655403,1,1,0.001906857,0.01906857,0.01907039,99.96993,655.2781
568.848,0.09664001,-0.0190207,-133.6159,0.0008759861,2,2,0.00190207,0.0190207,0.01902251,133.6159,875.8195
571.848,0.04652,-0.01910046,-199.9307,0.001310746,2,2,0.001910046,0.01910046,0.01910228,199.9307,1310.496
574.848,-0.003439999,-0.01929186,-262.2821,0.001719522,2,2,0.001929186,0.01929186,0.01929372,262.2821,1719.19
577.848,-0.05347999,-0.01946732,-307.6313,0.002016831,2,2,0.001946732,0.01946732,0.01946922,307.6313,2016.438
580.848,-0.10348,-0.01964279,-312.3168,0.00204755,2,2,0.001964279,0.01964279,0.01964471,312.3168,2047.147
583.848,-0.15352,-0.01954708,-312.6313,0.002049611,2,2,0.001954708,0.01954708,0.01954899,312.6313,2049.211
586.848,-0.20352,-0.01924403,-312.899,0.002051366,2,2,0.001924403,0.01924403,0.01924588,312.899,2050.972
589.848,-0.25344,-0.01929186,-313.8542,0.002057628,2,2,0.001929186,0.01929186,0.01929372,313.8542,2057.232
592.848,-0.30352,-0.01910046,-313.8815,0.002057808,2,2,0.001910046,0.01910046,0.01910228,313.8815,2057.415
595.848,-0.35348,-0.01964279,-327.4762,0.002146935,2,2,0.001964279,0.01964279,0.01964471,327.4762,2146.513
598.848,-0.4034399,-0.01957901,-381.5197,0.002501244,2,2,0.001957901,0.01957901,0.01958093,381.5197,2500.754
601.848,-0.45348,-0.0196109,-439.508,0.002881415,2,2,0.00196109,0.0196109,0.01961282,439.508,2880.85
604.848,-0.5035199,-0.01941949,-498.8871,0.003270704,2,2,0.001941949,0.01941949,0.01942138,498.8871,3270.069
607.848,-0.5534799,-0.01924403,-560.0333,0.003671579,2,2,0.001924403,0.01924403,0.01924588,560.0333,3670.872
610.848,-0.6035599,-0.01945138,-623.0641,0.004084809,2,2,0.001945138,0.01945138,0.01945327,623.0641,4084.014
613.848,-0.6534399,-0.01938757,-698.4261,0.004578882,2,2,0.001938757,0.01938757,0.01938945,698.4261,4577.995
616.848,-0.7035199,-0.01962684,-786.9538,0.00515927,2,2,0.001962684,0.01962684,0.01962877,786.9538,5158.258
619.848,-0.7534798,-0.01932379,-883.0628,0.005789361,2,2,0.001932379,0.01932379,0.01932566,883.0629,5788.242
622.848,-0.8034799,-0.01953114,-981.5361,0.006434952,2,2,0.001953114,0.01953114,0.01953305,981.5361,6433.695
625.848,-0.8534799,-0.01906857,-1083.311,0.007102187,2,2,0.001906857,0.01906857,0.01907039,1083.311,7100.833
628.848,-0.9035199,-0.01924403,-1187.348,0.007784259,2,2,0.001924403,0.01924403,0.01924588,1187.349,7782.761
631.848,-0.9534399,-0.01975447,-1293.704,0.008481524,2,2,0.001975447,0.01975447,0.01975642,1293.704,8479.849
634.848,-1.00352,-0.0198023,-1402.42,0.00919427,2,2,0.00198023,0.0198023,0.01980426,1402.42,9192.449
637.848,-1.05348,-0.0197066,-1514.644,0.009930009,2,2,0.00197066,0.0197066,0.01970854,1514.644,9928.052
640.848,-1.10352,-0.01965877,-1630.104,0.01068696,2,2,0.001965877,0.01965877,0.0196607,1630.104,10684.86
643.848,-1.15348,-0.0197066,-1751.821,0.01148494,2,2,0.00197066,0.0197066,0.01970854,1751.821,11482.68
646.848,-1.20348,-0.01948331,-1874.309,0.01228797,2,2,0.001948331,0.01948331,0.0194852,1874.309,12285.58
649.848,-1.25352,-0.01929186,-2000.833,0.01311747,2,2,0.001929186,0.01929186,0.01929372,2000.833,13114.94
652.848,-1.30352,-0.01930781,-2124.836,0.01393043,2,2,0.001930781,0.01930781,0.01930967,2124.836,13927.74
655.848,-1.35344,-0.01985017,-2250.917,0.01475702,2,2,0.001985017,0.01985017,0.01985214,2250.917,14754.09
658.848,-1.40348,-0.01948331,-2379.414,0.01559944,2,2,0.001948331,0.01948331,0.0194852,2379.414,15596.4
661.848,-1.45352,-0.01954708,-2511.147,0.01646308,2,2,0.001954708,0.01954708,0.01954899,2511.147,16459.87
664.848,-1.50352,-0.01954708,-2642.612,0.01732497,2,2,0.001954708,0.01954708,0.01954899,2642.612,17321.58
667.848,-1.55352,-0.01969066,-2776.511,0.01820281,2,2,0.001969066,0.01969066,0.01969259,2776.511,18199.23
670.848,-1.60348,-0.01949925,-2913.717,0.01910233,2,2,0.001949925,0.01949925,0.01950115,2913.717,19098.61
673.848,-1.65352,-0.01925997,-3051.517,0.02000575,2,2,0.001925997,0.01925997,0.01926183,3051.517,20001.89
676.848,-1.70348,-0.01978636,-3190.281,0.02091549,2,2,0.001978636,0.01978636,0.01978832,3190.281,20911.35
679.848,-1.75348,-0.01975447,-3331.653,0.02184232,2,2,0.001975447,0.01975447,0.01975642,3331.653,21838.01
682.848,-1.80352,-0.01956303,-3475.771,0.02278716,2,2,0.001956303,0.01956303,0.01956494,3475.771,22782.7
685.848,-1.85352,-0.01964279,-3620.378,0.0237352,2,2,0.001964279,0.01964279,0.01964471,3620.378,23730.54
688.848,-1.90348,-0.01932379,-3766.317,0.02469198,2,2,0.001932379,0.01932379,0.01932566,3766.317,24687.2
691.848,-1.95352,-0.01957901,-3913.184,0.02565484,2,2,0.001957901,0.01957901,0.01958093,3913.184,25649.82
694.848,-2.00344,-0.01986612,-4059.761,0.0266158,2,2,0.001986612,0.01986612,0.01986809,4059.761,26610.51
697.848,-2.05352,-0.01949925,-4222.939,0.02768559,2,2,0.001949925,0.01949925,0.01950115,4222.939,27680.19
700.848,-2.10348,-0.01972254,-4397.779,0.02883185,2,2,0.001972254,0.01972254,0.01972449,4397.779,28826.16
703.848,-2.15352,-0.02004158,-4574.916,0.02999316,2,2,0.002004158,0.02004158,0.02004359,4574.916,29987.15
706.848,-2.20352,-0.01978636,-4753.938,0.03116682,2,2,0.001978636,0.01978636,0.01978832,4753.938,31160.65
709.848,-2.25348,-0.01996182,-4935.386,0.0323564,2,2,0.001996182,0.01996182,0.01996381,4935.386,32349.94
710.942,-2.27168,-0.01978636,-5000.101,0.03278067,2,2,0.001978636,0.01978636,0.01978832,5000.101,32774.18
713.942,-2.22176,-0.01959495,-4740.927,0.03108153,2,2,0.001959495,0.01959495,0.01959687,4740.927,31075.44
716.942,-2.17168,-0.01957901,-4448.713,0.02916577,2,2,0.001957901,0.01957901,0.01958093,4448.713,29160.06
719.942,-2.12168,-0.02023298,-4181.573,0.0274144,2,2,0.002023298,0.02023298,0.02023503,4181.573,27408.85
722.942,-2.07168,-0.01981825,-3946.334,0.02587217,2,2,0.001981825,0.01981825,0.01982021,3946.334,25867.04
725.942,-2.02172,-0.01932379,-3738.108,0.02450704,2,2,0.001932379,0.01932379,0.01932566,3738.108,24502.31
728.942,-1.97168,-0.01951519,-3543.578,0.02323171,2,2,0.001951519,0.01951519,0.0195171,3543.578,23227.17
731.942,-1.92172,-0.01978636,-3358.473,0.02201815,2,2,0.001978636,0.01978636,0.01978832,3358.473,22013.8
734.942,-1.87168,-0.01975447,-3183.036,0.02086798,2,2,0.001975447,0.01975447,0.01975642,3183.036,20863.86
737.942,-1.82172,-0.02024896,-3026.905,0.01984439,2,2,0.002024896,0.02024896,0.02025102,3026.905,19840.37
740.942,-1.77168,-0.01983423,-2874.687,0.01884645,2,2,0.001983423,0.01983423,0.01983619,2874.687,18842.71
743.942,-1.72176,-0.01999374,-2726.638,0.01787584,2,2,0.001999374,0.01999374,0.01999574,2726.638,17872.27
746.942,-1.67168,-0.01967471,-2585.609,0.01695126,2,2,0.001967471,0.01967471,0.01967665,2585.609,16947.92
749.942,-1.62168,-0.02018515,-2446.284,0.01603784,2,2,0.002018515,0.02018515,0.02018719,2446.284,16034.61
752.942,-1.57172,-0.02007347,-2311.663,0.01515527,2,2,0.002007347,0.02007347,0.02007548,2311.663,15152.22
755.942,-1.52168,-0.019898,-2180.889,0.01429791,2,2,0.0019898,0.019898,0.01989998,2180.889,14295.06
758.942,-1.47168,-0.02005752,-2054.343,0.01346827,2,2,0.002005752,0.02005752,0.02005953,2054.343,13465.57
761.942,-1.42168,-0.02007347,-1930.256,0.01265476,2,2,0.002007347,0.02007347,0.02007548,1930.256,12652.22
764.942,-1.37172,-0.0198023,-1808.757,0.01185821,2,2,0.00198023,0.0198023,0.01980426,1808.757,11855.86
767.942,-1.32172,-0.01994587,-1692.49,0.01109597,2,2,0.001994587,0.01994587,0.01994786,1692.49,11093.75
770.942,-1.27168,-0.01985017,-1579.188,0.01035316,2,2,0.001985017,0.01985017,0.01985214,1579.188,10351.1
773.942,-1.22164,-0.02010539,-1466.789,0.009616268,2,2,0.002010539,0.02010539,0.02010741,1466.789,9614.334
776.942,-1.17172,-0.02016921,-1361.495,0.008925965,2,2,0.002016921,0.02016921,0.02017124,1361.495,8924.165
779.942,-1.12168,-0.02023298,-1263.253,0.008281891,2,2,0.002023298,0.02023298,0.02023503,1263.253,8280.215
782.942,-1.07172,-0.01991399,-1166.491,0.007647518,2,2,0.001991399,0.01991399,0.01991597,1166.491,7645.995
785.942,-1.02168,-0.02024896,-1073.602,0.007038539,2,2,0.002024896,0.02024896,0.02025102,1073.602,7037.114
788.942,-0.9716799,-0.02016921,-981.1092,0.006432153,2,2,0.002016921,0.02016921,0.02017124,981.1092,6430.856
791.942,-0.9217198,-0.01985017,-890.2611,0.005836553,2,2,0.001985017,0.01985017,0.01985214,890.2611,5835.395
794.942,-0.8716799,-0.0202968,-803.7289,0.005269248,2,2,0.00202968,0.0202968,0.02029886,803.7289,5268.178
797.942,-0.8216799,-0.02024896,-721.3459,0.004729145,2,2,0.002024896,0.02024896,0.02025102,721.3459,4728.187
800.942,-0.7717199,-0.01985017,-647.6213,0.004245806,2,2,0.001985017,0.01985017,0.01985214,647.6213,4244.963
803.942,-0.7217199,-0.02008945,-585.3336,0.003837448,2,2,0.002008945,0.02008945,0.02009147,585.3336,3836.677
806.942,-0.6716799,-0.02032869,-529.7258,0.003472883,2,2,0.002032869,0.02032869,0.02033075,529.7258,3472.177
809.942,-0.6216799,-0.0202968,-475.8304,0.003119545,2,2,0.00202968,0.0202968,0.02029886,475.8304,3118.912
812.942,-0.5716799,-0.01991399,-424.9701,0.002786104,2,2,0.001991399,0.01991399,0.01991597,424.9701,2785.55
815.942,-0.5216799,-0.01975447,-374.0819,0.002452482,2,2,0.001975447,0.01975447,0.01975642,374.0819,2451.997
818.942,-0.47168,-0.02002563,-327.2518,0.002145463,2,2,0.002002563,0.02002563,0.02002764,327.2518,2145.034
821.942,-0.4216799,-0.02005752,-312.8099,0.002050782,2,2,0.002005752,0.02005752,0.02005953,312.8099,2050.371
824.942,-0.3716799,-0.0202968,-313.0016,0.002052039,2,2,0.00202968,0.0202968,0.02029886,313.0016,2051.623
827.942,-0.3216799,-0.02012134,-312.8938,0.002051332,2,2,0.002012134,0.02012134,0.02012336,312.8938,2050.92
830.942,-0.2716799,-0.02008945,-311.8253,0.002044327,2,2,0.002008945,0.02008945,0.02009147,311.8253,2043.916
833.942,-0.22172,-0.01986612,-311.7114,0.00204358,2,2,0.001986612,0.01986612,0.01986809,311.7114,2043.174
836.942,-0.17168,-0.02037656,-311.428,0.002041722,2,2,0.002037656,0.02037656,0.02037863,311.428,2041.306
839.942,-0.12168,-0.02032869,-298.1769,0.001954848,2,2,0.002032869,0.02032869,0.02033075,298.1769,1954.451
842.942,-0.07171999,-0.0202968,-256.1763,0.001679492,2,2,0.00202968,0.0202968,0.02029886,256.1763,1679.152
845.942,-0.02168,-0.02020109,-212.1519,0.001390868,2,2,0.002020109,0.02020109,0.02020314,212.1519,1390.587
848.942,0.02828,-0.02008945,-169.0266,0.001108138,2,2,0.002008945,0.02008945,0.02009147,169.0266,1107.916
851.942,0.07828001,-0.02007347,-126.8185,0.0008314223,2,2,0.002007347,0.02007347,0.02007548,126.8185,831.2554
853.998,0.11252,-0.02034467,-99.93096,0.0006551475,2,2,0.002034467,0.02034467,0.02034674,99.93096,655.0142
855.002,0.0966,-0.02042443,-109.4981,0.0007178696,0,3,0.002042443,0.02042443,0.02042651,109.4981,717.7229
858.002,0.04592,-0.02024896,-178.5494,0.00117057,0,3,0.002024896,0.02024896,0.02025102,178.5494,1170.333
861.002,-0.004039999,-0.02036061,-241.053,0.001580344,0,3,0.002036061,0.02036061,0.02036268,241.053,1580.022
864.002,-0.05407999,-0.02021704,-296.2592,0.001942276,0,3,0.002021704,0.02021704,0.02021908,296.2592,1941.883
867.002,-0.10408,-0.02026491,-313.1514,0.002053021,0,3,0.002026491,0.02026491,0.02026696,313.1514,2052.605
870.002,-0.15416,-0.02040844,-312.703,0.002050081,0,3,0.002040844,0.02040844,0.02041053,312.703,2049.663
873.002,-0.20412,-0.01965877,-315.2051,0.002066485,0,3,0.001965877,0.01965877,0.0196607,315.2051,2066.079
876.002,-0.25404,-0.02021704,-313.8361,0.00205751,0,3,0.002021704,0.02021704,0.02021908,313.8361,2057.094
879.002,-0.3041199,-0.02042443,-314.0556,0.002058949,0,3,0.002042443,0.02042443,0.02042651,314.0556,2058.528
882.002,-0.35408,-0.02034467,-315.2679,0.002066897,0,3,0.002034467,0.02034467,0.02034674,315.2679,2066.476
885.002,-0.4040399,-0.02024896,-357.6236,0.002344581,0,3,0.002024896,0.02024896,0.02025102,357.6236,2344.106
888.002,-0.4540799,-0.02012134,-413.5599,0.0027113,0,3,0.002012134,0.02012134,0.02012336,413.5599,2710.754
891.002,-0.5041199,-0.02028085,-471.7808,0.003092995,0,3,0.002028085,0.02028085,0.02028291,471.7808,3092.368
894.002,-0.5540799,-0.02018515,-532.7778,0.003492892,0,3,0.002018515,0.02018515,0.02018719,532.7778,3492.187
897.002,-0.6041199,-0.02052013,-595.6841,0.003905306,0,3,0.002052013,0.02052013,0.02052223,595.6841,3904.504
900.002,-0.6540399,-0.02053607,-663.0613,0.004347031,0,3,0.002053607,0.02053607,0.02053818,663.0613,4346.138
903.002,-0.7041599,-0.02020109,-745.6767,0.004888657,0,3,0.002020109,0.02020109,0.02020314,745.6767,4887.67
906.002,-0.7540799,-0.02024896,-842.0225,0.005520301,0,3,0.002024896,0.02024896,0.02025102,842.0225,5519.183
909.002,-0.8040799,-0.02052013,-939.9486,0.006162304,0,3,0.002052013,0.02052013,0.02052223,939.9485,6161.04
912.002,-0.8540798,-0.02064772,-1040.739,0.006823084,0,3,0.002064772,0.02064772,0.02064985,1040.739,6821.675
915.002,-0.9040799,-0.02055202,-1144.324,0.007502188,0,3,0.002055202,0.02055202,0.02055413,1144.324,7500.646
918.002,-0.9540399,-0.02023298,-1249.543,0.008192007,0,3,0.002023298,0.02023298,0.02023503,1249.543,8190.35
921.002,-1.00412,-0.02026491,-1358.083,0.008903597,0,3,0.002026491,0.02026491,0.02026696,1358.083,8901.793
924.002,-1.05404,-0.02059989,-1468.311,0.009626246,0,3,0.002059989,0.02059989,0.02060201,1468.311,9624.263
927.002,-1.10412,-0.02040844,-1583.989,0.01038464,0,3,0.002040844,0.02040844,0.02041053,1583.989,10382.52
930.002,-1.15408,-0.02050415,-1703.654,0.01116916,0,3,0.002050415,0.02050415,0.02050625,1703.654,11166.87
933.002,-1.20408,-0.02069559,-1826.719,0.01197597,0,3,0.002069559,0.02069559,0.02069773,1826.719,11973.5
936.002,-1.25412,-0.02058391,-1951.771,0.01279581,0,3,0.002058391,0.02058391,0.02058602,1951.771,12793.18
939.002,-1.30412,-0.02050415,-2077.571,0.01362056,0,3,0.002050415,0.02050415,0.02050625,2077.571,13617.77
942.002,-1.35404,-0.02069559,-2202.616,0.01444035,0,3,0.002069559,0.02069559,0.02069773,2202.616,14437.36
945.002,-1.40408,-0.02066366,-2331.653,0.01528632,0,3,0.002066366,0.02066366,0.0206658,2331.653,15283.16
948.002,-1.45408,-0.0204882,-2462.858,0.0161465,0,3,0.00204882,0.0204882,0.0204903,2462.858,16143.19
951.002,-1.50412,-0.02079129,-2594.888,0.01701209,0,3,0.002079129,0.02079129,0.02079345,2594.888,17008.55
954.002,-1.55412,-0.02050415,-2729.242,0.01789291,0,3,0.002050415,0.02050415,0.02050625,2729.241,17889.24
957.002,-1.60408,-0.02031274,-2865.61,0.01878694,0,3,0.002031274,0.02031274,0.02031481,2865.61,18783.12
960.002,-1.65412,-0.02075937,-3003.498,0.01969094,0,3,0.002075937,0.02075937,0.02076152,3003.498,19686.85
963.002,-1.70408,-0.02083912,-3142.414,0.02060167,0,3,0.002083912,0.02083912,0.0208413,3142.414,20597.38
966.002,-1.75404,-0.02079129,-3283.809,0.02152865,0,3,0.002079129,0.02079129,0.02079345,3283.809,21524.18
969.002,-1.80412,-0.02091888,-3426.375,0.02246332,0,3,0.002091888,0.02091888,0.02092107,3426.375,22458.62
972.002,-1.85412,-0.02082318,-3570.738,0.02340976,0,3,0.002082318,0.02082318,0.02082535,3570.738,23404.89
975.002,-1.90408,-0.02061583,-3717.472,0.02437175,0,3,0.002061583,0.02061583,0.02061796,3717.472,24366.73
978.002,-1.95412,-0.02071153,-3863.752,0.02533076,0,3,0.002071153,0.02071153,0.02071368,3863.751,25325.51
981.002,-2.00404,-0.02042443,-4008.545,0.02628002,0,3,0.002042443,0.02042443,0.02042651,4008.545,26274.66
984.002,-2.05408,-0.02072748,-4172.377,0.02735411,0,3,0.002072748,0.02072748,0.02072963,4172.377,27348.44
987.002,-2.10408,-0.02080724,-4349.292,0.02851396,0,3,0.002080724,0.02080724,0.0208094,4349.292,28508.03
990.002,-2.15412,-0.02064772,-4527.12,0.02967981,0,3,0.002064772,0.02064772,0.02064985,4527.12,29673.68
993.002,-2.20412,-0.02067965,-4709.4,0.03087483,0,3,0.002067965,0.02067965,0.02068178,4709.4,30868.45
996.002,-2.25408,-0.02050415,-4893.352,0.03208082,0,3,0.002050415,0.02050415,0.02050625,4893.352,32074.24
999.002,-2.30408,-0.02047226,-5072.799,0.03325727,0,3,0.002047226,0.02047226,0.02047435,5072.798,33250.46
1002.002,-2.35412,-0.02072748,-5251.018,0.03442568,0,3,0.002072748,0.02072748,0.02072963,5251.018,34418.55
1005.002,-2.40404,-0.02042443,-5429.234,0.03559406,0,3,0.002042443,0.02042443,0.02042651,5429.233,35586.79
1008.002,-2.45412,-0.02069559,-5608.401,0.03676868,0,3,0.002069559,0.02069559,0.02069773,5608.401,36761.07
1011.002,-2.50408,-0.02055202,-5785.863,0.03793212,0,3,0.002055202,0.02055202,0.02055413,5785.863,37924.33
1014.002,-2.55412,-0.0209827,-5966.993,0.03911962,0,3,0.00209827,0.0209827,0.0209849,5966.994,39111.41
1017.002,-2.60412,-0.02050415,-6147.392,0.04030231,0,3,0.002050415,0.02050415,0.02050625,6147.392,40294.05
1020.002,-2.65408,-0.02115816,-6331.129,0.04150689,0,3,0.002115816,0.02115816,0.0211604,6331.128,41498.11
1023.002,-2.70408,-0.02059989,-6537.098,0.04285722,0,3,0.002059989,0.02059989,0.02060201,6537.098,42848.39
1026.002,-2.75416,-0.02114221,-6754.429,0.04428205,0,3,0.002114221,0.02114221,0.02114445,6754.429,44272.68
1029.002,-2.80404,-0.02040844,-6970.843,0.04570086,0,3,0.002040844,0.02040844,0.02041053,6970.843,45691.53
1031.808,-2.85092,-0.02072748,-6592.876,0.0432229,0,3,0.002072748,0.02072748,0.02072963,6592.875,43213.94
1034.808,-2.90084,-0.02044037,-6803.764,0.04460549,0,3,0.002044037,0.02044037,0.02044246,6803.764,44596.37
1037.808,-2.95084,-0.02083912,-7030.423,0.04609146,0,3,0.002083912,0.02083912,0.0208413,7030.423,46081.86
1040.808,-3.00088,-0.02104651,-7256.243,0.04757194,0,3,0.002104651,0.02104651,0.02104873,7256.243,47561.93
1043.808,-3.050839,-0.02074342,-7482.599,0.04905593,0,3,0.002074342,0.02074342,0.02074557,7482.6,49045.76
1046.808,-3.10088,-0.02042443,-7707.059,0.05052749,0,3,0.002042443,0.02042443,0.02042651,7707.06,50517.17
1049.808,-3.150839,-0.02055202,-7933.075,0.05200925,0,3,0.002055202,0.02055202,0.02055413,7933.075,51998.56
1052.808,-3.200879,-0.02082318,-8161.881,0.0535093,0,3,0.002082318,0.02082318,0.02082535,8161.881,53498.16
1055.808,-3.25088,-0.02059989,-8384.234,0.05496705,0,3,0.002059989,0.02059989,0.02060201,8384.234,54955.73
1058.808,-3.30088,-0.02074342,-8610.439,0.05645005,0,3,0.002074342,0.02074342,0.02074557,8610.438,56438.34
1061.808,-3.3508,-0.02037656,-8834.864,0.05792138,0,3,0.002037656,0.02037656,0.02037863,8834.864,57909.58
1064.808,-3.40088,-0.02063178,-9066.344,0.05943896,0,3,0.002063178,0.02063178,0.0206339,9066.344,59426.7
1067.808,-3.450839,-0.02082318,-9296.365,0.06094698,0,3,0.002082318,0.02082318,0.02082535,9296.365,60934.29
1070.808,-3.50084,-0.02075937,-9520.764,0.06241814,0,3,0.002075937,0.02075937,0.02076152,9520.764,62405.18
1073.808,-3.55084,-0.02072748,-9743.993,0.06388163,0,3,0.002072748,0.02072748,0.02072963,9743.993,63868.39
1076.808,-3.60088,-0.0204882,-9979.194,0.06542362,0,3,0.00204882,0.0204882,0.0204903,9979.194,65410.21
1079.808,-3.650839,-0.02069559,-10216.5,0.0669794,0,3,0.002069559,0.02069559,0.02069773,10216.5,66965.54
1082.808,-3.70092,-0.02074342,-10455.87,0.06854866,0,3,0.002074342,0.02074342,0.02074557,10455.87,68534.45
1085.808,-3.75084,-0.02090294,-10708.17,0.07020275,0,3,0.002090294,0.02090294,0.02090512,10708.17,70188.08
1088.808,-3.80088,-0.02040844,-10962.55,0.0718705,0,3,0.002040844,0.02040844,0.02041053,10962.55,71855.83
1091.808,-3.85084,-0.02080724,-11212.15,0.07350685,0,3,0.002080724,0.02080724,0.0208094,11212.15,73491.56
1094.808,-3.90084,-0.02075937,-11463.49,0.07515468,0,3,0.002075937,0.02075937,0.02076152,11463.49,75139.08
1097.808,-3.950839,-0.02063178,-11718.04,0.07682351,0,3,0.002063178,0.02063178,0.0206339,11718.04,76807.66
1100.808,-4.000839,-0.02052013,-11969.95,0.07847502,0,3,0.002052013,0.02052013,0.02052223,11969.95,78458.92
1103.808,-4.050839,-0.02061583,-12228.18,0.08016799,0,3,0.002061583,0.02061583,0.02061796,12228.18,80151.47
1106.808,-4.100879,-0.02112627,-12484.77,0.08185015,0,3,0.002112627,0.02112627,0.0211285,12484.77,81832.86
1109.808,-4.1508,-0.02103057,-12698.35,0.08325037,0,3,0.002103057,0.02103057,0.02103278,12698.35,83232.87
1112.808,-4.200879,-0.02104651,-12955.61,0.08493703,0,3,0.002104651,0.02104651,0.02104873,12955.62,84919.15
1115.808,-4.250839,-0.02072748,-13208.83,0.08659713,0,3,0.002072748,0.02072748,0.02072963,13208.83,86579.18
1118.808,-4.300839,-0.02075937,-13454.65,0.08820873,0,3,0.002075937,0.02075937,0.02076152,13454.66,88190.42
1121.808,-4.350839,-0.0211741,-13701.51,0.0898271,0,3,0.00211741,0.0211741,0.02117634,13701.51,89808.08
1124.808,-4.400879,-0.02074342,-13952.87,0.09147503,0,3,0.002074342,0.02074342,0.02074557,13952.87,91456.05
1127.808,-4.4508,-0.02072748,-14285.43,0.09365532,0,3,0.002072748,0.02072748,0.02072963,14285.43,93635.91
1130.808,-4.50084,-0.02126981,-14836.08,0.09726539,0,3,0.002126981,0.02126981,0.02127207,14836.08,97244.7
1133.808,-4.550839,-0.02042443,-15455.2,0.1013243,0,3,0.002042443,0.02042443,0.02042651,15455.2,101303.6
1136.808,-4.600919,-0.02061583,-16107.48,0.1056007,0,3,0.002061583,0.02061583,0.02061796,16107.48,105578.9
1139.808,-4.650839,-0.02095081,-16769.98,0.109944,0,3,0.002095081,0.02095081,0.020953,16769.97,109920.9
1142.808,-4.700839,-0.02074342,-17461.59,0.1144782,0,3,0.002074342,0.02074342,0.02074557,17461.59,114454.4
1145.806,-4.75088,-0.02119008,-18199.57,0.1193164,0,3,0.002119008,0.02119008,0.02119233,18199.57,119291.1
1148.752,-4.799959,-0.02120603,-18950.09,0.1242368,0,3,0.002120603,0.02120603,0.02120828,18950.09,124210.5
1151.502,-4.84576,-0.02144527,-19700.83,0.1291586,0,3,0.002144527,0.02144527,0.02144757,19700.83,129130.9
1154.132,-4.889599,-0.02141338,-20451.49,0.13408,0,3,0.002141338,0.02141338,0.02141567,20451.49,134051.3
1156.686,-4.932159,-0.02063178,-21202.28,0.1390022,0,3,0.002063178,0.02063178,0.0206339,21202.28,138973.5
1159.06,-4.971719,-0.0211741,-21953.48,0.143927,0,3,0.00211741,0.0211741,0.02117634,21953.47,143896.5
1161.344,-5.009839,-0.02119008,-22704.68,0.1488519,0,3,0.002119008,0.02119008,0.02119233,22704.68,148820.4
1163.62,-5.047719,-0.02091888,-23455.74,0.1537759,0,3,0.002091888,0.02091888,0.02092107,23455.74,153743.7
1165.88,-5.085399,-0.02120603,-24207.06,0.1587016,0,3,0.002120603,0.02120603,0.02120828,24207.06,158667.9
1168.108,-5.122479,-0.02112627,-24957.72,0.1636228,0,3,0.002112627,0.02112627,0.0211285,24957.72,163588.3
1170.334,-5.159639,-0.02131768,-25709.34,0.1685504,0,3,0.002131768,0.02131768,0.02131995,25709.34,168514.5
1172.582,-5.197079,-0.02120603,-26459.93,0.1734713,0,3,0.002120603,0.02120603,0.02120828,26459.93,173434.5
1174.804,-5.234079,-0.02119008,-27210.48,0.1783919,0,3,0.002119008,0.02119008,0.02119233,27210.48,178354.1
1177.032,-5.271279,-0.02111033,-27961.18,0.1833135,0,3,0.002111033,0.02111033,0.02111255,27961.18,183274.8
1179.286,-5.308879,-0.02103057,-28712.39,0.1882384,0,3,0.002103057,0.02103057,0.02103278,28712.39,188198.9
1181.524,-5.346119,-0.0210784,-29463.08,0.19316,0,3,0.00210784,0.0210784,0.02108062,29463.08,193119.3
1183.736,-5.382999,-0.02119008,-30214.41,0.1980857,0,3,0.002119008,0.02119008,0.02119233,30214.41,198043.7
1185.958,-5.42004,-0.02125386,-30964.99,0.2030065,0,3,0.002125386,0.02125386,0.02125612,30964.99,202963.3
1188.2,-5.4574,-0.02126981,-31716,0.2079301,0,3,0.002126981,0.02126981,0.02127207,31715.99,207885.9
1190.448,-5.494799,-0.02125386,-32466.38,0.2128496,0,3,0.002125386,0.02125386,0.02125612,32466.38,212804.4
1192.69,-5.532199,-0.02147719,-33217.5,0.217774,0,3,0.002147719,0.02147719,0.0214795,33217.5,217727.2
1194.918,-5.569319,-0.02139743,-33968.51,0.2226976,0,3,0.002139743,0.02139743,0.02139972,33968.52,222650
1197.136,-5.606359,-0.02126981,-34719.47,0.2276209,0,3,0.002126981,0.02126981,0.02127207,34719.47,227572.5
1199.346,-5.643159,-0.02173241,-35470.79,0.2325465,0,3,0.002173241,0.02173241,0.02173477,35470.79,232496
1201.57,-5.680239,-0.02152503,-36222.02,0.2374716,0,3,0.002152503,0.02152503,0.02152734,36222.02,237420.5
1203.802,-5.717439,-0.02106246,-36973.01,0.2423951,0,3,0.002106246,0.02106246,0.02106467,36973.02,242344.1
1206.024,-5.754439,-0.02130173,-37723.31,0.2473141,0,3,0.002130173,0.02130173,0.021304,37723.31,247261.4
1208.24,-5.791359,-0.02106246,-38474.37,0.252238,0,3,0.002106246,0.02106246,0.02106467,38474.37,252184.9
1210.448,-5.828199,-0.02123792,-39225.21,0.2571605,0,3,0.002123792,0.02123792,0.02124017,39225.21,257105.9
1212.674,-5.865239,-0.02119008,-39975.62,0.2620802,0,3,0.002119008,0.02119008,0.02119233,39975.62,262024.7
1214.892,-5.902239,-0.02141338,-40726.83,0.2670051,0,3,0.002141338,0.02141338,0.02141567,40726.82,266947.9
1217.118,-5.939319,-0.02158884,-41477.61,0.2719273,0,3,0.002158884,0.02158884,0.02159117,41477.61,271868.6
1219.34,-5.976399,-0.02131768,-42228.87,0.2768525,0,3,0.002131768,0.02131768,0.02131995,42228.88,276793.5
1221.572,-6.013599,-0.02139743,-42980.23,0.2817785,0,3,0.002139743,0.02139743,0.02139972,42980.23,281718.2
1223.806,-6.050839,-0.02147719,-43731.1,0.2867011,0,3,0.002147719,0.02147719,0.0214795,43731.1,286639.6
1226.072,-6.088599,-0.02146125,-44482.63,0.2916282,0,3,0.002146125,0.02146125,0.02146355,44482.63,291565.6
1228.33,-6.126159,-0.02119008,-45234.25,0.2965558,0,3,0.002119008,0.02119008,0.02119233,45234.25,296493
1230.582,-6.163719,-0.02184406,-45984.74,0.301476,0,3,0.002184406,0.02184406,0.02184645,45984.73,301410.1
1232.84,-6.201399,-0.0217643,-46736.21,0.3064027,0,3,0.00217643,0.0217643,0.02176667,46736.21,306336
1235.088,-6.238839,-0.02142932,-47487.29,0.3113267,0,3,0.002142932,0.02142932,0.02143162,47487.29,311260
1237.374,-6.276999,-0.02158884,-48238.47,0.3162515,0,3,0.002158884,0.02158884,0.02159117,48238.47,316183.2
1239.664,-6.315119,-0.02149314,-48989.17,0.3211731,0,3,0.002149314,0.02149314,0.02149545,48989.17,321104
1241.976,-6.353679,-0.02142932,-49739.92,0.326095,0,3,0.002142932,0.02142932,0.02143162,49739.93,326025.1
1244.308,-6.392479,-0.02155695,-50490.7,0.3310171,0,3,0.002155695,0.02155695,0.02155928,50490.7,330945.7
1246.648,-6.431479,-0.02152503,-51241.64,0.3359402,0,3,0.002152503,0.02152503,0.02152734,51241.64,335867.9
1248.902,-6.469079,-0.02184406,-51992.5,0.3408629,0,3,0.002184406,0.02184406,0.02184645,51992.5,340788.4
1251.228,-6.507839,-0.02142932,-52743.18,0.3457843,0,3,0.002142932,0.02142932,0.02143162,52743.18,345710.3
1253.986,-6.553839,-0.02152503,-53304.96,0.3494674,0,3,0.002152503,0.02152503,0.02152734,53304.96,349392.2
1256.28,-6.591999,-0.02192382,-54055.76,0.3543896,0,3,0.002192382,0.02192382,0.02192622,54055.76,354312
1258.558,-6.629999,-0.02122197,-54806.16,0.3593093,0,3,0.002122197,0.02122197,0.02122422,54806.16,359233
1260.878,-6.668639,-0.02133362,-55557.03,0.364232,0,3,0.002133362,0.02133362,0.0213359,55557.03,364154.3
1263.22,-6.707679,-0.0210784,-56307.83,0.3691542,0,3,0.00210784,0.0210784,0.02108062,56307.83,369076.4
1265.502,-6.745799,-0.02130173,-57059.09,0.3740795,0,3,0.002130173,0.02130173,0.021304,57059.09,373999.8
1267.818,-6.784399,-0.02130173,-57809.85,0.3790014,0,3,0.002130173,0.02130173,0.021304,57809.85,378920.7
1270.14,-6.823039,-0.02142932,-58560.45,0.3839224,0,3,0.002142932,0.02142932,0.02143162,58560.45,383840.1
1272.498,-6.862279,-0.0210784,-59312.01,0.3888496,0,3,0.00210784,0.0210784,0.02108062,59312.01,388767.7
1274.856,-6.901639,-0.02152503,-60062.63,0.3937707,0,3,0.002152503,0.02152503,0.02152734,60062.63,393685.9
1277.198,-6.940679,-0.02179623,-60813.65,0.3986944,0,3,0.002179623,0.02179623,0.0217986,60813.65,398607.5
1279.562,-6.980079,-0.02133362,-61564.73,0.4036184,0,3,0.002133362,0.02133362,0.0213359,61564.73,403532.3
1281.962,-7.020119,-0.02147719,-62315.88,0.408543,0,3,0.002147719,0.02147719,0.0214795,62315.88,408455.2
1284.36,-7.060039,-0.02158884,-63066.22,0.4134622,0,3,0.002158884,0.02158884,0.02159117,63066.22,413373
1286.786,-7.100439,-0.02122197,-63817.25,0.418386,0,3,0.002122197,0.02122197,0.02122422,63817.25,418297.2
1289.182,-7.140439,-0.02155695,-64568.25,0.4233095,0,3,0.002155695,0.02155695,0.02155928,64568.25,423218.3
1291.626,-7.181199,-0.02138149,-65318.91,0.4282309,0,3,0.002138149,0.02138149,0.02138378,65318.91,428139.3
1294.128,-7.222839,-0.02152503,-66069.23,0.43315,0,3,0.002152503,0.02152503,0.02152734,66069.23,433056.7
1296.582,-7.263679,-0.0216686,-66820.25,0.4380736,0,3,0.00216686,0.0216686,0.02167095,66820.24,437978.7
1299.036,-7.304639,-0.02134956,-67570.82,0.4429944,0,3,0.002134956,0.02134956,0.02135184,67570.82,442899.8
1301.558,-7.346719,-0.02174836,-68321.87,0.4479183,0,3,0.002174836,0.02174836,0.02175072,68321.88,447820.9
1304.152,-7.389919,-0.02193976,-69072.87,0.4528418,0,3,0.002193976,0.02193976,0.02194217,69072.88,452742.5
1306.696,-7.432279,-0.02141338,-69823.41,0.4577624,0,3,0.002141338,0.02141338,0.02141567,69823.41,457664.4
1309.198,-7.474039,-0.02136555,-70574.91,0.4626892,0,3,0.002136555,0.02136555,0.02136783,70574.91,462590.3
1311.38,-7.510399,-0.02149314,-71201.21,0.4667952,0,3,0.002149314,0.02149314,0.02149545,71201.2,466694.9