File: ElectricPoleSupport/ExptData/Raw/Heel_D1_cycle.raw.csv
"Test Type","Compression"
"Method Name:","C:\INSTRON\USER\TEMPLATE\Andyscomp.mtB"
"Name:","Transnet Compression Tests"
"Operator ID:","AndyS"
"Company:","IRL"
"Lab name:","Rm 3.09"
"Test date:","26/08/08"
"Temperature:","20.5"
"Humidity:","57.5"
"Note 1:","Plastic Telegraph Pole Breast and Heel Plate Tests"
"Note 2:",""
"Note 3:",""
"Geometry:","Rectangular"
"Specimen",1
"Specimen name:","D1"
"Width:",342.000000,"mm"
"Thickness:",888.000000,"mm"
"Anvil height:",90.000000,"mm"
"Diameter:",50.000000,"mm"
"Inner diameter:",0.500000,"mm"
"Outer diameter:",1.000000,"mm"
"Wall thickness:",0.500000,"mm"
"Area:",303696.000000,"mm*mm"
"Linear density:",1.000000,"den"
"Sled weight:",9.806650,"N"
"Loading span:",0.000000,"mm"
"Support span:",1.000000,"mm"
"Span ratio:","2"
"Fixture type:","3-point"
"Comment:","Transnet Large Rectangular Sample"
"Extensometer",-10.000000,"**mm"
"Included"
"Time sec","Extension mm","Strain 1 %","Load N","Comp. stress MPa","Cycle Count ","Total Cycle Count ","Comp. extension mm","Comp. strain %","True strain %","Comp. load N","True stress Pa"
0,-1.33596,-0.01973853,-4.330794,1.426029e-005,0,0,0.001973853,0.01973853,0.01974047,4.330794,14.25748
1,-1.35216,-0.01997776,-4.481819,1.475758e-005,0,0,0.001997776,0.01997776,0.01997976,4.481819,14.75464
2,-1.36928,-0.01978636,-4.553685,1.499422e-005,0,0,0.001978636,0.01978636,0.01978832,4.553685,14.99125
3,-1.386,-0.01983423,-6.179566,2.034787e-005,0,0,0.001983423,0.01983423,0.01983619,6.179566,20.34383
4,-1.40264,-0.01954708,-5.868949,1.932508e-005,0,0,0.001954708,0.01954708,0.01954899,5.868949,19.3213
5,-1.41932,-0.02008945,-6.067411,1.997857e-005,0,0,0.002008945,0.02008945,0.02009147,6.067411,19.97455
6,-1.43596,-0.01962684,-6.244774,2.056258e-005,0,0,0.001962684,0.01962684,0.01962877,6.244774,20.55855
7,-1.45264,-0.01964279,-7.033726,2.316042e-005,0,0,0.001964279,0.01964279,0.01964471,7.033726,23.15587
7.96,-1.46864,-0.01992993,-6.889556,2.26857e-005,0,0,0.001992993,0.01992993,0.01993192,6.889555,22.68118
"Specimen",2
"Specimen name:","D1.1"
"Width:",342.000000,"mm"
"Thickness:",888.000000,"mm"
"Anvil height:",90.000000,"mm"
"Diameter:",50.000000,"mm"
"Inner diameter:",0.500000,"mm"
"Outer diameter:",1.000000,"mm"
"Wall thickness:",0.500000,"mm"
"Area:",303696.000000,"mm*mm"
"Linear density:",1.000000,"den"
"Sled weight:",9.806650,"N"
"Loading span:",0.000000,"mm"
"Support span:",1.000000,"mm"
"Span ratio:","2"
"Fixture type:","3-point"
"Comment:","Transnet Large Rectangular Sample"
"Extensometer",-10.000000,"**mm"
"Included"
"Time sec","Extension mm","Strain 1 %","Load N","Comp. stress MPa","Cycle Count ","Total Cycle Count ","Comp. extension mm","Comp. strain %","True strain %","Comp. load N","True stress Pa"
0,0,-0.02026491,-116.3341,0.0003830609,0,0,0.002026491,0.02026491,0.02026696,116.3341,382.9833
1,-0.01624,-0.0196109,-122.2392,0.0004025052,0,0,0.00196109,0.0196109,0.01961282,122.2392,402.4262
2,-0.03331999,-0.02023298,-142.7118,0.0004699168,0,0,0.002023298,0.02023298,0.02023503,142.7118,469.8217
3,-0.04999999,-0.019898,-159.9989,0.0005268392,0,0,0.0019898,0.019898,0.01989998,159.9989,526.7343
4,-0.06671999,-0.02024896,-176.1442,0.0005800017,0,0,0.002024896,0.02024896,0.02025102,176.1442,579.8842
5,-0.08335999,-0.01978636,-190.3028,0.0006266227,0,0,0.001978636,0.01978636,0.01978832,190.3028,626.4987
6,-0.09999999,-0.01985017,-203.3198,0.0006694846,0,0,0.001985017,0.01985017,0.01985214,203.3198,669.3517
7,-0.11664,-0.02010539,-213.2995,0.0007023455,0,0,0.002010539,0.02010539,0.02010741,213.2995,702.2043
8,-0.13336,-0.01985017,-226.498,0.0007458049,0,0,0.001985017,0.01985017,0.01985214,226.498,745.6568
9,-0.15,-0.02004158,-241.0033,0.0007935677,0,0,0.002004158,0.02004158,0.02004359,241.0033,793.4087
10,-0.16672,-0.01985017,-254.6265,0.0008384255,0,0,0.001985017,0.01985017,0.01985214,254.6264,838.259
11,-0.18336,-0.01972254,-268.6682,0.0008846617,0,0,0.001972254,0.01972254,0.01972449,268.6682,884.4872
12,-0.20008,-0.01985017,-283.4332,0.0009332794,0,0,0.001985017,0.01985017,0.01985214,283.4332,933.0941
13,-0.21668,-0.01959495,-296.1773,0.0009752426,0,0,0.001959495,0.01959495,0.01959687,296.1773,975.0516
14,-0.23332,-0.01997776,-307.4418,0.001012334,0,0,0.001997776,0.01997776,0.01997976,307.4418,1012.132
15,-0.25,-0.01972254,-317.8777,0.001046697,0,0,0.001972254,0.01972254,0.01972449,317.8777,1046.491
16,-0.2666799,-0.019898,-325.2042,0.001070822,0,0,0.0019898,0.019898,0.01989998,325.2043,1070.609
17,-0.28332,-0.01972254,-328.5082,0.001081701,0,0,0.001972254,0.01972254,0.01972449,328.5082,1081.487
18,-0.30004,-0.01999374,-329.4629,0.001084844,0,0,0.001999374,0.01999374,0.01999574,329.4629,1084.627
19,-0.3166799,-0.01940355,-329.5931,0.001085273,0,0,0.001940355,0.01940355,0.01940543,329.5931,1085.063
20,-0.33336,-0.01983423,-330.212,0.001087311,0,0,0.001983423,0.01983423,0.01983619,330.212,1087.095
21,-0.3499999,-0.01986612,-330.8693,0.001089476,0,0,0.001986612,0.01986612,0.01986809,330.8694,1089.259
22,-0.3666799,-0.02016921,-330.9843,0.001089854,0,0,0.002016921,0.02016921,0.02017124,330.9843,1089.634
23,-0.3833199,-0.01972254,-330.5735,0.001088501,0,0,0.001972254,0.01972254,0.01972449,330.5735,1088.287
24,-0.4,-0.0198023,-330.1979,0.001087265,0,0,0.00198023,0.0198023,0.01980426,330.1979,1087.049
25,-0.41664,-0.02004158,-329.5806,0.001085232,0,0,0.002004158,0.02004158,0.02004359,329.5807,1085.015
26,-0.4333999,-0.01973853,-328.3946,0.001081327,0,0,0.001973853,0.01973853,0.01974047,328.3946,1081.113
27,-0.45004,-0.01977041,-328.0948,0.001080339,0,0,0.001977041,0.01977041,0.01977237,328.0948,1080.126
28,-0.46676,-0.01986612,-328.324,0.001081094,0,0,0.001986612,0.01986612,0.01986809,328.324,1080.88
29,-0.4833599,-0.01964279,-329.3486,0.001084468,0,0,0.001964279,0.01964279,0.01964471,329.3486,1084.255
30,-0.4999999,-0.019898,-332.2898,0.001094153,0,0,0.0019898,0.019898,0.01989998,332.2899,1093.935
31,-0.5166399,-0.01951519,-335.0877,0.001103365,0,0,0.001951519,0.01951519,0.0195171,335.0876,1103.15
32,-0.5333199,-0.02002563,-350.1994,0.001153125,0,0,0.002002563,0.02002563,0.02002764,350.1994,1152.894
33,-0.5499999,-0.01996182,-368.2884,0.001212688,0,0,0.001996182,0.01996182,0.01996381,368.2885,1212.446
34,-0.5667199,-0.01983423,-385.2889,0.001268666,0,0,0.001983423,0.01983423,0.01983619,385.2889,1268.415
35,-0.5833599,-0.01992993,-398.3008,0.001311511,0,0,0.001992993,0.01992993,0.01993192,398.3008,1311.25
36,-0.6000399,-0.02004158,-412.2899,0.001357574,0,0,0.002004158,0.02004158,0.02004359,412.2899,1357.302
37,-0.6167198,-0.01999374,-427.4307,0.00140743,0,0,0.001999374,0.01999374,0.01999574,427.4307,1407.148
38,-0.6333999,-0.01999374,-443.3908,0.001459982,0,0,0.001999374,0.01999374,0.01999574,443.3908,1459.691
39,-0.6499999,-0.02023298,-461.2717,0.00151886,0,0,0.002023298,0.02023298,0.02023503,461.2717,1518.553
40,-0.6666799,-0.0198023,-478.7663,0.001576466,0,0,0.00198023,0.0198023,0.01980426,478.7664,1576.154
41,-0.6833199,-0.01962684,-495.7013,0.001632229,0,0,0.001962684,0.01962684,0.01962877,495.7013,1631.908
42,-0.6999999,-0.02021704,-512.5465,0.001687696,0,0,0.002021704,0.02021704,0.02021908,512.5465,1687.355
43,-0.7167199,-0.01969066,-531.5292,0.001750201,0,0,0.001969066,0.01969066,0.01969259,531.5292,1749.857
44,-0.7333598,-0.01997776,-549.8137,0.001810408,0,0,0.001997776,0.01997776,0.01997976,549.8137,1810.047
45,-0.7500399,-0.01994587,-569.3077,0.001874597,0,0,0.001994587,0.01994587,0.01994786,569.3077,1874.223
46,-0.7667199,-0.01973853,-587.1149,0.001933232,0,0,0.001973853,0.01973853,0.01974047,587.1149,1932.851
47,-0.7833599,-0.02010539,-606.2801,0.001996339,0,0,0.002010539,0.02010539,0.02010741,606.2802,1995.938
48,-0.7999999,-0.02000969,-626.8812,0.002064174,0,0,0.002000969,0.02000969,0.02001169,626.8812,2063.76
49,-0.8166399,-0.019898,-648.1897,0.002134337,0,0,0.0019898,0.019898,0.01989998,648.1897,2133.913
50,-0.8333599,-0.01969066,-668.9002,0.002202532,0,0,0.001969066,0.01969066,0.01969259,668.9002,2202.099
51,-0.8500399,-0.01988206,-690.722,0.002274386,0,0,0.001988206,0.01988206,0.01988404,690.722,2273.934
52,-0.8667199,-0.019898,-712.1373,0.002344902,0,0,0.0019898,0.019898,0.01989998,712.1373,2344.435
53,-0.8833599,-0.01964279,-734.1293,0.002417316,0,0,0.001964279,0.01964279,0.01964471,734.1293,2416.841
54,-0.9000399,-0.01953114,-758.2346,0.002496689,0,0,0.001953114,0.01953114,0.01953305,758.2346,2496.202
55,-0.9167199,-0.01973853,-780.2909,0.002569316,0,0,0.001973853,0.01973853,0.01974047,780.2909,2568.808
56,-0.9333199,-0.01959495,-804.994,0.002650657,0,0,0.001959495,0.01959495,0.01959687,804.994,2650.138
57,-0.9499999,-0.01978636,-828.7186,0.002728777,0,0,0.001978636,0.01978636,0.01978832,828.7186,2728.237
58,-0.9666799,-0.01957901,-853.9355,0.00281181,0,0,0.001957901,0.01957901,0.01958093,853.9355,2811.26
59,-0.9833998,-0.02002563,-878.9091,0.002894043,0,0,0.002002563,0.02002563,0.02002764,878.9091,2893.463
60,-1.00004,-0.02007347,-903.7321,0.002975779,0,0,0.002007347,0.02007347,0.02007548,903.7321,2975.182
61,-1.01672,-0.0198023,-928.4965,0.003057322,0,0,0.00198023,0.0198023,0.01980426,928.4965,3056.717
62,-1.0334,-0.0196109,-954.6177,0.003143333,0,0,0.00196109,0.0196109,0.01961282,954.6177,3142.717
63,-1.05,-0.01975447,-980.367,0.00322812,0,0,0.001975447,0.01975447,0.01975642,980.3671,3227.482
64,-1.06668,-0.02002563,-1006.772,0.003315066,0,0,0.002002563,0.02002563,0.02002764,1006.772,3314.402
65,-1.08336,-0.01992993,-1033.85,0.003404226,0,0,0.001992993,0.01992993,0.01993192,1033.85,3403.548
66,-1.10004,-0.02005752,-1061.763,0.003496139,0,0,0.002005752,0.02005752,0.02005953,1061.763,3495.437
67,-1.11672,-0.02007347,-1089.14,0.003586284,0,0,0.002007347,0.02007347,0.02007548,1089.14,3585.564
68,-1.13336,-0.01985017,-1117.132,0.003678455,0,0,0.001985017,0.01985017,0.01985214,1117.132,3677.725
69,-1.14996,-0.02028085,-1145.316,0.003771257,0,0,0.002028085,0.02028085,0.02028291,1145.316,3770.492
70,-1.16668,-0.02005752,-1173.911,0.003865414,0,0,0.002005752,0.02005752,0.02005953,1173.911,3864.638
71,-1.18332,-0.02002563,-1201.968,0.003957801,0,0,0.002002563,0.02002563,0.02002764,1201.968,3957.008
72,-1.2,-0.02015322,-1229.838,0.004049569,0,0,0.002015322,0.02015322,0.02015526,1229.838,4048.753
73,-1.21668,-0.0198023,-1257.34,0.004140126,0,0,0.00198023,0.0198023,0.01980426,1257.34,4139.306
74,-1.23336,-0.01999374,-1285.367,0.004232413,0,0,0.001999374,0.01999374,0.01999574,1285.367,4231.567
75,-1.25008,-0.01977041,-1313.938,0.004326492,0,0,0.001977041,0.01977041,0.01977237,1313.938,4325.636
76,-1.26672,-0.01977041,-1341.791,0.004418205,0,0,0.001977041,0.01977041,0.01977237,1341.791,4417.332
77,-1.2834,-0.02015322,-1369.706,0.004510121,0,0,0.002015322,0.02015322,0.02015526,1369.706,4509.212
78,-1.30004,-0.02016921,-1398.339,0.004604403,0,0,0.002016921,0.02016921,0.02017124,1398.339,4603.474
79,-1.31672,-0.01992993,-1427.063,0.004698984,0,0,0.001992993,0.01992993,0.01993192,1427.063,4698.048
80,-1.33332,-0.01986612,-1455.434,0.004792403,0,0,0.001986612,0.01986612,0.01986809,1455.434,4791.451
81,-1.35,-0.01985017,-1485.107,0.004890109,0,0,0.001985017,0.01985017,0.01985214,1485.107,4889.139
82,-1.36668,-0.01999374,-1513.804,0.004984601,0,0,0.001999374,0.01999374,0.01999574,1513.804,4983.605
83,-1.3834,-0.02004158,-1542.858,0.00508027,0,0,0.002004158,0.02004158,0.02004359,1542.858,5079.252
84,-1.40004,-0.02010539,-1570.991,0.005172906,0,0,0.002010539,0.02010539,0.02010741,1570.991,5171.867
85,-1.41672,-0.02004158,-1600.979,0.005271649,0,0,0.002004158,0.02004158,0.02004359,1600.979,5270.592
86,-1.4334,-0.02004158,-1632.049,0.005373955,0,0,0.002004158,0.02004158,0.02004359,1632.049,5372.878
87,-1.45004,-0.02005752,-1663.27,0.005476761,0,0,0.002005752,0.02005752,0.02005953,1663.27,5475.662
88,-1.46668,-0.01988206,-1695.157,0.005581756,0,0,0.001988206,0.01988206,0.01988404,1695.157,5580.646
89,-1.4834,-0.02045631,-1729.121,0.00569359,0,0,0.002045631,0.02045631,0.02045841,1729.12,5692.425
90,-1.5,-0.02005752,-1760.906,0.005798252,0,0,0.002005752,0.02005752,0.02005953,1760.906,5797.089
91,-1.51672,-0.02018515,-1795.001,0.005910518,0,0,0.002018515,0.02018515,0.02018719,1795.001,5909.325
92,-1.53336,-0.01997776,-1828.077,0.006019431,0,0,0.001997776,0.01997776,0.01997976,1828.077,6018.228
93,-1.55004,-0.02036061,-1860.612,0.00612656,0,0,0.002036061,0.02036061,0.02036268,1860.612,6125.313
94,-1.56672,-0.02010539,-1894.416,0.006237868,0,0,0.002010539,0.02010539,0.02010741,1894.416,6236.614
95,-1.58336,-0.02010539,-1927.114,0.006345536,0,0,0.002010539,0.02010539,0.02010741,1927.114,6344.26
96,-1.59996,-0.02005752,-1961.136,0.006457563,0,0,0.002005752,0.02005752,0.02005953,1961.136,6456.267
97,-1.61668,-0.01985017,-1994.823,0.006568486,0,0,0.001985017,0.01985017,0.01985214,1994.823,6567.182
98,-1.63332,-0.02005752,-2028.448,0.006679206,0,0,0.002005752,0.02005752,0.02005953,2028.448,6677.866
99,-1.65004,-0.01978636,-2062.562,0.006791534,0,0,0.001978636,0.01978636,0.01978832,2062.562,6790.19
100,-1.66672,-0.01996182,-2095.879,0.006901241,0,0,0.001996182,0.01996182,0.01996381,2095.879,6899.863
101,-1.6834,-0.02007347,-2129.849,0.007013096,0,0,0.002007347,0.02007347,0.02007548,2129.849,7011.688
102,-1.7,-0.02005752,-2163.506,0.00712392,0,0,0.002005752,0.02005752,0.02005953,2163.506,7122.491
103,-1.71672,-0.02026491,-2197.86,0.00723704,0,0,0.002026491,0.02026491,0.02026696,2197.86,7235.574
104,-1.73332,-0.02013728,-2229.759,0.007342076,0,0,0.002013728,0.02013728,0.02013931,2229.759,7340.597
105,-1.75,-0.02007347,-2264.899,0.007457783,0,0,0.002007347,0.02007347,0.02007548,2264.899,7456.286
106,-1.76672,-0.01994587,-2298.736,0.007569201,0,0,0.001994587,0.01994587,0.01994786,2298.736,7567.691
107,-1.7834,-0.01985017,-2333.036,0.00768214,0,0,0.001985017,0.01985017,0.01985214,2333.035,7680.616
108,-1.80004,-0.02010539,-2367.494,0.007795606,0,0,0.002010539,0.02010539,0.02010741,2367.494,7794.039
109,-1.81664,-0.01969066,-2402.389,0.007910506,0,0,0.001969066,0.01969066,0.01969259,2402.389,7908.948
110,-1.83332,-0.01985017,-2437.42,0.008025854,0,0,0.001985017,0.01985017,0.01985214,2437.42,8024.26
111,-1.85004,-0.01988206,-2473.222,0.008143744,0,0,0.001988206,0.01988206,0.01988404,2473.222,8142.125
112,-1.86664,-0.02005752,-2509.839,0.008264313,0,0,0.002005752,0.02005752,0.02005953,2509.839,8262.655
113,-1.88336,-0.01978636,-2546.087,0.00838367,0,0,0.001978636,0.01978636,0.01978832,2546.087,8382.011
114,-1.9,-0.0198023,-2582.458,0.008503432,0,0,0.00198023,0.0198023,0.01980426,2582.458,8501.749
115,-1.91672,-0.01986612,-2619.885,0.00862667,0,0,0.001986612,0.01986612,0.01986809,2619.885,8624.956
116,-1.93336,-0.01972254,-2657.486,0.00875048,0,0,0.001972254,0.01972254,0.01972449,2657.486,8748.754
117,-1.95008,-0.01997776,-2694.719,0.008873079,0,0,0.001997776,0.01997776,0.01997976,2694.719,8871.306
118,-1.96668,-0.01973853,-2732.668,0.008998039,0,0,0.001973853,0.01973853,0.01974047,2732.668,8996.263
119,-1.9834,-0.02028085,-2771.449,0.009125734,0,0,0.002028085,0.02028085,0.02028291,2771.449,9123.883
120,-1.99996,-0.01973853,-2808.856,0.009248907,0,0,0.001973853,0.01973853,0.01974047,2808.856,9247.081
121,-2.01668,-0.02026491,-2848.249,0.009378619,0,0,0.002026491,0.02026491,0.02026696,2848.249,9376.719
122,-2.03332,-0.02016921,-2886.125,0.009503334,0,0,0.002016921,0.02016921,0.02017124,2886.125,9501.417
123,-2.05008,-0.01996182,-2923.641,0.009626866,0,0,0.001996182,0.01996182,0.01996381,2923.641,9624.945
124,-2.06672,-0.02005752,-2961.959,0.00975304,0,0,0.002005752,0.02005752,0.02005953,2961.959,9751.084
125,-2.0834,-0.02012134,-2999.022,0.00987508,0,0,0.002012134,0.02012134,0.02012336,2999.022,9873.092
126,-2.09996,-0.02024896,-3036.291,0.009997796,0,0,0.002024896,0.02024896,0.02025102,3036.291,9995.772
127,-2.11672,-0.02037656,-3075.052,0.01012543,0,0,0.002037656,0.02037656,0.02037863,3075.052,10123.36
128,-2.13336,-0.02023298,-3113.591,0.01025233,0,0,0.002023298,0.02023298,0.02023503,3113.591,10250.25
129,-2.15,-0.02016921,-3151.326,0.01037658,0,0,0.002016921,0.02016921,0.02017124,3151.326,10374.49
130,-2.16664,-0.02024896,-3189.799,0.01050326,0,0,0.002024896,0.02024896,0.02025102,3189.799,10501.14
131,-2.18336,-0.02013728,-3226.615,0.01062449,0,0,0.002013728,0.02013728,0.02013931,3226.615,10622.35
132,-2.20004,-0.02066366,-3264.948,0.01075071,0,0,0.002066366,0.02066366,0.0206658,3264.948,10748.49
133,-2.21672,-0.02036061,-3302.123,0.01087312,0,0,0.002036061,0.02036061,0.02036268,3302.123,10870.91
134,-2.23336,-0.02045631,-3339.93,0.01099761,0,0,0.002045631,0.02045631,0.02045841,3339.93,10995.36
135,-2.25004,-0.02016921,-3377.676,0.0111219,0,0,0.002016921,0.02016921,0.02017124,3377.676,11119.66
136,-2.26668,-0.01996182,-3415.136,0.01124525,0,0,0.001996182,0.01996182,0.01996381,3415.136,11243
137,-2.28336,-0.02012134,-3453.271,0.01137082,0,0,0.002012134,0.02012134,0.02012336,3453.271,11368.53
138,-2.3,-0.0203925,-3492.325,0.01149941,0,0,0.00203925,0.0203925,0.02039458,3492.325,11497.06
139,-2.31672,-0.01992993,-3531.655,0.01162891,0,0,0.001992993,0.01992993,0.01993192,3531.655,11626.6
140,-2.3334,-0.02004158,-3570.615,0.0117572,0,0,0.002004158,0.02004158,0.02004359,3570.615,11754.84
141,-2.35008,-0.02008945,-3609.651,0.01188574,0,0,0.002008945,0.02008945,0.02009147,3609.651,11883.35
142,-2.36668,-0.02021704,-3647.647,0.01201085,0,0,0.002021704,0.02021704,0.02021908,3647.647,12008.42
143,-2.3834,-0.01999374,-3686.672,0.01213935,0,0,0.001999374,0.01999374,0.01999574,3686.672,12136.92
144,-2.40008,-0.02050415,-3725.494,0.01226718,0,0,0.002050415,0.02050415,0.02050625,3725.494,12264.67
145,-2.41668,-0.02021704,-3762.402,0.01238871,0,0,0.002021704,0.02021704,0.02021908,3762.402,12386.21
146,-2.43336,-0.0203925,-3802.415,0.01252047,0,0,0.00203925,0.0203925,0.02039458,3802.415,12517.91
147,-2.449999,-0.02024896,-3840.305,0.01264523,0,0,0.002024896,0.02024896,0.02025102,3840.304,12642.67
148,-2.466679,-0.02028085,-3879.696,0.01277493,0,0,0.002028085,0.02028085,0.02028291,3879.696,12772.34
149,-2.483359,-0.02015322,-3919.543,0.01290614,0,0,0.002015322,0.02015322,0.02015526,3919.543,12903.54
150,-2.5,-0.02050415,-3958.066,0.01303299,0,0,0.002050415,0.02050415,0.02050625,3958.066,13030.31
151,-2.51668,-0.02015322,-3997.657,0.01316335,0,0,0.002015322,0.02015322,0.02015526,3997.657,13160.7
152,-2.5334,-0.01994587,-4036.6,0.01329158,0,0,0.001994587,0.01994587,0.01994786,4036.6,13288.93
153,-2.55,-0.02004158,-4073.885,0.01341435,0,0,0.002004158,0.02004158,0.02004359,4073.885,13411.66
154,-2.56668,-0.02034467,-4113.765,0.01354567,0,0,0.002034467,0.02034467,0.02034674,4113.766,13542.91
155,-2.58336,-0.01983423,-4152.014,0.01367161,0,0,0.001983423,0.01983423,0.01983619,4152.014,13668.9
156,-2.60004,-0.02002563,-4191.719,0.01380235,0,0,0.002002563,0.02002563,0.02002764,4191.719,13799.59
157,-2.61672,-0.02028085,-4231.69,0.01393397,0,0,0.002028085,0.02028085,0.02028291,4231.69,13931.14
158,-2.63336,-0.01994587,-4270.714,0.01406247,0,0,0.001994587,0.01994587,0.01994786,4270.714,14059.66
159,-2.65004,-0.02008945,-4311.842,0.01419789,0,0,0.002008945,0.02008945,0.02009147,4311.842,14195.04
160,-2.66672,-0.02015322,-4351.608,0.01432883,0,0,0.002015322,0.02015322,0.02015526,4351.608,14325.94
161,-2.68332,-0.02015322,-4391.226,0.01445928,0,0,0.002015322,0.02015322,0.02015526,4391.226,14456.37
162,-2.7,-0.02018515,-4431.78,0.01459282,0,0,0.002018515,0.02018515,0.02018719,4431.78,14589.87
163,-2.716719,-0.01991399,-4470.024,0.01471874,0,0,0.001991399,0.01991399,0.01991597,4470.024,14715.81
164,-2.73336,-0.02024896,-4510.032,0.01485048,0,0,0.002024896,0.02024896,0.02025102,4510.032,14847.47
165,-2.749999,-0.02007347,-4548.722,0.01497788,0,0,0.002007347,0.02007347,0.02007548,4548.722,14974.87
166,-2.76672,-0.02034467,-4587.831,0.01510666,0,0,0.002034467,0.02034467,0.02034674,4587.831,15103.58
167,-2.78332,-0.02040844,-4629.336,0.01524332,0,0,0.002040844,0.02040844,0.02041053,4629.336,15240.21
168,-2.799999,-0.01994587,-4670.098,0.01537754,0,0,0.001994587,0.01994587,0.01994786,4670.098,15374.47
169,-2.81664,-0.01999374,-4711.574,0.01551411,0,0,0.001999374,0.01999374,0.01999574,4711.574,15511.01
170,-2.83332,-0.0203925,-4753.651,0.01565266,0,0,0.00203925,0.0203925,0.02039458,4753.651,15649.47
171,-2.850039,-0.02036061,-4796.382,0.01579337,0,0,0.002036061,0.02036061,0.02036268,4796.382,15790.15
172,-2.866719,-0.02032869,-4837.664,0.0159293,0,0,0.002032869,0.02032869,0.02033075,4837.664,15926.06
173,-2.883399,-0.01973853,-4879.674,0.01606762,0,0,0.001973853,0.01973853,0.01974047,4879.673,16064.45
174,-2.900079,-0.02023298,-4920.255,0.01620125,0,0,0.002023298,0.02023298,0.02023503,4920.255,16197.97
175,-2.91668,-0.02026491,-4961.286,0.01633636,0,0,0.002026491,0.02026491,0.02026696,4961.286,16333.04
176,-2.933319,-0.01991399,-5003.941,0.01647681,0,0,0.001991399,0.01991399,0.01991597,5003.941,16473.53
177,-2.94996,-0.02004158,-5046.53,0.01661705,0,0,0.002004158,0.02004158,0.02004359,5046.53,16613.72
178,-2.966679,-0.02015322,-5090.288,0.01676113,0,0,0.002015322,0.02015322,0.02015526,5090.289,16757.75
179,-2.983359,-0.02008945,-5133.187,0.01690239,0,0,0.002008945,0.02008945,0.02009147,5133.188,16898.99
180,-3.000039,-0.01937162,-5176.454,0.01704485,0,0,0.001937162,0.01937162,0.0193735,5176.454,17041.55
181,-3.01668,-0.02002563,-5219.83,0.01718768,0,0,0.002002563,0.02002563,0.02002764,5219.83,17184.24
182,-3.033399,-0.02005752,-5262.291,0.0173275,0,0,0.002005752,0.02005752,0.02005953,5262.292,17324.02
183,-3.05,-0.02012134,-5304.666,0.01746703,0,0,0.002012134,0.02012134,0.02012336,5304.666,17463.51
184,-3.06672,-0.02037656,-5348.565,0.01761157,0,0,0.002037656,0.02037656,0.02037863,5348.564,17607.98
185,-3.08336,-0.02020109,-5391.454,0.0177528,0,0,0.002020109,0.02020109,0.02020314,5391.454,17749.21
186,-3.099999,-0.02024896,-5434.651,0.01789504,0,0,0.002024896,0.02024896,0.02025102,5434.651,17891.41
187,-3.11664,-0.02008945,-5477.9,0.01803745,0,0,0.002008945,0.02008945,0.02009147,5477.9,18033.82
188,-3.1334,-0.02018515,-5522.403,0.01818399,0,0,0.002018515,0.02018515,0.02018719,5522.403,18180.31
189,-3.150039,-0.02040844,-5566.7,0.01832984,0,0,0.002040844,0.02040844,0.02041053,5566.7,18326.1
190,-3.166719,-0.02004158,-5610.514,0.01847411,0,0,0.002004158,0.02004158,0.02004359,5610.514,18470.41
191,-3.18332,-0.02024896,-5653.852,0.01861681,0,0,0.002024896,0.02024896,0.02025102,5653.852,18613.05
192,-3.2,-0.02004158,-5698.241,0.01876298,0,0,0.002004158,0.02004158,0.02004359,5698.241,18759.22
193,-3.21668,-0.02037656,-5740.257,0.01890133,0,0,0.002037656,0.02037656,0.02037863,5740.257,18897.48
194,-3.23336,-0.01997776,-5784.963,0.01904853,0,0,0.001997776,0.01997776,0.01997976,5784.963,19044.73
195,-3.249999,-0.02002563,-5829.241,0.01919433,0,0,0.002002563,0.02002563,0.02002764,5829.241,19190.48
196,-3.26672,-0.02040844,-5873.238,0.0193392,0,0,0.002040844,0.02040844,0.02041053,5873.238,19335.25
197,-3.283359,-0.02000969,-5917.862,0.01948614,0,0,0.002000969,0.02000969,0.02001169,5917.862,19482.24
198,-3.3,-0.02028085,-5962.803,0.01963412,0,0,0.002028085,0.02028085,0.02028291,5962.803,19630.14
199,-3.31664,-0.02024896,-6006.172,0.01977692,0,0,0.002024896,0.02024896,0.02025102,6006.172,19772.92
200,-3.33332,-0.02031274,-6051.678,0.01992676,0,0,0.002031274,0.02031274,0.02031481,6051.678,19922.72
201,-3.350039,-0.02021704,-6095.446,0.02007088,0,0,0.002021704,0.02021704,0.02021908,6095.446,20066.82
202,-3.36668,-0.02031274,-6140.795,0.0202202,0,0,0.002031274,0.02031274,0.02031481,6140.795,20216.1
203,-3.383319,-0.02010539,-6185.486,0.02036736,0,0,0.002010539,0.02010539,0.02010741,6185.486,20363.27
204,-3.400079,-0.02040844,-6230.206,0.02051461,0,0,0.002040844,0.02040844,0.02041053,6230.207,20510.43
205,-3.416679,-0.02012134,-6274.637,0.02066091,0,0,0.002012134,0.02012134,0.02012336,6274.637,20656.76
206,-3.4334,-0.02044037,-6319.847,0.02080978,0,0,0.002044037,0.02044037,0.02044246,6319.847,20805.53
207,-3.450039,-0.019898,-6363.965,0.02095505,0,0,0.0019898,0.019898,0.01989998,6363.965,20950.88
208,-3.466719,-0.02005752,-6409.463,0.02110486,0,0,0.002005752,0.02005752,0.02005953,6409.462,21100.63
209,-3.483359,-0.02008945,-6455.757,0.0212573,0,0,0.002008945,0.02008945,0.02009147,6455.757,21253.03
210,-3.5,-0.02018515,-6500.414,0.02140434,0,0,0.002018515,0.02018515,0.02018719,6500.414,21400.02
211,-3.51668,-0.0204882,-6546.097,0.02155477,0,0,0.00204882,0.0204882,0.0204903,6546.097,21550.35
212,-3.533399,-0.0202968,-6591.877,0.02170551,0,0,0.00202968,0.0202968,0.02029886,6591.877,21701.11
213,-3.55004,-0.02037656,-6635.333,0.0218486,0,0,0.002037656,0.02037656,0.02037863,6635.333,21844.15
214,-3.56672,-0.0202968,-6680.86,0.02199851,0,0,0.00202968,0.0202968,0.02029886,6680.86,21994.05
215,-3.583359,-0.02000969,-6724.95,0.02214369,0,0,0.002000969,0.02000969,0.02001169,6724.95,22139.26
216,-3.599999,-0.01997776,-6770.862,0.02229487,0,0,0.001997776,0.01997776,0.01997976,6770.862,22290.41
217,-3.616679,-0.02004158,-6817.877,0.02244968,0,0,0.002004158,0.02004158,0.02004359,6817.876,22445.18
218,-3.63332,-0.02066366,-6862.671,0.02259717,0,0,0.002066366,0.02066366,0.0206658,6862.671,22592.5
219,-3.649959,-0.0203925,-6910.238,0.0227538,0,0,0.00203925,0.0203925,0.02039458,6910.238,22749.16
220,-3.666719,-0.02045631,-6957.453,0.02290927,0,0,0.002045631,0.02045631,0.02045841,6957.453,22904.58
221,-3.683399,-0.02023298,-7002.185,0.02305656,0,0,0.002023298,0.02023298,0.02023503,7002.185,23051.9
222,-3.700079,-0.02050415,-7048.523,0.02320914,0,0,0.002050415,0.02050415,0.02050625,7048.523,23204.38
223,-3.71672,-0.02007347,-7092.428,0.02335371,0,0,0.002007347,0.02007347,0.02007548,7092.428,23349.02
224,-3.73336,-0.02044037,-7138.091,0.02350407,0,0,0.002044037,0.02044037,0.02044246,7138.091,23499.26
225,-3.74996,-0.02000969,-7183.007,0.02365196,0,0,0.002000969,0.02000969,0.02001169,7183.007,23647.23
226,-3.766679,-0.02020109,-7229.351,0.02380456,0,0,0.002020109,0.02020109,0.02020314,7229.351,23799.75
227,-3.783279,-0.02058391,-7274.554,0.02395341,0,0,0.002058391,0.02058391,0.02058602,7274.554,23948.48
228,-3.80008,-0.02028085,-7321.821,0.02410905,0,0,0.002028085,0.02028085,0.02028291,7321.821,24104.16
229,-3.81668,-0.02053607,-7366.163,0.02425506,0,0,0.002053607,0.02053607,0.02053818,7366.163,24250.07
230,-3.833399,-0.02031274,-7413.738,0.02441171,0,0,0.002031274,0.02031274,0.02031481,7413.738,24406.75
231,-3.849999,-0.02059989,-7458.92,0.02456048,0,0,0.002059989,0.02059989,0.02060201,7458.92,24555.42
232,-3.86668,-0.02042443,-7504.243,0.02470972,0,0,0.002042443,0.02042443,0.02042651,7504.243,24704.67
233,-3.88336,-0.02067965,-7550.132,0.02486082,0,0,0.002067965,0.02067965,0.02068178,7550.131,24855.68
234,-3.899999,-0.0204882,-7593.821,0.02500468,0,0,0.00204882,0.0204882,0.0204903,7593.821,24999.56
235,-3.91664,-0.02036061,-7639.431,0.02515486,0,0,0.002036061,0.02036061,0.02036268,7639.431,25149.74
236,-3.9334,-0.02026491,-7687.134,0.02531194,0,0,0.002026491,0.02026491,0.02026696,7687.134,25306.81
237,-3.950039,-0.02052013,-7732.952,0.0254628,0,0,0.002052013,0.02052013,0.02052223,7732.952,25457.58
238,-3.966719,-0.02040844,-7779.712,0.02561678,0,0,0.002040844,0.02040844,0.02041053,7779.712,25611.55
239,-3.983359,-0.02031274,-7825.84,0.02576866,0,0,0.002031274,0.02031274,0.02031481,7825.839,25763.43
240,-4.000039,-0.02036061,-7871.041,0.0259175,0,0,0.002036061,0.02036061,0.02036268,7871.041,25912.22
241,-4.016679,-0.02024896,-7917.123,0.02606924,0,0,0.002024896,0.02024896,0.02025102,7917.123,26063.96
242,-4.033359,-0.02016921,-7962.489,0.02621862,0,0,0.002016921,0.02016921,0.02017124,7962.489,26213.33
243,-4.049959,-0.02055202,-8006.976,0.0263651,0,0,0.002055202,0.02055202,0.02055413,8006.976,26359.68
244,-4.066719,-0.02056796,-8053.987,0.0265199,0,0,0.002056796,0.02056796,0.02057008,8053.987,26514.45
245,-4.083359,-0.02028085,-8098.048,0.02666498,0,0,0.002028085,0.02028085,0.02028291,8098.048,26659.57
246,-4.100039,-0.02002563,-8143.536,0.02681476,0,0,0.002002563,0.02002563,0.02002764,8143.536,26809.39
247,-4.116679,-0.02058391,-8189.051,0.02696463,0,0,0.002058391,0.02058391,0.02058602,8189.051,26959.08
248,-4.133359,-0.02037656,-8235.364,0.02711713,0,0,0.002037656,0.02037656,0.02037863,8235.363,27111.6
249,-4.15,-0.02058391,-8280.561,0.02726596,0,0,0.002058391,0.02058391,0.02058602,8280.562,27260.34
250,-4.16668,-0.02058391,-8325.35,0.02741343,0,0,0.002058391,0.02058391,0.02058602,8325.35,27407.79
251,-4.18336,-0.02055202,-8369.72,0.02755953,0,0,0.002055202,0.02055202,0.02055413,8369.72,27553.87
252,-4.20004,-0.0204882,-8416.075,0.02771217,0,0,0.00204882,0.0204882,0.0204903,8416.074,27706.49
253,-4.21672,-0.02063178,-8459.941,0.02785661,0,0,0.002063178,0.02063178,0.0206339,8459.94,27850.86
254,-4.233359,-0.02072748,-8504.198,0.02800234,0,0,0.002072748,0.02072748,0.02072963,8504.198,27996.54
255,-4.250039,-0.02052013,-8548.409,0.02814792,0,0,0.002052013,0.02052013,0.02052223,8548.409,28142.14
256,-4.266679,-0.02045631,-8592.623,0.0282935,0,0,0.002045631,0.02045631,0.02045841,8592.623,28287.71
257,-4.283319,-0.02059989,-8637.388,0.0284409,0,0,0.002059989,0.02059989,0.02060201,8637.388,28435.04
258,-4.299999,-0.02052013,-8682.366,0.028589,0,0,0.002052013,0.02052013,0.02052223,8682.365,28583.13
259,-4.316679,-0.02080724,-8727.087,0.02873626,0,0,0.002080724,0.02080724,0.0208094,8727.087,28730.28
260,-4.333359,-0.02083912,-8773.72,0.02888981,0,0,0.002083912,0.02083912,0.0208413,8773.72,28883.79
261,-4.350079,-0.02079129,-8817.39,0.02903361,0,0,0.002079129,0.02079129,0.02079345,8817.39,29027.57
262,-4.366719,-0.02047226,-8863.016,0.02918384,0,0,0.002047226,0.02047226,0.02047435,8863.017,29177.87
263,-4.383359,-0.02064772,-8906.943,0.02932848,0,0,0.002064772,0.02064772,0.02064985,8906.942,29322.43
264,-4.400039,-0.02045631,-8950.761,0.02947276,0,0,0.002045631,0.02045631,0.02045841,8950.761,29466.74
265,-4.41664,-0.02075937,-8993.851,0.02961465,0,0,0.002075937,0.02075937,0.02076152,8993.852,29608.5
266,-4.43332,-0.02083912,-9038.93,0.02976308,0,0,0.002083912,0.02083912,0.0208413,9038.93,29756.88
267,-4.450039,-0.02045631,-9082.967,0.02990809,0,0,0.002045631,0.02045631,0.02045841,9082.967,29901.97
268,-4.46668,-0.02067965,-9128.518,0.03005808,0,0,0.002067965,0.02067965,0.02068178,9128.519,30051.86
269,-4.483399,-0.02036061,-9173.908,0.03020754,0,0,0.002036061,0.02036061,0.02036268,9173.908,30201.39
270,-4.50004,-0.02036061,-9218.656,0.03035488,0,0,0.002036061,0.02036061,0.02036268,9218.655,30348.7
271,-4.516719,-0.02059989,-9263.718,0.03050326,0,0,0.002059989,0.02059989,0.02060201,9263.718,30496.98
272,-4.533359,-0.02047226,-9307.949,0.0306489,0,0,0.002047226,0.02047226,0.02047435,9307.949,30642.63
273,-4.549999,-0.02059989,-9352.217,0.03079467,0,0,0.002059989,0.02059989,0.02060201,9352.217,30788.32
274,-4.566679,-0.02044037,-9397.08,0.03094239,0,0,0.002044037,0.02044037,0.02044246,9397.08,30936.06
275,-4.583359,-0.02047226,-9440.391,0.031085,0,0,0.002047226,0.02047226,0.02047435,9440.391,31078.64
276,-4.599959,-0.02061583,-9484.736,0.03123102,0,0,0.002061583,0.02061583,0.02061796,9484.736,31224.58
277,-4.616719,-0.02067965,-9529.936,0.03137986,0,0,0.002067965,0.02067965,0.02068178,9529.937,31373.37
278,-4.633359,-0.02077535,-9574.81,0.03152761,0,0,0.002077535,0.02077535,0.02077751,9574.81,31521.06
279,-4.650079,-0.02026491,-9619.194,0.03167376,0,0,0.002026491,0.02026491,0.02026696,9619.194,31667.34
280,-4.666719,-0.02044037,-9661.746,0.03181387,0,0,0.002044037,0.02044037,0.02044246,9661.746,31807.37
281,-4.683319,-0.0204882,-9705.368,0.03195751,0,0,0.00204882,0.0204882,0.0204903,9705.368,31950.96
282,-4.699999,-0.02045631,-9749.319,0.03210223,0,0,0.002045631,0.02045631,0.02045841,9749.319,32095.66
283,-4.716679,-0.02071153,-9793.286,0.032247,0,0,0.002071153,0.02071153,0.02071368,9793.286,32240.32
284,-4.733359,-0.02050415,-9838.079,0.03239449,0,0,0.002050415,0.02050415,0.02050625,9838.079,32387.85
285,-4.75008,-0.02056796,-9883.025,0.03254249,0,0,0.002056796,0.02056796,0.02057008,9883.025,32535.8
286,-4.766719,-0.02053607,-9925.675,0.03268293,0,0,0.002053607,0.02053607,0.02053818,9925.675,32676.22
287,-4.783399,-0.02044037,-9970.119,0.03282927,0,0,0.002044037,0.02044037,0.02044246,9970.119,32822.56
288,-4.800039,-0.02002563,-10015.24,0.03297785,0,0,0.002002563,0.02002563,0.02002764,10015.24,32971.24
289,-4.816679,-0.02061583,-10058.88,0.03312155,0,0,0.002061583,0.02061583,0.02061796,10058.88,33114.72
290,-4.833319,-0.02045631,-10102.94,0.03326662,0,0,0.002045631,0.02045631,0.02045841,10102.94,33259.81
291,-4.850039,-0.02075937,-10148.06,0.03341518,0,0,0.002075937,0.02075937,0.02076152,10148.06,33408.25
292,-4.866679,-0.02036061,-10191.6,0.03355856,0,0,0.002036061,0.02036061,0.02036268,10191.6,33551.73
293,-4.883399,-0.02032869,-10234.71,0.03370052,0,0,0.002032869,0.02032869,0.02033075,10234.71,33693.67
294,-4.899999,-0.02040844,-10276.18,0.03383704,0,0,0.002040844,0.02040844,0.02041053,10276.17,33830.14
295,-4.916719,-0.02058391,-10318.31,0.03397579,0,0,0.002058391,0.02058391,0.02058602,10318.31,33968.79
296,-4.933319,-0.02075937,-10362.09,0.03411993,0,0,0.002075937,0.02075937,0.02076152,10362.09,34112.85
297,-4.949959,-0.02047226,-10405.01,0.03426128,0,0,0.002047226,0.02047226,0.02047435,10405.01,34254.27
298,-4.966639,-0.02032869,-10449.99,0.03440937,0,0,0.002032869,0.02032869,0.02033075,10449.99,34402.37
299,-4.983399,-0.02056796,-10494.6,0.03455626,0,0,0.002056796,0.02056796,0.02057008,10494.6,34549.15
300,-4.999999,-0.02036061,-10537.04,0.03469602,0,0,0.002036061,0.02036061,0.02036268,10537.04,34688.95
301,-5.016759,-0.02058391,-10580.08,0.03483773,0,0,0.002058391,0.02058391,0.02058602,10580.08,34830.55
302,-5.033399,-0.02044037,-10620.77,0.03497172,0,0,0.002044037,0.02044037,0.02044246,10620.77,34964.57
303,-5.050039,-0.02045631,-10659.92,0.03510063,0,0,0.002045631,0.02045631,0.02045841,10659.92,35093.45
304,-5.066679,-0.02045631,-10699.49,0.03523094,0,0,0.002045631,0.02045631,0.02045841,10699.5,35223.73
305,-5.083359,-0.02040844,-10737.64,0.03535654,0,0,0.002040844,0.02040844,0.02041053,10737.64,35349.33
306,-5.099959,-0.02069559,-10775.98,0.03548279,0,0,0.002069559,0.02069559,0.02069773,10775.98,35475.45
307,-5.116719,-0.02061583,-10813.97,0.03560787,0,0,0.002061583,0.02061583,0.02061796,10813.97,35600.53
308,-5.133319,-0.02085511,-10850.36,0.03572771,0,0,0.002085511,0.02085511,0.02085728,10850.36,35720.26
309,-5.150039,-0.02008945,-10887.75,0.03585081,0,0,0.002008945,0.02008945,0.02009147,10887.75,35843.61
310,-5.166719,-0.02091888,-10923.14,0.03596734,0,0,0.002091888,0.02091888,0.02092107,10923.14,35959.81
311,-5.183399,-0.02069559,-10959.79,0.03608803,0,0,0.002069559,0.02069559,0.02069773,10959.79,36080.56
312,-5.200039,-0.02093486,-10997.15,0.03621104,0,0,0.002093486,0.02093486,0.02093706,10997.15,36203.45
313,-5.216719,-0.02066366,-11032.88,0.03632869,0,0,0.002066366,0.02066366,0.0206658,11032.88,36321.19
314,-5.233319,-0.02040844,-11070.69,0.0364532,0,0,0.002040844,0.02040844,0.02041053,11070.69,36445.76
315,-5.250039,-0.02079129,-11109.64,0.03658145,0,0,0.002079129,0.02079129,0.02079345,11109.64,36573.85
316,-5.266639,-0.02069559,-11147.59,0.03670641,0,0,0.002069559,0.02069559,0.02069773,11147.59,36698.81
317,-5.283399,-0.02080724,-11190.52,0.03684778,0,0,0.002080724,0.02080724,0.0208094,11190.52,36840.11
318,-5.300039,-0.02063178,-11239.12,0.03700779,0,0,0.002063178,0.02063178,0.0206339,11239.12,37000.16
319,-5.316719,-0.02083912,-11290.6,0.03717732,0,0,0.002083912,0.02083912,0.0208413,11290.6,37169.57
320,-5.333359,-0.02069559,-11344.68,0.03735537,0,0,0.002069559,0.02069559,0.02069773,11344.68,37347.64
321,-5.350039,-0.02045631,-11397.99,0.03753091,0,0,0.002045631,0.02045631,0.02045841,11397.99,37523.24
322,-5.366639,-0.0202968,-11450.39,0.03770346,0,0,0.00202968,0.0202968,0.02029886,11450.39,37695.81
323,-5.383359,-0.02093486,-11504.78,0.03788254,0,0,0.002093486,0.02093486,0.02093706,11504.78,37874.61
324,-5.399999,-0.02063178,-11557.88,0.03805739,0,0,0.002063178,0.02063178,0.0206339,11557.88,38049.54
325,-5.416719,-0.02064772,-11611.62,0.03823435,0,0,0.002064772,0.02064772,0.02064985,11611.62,38226.45
326,-5.433359,-0.02058391,-11667.59,0.03841865,0,0,0.002058391,0.02058391,0.02058602,11667.59,38410.75
327,-5.450079,-0.02067965,-11722.05,0.03859796,0,0,0.002067965,0.02067965,0.02068178,11722.04,38589.97
328,-5.466679,-0.02052013,-11777.92,0.03878194,0,0,0.002052013,0.02052013,0.02052223,11777.92,38773.99
329,-5.483399,-0.02042443,-11833.51,0.03896498,0,0,0.002042443,0.02042443,0.02042651,11833.51,38957.02
330,-5.499999,-0.02090294,-11888.4,0.03914573,0,0,0.002090294,0.02090294,0.02090512,11888.4,39137.55
331,-5.516679,-0.02069559,-11947.28,0.0393396,0,0,0.002069559,0.02069559,0.02069773,11947.28,39331.46
332,-5.533319,-0.02024896,-12004.21,0.03952705,0,0,0.002024896,0.02024896,0.02025102,12004.21,39519.05
333,-5.550039,-0.02055202,-12063.55,0.03972246,0,0,0.002055202,0.02055202,0.02055413,12063.55,39714.3
334,-5.566719,-0.02037656,-12121.53,0.03991336,0,0,0.002037656,0.02037656,0.02037863,12121.53,39905.23
335,-5.583399,-0.02061583,-12178.27,0.0401002,0,0,0.002061583,0.02061583,0.02061796,12178.27,40091.93
336,-5.599999,-0.02079129,-12236.62,0.04029233,0,0,0.002079129,0.02079129,0.02079345,12236.62,40283.96
337,-5.616679,-0.02042443,-12297.06,0.04049133,0,0,0.002042443,0.02042443,0.02042651,12297.05,40483.06
338,-5.633319,-0.02056796,-12356.63,0.04068749,0,0,0.002056796,0.02056796,0.02057008,12356.63,40679.12
339,-5.649999,-0.02080724,-12418.36,0.04089076,0,0,0.002080724,0.02080724,0.0208094,12418.36,40882.25
340,-5.666639,-0.02099864,-12477.86,0.04108668,0,0,0.002099864,0.02099864,0.02100085,12477.86,41078.05
341,-5.683399,-0.02064772,-12539.6,0.04128996,0,0,0.002064772,0.02064772,0.02064985,12539.6,41281.44
342,-5.700039,-0.02059989,-12602.83,0.04149818,0,0,0.002059989,0.02059989,0.02060201,12602.83,41489.64
343,-5.716719,-0.02079129,-12668.26,0.04171362,0,0,0.002079129,0.02079129,0.02079345,12668.26,41704.95
344,-5.733319,-0.02069559,-12739.94,0.04194964,0,0,0.002069559,0.02069559,0.02069773,12739.94,41940.96
345,-5.750039,-0.02090294,-12814.23,0.04219427,0,0,0.002090294,0.02090294,0.02090512,12814.23,42185.45
346,-5.766719,-0.02079129,-12891.16,0.04244759,0,0,0.002079129,0.02079129,0.02079345,12891.16,42438.77
347,-5.783359,-0.02066366,-12971.09,0.04271076,0,0,0.002066366,0.02066366,0.0206658,12971.09,42701.93
348,-5.799999,-0.02028085,-13055.15,0.04298754,0,0,0.002028085,0.02028085,0.02028291,13055.15,42978.83
349,-5.816719,-0.02099864,-13137.89,0.04326002,0,0,0.002099864,0.02099864,0.02100085,13137.89,43250.93
350,-5.833399,-0.02104651,-13221.35,0.0435348,0,0,0.002104651,0.02104651,0.02104873,13221.35,43525.64
351,-5.850079,-0.02058391,-13305.36,0.04381146,0,0,0.002058391,0.02058391,0.02058602,13305.36,43802.44
352,-5.866679,-0.02066366,-13388.45,0.04408504,0,0,0.002066366,0.02066366,0.0206658,13388.45,44075.93
353,-5.883399,-0.02056796,-13473.95,0.04436659,0,0,0.002056796,0.02056796,0.02057008,13473.96,44357.46
354,-5.899999,-0.02071153,-13558.02,0.0446434,0,0,0.002071153,0.02071153,0.02071368,13558.02,44634.16
355,-5.916639,-0.02071153,-13644.28,0.04492742,0,0,0.002071153,0.02071153,0.02071368,13644.28,44918.12
356,-5.933359,-0.02063178,-13735.52,0.04522786,0,0,0.002063178,0.02063178,0.0206339,13735.52,45218.53
357,-5.950039,-0.02064772,-13826.25,0.04552662,0,0,0.002064772,0.02064772,0.02064985,13826.25,45517.22
358,-5.966719,-0.02087105,-13920.03,0.04583541,0,0,0.002087105,0.02087105,0.02087323,13920.03,45825.84
359,-5.983399,-0.02044037,-14014.67,0.04614702,0,0,0.002044037,0.02044037,0.02044246,14014.67,46137.59
360,-5.999999,-0.02080724,-14107.13,0.0464515,0,0,0.002080724,0.02080724,0.0208094,14107.13,46441.84
361,-6.016719,-0.02045631,-14202.57,0.04676573,0,0,0.002045631,0.02045631,0.02045841,14202.57,46756.17
362,-6.033359,-0.02055202,-14296.85,0.04707618,0,0,0.002055202,0.02055202,0.02055413,14296.85,47066.5
363,-6.049999,-0.0204882,-14392.17,0.04739006,0,0,0.00204882,0.0204882,0.0204903,14392.17,47380.35
364,-6.066679,-0.02075937,-14490.29,0.04771316,0,0,0.002075937,0.02075937,0.02076152,14490.29,47703.25
365,-6.083399,-0.02083912,-14590.12,0.04804185,0,0,0.002083912,0.02083912,0.0208413,14590.12,48031.84
[...]
1305.78,-4.677839,-0.02347108,-7311.321,0.02407447,2,2,0.002347108,0.02347108,0.02347383,7311.321,24068.82
1310.78,-4.761279,-0.02315205,-7570.472,0.0249278,2,2,0.002315205,0.02315205,0.02315473,7570.472,24922.03
1315.78,-4.844599,-0.02337538,-7831.325,0.02578672,2,2,0.002337538,0.02337538,0.02337811,7831.325,25780.7
1320.78,-4.927879,-0.02350301,-8084.966,0.02662191,2,2,0.002350301,0.02350301,0.02350577,8084.966,26615.65
1325.78,-5.011239,-0.02358273,-8343.772,0.02747409,2,2,0.002358273,0.02358273,0.02358551,8343.771,27467.61
1330.78,-5.094599,-0.02302445,-8596.075,0.02830487,2,2,0.002302445,0.02302445,0.02302711,8596.075,28298.35
1335.78,-5.177919,-0.02340727,-8847.354,0.02913227,2,2,0.002340727,0.02340727,0.02341001,8847.354,29125.45
1340.78,-5.261279,-0.02343919,-9089.123,0.02992836,2,2,0.002343919,0.02343919,0.02344194,9089.123,29921.34
1345.78,-5.344559,-0.02326373,-9333.868,0.03073424,2,2,0.002326373,0.02326373,0.02326644,9333.867,30727.09
1350.78,-5.427919,-0.02340727,-9585.393,0.03156246,2,2,0.002340727,0.02340727,0.02341001,9585.394,31555.07
1355.78,-5.511279,-0.02383795,-9899.948,0.03259822,2,2,0.002383795,0.02383795,0.02384079,9899.948,32590.45
1360.78,-5.594519,-0.02369441,-10218.76,0.03364799,2,2,0.002369441,0.02369441,0.02369722,10218.76,33640.02
1365.78,-5.677959,-0.02350301,-10561.56,0.03477674,2,2,0.002350301,0.02350301,0.02350577,10561.56,34768.57
1370.78,-5.761239,-0.02361465,-10910.71,0.03592641,2,2,0.002361465,0.02361465,0.02361744,10910.71,35917.93
1375.78,-5.844559,-0.02334349,-11337.61,0.03733211,2,2,0.002334349,0.02334349,0.02334621,11337.61,37323.4
1380.78,-5.927919,-0.0236306,-11803.9,0.0388675,2,2,0.00236306,0.0236306,0.02363339,11803.9,38858.31
1385.78,-6.011239,-0.02350301,-12314.48,0.04054871,2,2,0.002350301,0.02350301,0.02350577,12314.48,40539.18
1390.78,-6.094559,-0.02342325,-12849.01,0.0423088,2,2,0.002342325,0.02342325,0.02342599,12849.01,42298.9
1395.78,-6.177919,-0.02315205,-13425.43,0.04420679,2,2,0.002315205,0.02315205,0.02315473,13425.43,44196.56
1400.78,-6.261199,-0.02353489,-14073.65,0.04634123,2,2,0.002353489,0.02353489,0.02353766,14073.65,46330.32
1405.78,-6.344599,-0.02390176,-14770.63,0.04863623,2,2,0.002390176,0.02390176,0.02390462,14770.63,48624.61
1410.78,-6.427879,-0.02351895,-15508.21,0.0510649,2,2,0.002351895,0.02351895,0.02352172,15508.21,51052.9
1415.78,-6.511239,-0.02358273,-16363.23,0.05388028,2,2,0.002358273,0.02358273,0.02358551,16363.23,53867.57
1420.78,-6.594599,-0.02412509,-17308.36,0.0569924,2,2,0.002412509,0.02412509,0.024128,17308.37,56978.65
1425.78,-6.677919,-0.02369441,-18365.26,0.06047252,2,2,0.002369441,0.02369441,0.02369722,18365.26,60458.19
1430.78,-6.761279,-0.02380606,-19550.57,0.06437545,2,2,0.002380606,0.02380606,0.02380889,19550.57,64360.12
1434.164,-6.764999,-0.0237263,-19559.76,0.06440571,2,2,0.00237263,0.0237263,0.02372911,19559.76,64390.43
1437.26,-6.713199,-0.0236306,-18307.34,0.06028181,2,2,0.00236306,0.0236306,0.02363339,18307.34,60267.56
1440.912,-6.652319,-0.02364654,-17055.76,0.05616064,2,2,0.002364654,0.02364654,0.02364934,17055.76,56147.36
1445.198,-6.580839,-0.0236306,-15804.2,0.05203953,2,2,0.00236306,0.0236306,0.02363339,15804.2,52027.24
1450.094,-6.499279,-0.02375823,-14557.05,0.04793298,2,2,0.002375823,0.02375823,0.02376105,14557.05,47921.59
1455.094,-6.415919,-0.02329562,-13428.16,0.0442158,2,2,0.002329562,0.02329562,0.02329833,13428.16,44205.5
1460.094,-6.332559,-0.02359871,-12450.46,0.04099646,2,2,0.002359871,0.02359871,0.02360149,12450.46,40986.79
1465.094,-6.249239,-0.02358273,-11562.85,0.03807375,2,2,0.002358273,0.02358273,0.02358551,11562.85,38064.77
1470.094,-6.165959,-0.02332751,-10788.36,0.03552355,2,2,0.002332751,0.02332751,0.02333023,10788.36,35515.27
1475.094,-6.082599,-0.02359871,-10116.64,0.03331174,2,2,0.002359871,0.02359871,0.02360149,10116.64,33303.87
1480.094,-5.999239,-0.02340727,-9528.889,0.03137641,2,2,0.002340727,0.02340727,0.02341001,9528.889,31369.06
1485.094,-5.915879,-0.02327967,-9026.467,0.02972205,2,2,0.002327967,0.02327967,0.02328238,9026.467,29715.13
1490.094,-5.832639,-0.02343919,-8576.255,0.0282396,2,2,0.002343919,0.02343919,0.02344194,8576.255,28232.98
1495.094,-5.749199,-0.02334349,-8177.588,0.02692689,2,2,0.002334349,0.02334349,0.02334621,8177.588,26920.6
1500.094,-5.665919,-0.02371036,-7826.196,0.02576984,2,2,0.002371036,0.02371036,0.02371317,7826.196,25763.73
1505.094,-5.582559,-0.02315205,-7495.42,0.02468067,2,2,0.002315205,0.02315205,0.02315473,7495.42,24674.95
1510.094,-5.499239,-0.02377417,-7186.531,0.02366357,2,2,0.002377417,0.02377417,0.023777,7186.531,23657.94
1515.094,-5.415919,-0.02342325,-6901.392,0.02272467,2,2,0.002342325,0.02342325,0.02342599,6901.393,22719.35
1520.094,-5.332599,-0.02364654,-6651.207,0.02190087,2,2,0.002364654,0.02364654,0.02364934,6651.207,21895.69
1525.094,-5.249199,-0.02353489,-6409.644,0.02110546,2,2,0.002353489,0.02353489,0.02353766,6409.644,21100.49
1530.094,-5.165959,-0.02367847,-6171.195,0.0203203,2,2,0.002367847,0.02367847,0.02368127,6171.195,20315.49
1535.094,-5.082559,-0.02375823,-5937.834,0.0195519,2,2,0.002375823,0.02375823,0.02376105,5937.834,19547.26
1540.094,-4.999279,-0.02390176,-5707.544,0.01879361,2,2,0.002390176,0.02390176,0.02390462,5707.544,18789.12
1545.094,-4.915879,-0.02361465,-5481.291,0.01804861,2,2,0.002361465,0.02361465,0.02361744,5481.291,18044.35
1550.094,-4.832559,-0.02358273,-5264.027,0.01733321,2,2,0.002358273,0.02358273,0.02358551,5264.027,17329.13
1555.094,-4.74924,-0.02386987,-5049.695,0.01662747,2,2,0.002386987,0.02386987,0.02387272,5049.695,16623.5
1560.094,-4.665919,-0.02385393,-4837.98,0.01593034,2,2,0.002385393,0.02385393,0.02385677,4837.98,15926.54
1565.094,-4.582599,-0.02358273,-4633.179,0.01525597,2,2,0.002358273,0.02358273,0.02358551,4633.179,15252.38
1570.094,-4.499239,-0.02393369,-4431.427,0.01459165,2,2,0.002393369,0.02393369,0.02393655,4431.427,14588.16
1575.094,-4.415919,-0.02375823,-4236.78,0.01395073,2,2,0.002375823,0.02375823,0.02376105,4236.78,13947.41
1580.094,-4.332559,-0.02379011,-4045.969,0.01332243,2,2,0.002379011,0.02379011,0.02379294,4045.969,13319.26
1585.094,-4.249279,-0.02410915,-3862.667,0.01271886,2,2,0.002410915,0.02410915,0.02411206,3862.667,12715.79
1590.094,-4.16588,-0.02347108,-3681.65,0.01212281,2,2,0.002347108,0.02347108,0.02347383,3681.65,12119.97
1595.094,-4.082599,-0.02367847,-3503.891,0.0115375,2,2,0.002367847,0.02367847,0.02368127,3503.891,11534.76
1600.094,-3.999239,-0.02379011,-3325.075,0.0109487,2,2,0.002379011,0.02379011,0.02379294,3325.075,10946.09
1605.094,-3.91596,-0.023822,-3151.58,0.01037742,2,2,0.0023822,0.023822,0.02382484,3151.58,10374.94
1610.094,-3.832559,-0.02386987,-2979.492,0.00981077,2,2,0.002386987,0.02386987,0.02387272,2979.492,9808.428
1615.094,-3.74924,-0.02393369,-2813.507,0.00926422,2,2,0.002393369,0.02393369,0.02393655,2813.507,9262.003
1620.094,-3.665879,-0.02369441,-2648.373,0.008720474,2,2,0.002369441,0.02369441,0.02369722,2648.373,8718.408
1625.094,-3.582599,-0.02406128,-2485.444,0.008183986,2,2,0.002406128,0.02406128,0.02406417,2485.444,8182.017
1630.094,-3.49924,-0.02369441,-2325.55,0.007657494,2,2,0.002369441,0.02369441,0.02369722,2325.551,7655.68
1635.094,-3.415919,-0.0243165,-2171.781,0.007151167,2,2,0.00243165,0.0243165,0.02431945,2171.781,7149.428
1640.094,-3.33256,-0.0236306,-2021.141,0.006655145,2,2,0.00236306,0.0236306,0.02363339,2021.141,6653.573
1645.094,-3.24924,-0.0239177,-1874.226,0.006171387,2,2,0.00239177,0.0239177,0.02392057,1874.226,6169.911
1650.094,-3.165919,-0.02377417,-1732.449,0.005704551,2,2,0.002377417,0.02377417,0.023777,1732.449,5703.195
1655.094,-3.08256,-0.023822,-1594.125,0.005249082,2,2,0.0023822,0.023822,0.02382484,1594.125,5247.831
1660.094,-2.99928,-0.02422079,-1456.038,0.004794392,2,2,0.002422079,0.02422079,0.02422373,1456.038,4793.231
1665.094,-2.91588,-0.02393369,-1321.627,0.004351809,2,2,0.002393369,0.02393369,0.02393655,1321.627,4350.767
1670.094,-2.8326,-0.02379011,-1189.348,0.003916245,2,2,0.002379011,0.02379011,0.02379294,1189.348,3915.314
1675.094,-2.74924,-0.02407722,-1059.774,0.003489588,2,2,0.002407722,0.02407722,0.02408012,1059.774,3488.748
1680.094,-2.66592,-0.02379011,-935.8519,0.003081542,2,2,0.002379011,0.02379011,0.02379294,935.8519,3080.809
1685.094,-2.58256,-0.02385393,-818.5214,0.0026952,2,2,0.002385393,0.02385393,0.02385677,818.5214,2694.557
1690.094,-2.49928,-0.02423674,-705.8713,0.00232427,2,2,0.002423674,0.02423674,0.02423968,705.8713,2323.706
1695.094,-2.41588,-0.0239177,-607.1086,0.001999067,2,2,0.00239177,0.0239177,0.02392057,607.1086,1998.589
1700.094,-2.3326,-0.02399746,-521.8572,0.001718354,2,2,0.002399746,0.02399746,0.02400034,521.8572,1717.942
1705.094,-2.24924,-0.02383795,-444.0658,0.001462205,2,2,0.002383795,0.02383795,0.02384079,444.0658,1461.856
1708.112,-2.199,-0.02404533,-399.9732,0.001317018,3,3,0.002404533,0.02404533,0.02404822,399.9731,1316.701
1712.114,-2.26568,-0.023822,-509.1455,0.001676497,0,3,0.0023822,0.023822,0.02382484,509.1455,1676.098
1717.114,-2.34892,-0.02390176,-677.0452,0.002229352,0,3,0.002390176,0.02390176,0.02390462,677.0452,2228.819
1722.114,-2.43236,-0.02374224,-850.1007,0.002799183,0,3,0.002374224,0.02374224,0.02374506,850.1007,2798.519
1727.114,-2.51564,-0.02402939,-1032.259,0.003398988,0,3,0.002402939,0.02402939,0.02403228,1032.259,3398.171
1732.114,-2.598999,-0.02398152,-1225.136,0.004034088,0,3,0.002398152,0.02398152,0.02398439,1225.136,4033.121
1737.114,-2.68232,-0.02374224,-1422.865,0.004685162,0,3,0.002374224,0.02374224,0.02374506,1422.865,4684.049
1742.114,-2.76564,-0.02407722,-1619.953,0.005334125,0,3,0.002407722,0.02407722,0.02408012,1619.953,5332.841
1747.114,-2.848959,-0.02407722,-1830.148,0.006026248,0,3,0.002407722,0.02407722,0.02408012,1830.148,6024.798
1752.114,-2.932319,-0.02412509,-2045.299,0.006734691,0,3,0.002412509,0.02412509,0.024128,2045.299,6733.066
1757.114,-3.0156,-0.02383795,-2261.03,0.007445045,0,3,0.002383795,0.02383795,0.02384079,2261.031,7443.271
1762.114,-3.098999,-0.02401344,-2476.656,0.008155051,0,3,0.002401344,0.02401344,0.02401633,2476.656,8153.092
1767.114,-3.182279,-0.02375823,-2694.412,0.00887207,0,3,0.002375823,0.02375823,0.02376105,2694.412,8869.963
1772.114,-3.265679,-0.02394963,-2912.504,0.009590195,0,3,0.002394963,0.02394963,0.0239525,2912.504,9587.898
1777.114,-3.349039,-0.0239177,-3135.959,0.01032598,0,3,0.00239177,0.0239177,0.02392057,3135.959,10323.51
1782.114,-3.43228,-0.02385393,-3357.455,0.01105532,0,3,0.002385393,0.02385393,0.02385677,3357.455,11052.68
1787.114,-3.51568,-0.02404533,-3583.542,0.01179976,0,3,0.002404533,0.02404533,0.02404822,3583.542,11796.93
1792.114,-3.59896,-0.02371036,-3811.057,0.01254892,0,3,0.002371036,0.02371036,0.02371317,3811.057,12545.94
1797.114,-3.682319,-0.02371036,-4054.269,0.01334976,0,3,0.002371036,0.02371036,0.02371317,4054.269,13346.6
1802.114,-3.765679,-0.02379011,-4300.543,0.01416068,0,3,0.002379011,0.02379011,0.02379294,4300.542,14157.31
1807.114,-3.849,-0.02396557,-4549.268,0.01497968,0,3,0.002396557,0.02396557,0.02396845,4549.268,14976.09
1812.114,-3.932319,-0.02394963,-4801.776,0.01581113,0,3,0.002394963,0.02394963,0.0239525,4801.776,15807.34
1817.114,-4.01568,-0.02385393,-5057.184,0.01665213,0,3,0.002385393,0.02385393,0.02385677,5057.184,16648.15
1822.114,-4.098919,-0.02420485,-5309.067,0.01748152,0,3,0.002420485,0.02420485,0.02420778,5309.066,17477.28
1827.114,-4.182359,-0.02410915,-5566.934,0.01833061,0,3,0.002410915,0.02410915,0.02411206,5566.934,18326.19
1832.114,-4.265599,-0.02415698,-5820.29,0.01916485,0,3,0.002415698,0.02415698,0.0241599,5820.29,19160.22
1837.114,-4.348959,-0.02418891,-6079.175,0.02001731,0,3,0.002418891,0.02418891,0.02419183,6079.175,20012.46
1842.114,-4.432319,-0.02364654,-6335.655,0.02086183,0,3,0.002364654,0.02364654,0.02364934,6335.655,20856.9
1847.114,-4.515639,-0.02386987,-6594.383,0.02171376,0,3,0.002386987,0.02386987,0.02387272,6594.383,21708.58
1852.114,-4.598919,-0.02393369,-6852.632,0.02256412,0,3,0.002393369,0.02393369,0.02393655,6852.632,22558.72
1857.114,-4.682359,-0.02406128,-7111.558,0.0234167,0,3,0.002406128,0.02406128,0.02406417,7111.558,23411.06
1862.114,-4.765639,-0.02422079,-7371.222,0.02427171,0,3,0.002422079,0.02422079,0.02422373,7371.222,24265.83
1867.114,-4.84904,-0.02422079,-7633.987,0.02513694,0,3,0.002422079,0.02422079,0.02422373,7633.987,25130.85
1872.114,-4.932279,-0.02407722,-7889.233,0.0259774,0,3,0.002407722,0.02407722,0.02408012,7889.233,25971.15
1877.114,-5.015639,-0.02417292,-8149.175,0.02683333,0,3,0.002417292,0.02417292,0.02417585,8149.175,26826.84
1882.114,-5.098999,-0.02436437,-8401.753,0.02766501,0,3,0.002436437,0.02436437,0.02436734,8401.753,27658.27
1887.114,-5.182279,-0.02410915,-8653.428,0.02849372,0,3,0.002410915,0.02410915,0.02411206,8653.428,28486.85
1892.114,-5.265679,-0.02414104,-8897.81,0.02929841,0,3,0.002414104,0.02414104,0.02414395,8897.81,29291.34
1897.114,-5.348959,-0.02379011,-9145.182,0.03011295,0,3,0.002379011,0.02379011,0.02379294,9145.183,30105.79
1902.114,-5.432279,-0.0243165,-9397.338,0.03094324,0,3,0.00243165,0.0243165,0.02431945,9397.338,30935.71
1907.114,-5.515639,-0.02371036,-9713.477,0.03198421,0,3,0.002371036,0.02371036,0.02371317,9713.477,31976.63
1912.114,-5.598959,-0.02371036,-10033.87,0.0330392,0,3,0.002371036,0.02371036,0.02371317,10033.87,33031.37
1917.114,-5.682319,-0.02385393,-10375.72,0.03416481,0,3,0.002385393,0.02385393,0.02385677,10375.72,34156.66
1922.114,-5.765679,-0.02412509,-10725.68,0.03531715,0,3,0.002412509,0.02412509,0.024128,10725.68,35308.63
1927.114,-5.848959,-0.02402939,-11156.02,0.03673418,0,3,0.002402939,0.02402939,0.02403228,11156.02,36725.36
1932.114,-5.932359,-0.02393369,-11632.68,0.03830371,0,3,0.002393369,0.02393369,0.02393655,11632.68,38294.55
1937.114,-6.015639,-0.02410915,-12145.4,0.03999197,0,3,0.002410915,0.02410915,0.02411206,12145.4,39982.33
1942.114,-6.098959,-0.02410915,-12683.58,0.04176407,0,3,0.002410915,0.02410915,0.02411206,12683.58,41754
1947.114,-6.182319,-0.02371036,-13268.04,0.04368855,0,3,0.002371036,0.02371036,0.02371317,13268.04,43678.19
1952.114,-6.265639,-0.02423674,-13922.78,0.04584447,0,3,0.002423674,0.02423674,0.02423968,13922.78,45833.35
1957.114,-6.348959,-0.02396557,-14625.27,0.0481576,0,3,0.002396557,0.02396557,0.02396845,14625.27,48146.05
1962.114,-6.432359,-0.02446007,-15376.54,0.05063134,0,3,0.002446007,0.02446007,0.02446306,15376.54,50618.95
1967.114,-6.515639,-0.02447601,-16248.53,0.05350261,0,3,0.002447601,0.02447601,0.02447901,16248.53,53489.51
1972.114,-6.598999,-0.02452385,-17209.48,0.05666681,0,3,0.002452385,0.02452385,0.02452686,17209.48,56652.91
1977.114,-6.682279,-0.02430055,-18283.14,0.0602021,0,3,0.002430055,0.02430055,0.02430351,18283.14,60187.47
1982.114,-6.765679,-0.02390176,-19491.3,0.06418031,0,3,0.002390176,0.02390176,0.02390462,19491.3,64164.96
1986.93,-6.845879,-0.02412509,-20742.45,0.06830002,0,3,0.002412509,0.02412509,0.024128,20742.45,68283.55
1991.496,-6.921959,-0.0243165,-21993.28,0.07241875,0,3,0.00243165,0.0243165,0.02431945,21993.28,72401.14
1995.82,-6.994079,-0.02418891,-23244.88,0.07653997,0,3,0.002418891,0.02418891,0.02419183,23244.88,76521.46
2000.008,-7.063839,-0.02417292,-24495.99,0.08065957,0,3,0.002417292,0.02417292,0.02417585,24495.99,80640.07
2004.074,-7.131639,-0.02409317,-25746.91,0.08477857,0,3,0.002409317,0.02409317,0.02409607,25746.91,84758.14
2008.004,-7.197119,-0.02410915,-26998.1,0.08889845,0,3,0.002410915,0.02410915,0.02411206,26998.1,88877.01
2011.858,-7.261399,-0.0243165,-28250.01,0.09302068,0,3,0.00243165,0.0243165,0.02431945,28250.01,92998.06
2015.628,-7.324159,-0.02430055,-29501.95,0.09714302,0,3,0.002430055,0.02430055,0.02430351,29501.95,97119.42
2019.24,-7.384439,-0.02417292,-30754.38,0.101267,0,3,0.002417292,0.02417292,0.02417585,30754.38,101242.5
2022.838,-7.444399,-0.02444413,-32005.97,0.1053882,0,3,0.002444413,0.02444413,0.02444711,32005.97,105362.4
2026.35,-7.502879,-0.02452385,-33257.11,0.1095079,0,3,0.002452385,0.02452385,0.02452686,33257.11,109481
2029.802,-7.560439,-0.02414104,-34508.66,0.113629,0,3,0.002414104,0.02414104,0.02414395,34508.66,113601.5
2033.27,-7.618279,-0.02461959,-35761.13,0.117753,0,3,0.002461959,0.02461959,0.02462262,35761.13,117724
2036.648,-7.674559,-0.02452385,-37012.72,0.1218742,0,3,0.002452385,0.02452385,0.02452686,37012.72,121844.4
2040.034,-7.730919,-0.02426863,-38263.99,0.1259944,0,3,0.002426863,0.02426863,0.02427157,38264,125963.8
2043.388,-7.786879,-0.0245079,-39515.84,0.1301164,0,3,0.00245079,0.0245079,0.02451091,39515.84,130084.6
2046.742,-7.842759,-0.02409317,-40767.8,0.1342389,0,3,0.002409317,0.02409317,0.02409607,40767.8,134206.5
2050.042,-7.897759,-0.02410915,-42019.86,0.1383616,0,3,0.002410915,0.02410915,0.02411206,42019.86,138328.2
2053.38,-7.953399,-0.02401344,-43271.68,0.1424835,0,3,0.002401344,0.02401344,0.02401633,43271.68,142449.3
2056.712,-8.008919,-0.02452385,-44523.26,0.1466047,0,3,0.002452385,0.02452385,0.02452686,44523.26,146568.7
2059.962,-8.063079,-0.0245079,-45775.87,0.1507292,0,3,0.00245079,0.0245079,0.02451091,45775.87,150692.3
2063.318,-8.119039,-0.02404533,-47027.73,0.1548513,0,3,0.002404533,0.02404533,0.02404822,47027.73,154814.1
2066.644,-8.174479,-0.02436437,-48280.04,0.1589749,0,3,0.002436437,0.02436437,0.02436734,48280.04,158936.2
2069.976,-8.229959,-0.02428461,-49532.13,0.1630977,0,3,0.002428461,0.02428461,0.02428756,49532.13,163058.1
2073.32,-8.285759,-0.02434839,-50785.05,0.1672233,0,3,0.002434839,0.02434839,0.02435135,50785.05,167182.6
2076.646,-8.341199,-0.02396557,-52037.54,0.1713475,0,3,0.002396557,0.02396557,0.02396845,52037.54,171306.4
2079.97,-8.396559,-0.02402939,-53289.03,0.1754683,0,3,0.002402939,0.02402939,0.02403228,53289.03,175426.2
2083.332,-8.452599,-0.02433244,-54541.56,0.1795926,0,3,0.002433244,0.02433244,0.0243354,54541.56,179548.9
2086.672,-8.508239,-0.02418891,-55794.19,0.1837172,0,3,0.002418891,0.02418891,0.02419183,55794.19,183672.8
2089.964,-8.563119,-0.02453983,-57045.39,0.1878372,0,3,0.002453983,0.02453983,0.02454284,57045.39,187791.1
2093.338,-8.619439,-0.02433244,-58296.98,0.1919584,0,3,0.002433244,0.02433244,0.0243354,58296.98,191911.6
2096.684,-8.675119,-0.02409317,-59548.62,0.1960797,0,3,0.002409317,0.02409317,0.02409607,59548.62,196032.5
2100.034,-8.730918,-0.02428461,-60800.65,0.2002023,0,3,0.002428461,0.02428461,0.02428756,60800.65,200153.7
2103.408,-8.787159,-0.02453983,-62051.96,0.2043226,0,3,0.002453983,0.02453983,0.02454284,62051.96,204272.5
2106.76,-8.843078,-0.02423674,-63303.16,0.2084425,0,3,0.002423674,0.02423674,0.02423968,63303.16,208392
2110.15,-8.899558,-0.02439626,-64555.16,0.2125651,0,3,0.002439626,0.02439626,0.02439923,64555.16,212513.2
2113.55,-8.956199,-0.02388582,-65807.64,0.2166892,0,3,0.002388582,0.02388582,0.02388867,65807.64,216637.4
2116.994,-9.013639,-0.02423674,-67059.12,0.22081,0,3,0.002423674,0.02423674,0.02423968,67059.12,220756.5
2120.466,-9.071479,-0.02428461,-68310.44,0.2249303,0,3,0.002428461,0.02428461,0.02428756,68310.44,224875.7
2123.944,-9.129479,-0.02422079,-69561.58,0.2290501,0,3,0.002422079,0.02422079,0.02422373,69561.59,228994.6
2127.416,-9.187278,-0.02447601,-70813.58,0.2331726,0,3,0.002447601,0.02447601,0.02447901,70813.58,233115.5
2130.87,-9.244919,-0.02446007,-72065,0.2372932,0,3,0.002446007,0.02446007,0.02446306,72064.99,237235.1
2134.404,-9.303799,-0.02414104,-73316.34,0.2414136,0,3,0.002414104,0.02414104,0.02414395,73316.34,241355.3
2137.956,-9.362958,-0.02415698,-74567.98,0.2455349,0,3,0.002415698,0.02415698,0.0241599,74567.98,245475.6
2141.414,-9.420679,-0.02377417,-75819.78,0.2496568,0,3,0.002377417,0.02377417,0.023777,75819.78,249597.5
2144.992,-9.480319,-0.02457172,-77071.14,0.2537773,0,3,0.002457172,0.02457172,0.02457474,77071.14,253714.9
2148.498,-9.538719,-0.02375823,-78322.6,0.257898,0,3,0.002375823,0.02375823,0.02376105,78322.59,257836.7
2152.056,-9.597959,-0.02420485,-79573.8,0.2620179,0,3,0.002420485,0.02420485,0.02420778,79573.8,261954.5
2155.626,-9.657559,-0.02422079,-80821.56,0.2661265,0,3,0.002422079,0.02422079,0.02422373,80821.55,266062