File: ElectricPoleSupport/ExptData/Raw/Heel_F1_cycle.raw.csv
"Test Type","Compression"
"Temperature:","20.5"
"Humidity:","57.5"
"Geometry:","Rectangular"
"Specimen",1
"Specimen name:","F1"
"Width:",330.000000,"mm"
"Thickness:",897.000000,"mm"
"Anvil height:",90.000000,"mm"
"Diameter:",50.000000,"mm"
"Inner diameter:",0.500000,"mm"
"Outer diameter:",1.000000,"mm"
"Wall thickness:",0.500000,"mm"
"Area:",296010.000000,"mm*mm"
"Linear density:",1.000000,"den"
"Sled weight:",9.806650,"N"
"Loading span:",0.000000,"mm"
"Support span:",1.000000,"mm"
"Span ratio:","2"
"Fixture type:","3-point"
"Extensometer",-10.000000,"**mm"
"Included"
"Time sec","Extension mm","Strain 1 %","Load N","Comp. stress MPa","Cycle Count ","Total Cycle Count ","Comp. extension mm","Comp. strain %","True strain %","Comp. load N","True stress Pa"
0,0,-0.02607115,-4.646094,1.569573e-005,0,0,0.002607115,0.02607115,0.02607454,4.646094,15.69164
1,-0.0162,-0.02572019,-12.61317,4.261061e-005,0,0,0.002572019,0.02572019,0.02572349,12.61317,42.59965
2,-0.03323999,-0.02586376,-67.06727,0.000226571,0,0,0.002586376,0.02586376,0.0258671,67.06727,226.5124
3,-0.04992,-0.02591163,-158.505,0.0005354719,0,0,0.002591163,0.02591163,0.02591499,158.505,535.3331
4,-0.06659999,-0.02591163,-280.9518,0.0009491296,0,0,0.002591163,0.02591163,0.02591499,280.9518,948.8836
5,-0.08327998,-0.02586376,-308.7912,0.001043178,0,0,0.002586376,0.02586376,0.0258671,308.7912,1042.909
6,-0.09995998,-0.02592757,-311.5101,0.001052363,0,0,0.002592757,0.02592757,0.02593094,311.51,1052.09
7,-0.11664,-0.02581593,-312.199,0.001054691,0,0,0.002581593,0.02581593,0.02581926,312.1989,1054.418
8,-0.13332,-0.02592757,-312.3184,0.001055094,0,0,0.002592757,0.02592757,0.02593094,312.3184,1054.821
9,-0.14996,-0.025784,-311.9996,0.001054017,0,0,0.0025784,0.025784,0.02578733,311.9996,1053.745
10,-0.16664,-0.02597541,-311.6975,0.001052996,0,0,0.002597541,0.02597541,0.02597878,311.6975,1052.723
11,-0.18328,-0.02589568,-312.885,0.001057008,0,0,0.002589568,0.02589568,0.02589904,312.885,1056.734
12,-0.19992,-0.02551284,-312.7626,0.001056595,0,0,0.002551284,0.02551284,0.02551609,312.7626,1056.325
13,-0.2166,-0.02592757,-312.9374,0.001057185,0,0,0.002592757,0.02592757,0.02593094,312.9374,1056.911
14,-0.23336,-0.02575211,-313.4819,0.001059024,0,0,0.002575211,0.02575211,0.02575543,313.4818,1058.752
15,-0.25,-0.02573617,-312.9185,0.001057121,0,0,0.002573617,0.02573617,0.02573948,312.9185,1056.849
16,-0.2666799,-0.02602328,-313.293,0.001058387,0,0,0.002602328,0.02602328,0.02602666,313.293,1058.111
17,-0.28328,-0.02610303,-313.2437,0.00105822,0,0,0.002610303,0.02610303,0.02610644,313.2437,1057.944
18,-0.29996,-0.02618279,-312.8803,0.001056992,0,0,0.002618279,0.02618279,0.02618622,312.8803,1056.716
19,-0.3165999,-0.02594352,-313.1715,0.001057976,0,0,0.002594352,0.02594352,0.02594688,313.1715,1057.702
20,-0.3333199,-0.02575211,-312.8597,0.001056923,0,0,0.002575211,0.02575211,0.02575543,312.8597,1056.65
21,-0.3499599,-0.02591163,-312.3575,0.001055226,0,0,0.002591163,0.02591163,0.02591499,312.3575,1054.953
22,-0.3666399,-0.02592757,-313.2049,0.001058089,0,0,0.002592757,0.02592757,0.02593094,313.2049,1057.814
23,-0.3832799,-0.02586376,-389.7497,0.001316677,0,0,0.002586376,0.02586376,0.0258671,389.7497,1316.337
24,-0.3999599,-0.02599139,-560.791,0.0018945,0,0,0.002599139,0.02599139,0.02599477,560.791,1894.008
25,-0.4165999,-0.02629444,-769.9718,0.002601168,0,0,0.002629444,0.02629444,0.0262979,769.9718,2600.484
26,-0.4333199,-0.02594352,-1016.994,0.003435675,0,0,0.002594352,0.02594352,0.02594688,1016.994,3434.784
26.936,-0.4488799,-0.02643801,-1267.004,0.004280275,0,0,0.002643801,0.02643801,0.02644151,1267.004,4279.144
27.838,-0.4639199,-0.02597541,-1517.388,0.005126138,0,0,0.002597541,0.02597541,0.02597878,1517.388,5124.807
28.696,-0.4781999,-0.02613492,-1767.723,0.005971836,0,0,0.002613492,0.02613492,0.02613834,1767.723,5970.276
29.534,-0.4921999,-0.02602328,-2017.724,0.006816404,0,0,0.002602328,0.02602328,0.02602666,2017.724,6814.63
30.35,-0.5057999,-0.02611898,-2267.91,0.007661598,0,0,0.002611898,0.02611898,0.02612239,2267.91,7659.597
31.16,-0.5192799,-0.02595946,-2518.103,0.008506819,0,0,0.002595946,0.02595946,0.02596283,2518.104,8504.611
31.908,-0.5317999,-0.02631038,-2768.382,0.009352326,0,0,0.002631038,0.02631038,0.02631384,2768.382,9349.866
32.626,-0.5437999,-0.02605516,-3018.77,0.0101982,0,0,0.002605516,0.02605516,0.02605856,3018.77,10195.55
33.296,-0.5548799,-0.02651777,-3269.183,0.01104416,0,0,0.002651777,0.02651777,0.02652129,3269.183,11041.23
33.934,-0.5655199,-0.02610303,-3519.562,0.01189001,0,0,0.002610303,0.02610303,0.02610644,3519.562,11886.91
34.56,-0.5759599,-0.02626255,-3769.921,0.01273579,0,0,0.002626255,0.02626255,0.026266,3769.921,12732.45
35.17,-0.5861199,-0.02608709,-4020.23,0.0135814,0,0,0.002608709,0.02608709,0.02609049,4020.23,13577.86
35.77,-0.5960799,-0.02605516,-4270.321,0.01442627,0,0,0.002605516,0.02605516,0.02605856,4270.321,14422.51
36.356,-0.6058799,-0.02611898,-4520.728,0.01527221,0,0,0.002611898,0.02611898,0.02612239,4520.728,15268.23
36.942,-0.6156399,-0.02605516,-4771.267,0.0161186,0,0,0.002605516,0.02605516,0.02605856,4771.267,16114.4
37.53,-0.6254399,-0.0258797,-5021.315,0.01696333,0,0,0.00258797,0.0258797,0.02588305,5021.315,16958.94
38.134,-0.6355599,-0.02594352,-5271.456,0.01780837,0,0,0.002594352,0.02594352,0.02594688,5271.456,17803.75
38.732,-0.6455199,-0.02576806,-5521.794,0.01865408,0,0,0.002576806,0.02576806,0.02577138,5521.794,18649.27
39.366,-0.6560799,-0.02618279,-5772.058,0.01949954,0,0,0.002618279,0.02618279,0.02618622,5772.058,19494.43
40.004,-0.6667199,-0.02599139,-6022.872,0.02034685,0,0,0.002599139,0.02599139,0.02599477,6022.872,20341.56
40.634,-0.6772399,-0.02613492,-6273.295,0.02119285,0,0,0.002613492,0.02613492,0.02613834,6273.295,21187.31
41.272,-0.6877998,-0.02613492,-6523.768,0.02203901,0,0,0.002613492,0.02613492,0.02613834,6523.768,22033.25
41.912,-0.6984799,-0.02597541,-6774.408,0.02288574,0,0,0.002597541,0.02597541,0.02597878,6774.408,22879.79
42.6,-0.7099599,-0.02621468,-7024.571,0.02373086,0,0,0.002621468,0.02621468,0.02621812,7024.57,23724.63
43.234,-0.7205199,-0.02579994,-7274.956,0.02457673,0,0,0.002579994,0.02579994,0.02580327,7274.956,24570.38
43.922,-0.7319599,-0.02592757,-7525.229,0.02542221,0,0,0.002592757,0.02592757,0.02593094,7525.229,25415.62
44.638,-0.7439199,-0.0258797,-7775.456,0.02626755,0,0,0.00258797,0.0258797,0.02588305,7775.457,26260.75
45.596,-0.7598798,-0.02595946,-8025.944,0.02711376,0,0,0.002595946,0.02595946,0.02596283,8025.944,27106.72
46.426,-0.7737998,-0.02594352,-8276.115,0.0279589,0,0,0.002594352,0.02594352,0.02594688,8276.114,27951.65
47.426,-0.7904399,-0.02594352,-8459.575,0.02857868,0,0,0.002594352,0.02594352,0.02594688,8459.575,28571.27
48.426,-0.8071199,-0.02552878,-8554.189,0.02889831,0,0,0.002552878,0.02552878,0.02553204,8554.188,28890.93
49.426,-0.8237199,-0.0258797,-8677.062,0.02931341,0,0,0.00258797,0.0258797,0.02588305,8677.063,29305.82
50.426,-0.8403999,-0.02592757,-8588.451,0.02901406,0,0,0.002592757,0.02592757,0.02593094,8588.451,29006.53
51.426,-0.8570398,-0.02640609,-8660.566,0.02925768,0,0,0.002640609,0.02640609,0.02640957,8660.566,29249.95
52.368,-0.8727598,-0.02595946,-8910.801,0.03010304,0,0,0.002595946,0.02595946,0.02596283,8910.801,30095.22
53.104,-0.8849999,-0.02599139,-9161.421,0.0309497,0,0,0.002599139,0.02599139,0.02599477,9161.421,30941.66
53.838,-0.8972798,-0.02581593,-9411.436,0.03179432,0,0,0.002581593,0.02581593,0.02581926,9411.436,31786.11
54.508,-0.9084799,-0.0262785,-9661.445,0.03263891,0,0,0.00262785,0.0262785,0.02628195,9661.445,32630.34
55.126,-0.9187599,-0.02594352,-9911.766,0.03348456,0,0,0.002594352,0.02594352,0.02594688,9911.766,33475.88
55.718,-0.9286399,-0.02573617,-10161.99,0.03432988,0,0,0.002573617,0.02573617,0.02573948,10161.99,34321.04
56.348,-0.9391599,-0.025784,-10412.16,0.03517504,0,0,0.0025784,0.025784,0.02578733,10412.16,35165.97
56.976,-0.9495999,-0.02586376,-10662.62,0.03602114,0,0,0.002586376,0.02586376,0.0258671,10662.62,36011.82
57.582,-0.9596399,-0.02562448,-10912.7,0.03686598,0,0,0.002562448,0.02562448,0.02562777,10912.7,36856.54
58.168,-0.9693999,-0.02599139,-11163.09,0.03771186,0,0,0.002599139,0.02599139,0.02599477,11163.09,37702.06
58.752,-0.9791599,-0.02573617,-11413.74,0.03855863,0,0,0.002573617,0.02573617,0.02573948,11413.74,38548.71
59.32,-0.9885999,-0.02570424,-11664.29,0.03940504,0,0,0.002570424,0.02570424,0.02570755,11664.29,39394.91
59.894,-0.9981599,-0.02543308,-11914.44,0.04025013,0,0,0.002543308,0.02543308,0.02543631,11914.44,40239.89
60.462,-1.00764,-0.02594352,-12164.79,0.04109586,0,0,0.002594352,0.02594352,0.02594688,12164.79,41085.2
61.024,-1.017,-0.02586376,-12414.88,0.04194076,0,0,0.002586376,0.02586376,0.0258671,12414.88,41929.91
61.598,-1.0266,-0.02551284,-12665.66,0.04278795,0,0,0.002551284,0.02551284,0.02551609,12665.66,42777.03
62.156,-1.03592,-0.02600733,-12916.03,0.04363375,0,0,0.002600733,0.02600733,0.02601071,12916.03,43622.4
62.704,-1.04504,-0.02599139,-13166.58,0.04448018,0,0,0.002599139,0.02599139,0.02599477,13166.58,44468.62
63.234,-1.05388,-0.02579994,-13416.77,0.0453254,0,0,0.002579994,0.02579994,0.02580327,13416.77,45313.71
63.764,-1.06272,-0.02583187,-13667.15,0.04617126,0,0,0.002583187,0.02583187,0.02583521,13667.15,46159.33
64.316,-1.07196,-0.02610303,-13917.74,0.04701782,0,0,0.002610303,0.02610303,0.02610644,13917.74,47005.54
64.88,-1.08136,-0.02626255,-14167.95,0.04786306,0,0,0.002626255,0.02626255,0.026266,14167.95,47850.49
65.63,-1.0938,-0.02586376,-14418.4,0.04870915,0,0,0.002586376,0.02586376,0.0258671,14418.4,48696.55
66.314,-1.1052,-0.02572019,-14668.48,0.04955399,0,0,0.002572019,0.02572019,0.02572349,14668.48,49541.25
66.892,-1.11484,-0.025784,-14918.8,0.05039965,0,0,0.0025784,0.025784,0.02578733,14918.8,50386.66
67.464,-1.12436,-0.02610303,-15168.91,0.05124459,0,0,0.002610303,0.02610303,0.02610644,15168.91,51231.21
67.998,-1.1332,-0.02600733,-15419.67,0.05209173,0,0,0.002600733,0.02600733,0.02601071,15419.67,52078.19
68.522,-1.142,-0.02575211,-15670.3,0.0529384,0,0,0.002575211,0.02575211,0.02575543,15670.29,52924.76
69.036,-1.15052,-0.02597541,-15920.35,0.05378313,0,0,0.002597541,0.02597541,0.02597878,15920.35,53769.16
69.6,-1.15996,-0.02579994,-16170.5,0.05462822,0,0,0.002579994,0.02579994,0.02580327,16170.5,54614.12
70.156,-1.16924,-0.02600733,-16420.57,0.05547303,0,0,0.002600733,0.02600733,0.02601071,16420.57,55458.61
70.692,-1.17816,-0.02567235,-16670.76,0.05631823,0,0,0.002567235,0.02567235,0.02567565,16670.76,56303.77
71.224,-1.18704,-0.025784,-16921.16,0.05716416,0,0,0.0025784,0.025784,0.02578733,16921.16,57149.42
71.764,-1.196,-0.02565641,-17171.67,0.05801045,0,0,0.002565641,0.02565641,0.0256597,17171.67,57995.57
72.322,-1.20532,-0.02575211,-17421.94,0.05885591,0,0,0.002575211,0.02575211,0.02575543,17421.94,58840.75
72.882,-1.21468,-0.0261509,-17672.58,0.05970263,0,0,0.002615091,0.0261509,0.02615433,17672.58,59687.02
73.456,-1.2242,-0.0261509,-17923.47,0.06055023,0,0,0.002615091,0.0261509,0.02615433,17923.47,60534.39
74.016,-1.23356,-0.02632637,-18174.23,0.06139737,0,0,0.002632637,0.02632637,0.02632983,18174.23,61381.2
74.58,-1.243,-0.02600733,-18424.63,0.06224328,0,0,0.002600733,0.02600733,0.02601071,18424.63,62227.09
75.124,-1.25208,-0.0258797,-18675.38,0.06309037,0,0,0.00258797,0.0258797,0.02588305,18675.38,63074.04
75.672,-1.26116,-0.02603922,-18926.12,0.06393744,0,0,0.002603922,0.02603922,0.02604261,18926.12,63920.8
76.174,-1.26952,-0.02576806,-19176.52,0.06478334,0,0,0.002576806,0.02576806,0.02577138,19176.52,64766.65
76.668,-1.27776,-0.02557665,-19426.96,0.06562939,0,0,0.002557665,0.02557665,0.02557992,19426.96,65612.6
77.152,-1.2858,-0.02575211,-19677.08,0.06647437,0,0,0.002575211,0.02575211,0.02575543,19677.08,66457.25
77.646,-1.29404,-0.02610303,-19927.46,0.06732024,0,0,0.002610303,0.02610303,0.02610644,19927.46,67302.66
78.136,-1.3022,-0.02607115,-20178.01,0.06816664,0,0,0.002607115,0.02607115,0.02607454,20178.01,68148.87
78.65,-1.31076,-0.02597541,-20428.89,0.06901421,0,0,0.002597541,0.02597541,0.02597878,20428.89,68996.28
79.16,-1.31928,-0.02586376,-20679.05,0.0698593,0,0,0.002586376,0.02586376,0.0258671,20679.05,69841.23
79.646,-1.32736,-0.02619874,-20929.82,0.07070646,0,0,0.002619874,0.02619874,0.02620217,20929.82,70687.94
80.116,-1.3352,-0.02611898,-21180.16,0.07155217,0,0,0.002611898,0.02611898,0.02612239,21180.16,71533.48
80.588,-1.34312,-0.02610303,-21430.23,0.07239698,0,0,0.002610303,0.02610303,0.02610644,21430.23,72378.08
81.048,-1.3508,-0.02643801,-21680.96,0.07324402,0,0,0.002643801,0.02643801,0.02644151,21680.96,73224.65
81.52,-1.3586,-0.02592757,-21931.9,0.07409175,0,0,0.002592757,0.02592757,0.02593094,21931.9,74072.54
81.982,-1.36628,-0.02600733,-22182.97,0.07493994,0,0,0.002600733,0.02600733,0.02601071,22182.97,74920.45
82.426,-1.37372,-0.02605516,-22433.76,0.07578718,0,0,0.002605516,0.02605516,0.02605856,22433.76,75767.43
82.886,-1.3814,-0.02603922,-22684.36,0.07663376,0,0,0.002603922,0.02603922,0.02604261,22684.36,76613.8
83.322,-1.38864,-0.02635825,-22934.66,0.07747936,0,0,0.002635826,0.02635825,0.02636173,22934.66,77458.94
83.758,-1.39588,-0.02603922,-23185.63,0.07832719,0,0,0.002603922,0.02603922,0.02604261,23185.63,78306.79
84.176,-1.40284,-0.02603922,-23435.89,0.07917265,0,0,0.002603922,0.02603922,0.02604261,23435.89,79152.03
84.594,-1.40984,-0.02603922,-23686.14,0.08001805,0,0,0.002603922,0.02603922,0.02604261,23686.14,79997.21
85.02,-1.41692,-0.02564047,-23937.01,0.08086555,0,0,0.002564047,0.02564047,0.02564375,23937.01,80844.82
85.452,-1.42412,-0.02618279,-24187.39,0.08171138,0,0,0.002618279,0.02618279,0.02618622,24187.39,81689.99
85.896,-1.43152,-0.0258797,-24438.53,0.08255983,0,0,0.00258797,0.0258797,0.02588305,24438.54,82538.46
86.33,-1.43884,-0.0258797,-24689.42,0.08340737,0,0,0.00258797,0.0258797,0.02588305,24689.42,83385.79
86.758,-1.44596,-0.02600733,-24940.07,0.08425415,0,0,0.002600733,0.02600733,0.02601071,24940.07,84232.23
87.18,-1.453,-0.02572019,-25190.96,0.08510172,0,0,0.002572019,0.02572019,0.02572349,25190.96,85079.84
87.59,-1.45984,-0.02591163,-25441.2,0.0859471,0,0,0.002591163,0.02591163,0.02591499,25441.2,85924.82
88.004,-1.46668,-0.02591163,-25691.89,0.086794,0,0,0.002591163,0.02591163,0.02591499,25691.89,86771.52
88.42,-1.47368,-0.02573617,-25942.8,0.08764164,0,0,0.002573617,0.02573617,0.02573948,25942.8,87619.09
88.868,-1.48116,-0.02599139,-26193.87,0.0884898,0,0,0.002599139,0.02599139,0.02599477,26193.87,88466.8
89.322,-1.48868,-0.02616685,-26444.84,0.08933766,0,0,0.002616685,0.02616685,0.02617027,26444.84,89314.28
89.762,-1.49596,-0.02594352,-26695.68,0.09018508,0,0,0.002594352,0.02594352,0.02594688,26695.68,90161.68
90.202,-1.50328,-0.0258797,-26945.91,0.0910304,0,0,0.00258797,0.0258797,0.02588305,26945.91,91006.85
90.626,-1.51036,-0.02564047,-27196.27,0.09187619,0,0,0.002564047,0.02564047,0.02564375,27196.27,91852.63
91.062,-1.51764,-0.0258797,-27446.95,0.09272304,0,0,0.00258797,0.0258797,0.02588305,27446.95,92699.04
91.496,-1.52488,-0.02579994,-27697.51,0.09356949,0,0,0.002579994,0.02579994,0.02580327,27697.51,93545.36
91.934,-1.53216,-0.02599139,-27947.79,0.09441502,0,0,0.002599139,0.02599139,0.02599477,27947.79,94390.48
92.378,-1.5396,-0.02589568,-28198.6,0.09526233,0,0,0.002589568,0.02589568,0.02589904,28198.6,95237.66
92.818,-1.54692,-0.0261509,-28449.7,0.09611061,0,0,0.002615091,0.0261509,0.02615433,28449.7,96085.48
93.246,-1.55404,-0.02594352,-28700.49,0.09695783,0,0,0.002594352,0.02594352,0.02594688,28700.49,96932.67
93.676,-1.56116,-0.025784,-28951.03,0.09780423,0,0,0.0025784,0.025784,0.02578733,28951.03,97779
94.092,-1.56816,-0.02599139,-29201.47,0.09865028,0,0,0.002599139,0.02599139,0.02599477,29201.47,98624.64
94.516,-1.57528,-0.02629444,-29452.15,0.09949716,0,0,0.002629444,0.02629444,0.0262979,29452.15,99471
94.94,-1.58236,-0.02613492,-29703.18,0.1003452,0,0,0.002613492,0.02613492,0.02613834,29703.18,100319
95.364,-1.58936,-0.02597541,-29953.79,0.1011918,0,0,0.002597541,0.02597541,0.02597878,29953.79,101165.5
95.796,-1.59656,-0.02592757,-30204.65,0.1020393,0,0,0.002592757,0.02592757,0.02593094,30204.65,102012.8
96.238,-1.60392,-0.02613492,-30455.53,0.1028868,0,0,0.002613492,0.02613492,0.02613834,30455.53,102859.9
96.682,-1.6114,-0.0263742,-30706.11,0.1037334,0,0,0.00263742,0.0263742,0.02637768,30706.11,103706
97.124,-1.61876,-0.02626255,-30956.59,0.1045795,0,0,0.002626255,0.02626255,0.026266,30956.59,104552.1
97.554,-1.62584,-0.02599139,-31207.2,0.1054262,0,0,0.002599139,0.02599139,0.02599477,31207.2,105398.8
97.966,-1.63272,-0.02611898,-31457.51,0.1062718,0,0,0.002611898,0.02611898,0.02612239,31457.51,106244
98.376,-1.63956,-0.02576806,-31708.19,0.1071187,0,0,0.002576806,0.02576806,0.02577138,31708.19,107091.1
98.782,-1.64632,-0.02629444,-31958.53,0.1079643,0,0,0.002629444,0.02629444,0.0262979,31958.53,107936
99.19,-1.65312,-0.02592757,-32209.23,0.1088113,0,0,0.002592757,0.02592757,0.02593094,32209.23,108783.1
99.602,-1.66,-0.0256883,-32459.86,0.109658,0,0,0.00256883,0.0256883,0.0256916,32459.86,109629.8
100.028,-1.66704,-0.02597541,-32710.13,0.1105035,0,0,0.002597541,0.02597541,0.02597878,32710.13,110474.8
100.438,-1.67392,-0.02624661,-32960.85,0.1113505,0,0,0.002624661,0.02624661,0.02625005,32960.85,111321.2
100.86,-1.68092,-0.02586376,-33211.02,0.1121956,0,0,0.002586376,0.02586376,0.0258671,33211.02,112166.6
101.278,-1.68788,-0.02581593,-33461.99,0.1130434,0,0,0.002581593,0.02581593,0.02581926,33461.99,113014.3
101.682,-1.6946,-0.02549689,-33712.85,0.1138909,0,0,0.002549689,0.02549689,0.02550014,33712.85,113861.9
102.072,-1.70116,-0.02594352,-33963.32,0.1147371,0,0,0.002594352,0.02594352,0.02594688,33963.32,114707.3
102.472,-1.70788,-0.02603922,-34214.18,0.1155845,0,0,0.002603922,0.02603922,0.02604261,34214.18,115554.4
102.88,-1.71468,-0.02584781,-34464.51,0.1164302,0,0,0.002584781,0.02584781,0.02585116,34464.51,116400.1
103.35,-1.72248,-0.02605516,-34715.45,0.1172779,0,0,0.002605516,0.02605516,0.02605856,34715.45,117247.4
103.844,-1.73068,-0.02611898,-34966.12,0.1181248,0,0,0.002611898,0.02611898,0.02612239,34966.12,118093.9
104.336,-1.73892,-0.025784,-35216.57,0.1189709,0,0,0.0025784,0.025784,0.02578733,35216.57,118940.2
104.872,-1.74788,-0.02610303,-35466.92,0.1198166,0,0,0.002610303,0.02610303,0.02610644,35466.92,119785.4
105.378,-1.75628,-0.02607115,-35716.99,0.1206614,0,0,0.002607115,0.02607115,0.02607454,35716.99,120630
105.872,-1.76448,-0.02602328,-35967.64,0.1215082,0,0,0.002602328,0.02602328,0.02602666,35967.64,121476.6
106.378,-1.77292,-0.02611898,-36217.81,0.1223533,0,0,0.002611898,0.02611898,0.02612239,36217.81,122321.4
106.88,-1.78128,-0.02610303,-36468.43,0.1232,0,0,0.002610303,0.02610303,0.02610644,36468.43,123167.8
107.348,-1.78908,-0.02616685,-36718.48,0.1240447,0,0,0.002616685,0.02616685,0.02617027,36718.48,124012.3
107.816,-1.79684,-0.02583187,-36969.01,0.1248911,0,0,0.002583187,0.02583187,0.02583521,36969.01,124858.8
108.268,-1.8044,-0.02603922,-37219.46,0.1257372,0,0,0.002603922,0.02603922,0.02604261,37219.46,125704.4
108.726,-1.81204,-0.02594352,-37470.3,0.1265846,0,0,0.002594352,0.02594352,0.02594688,37470.3,126551.7
109.198,-1.81988,-0.0258797,-37720.62,0.1274302,0,0,0.00258797,0.0258797,0.02588305,37720.62,127397.2
109.674,-1.8278,-0.02595946,-37971.08,0.1282763,0,0,0.002595946,0.02595946,0.02596283,37971.08,128243
110.116,-1.8352,-0.02594352,-38221.65,0.1291228,0,0,0.002594352,0.02594352,0.02594688,38221.64,129089.3
110.536,-1.84228,-0.02573617,-38471.75,0.1299677,0,0,0.002573617,0.02573617,0.02573948,38471.75,129934.3
110.96,-1.84936,-0.02586376,-38722.68,0.1308154,0,0,0.002586376,0.02586376,0.0258671,38722.68,130781.6
111.384,-1.8564,-0.02603922,-38973.81,0.1316638,0,0,0.002603922,0.02603922,0.02604261,38973.8,131629.5
111.8,-1.86328,-0.02608709,-39224.8,0.1325117,0,0,0.002608709,0.02608709,0.02609049,39224.8,132477.2
112.21,-1.87012,-0.02592757,-39475.89,0.13336,0,0,0.002592757,0.02592757,0.02593094,39475.89,133325.4
112.622,-1.877,-0.02595946,-39726.53,0.1342067,0,0,0.002595946,0.02595946,0.02596283,39726.53,134171.9
113.038,-1.88396,-0.0258797,-39977.51,0.1350546,0,0,0.00258797,0.0258797,0.02588305,39977.5,135019.6
113.456,-1.89092,-0.02608709,-40228.26,0.1359017,0,0,0.002608709,0.02608709,0.02609049,40228.26,135866.2
113.876,-1.89788,-0.02597541,-40479.05,0.1367489,0,0,0.002597541,0.02597541,0.02597878,40479.05,136713.4
114.306,-1.90504,-0.02623063,-40730.02,0.1375968,0,0,0.002623063,0.02623063,0.02623407,40730.02,137560.7
114.732,-1.91216,-0.02594352,-40981.13,0.1384451,0,0,0.002594352,0.02594352,0.02594688,40981.13,138409.2
115.164,-1.91932,-0.02608709,-41232.12,0.139293,0,0,0.002608709,0.02608709,0.02609049,41232.12,139256.7
115.578,-1.92624,-0.02560854,-41482.83,0.14014,0,0,0.002560854,0.02560854,0.02561182,41482.83,140104.1
115.992,-1.93312,-0.02603922,-41732.97,0.140985,0,0,0.002603922,0.02603922,0.02604261,41732.97,140948.3
116.434,-1.94052,-0.02594352,-41983.7,0.141832,0,0,0.002594352,0.02594352,0.02594688,41983.7,141795.2
116.922,-1.94864,-0.0264699,-42233.8,0.1426769,0,0,0.00264699,0.0264699,0.0264734,42233.8,142639.2
117.446,-1.95732,-0.02595946,-42484.41,0.1435236,0,0,0.002595946,0.02595946,0.02596283,42484.41,143486.3
118.438,-1.97396,-0.02607115,-42232.91,0.1426739,0,0,0.002607115,0.02607115,0.02607454,42232.91,142636.7
118.506,-1.97512,-0.02608709,-41975.89,0.1418056,0,0,0.002608709,0.02608709,0.02609049,41975.89,141768.7
118.566,-1.97612,-0.02581593,-41720.1,0.1409415,0,0,0.002581593,0.02581593,0.02581926,41720.11,140905.2
118.618,-1.977,-0.02589568,-41464.5,0.140078,0,0,0.002589568,0.02589568,0.02589904,41464.5,140041.7
118.658,-1.97768,-0.02584781,-41209.41,0.1392163,0,0,0.002584781,0.02584781,0.02585116,41209.41,139180.3
118.694,-1.97828,-0.02575211,-40948.58,0.1383351,0,0,0.002575211,0.02575211,0.02575543,40948.58,138299.5
118.738,-1.97904,-0.02592757,-40691.07,0.1374652,0,0,0.002592757,0.02592757,0.02593094,40691.07,137429.5
118.798,-1.98004,-0.02584781,-40440.87,0.13662,0,0,0.002584781,0.02584781,0.02585116,40440.87,136584.6
118.89,-1.98156,-0.02592757,-40189.98,0.1357724,0,0,0.002592757,0.02592757,0.02593094,40189.98,135737.2
119.052,-1.98424,-0.02572019,-39938.43,0.1349226,0,0,0.002572019,0.02572019,0.02572349,39938.43,134887.9
119.3,-1.98836,-0.02602328,-39687.8,0.1340759,0,0,0.002602328,0.02602328,0.02602666,39687.8,134041
119.684,-1.99472,-0.02619874,-39437.61,0.1332307,0,0,0.002619874,0.02619874,0.02620217,39437.61,133195.8
120.684,-2.0114,-0.02631038,-39554.67,0.1336261,0,0,0.002631038,0.02631038,0.02631384,39554.67,133591
121.248,-2.0208,-0.02616685,-39805.31,0.1344728,0,0,0.002616685,0.02616685,0.02617027,39805.3,134437.7
121.708,-2.0284,-0.02619874,-40055.44,0.1353179,0,0,0.002619874,0.02619874,0.02620217,40055.44,135282.4
122.108,-2.03508,-0.02613492,-40305.48,0.1361626,0,0,0.002613492,0.02613492,0.02613834,40305.48,136127
122.49,-2.04144,-0.02613492,-40556.15,0.1370094,0,0,0.002613492,0.02613492,0.02613834,40556.15,136973.6
122.858,-2.04756,-0.02643801,-40806.31,0.1378545,0,0,0.002643801,0.02643801,0.02644151,40806.31,137818.1
123.226,-2.05368,-0.02608709,-41056.9,0.1387011,0,0,0.002608709,0.02608709,0.02609049,41056.9,138664.9
123.59,-2.05976,-0.025784,-41307.53,0.1395477,0,0,0.0025784,0.025784,0.02578733,41307.53,139511.8
123.95,-2.06576,-0.02599139,-41558.32,0.140395,0,0,0.002599139,0.02599139,0.02599477,41558.32,140358.5
124.308,-2.07172,-0.02624661,-41808.79,0.1412411,0,0,0.002624661,0.02624661,0.02625005,41808.79,141204
124.702,-2.07828,-0.02584781,-42059.38,0.1420877,0,0,0.002584781,0.02584781,0.02585116,42059.38,142051
124.928,-2.08208,-0.0262785,-42195.62,0.142548,0,0,0.00262785,0.0262785,0.02628195,42195.63,142510.5
"Specimen",2
"Specimen name:","F1 cycle"
"Width:",330.000000,"mm"
"Thickness:",897.000000,"mm"
"Anvil height:",90.000000,"mm"
"Diameter:",50.000000,"mm"
"Inner diameter:",0.500000,"mm"
"Outer diameter:",1.000000,"mm"
"Wall thickness:",0.500000,"mm"
"Area:",296010.000000,"mm*mm"
"Linear density:",1.000000,"den"
"Sled weight:",9.806650,"N"
"Loading span:",0.000000,"mm"
"Support span:",1.000000,"mm"
"Span ratio:","2"
"Fixture type:","3-point"
"Extensometer",-10.000000,"**mm"
"Included"
"Time sec","Extension mm","Strain 1 %","Load N","Comp. stress MPa","Cycle Count ","Total Cycle Count ","Comp. extension mm","Comp. strain %","True strain %","Comp. load N","True stress Pa"
0,-1.02576,-0.02616685,-806.4624,0.002724443,0,0,0.002616685,0.02616685,0.02617027,806.4624,2723.73
3,-1.07576,-0.02540119,-1138.566,0.003846376,0,0,0.002540119,0.02540119,0.02540442,1138.566,3845.399
6,-1.12572,-0.02570424,-1553.723,0.005248888,0,0,0.002570424,0.02570424,0.02570755,1553.724,5247.539
9,-1.17576,-0.02597541,-2098.355,0.007088798,0,0,0.002597541,0.02597541,0.02597878,2098.355,7086.957
11.968,-1.22516,-0.0256883,-2815.37,0.009511066,0,0,0.00256883,0.0256883,0.0256916,2815.37,9508.622
14.75,-1.27156,-0.02595946,-3565.955,0.01204674,0,0,0.002595946,0.02595946,0.02596283,3565.955,12043.61
17.506,-1.31752,-0.02565641,-4316.764,0.01458317,0,0,0.002565641,0.02565641,0.0256597,4316.764,14579.43
19.876,-1.357,-0.02594352,-5067.33,0.01711878,0,0,0.002594352,0.02594352,0.02594688,5067.33,17114.34
21.67,-1.38684,-0.02597541,-5818.664,0.01965698,0,0,0.002597541,0.02597541,0.02597878,5818.664,19651.88
23.246,-1.41312,-0.02592757,-6569.748,0.02219434,0,0,0.002592757,0.02592757,0.02593094,6569.748,22188.59
24.696,-1.43736,-0.02573617,-7321.006,0.02473229,0,0,0.002573617,0.02573617,0.02573948,7321.006,24725.93
26.072,-1.46032,-0.02564047,-8073.254,0.02727359,0,0,0.002564047,0.02564047,0.02564375,8073.254,27266.59
27.368,-1.48188,-0.02583187,-8825.537,0.029815,0,0,0.002583187,0.02583187,0.02583521,8825.537,29807.29
28.602,-1.5024,-0.02589568,-9576.494,0.03235193,0,0,0.002589568,0.02589568,0.02589904,9576.494,32343.55
29.76,-1.52168,-0.02573617,-10327.55,0.03488918,0,0,0.002573617,0.02573617,0.02573948,10327.55,34880.2
30.888,-1.54056,-0.02573617,-11078.38,0.0374257,0,0,0.002573617,0.02573617,0.02573948,11078.38,37416.07
31.984,-1.55876,-0.02605516,-11830.68,0.03996716,0,0,0.002605516,0.02605516,0.02605856,11830.68,39956.74
33.056,-1.57672,-0.02607115,-12581.88,0.04250493,0,0,0.002607115,0.02607115,0.02607454,12581.88,42493.85
34.11,-1.59424,-0.02583187,-13333.01,0.04504243,0,0,0.002583187,0.02583187,0.02583521,13333.01,45030.79
35.116,-1.61104,-0.02616685,-14085.04,0.04758298,0,0,0.002616685,0.02616685,0.02617027,14085.04,47570.53
36.126,-1.62784,-0.02586376,-14836.47,0.05012152,0,0,0.002586376,0.02586376,0.0258671,14836.47,50108.56
37.106,-1.64416,-0.0256883,-15589.25,0.05266461,0,0,0.00256883,0.0256883,0.0256916,15589.25,52651.08
38.066,-1.66012,-0.02597541,-16341.72,0.05520664,0,0,0.002597541,0.02597541,0.02597878,16341.72,55192.3
39.014,-1.67596,-0.02589568,-17094.82,0.05775082,0,0,0.002589568,0.02589568,0.02589904,17094.82,57735.87
39.942,-1.69136,-0.02602328,-17848.65,0.06029747,0,0,0.002602328,0.02602328,0.02602666,17848.65,60281.77
40.852,-1.70664,-0.0261509,-18601.09,0.0628394,0,0,0.002615091,0.0261509,0.02615433,18601.09,62822.97
41.77,-1.72192,-0.02611898,-19354.14,0.0653834,0,0,0.002611898,0.02611898,0.02612239,19354.14,65366.32
42.67,-1.73692,-0.02583187,-20106.71,0.06792579,0,0,0.002583187,0.02583187,0.02583521,20106.71,67908.24
43.57,-1.75188,-0.02572019,-20859.87,0.07047014,0,0,0.002572019,0.02572019,0.02572349,20859.87,70452.01
44.454,-1.7666,-0.02626255,-21612.82,0.07301383,0,0,0.002626255,0.02626255,0.026266,21612.82,72994.65
45.318,-1.781,-0.025784,-22365.98,0.07555817,0,0,0.0025784,0.025784,0.02578733,22365.97,75538.69
46.168,-1.79516,-0.02554473,-23119.84,0.07810493,0,0,0.002554473,0.02554473,0.02554799,23119.84,78084.98
47.004,-1.80912,-0.02603922,-23872.43,0.08064737,0,0,0.002603922,0.02603922,0.02604261,23872.43,80626.37
47.83,-1.82284,-0.02562448,-24625.33,0.08319089,0,0,0.002562448,0.02562448,0.02562777,24625.33,83169.57
48.63,-1.83624,-0.02611898,-25379.14,0.08573744,0,0,0.002611898,0.02611898,0.02612239,25379.14,85715.04
49.426,-1.84952,-0.02586376,-26130.18,0.08827466,0,0,0.002586376,0.02586376,0.0258671,26130.18,88251.83
50.226,-1.8628,-0.02584781,-26882.17,0.09081507,0,0,0.002584781,0.02584781,0.02585116,26882.17,90791.6
51.012,-1.87596,-0.02581593,-27636.65,0.0933639,0,0,0.002581593,0.02581593,0.02581926,27636.65,93339.79
51.796,-1.88896,-0.02595946,-28388.68,0.09590448,0,0,0.002595946,0.02595946,0.02596283,28388.69,95879.58
52.57,-1.90188,-0.02581593,-29140,0.09844264,0,0,0.002581593,0.02581593,0.02581926,29140,98417.22
53.342,-1.91472,-0.02549689,-29892.42,0.1009845,0,0,0.002549689,0.02549689,0.02550014,29892.42,100958.8
54.11,-1.92748,-0.02595946,-30645.14,0.1035274,0,0,0.002595946,0.02595946,0.02596283,30645.13,103500.5
54.87,-1.94024,-0.02556071,-31397.19,0.106068,0,0,0.002556071,0.02556071,0.02556397,31397.19,106040.9
55.632,-1.95288,-0.02583187,-32149.08,0.1086081,0,0,0.002583187,0.02583187,0.02583521,32149.08,108580
56.388,-1.96552,-0.02589568,-32903.27,0.1111559,0,0,0.002589568,0.02589568,0.02589904,32903.27,111127.1
57.142,-1.97812,-0.02591163,-33656.6,0.1137009,0,0,0.002591163,0.02591163,0.02591499,33656.6,113671.4
57.908,-1.99084,-0.02551284,-34410.06,0.1162463,0,0,0.002551284,0.02551284,0.02551609,34410.06,116216.6
58.664,-2.00344,-0.02541713,-35163.28,0.1187909,0,0,0.002541713,0.02541713,0.02542036,35163.29,118760.7
59.422,-2.01608,-0.02565641,-35916.77,0.1213363,0,0,0.002565641,0.02565641,0.0256597,35916.77,121305.2
60.188,-2.02884,-0.02608709,-36670.45,0.1238825,0,0,0.002608709,0.02608709,0.02609049,36670.45,123850.1
60.968,-2.04184,-0.02584781,-37422.01,0.1264214,0,0,0.002584781,0.02584781,0.02585116,37422.01,126388.8
61.764,-2.05508,-0.02556071,-38176.92,0.1289717,0,0,0.002556071,0.02556071,0.02556397,38176.91,128938.7
62.566,-2.06848,-0.02573617,-38930.68,0.1315181,0,0,0.002573617,0.02573617,0.02573948,38930.68,131484.3
63.388,-2.08212,-0.02564047,-39683.16,0.1340602,0,0,0.002564047,0.02564047,0.02564375,39683.16,134025.8
64.22,-2.09604,-0.02595946,-40436.58,0.1366055,0,0,0.002595946,0.02595946,0.02596283,40436.58,136570
65.066,-2.1102,-0.02579994,-41188.7,0.1391463,0,0,0.002579994,0.02579994,0.02580327,41188.7,139110.4
65.964,-2.12512,-0.02611898,-41942.1,0.1416915,0,0,0.002611898,0.02611898,0.02612239,41942.1,141654.5
66.646,-2.13652,-0.02557665,-42500.97,0.1435795,0,0,0.002557665,0.02557665,0.02557992,42500.97,143542.8
67.766,-2.11872,-0.02595946,-42000.62,0.1418892,0,0,0.002595946,0.02595946,0.02596283,42000.62,141852.4
68.542,-2.10532,-0.02581593,-41246.69,0.1393422,0,0,0.002581593,0.02581593,0.02581926,41246.68,139306.2
69.054,-2.09656,-0.02594352,-40493.45,0.1367976,0,0,0.002594352,0.02594352,0.02594688,40493.45,136762.1
69.578,-2.08772,-0.0258797,-39740.93,0.1342554,0,0,0.00258797,0.0258797,0.02588305,39740.93,134220.6
70.12,-2.07872,-0.02599139,-38985.66,0.1317039,0,0,0.002599139,0.02599139,0.02599477,38985.66,131669.6
70.668,-2.06956,-0.02600733,-38231.72,0.1291568,0,0,0.002600733,0.02600733,0.02601071,38231.72,129123.3
71.214,-2.06044,-0.02611898,-37478.5,0.1266123,0,0,0.002611898,0.02611898,0.02612239,37478.5,126579.2
71.774,-2.05112,-0.02584781,-36723.85,0.1240629,0,0,0.002584781,0.02584781,0.02585116,36723.85,124030.8
72.338,-2.04172,-0.02599139,-35969.11,0.1215132,0,0,0.002599139,0.02599139,0.02599477,35969.11,121481.6
72.916,-2.03208,-0.0255926,-35213.01,0.1189589,0,0,0.00255926,0.0255926,0.02559587,35213.01,118928.4
73.498,-2.0224,-0.02613492,-34458.17,0.1164088,0,0,0.002613492,0.02613492,0.02613834,34458.17,116378.4
74.086,-2.0126,-0.02575211,-33703.91,0.1138607,0,0,0.002575211,0.02575211,0.02575543,33703.91,113831.4
74.68,-2.00268,-0.02589568,-32949.32,0.1113115,0,0,0.002589568,0.02589568,0.02589904,32949.32,111282.7
75.292,-1.99248,-0.02592757,-32194.4,0.1087612,0,0,0.002592757,0.02592757,0.02593094,32194.4,108733
75.912,-1.98216,-0.02579994,-31441.45,0.1062175,0,0,0.002579994,0.02579994,0.02580327,31441.45,106190.1
76.55,-1.97152,-0.02551284,-30686,0.1036654,0,0,0.002551284,0.02551284,0.02551609,30686,103639
77.19,-1.96088,-0.02584781,-29931.05,0.101115,0,0,0.002584781,0.02584781,0.02585116,29931.05,101088.9
77.846,-1.94992,-0.02562448,-29176.46,0.09856578,0,0,0.002562448,0.02562448,0.02562777,29176.46,98540.52
78.506,-1.93892,-0.02572019,-28425.29,0.09602813,0,0,0.002572019,0.02572019,0.02572349,28425.29,96003.43
79.176,-1.92776,-0.02573617,-27671.75,0.09348249,0,0,0.002573617,0.02573617,0.02573948,27671.75,93458.43
79.848,-1.91656,-0.025784,-26918.73,0.09093858,0,0,0.0025784,0.025784,0.02578733,26918.73,90915.14
80.528,-1.90524,-0.0258797,-26165.99,0.08839562,0,0,0.00258797,0.0258797,0.02588305,26165.99,88372.74
81.222,-1.89364,-0.02576806,-25412.43,0.08584992,0,0,0.002576806,0.02576806,0.02577138,25412.43,85827.8
81.922,-1.882,-0.02565641,-24658.86,0.08330413,0,0,0.002565641,0.02565641,0.0256597,24658.86,83282.76
82.634,-1.87012,-0.02599139,-23904.79,0.0807567,0,0,0.002599139,0.02599139,0.02599477,23904.79,80735.71
83.362,-1.85796,-0.02611898,-23152.34,0.07821473,0,0,0.002611898,0.02611898,0.02612239,23152.34,78194.31
84.114,-1.84544,-0.02592757,-22398.32,0.07566746,0,0,0.002592757,0.02592757,0.02593094,22398.32,75647.84
84.87,-1.83284,-0.02594352,-21644.73,0.07312162,0,0,0.002594352,0.02594352,0.02594688,21644.73,73102.65
85.64,-1.82,-0.02562448,-20892.54,0.0705805,0,0,0.002562448,0.02562448,0.02562777,20892.54,70562.42
86.45,-1.80652,-0.02586376,-20139.97,0.06803814,0,0,0.002586376,0.02586376,0.0258671,20139.97,68020.54
87.274,-1.7928,-0.02575211,-19386.73,0.06549349,0,0,0.002575211,0.02575211,0.02575543,19386.73,65476.62
88.12,-1.77868,-0.02595946,-18632.92,0.06294695,0,0,0.002595946,0.02595946,0.02596283,18632.92,62930.6
89.002,-1.764,-0.025784,-17879.5,0.06040169,0,0,0.0025784,0.025784,0.02578733,17879.5,60386.11
89.904,-1.74896,-0.02599139,-17126.23,0.05785694,0,0,0.002599139,0.02599139,0.02599477,17126.23,57841.9
90.826,-1.7336,-0.02607115,-16373.82,0.05531508,0,0,0.002607115,0.02607115,0.02607454,16373.82,55300.66
91.774,-1.71776,-0.02573617,-15622.24,0.05277604,0,0,0.002573617,0.02573617,0.02573948,15622.24,52762.46
92.754,-1.70148,-0.02543308,-14870.45,0.05023631,0,0,0.002543308,0.02543308,0.02543631,14870.45,50223.53
93.738,-1.68508,-0.02594352,-14117.47,0.04769255,0,0,0.002594352,0.02594352,0.02594688,14117.47,47680.18
94.77,-1.66788,-0.02565641,-13365.67,0.04515278,0,0,0.002565641,0.02565641,0.0256597,13365.67,45141.19
95.84,-1.65,-0.02602328,-12613.5,0.04261173,0,0,0.002602328,0.02602328,0.02602666,12613.5,42600.64
96.948,-1.63156,-0.025784,-11861.47,0.04007117,0,0,0.0025784,0.025784,0.02578733,11861.47,40060.84
98.112,-1.61216,-0.02551284,-11110.05,0.0375327,0,0,0.002551284,0.02551284,0.02551609,11110.05,37523.12
99.308,-1.5922,-0.02573617,-10358.2,0.03499274,0,0,0.002573617,0.02573617,0.02573948,10358.2,34983.73
100.592,-1.57084,-0.0258797,-9605.59,0.03245022,0,0,0.00258797,0.0258797,0.02588305,9605.59,32441.82
101.946,-1.54824,-0.02594352,-8854.147,0.02991165,0,0,0.002594352,0.02594352,0.02594688,8854.147,29903.89
103.414,-1.5238,-0.02611898,-8101.944,0.02737051,0,0,0.002611898,0.02611898,0.02612239,8101.944,27363.36
104.978,-1.49772,-0.02583187,-7350.437,0.02483172,0,0,0.002583187,0.02583187,0.02583521,7350.437,24825.3
106.664,-1.4696,-0.02591163,-6599.318,0.02229424,0,0,0.002591163,0.02591163,0.02591499,6599.318,22288.46
108.436,-1.44004,-0.02565641,-5847.821,0.01975548,0,0,0.002565641,0.02565641,0.0256597,5847.821,19750.41
110.322,-1.40864,-0.02594352,-5096.079,0.0172159,0,0,0.002594352,0.02594352,0.02594688,5096.08,17211.44
112.6,-1.37068,-0.02595946,-4344.868,0.01467811,0,0,0.002595946,0.02595946,0.02596283,4344.868,14674.3
115.438,-1.32332,-0.025784,-3594.004,0.0121415,0,0,0.0025784,0.025784,0.02578733,3594.004,12138.37
118.4,-1.274,-0.02564047,-2843.547,0.009606254,0,0,0.002564047,0.02564047,0.02564375,2843.547,9603.792
121.4,-1.22396,-0.02552878,-2145.137,0.007246839,0,0,0.002552878,0.02552878,0.02553204,2145.137,7244.989
124.4,-1.174,-0.02583187,-1594.092,0.005385263,0,0,0.002583187,0.02583187,0.02583521,1594.092,5383.872
127.4,-1.124,-0.02552878,-1180.757,0.003988908,0,0,0.002552878,0.02552878,0.02553204,1180.757,3987.889
129.144,-1.09496,-0.02565641,-999.5941,0.003376893,1,1,0.002565641,0.02565641,0.0256597,999.5941,3376.027
132.144,-1.14488,-0.02546497,-1254.849,0.004239213,1,1,0.002546497,0.02546497,0.02546821,1254.849,4238.133
135.144,-1.19496,-0.02552878,-1763.809,0.005958614,1,1,0.002552878,0.02552878,0.02553204,1763.809,5957.093
138.144,-1.24492,-0.02594352,-2427.423,0.008200477,1,1,0.002594352,0.02594352,0.02594688,2427.423,8198.349
140.938,-1.29152,-0.02557665,-3178.452,0.01073765,1,1,0.002557665,0.02557665,0.02557992,3178.452,10734.9
143.63,-1.3364,-0.02551284,-3929.4,0.01327455,1,1,0.002551284,0.02551284,0.02551609,3929.4,13271.17
146.184,-1.37892,-0.02570424,-4679.978,0.0158102,1,1,0.002570424,0.02570424,0.02570755,4679.978,15806.14
148.132,-1.41136,-0.025784,-5431.306,0.01834839,1,1,0.0025784,0.025784,0.02578733,5431.306,18343.66
149.818,-1.43956,-0.02595946,-6181.506,0.02088276,1,1,0.002595946,0.02595946,0.02596283,6181.506,20877.34
151.414,-1.46616,-0.02591163,-6933.791,0.02342418,1,1,0.002591163,0.02591163,0.02591499,6933.791,23418.11
152.894,-1.49076,-0.02642207,-7684.763,0.02596116,1,1,0.002642207,0.02642207,0.02642556,7684.763,25954.3
154.254,-1.5134,-0.02581593,-8436.178,0.02849964,1,1,0.002581593,0.02581593,0.02581926,8436.178,28492.28
155.53,-1.53472,-0.02597541,-9187.635,0.03103826,1,1,0.002597541,0.02597541,0.02597878,9187.635,31030.2
156.748,-1.55496,-0.02564047,-9939.359,0.03357778,1,1,0.002564047,0.02564047,0.02564375,9939.359,33569.17
157.922,-1.5746,-0.02592757,-10692.33,0.03612152,1,1,0.002592757,0.02592757,0.02593094,10692.33,36112.16
159.056,-1.59348,-0.02556071,-11443.7,0.03865985,1,1,0.002556071,0.02556071,0.02556397,11443.7,38649.97
160.128,-1.61136,-0.02602328,-12196.53,0.0412031,1,1,0.002602328,0.02602328,0.02602666,12196.53,41192.38
161.184,-1.62896,-0.02564047,-12948.51,0.04374348,1,1,0.002564047,0.02564047,0.02564375,12948.51,43732.27
162.206,-1.64592,-0.02591163,-13701.96,0.04628885,1,1,0.002591163,0.02591163,0.02591499,13701.96,46276.86
163.194,-1.66244,-0.025784,-14453.85,0.04882893,1,1,0.0025784,0.025784,0.02578733,14453.85,48816.34
164.172,-1.67868,-0.02573617,-15205.86,0.05136941,1,1,0.002573617,0.02573617,0.02573948,15205.86,51356.19
165.114,-1.6944,-0.02565641,-15959.16,0.05391426,1,1,0.002565641,0.02565641,0.0256597,15959.16,53900.42
166.052,-1.71008,-0.02576806,-16712.38,0.05645885,1,1,0.002576806,0.02576806,0.02577138,16712.38,56444.31
166.988,-1.72564,-0.02591163,-17464.21,0.05899873,1,1,0.002591163,0.02591163,0.02591499,17464.21,58983.44
167.896,-1.7408,-0.02600733,-18217.46,0.0615434,1,1,0.002600733,0.02600733,0.02601071,18217.46,61527.39
168.8,-1.75584,-0.02556071,-18970.04,0.06408581,1,1,0.002556071,0.02556071,0.02556397,18970.04,64069.43
169.686,-1.7706,-0.02560854,-19723.14,0.06662998,1,1,0.002560854,0.02560854,0.02561182,19723.14,66612.91
170.552,-1.785,-0.02565641,-20475.62,0.06917204,1,1,0.002565641,0.02565641,0.0256597,20475.62,69154.29
171.4,-1.7992,-0.02584781,-21227.98,0.07171372,1,1,0.002584781,0.02584781,0.02585116,21227.98,71695.18
172.24,-1.81316,-0.0256883,-21979.78,0.07425352,1,1,0.00256883,0.0256883,0.0256916,21979.79,74234.45
173.06,-1.82688,-0.02600733,-22733.56,0.07679999,1,1,0.002600733,0.02600733,0.02601071,22733.56,76780.02
173.866,-1.84032,-0.02608709,-23486.54,0.07934373,1,1,0.002608709,0.02608709,0.02609049,23486.54,79323.03
174.67,-1.85368,-0.02594352,-24237.66,0.08188122,1,1,0.002594352,0.02594352,0.02594688,24237.66,81859.98
175.47,-1.86704,-0.0256883,-24991.24,0.08442701,1,1,0.00256883,0.0256883,0.0256916,24991.24,84405.32
176.256,-1.88008,-0.02592757,-25743.67,0.08696891,1,1,0.002592757,0.02592757,0.02593094,25743.67,86946.36
177.03,-1.89304,-0.02575211,-26496.48,0.08951209,1,1,0.002575211,0.02575211,0.02575543,26496.48,89489.05
177.804,-1.90588,-0.02603922,-27251.06,0.0920613,1,1,0.002603922,0.02603922,0.02604261,27251.06,92037.33
178.564,-1.91856,-0.0256883,-28003.87,0.09460445,1,1,0.00256883,0.0256883,0.0256916,28003.87,94580.16
[...]
316.736,-2.129,-0.0256883,-39776.7,0.1343762,2,2,0.00256883,0.0256883,0.0256916,39776.7,134341.7
317.494,-2.1416,-0.02565641,-40528.65,0.1369165,2,2,0.002565641,0.02565641,0.0256597,40528.65,136881.4
318.264,-2.15444,-0.02573617,-41283.1,0.1394652,2,2,0.002573617,0.02573617,0.02573948,41283.1,139429.3
319.056,-2.16764,-0.02532143,-42034.99,0.1420053,2,2,0.002532143,0.02532143,0.02532464,42034.99,141969.4
319.556,-2.17596,-0.02532143,-42503.15,0.1435869,2,2,0.002532143,0.02532143,0.02532464,42503.15,143550.5
321.058,-2.15152,-0.02599139,-41752.17,0.1410498,2,2,0.002599139,0.02599139,0.02599477,41752.16,141013.2
321.588,-2.14232,-0.02560854,-40997,0.1384987,2,2,0.002560854,0.02560854,0.02561182,40997,138463.2
322.112,-2.13348,-0.02575211,-40243.39,0.1359528,2,2,0.002575211,0.02575211,0.02575543,40243.39,135917.8
322.646,-2.12452,-0.02573617,-39489.09,0.1334046,2,2,0.002573617,0.02573617,0.02573948,39489.09,133370.2
323.19,-2.11544,-0.02532143,-38735.37,0.1308583,2,2,0.002532143,0.02532143,0.02532464,38735.38,130825.2
323.74,-2.10628,-0.02624661,-37982.61,0.1283153,2,2,0.002624661,0.02624661,0.02625005,37982.61,128281.6
324.294,-2.09704,-0.02584781,-37229.31,0.1257704,2,2,0.002584781,0.02584781,0.02585116,37229.31,125737.9
324.862,-2.0876,-0.02597541,-36474.45,0.1232203,2,2,0.002597541,0.02597541,0.02597878,36474.45,123188.3
325.438,-2.07796,-0.0255926,-35719.3,0.1206692,2,2,0.00255926,0.0255926,0.02559587,35719.3,120638.3
326.018,-2.06832,-0.02565641,-34967.16,0.1181283,2,2,0.002565641,0.02565641,0.0256597,34967.16,118098
326.602,-2.05856,-0.02556071,-34211.99,0.1155772,2,2,0.002556071,0.02556071,0.02556397,34211.99,115547.6
327.196,-2.04868,-0.02575211,-33458.89,0.113033,2,2,0.002575211,0.02575211,0.02575543,33458.89,113003.9
327.798,-2.03864,-0.0255926,-32704.73,0.1104852,2,2,0.00255926,0.0255926,0.02559587,32704.73,110456.9
328.41,-2.02844,-0.02573617,-31951.67,0.1079412,2,2,0.002573617,0.02573617,0.02573948,31951.68,107913.4
329.028,-2.01816,-0.02584781,-31199.91,0.1054015,2,2,0.002584781,0.02584781,0.02585116,31199.91,105374.3
329.65,-2.0078,-0.02583187,-30445.16,0.1028518,2,2,0.002583187,0.02583187,0.02583521,30445.16,102825.2
330.286,-1.9972,-0.02549689,-29693.56,0.1003127,2,2,0.002549689,0.02549689,0.02550014,29693.56,100287.1
330.938,-1.98632,-0.02575211,-28938.55,0.09776207,2,2,0.002575211,0.02575211,0.02575543,28938.55,97736.89
331.606,-1.9752,-0.02591163,-28184.86,0.09521591,2,2,0.002591163,0.02591163,0.02591499,28184.86,95191.24
332.282,-1.96392,-0.02586376,-27431.47,0.09267075,2,2,0.002586376,0.02586376,0.0258671,27431.47,92646.79
332.974,-1.9524,-0.02579994,-26678.44,0.09012681,2,2,0.002579994,0.02579994,0.02580327,26678.44,90103.56
333.672,-1.94076,-0.025784,-25924.51,0.08757985,2,2,0.0025784,0.025784,0.02578733,25924.51,87557.26
334.384,-1.92888,-0.0255926,-25170.68,0.0850332,2,2,0.00255926,0.0255926,0.02559587,25170.68,85011.44
335.096,-1.917,-0.02567235,-24416.85,0.08248656,2,2,0.002567235,0.02567235,0.02567565,24416.85,82465.39
335.82,-1.90496,-0.0258797,-23662.91,0.07993955,2,2,0.00258797,0.0258797,0.02588305,23662.91,79918.86
336.558,-1.89264,-0.02583187,-22909.89,0.07739567,2,2,0.002583187,0.02583187,0.02583521,22909.89,77375.68
337.302,-1.88024,-0.02583187,-22157.24,0.074853,2,2,0.002583187,0.02583187,0.02583521,22157.24,74833.67
338.064,-1.86756,-0.0258797,-21406.22,0.07231587,2,2,0.00258797,0.0258797,0.02588305,21406.22,72297.16
338.85,-1.85444,-0.02572019,-20655.34,0.0697792,2,2,0.002572019,0.02572019,0.02572349,20655.34,69761.25
339.658,-1.841,-0.02579994,-19902.25,0.06723507,2,2,0.002579994,0.02579994,0.02580327,19902.25,67217.72
340.474,-1.8274,-0.02575211,-19152.05,0.06470068,2,2,0.002575211,0.02575211,0.02575543,19152.05,64684.02
341.326,-1.81316,-0.02600733,-18400.11,0.06216044,2,2,0.002600733,0.02600733,0.02601071,18400.11,62144.27
342.212,-1.79844,-0.02576806,-17646.27,0.05961376,2,2,0.002576806,0.02576806,0.02577138,17646.27,59598.4
343.11,-1.78344,-0.02583187,-16893.39,0.05707034,2,2,0.002583187,0.02583187,0.02583521,16893.39,57055.6
344.048,-1.76784,-0.02599139,-16141.01,0.05452859,2,2,0.002599139,0.02599139,0.02599477,16141.01,54514.42
345.022,-1.7516,-0.02608709,-15388.87,0.05198768,2,2,0.002608709,0.02608709,0.02609049,15388.87,51974.12
346.01,-1.73512,-0.0255926,-14636.62,0.04944637,2,2,0.00255926,0.0255926,0.02559587,14636.62,49433.71
347.034,-1.71804,-0.02592757,-13884.73,0.04690629,2,2,0.002592757,0.02592757,0.02593094,13884.73,46894.13
348.098,-1.70032,-0.02554473,-13133.73,0.04436919,2,2,0.002554473,0.02554473,0.02554799,13133.73,44357.86
349.182,-1.68228,-0.02591163,-12382.04,0.0418298,2,2,0.002591163,0.02591163,0.02591499,12382.04,41818.96
350.336,-1.66304,-0.025784,-11629.4,0.03928721,2,2,0.0025784,0.025784,0.02578733,11629.41,39277.08
351.536,-1.643,-0.02600733,-10878.6,0.03675078,2,2,0.002600733,0.02600733,0.02601071,10878.6,36741.22
352.826,-1.62152,-0.02551284,-10127.01,0.03421173,2,2,0.002551284,0.02551284,0.02551609,10127.01,34203
354.18,-1.59896,-0.02562448,-9376.068,0.03167484,2,2,0.002562448,0.02562448,0.02562777,9376.067,31666.72
355.63,-1.57476,-0.02599139,-8624.535,0.02913596,2,2,0.002599139,0.02599139,0.02599477,8624.535,29128.39
357.18,-1.54896,-0.0256883,-7872.614,0.02659577,2,2,0.00256883,0.0256883,0.0256916,7872.613,26588.94
358.822,-1.5216,-0.0255926,-7120.977,0.02405654,2,2,0.00255926,0.0255926,0.02559587,7120.978,24050.39
360.52,-1.49332,-0.02543308,-6370.594,0.02152155,2,2,0.002543308,0.02543308,0.02543631,6370.594,21516.08
362.3,-1.46364,-0.02536926,-5620.047,0.018986,2,2,0.002536926,0.02536926,0.02537248,5620.047,18981.19
364.276,-1.43068,-0.02554473,-4869.079,0.01644903,2,2,0.002554473,0.02554473,0.02554799,4869.079,16444.83
366.742,-1.38956,-0.02591163,-4117.455,0.01390985,2,2,0.002591163,0.02591163,0.02591499,4117.455,13906.25
369.594,-1.34204,-0.02579994,-3366.257,0.01137211,2,2,0.002579994,0.02579994,0.02580327,3366.257,11369.17
372.578,-1.29232,-0.02554473,-2622.172,0.008858389,2,2,0.002554473,0.02554473,0.02554799,2622.172,8856.126
375.578,-1.24224,-0.0256883,-1965.775,0.006640906,2,2,0.00256883,0.0256883,0.0256916,1965.775,6639.2
378.578,-1.19232,-0.02591163,-1451.765,0.004904445,2,2,0.002591163,0.02591163,0.02591499,1451.765,4903.175
381.578,-1.14228,-0.02543308,-1084.877,0.003665003,2,2,0.002543308,0.02543308,0.02543631,1084.877,3664.07
382.458,-1.1276,-0.02564047,-999.3949,0.00337622,0,3,0.002564047,0.02564047,0.02564375,999.3949,3375.354
385.458,-1.17764,-0.02552878,-1239.971,0.004188949,0,3,0.002552878,0.02552878,0.02553204,1239.971,4187.88
388.458,-1.22764,-0.02554473,-1753.964,0.005925353,0,3,0.002554473,0.02554473,0.02554799,1753.964,5923.839
391.458,-1.27768,-0.02544902,-2409.46,0.008139794,0,3,0.002544902,0.02544902,0.02545226,2409.46,8137.722
394.276,-1.32468,-0.02584781,-3160.98,0.01067862,0,3,0.002584781,0.02584781,0.02585116,3160.979,10675.86
396.936,-1.36892,-0.02535332,-3912.52,0.01321753,0,3,0.002535332,0.02535332,0.02535653,3912.521,13214.18
399.468,-1.41116,-0.02549689,-4663.755,0.0157554,0,3,0.002549689,0.02549689,0.02550014,4663.755,15751.38
401.414,-1.44364,-0.02543308,-5414.406,0.01829129,0,3,0.002543308,0.02543308,0.02543631,5414.406,18286.64
403.108,-1.47184,-0.02556071,-6166.353,0.02083157,0,3,0.002556071,0.02556071,0.02556397,6166.353,20826.25
404.718,-1.49864,-0.02532143,-6918.646,0.02337302,0,3,0.002532143,0.02532143,0.02532464,6918.646,23367.1
406.242,-1.52408,-0.02543308,-7670.194,0.02591194,0,3,0.002543308,0.02543308,0.02543631,7670.194,25905.35
407.698,-1.54832,-0.02579994,-8422.709,0.02845414,0,3,0.002579994,0.02579994,0.02580327,8422.709,28446.8
409.052,-1.57092,-0.02541713,-9174.643,0.03099437,0,3,0.002541713,0.02541713,0.02542036,9174.644,30986.49
410.334,-1.59228,-0.02543308,-9925.881,0.03353225,0,3,0.002543308,0.02543308,0.02543631,9925.881,33523.72
411.53,-1.6122,-0.02538525,-10677.58,0.0360717,0,3,0.002538525,0.02538525,0.02538847,10677.58,36062.54
412.688,-1.63148,-0.0256883,-11429.1,0.03861053,0,3,0.00256883,0.0256883,0.0256916,11429.1,38600.61
413.79,-1.64984,-0.02573617,-12181.64,0.04115282,0,3,0.002573617,0.02573617,0.02573948,12181.64,41142.22
414.852,-1.66756,-0.02546497,-12933.07,0.04369131,0,3,0.002546497,0.02546497,0.02546821,12933.07,43680.19
415.882,-1.68472,-0.02543308,-13684.97,0.04623144,0,3,0.002543308,0.02543308,0.02543631,13684.97,46219.68
416.87,-1.7012,-0.02524167,-14436.05,0.0487688,0,3,0.002524167,0.02524167,0.02524486,14436.05,48756.49
417.864,-1.71776,-0.0255926,-15188.57,0.05131099,0,3,0.00255926,0.0255926,0.02559587,15188.57,51297.86
418.834,-1.73392,-0.02551284,-15941.07,0.05385316,0,3,0.002551284,0.02551284,0.02551609,15941.07,53839.42
419.784,-1.74976,-0.02549689,-16693.7,0.05639572,0,3,0.002549689,0.02549689,0.02550014,16693.7,56381.34
420.72,-1.76532,-0.02528951,-17446.37,0.05893844,0,3,0.002528951,0.02528951,0.0252927,17446.37,58923.54
421.634,-1.78052,-0.02573617,-18199.37,0.06148227,0,3,0.002573617,0.02573617,0.02573948,18199.37,61466.45
422.516,-1.79532,-0.02556071,-18953.15,0.06402875,0,3,0.002556071,0.02556071,0.02556397,18953.15,64012.38
423.39,-1.80984,-0.02541713,-19705.4,0.06657007,0,3,0.002541713,0.02541713,0.02542036,19705.4,66553.14
424.24,-1.82404,-0.0256883,-20458.05,0.06911269,0,3,0.00256883,0.0256883,0.0256916,20458.05,69094.94
425.072,-1.83788,-0.02595946,-21210.87,0.07165594,0,3,0.002595946,0.02595946,0.02596283,21210.88,71637.34
425.898,-1.85164,-0.02560854,-21964.42,0.07420162,0,3,0.002560854,0.02560854,0.02561182,21964.42,74182.62
426.722,-1.8654,-0.02544902,-22717.6,0.07674605,0,3,0.002544902,0.02544902,0.02545226,22717.6,76726.52
427.53,-1.87884,-0.02591163,-23472.51,0.07929635,0,3,0.002591163,0.02591163,0.02591499,23472.51,79275.8
428.322,-1.89208,-0.02546497,-24225.43,0.08183991,0,3,0.002546497,0.02546497,0.02546821,24225.43,81819.07
429.112,-1.9052,-0.02554473,-24978.12,0.08438271,0,3,0.002554473,0.02554473,0.02554799,24978.12,84361.15
429.888,-1.91812,-0.02556071,-25732.37,0.08693076,0,3,0.002556071,0.02556071,0.02556397,25732.38,86908.54
430.648,-1.93084,-0.02567235,-26485.17,0.0894739,0,3,0.002567235,0.02567235,0.02567565,26485.17,89450.93
431.414,-1.94356,-0.02573617,-27236.83,0.09201322,0,3,0.002573617,0.02573617,0.02573948,27236.83,91989.54
432.158,-1.956,-0.0251938,-27989.86,0.09455716,0,3,0.00251938,0.0251938,0.02519698,27989.87,94533.34
432.904,-1.9684,-0.02487481,-28741.15,0.09709521,0,3,0.002487481,0.02487481,0.0248779,28741.15,97071.05
433.65,-1.98084,-0.02527356,-29493.87,0.0996381,0,3,0.002527356,0.02527356,0.02527676,29493.88,99612.92
434.388,-1.99316,-0.02546497,-30246.76,0.1021816,0,3,0.002546497,0.02546497,0.02546821,30246.76,102155.5
435.126,-2.0054,-0.02543308,-30999.44,0.1047243,0,3,0.002543308,0.02543308,0.02543631,30999.44,104697.7
435.848,-2.01748,-0.02517786,-31753.15,0.1072705,0,3,0.002517786,0.02517786,0.02518103,31753.15,107243.5
436.57,-2.02952,-0.02557665,-32507.12,0.1098176,0,3,0.002557665,0.02557665,0.02557992,32507.12,109789.6
437.288,-2.04144,-0.02540119,-33259.55,0.1123595,0,3,0.002540119,0.02540119,0.02540442,33259.55,112331
437.998,-2.05332,-0.02527356,-34011.64,0.1149003,0,3,0.002527356,0.02527356,0.02527676,34011.64,114871.3
438.704,-2.06508,-0.0256883,-34765.03,0.1174454,0,3,0.00256883,0.0256883,0.0256916,34765.03,117415.3
439.41,-2.07684,-0.02560854,-35519.98,0.1199959,0,3,0.002560854,0.02560854,0.02561182,35519.98,119965.1
440.108,-2.08848,-0.02543308,-36272.16,0.122537,0,3,0.002543308,0.02543308,0.02543631,36272.16,122505.8
440.812,-2.1002,-0.02551284,-37024.27,0.1250778,0,3,0.002551284,0.02551284,0.02551609,37024.27,125045.8
441.512,-2.11188,-0.02570424,-37777.16,0.1276212,0,3,0.002570424,0.02570424,0.02570755,37777.16,127588.4
442.22,-2.12372,-0.02557665,-38530.27,0.1301654,0,3,0.002557665,0.02557665,0.02557992,38530.27,130132.1
442.938,-2.13564,-0.02556071,-39284.47,0.1327133,0,3,0.002556071,0.02556071,0.02556397,39284.47,132679.4
443.664,-2.14772,-0.02554473,-40035.13,0.1352492,0,3,0.002554473,0.02554473,0.02554799,40035.13,135214.7
444.406,-2.16012,-0.02498645,-40787.84,0.1377921,0,3,0.002498645,0.02498645,0.02498958,40787.84,137757.7
445.172,-2.17284,-0.02552878,-41541.65,0.1403387,0,3,0.002552878,0.02552878,0.02553204,41541.65,140302.8
445.944,-2.18568,-0.0255926,-42295.66,0.1428859,0,3,0.00255926,0.0255926,0.02559587,42295.66,142849.4
446.716,-2.1986,-0.02567235,-43049.2,0.1454316,0,3,0.002567235,0.02567235,0.02567565,43049.2,145394.3
447.508,-2.21184,-0.02591163,-43802.14,0.1479752,0,3,0.002591163,0.02591163,0.02591499,43802.14,147936.9
448.32,-2.2254,-0.02533738,-44554.75,0.1505177,0,3,0.002533738,0.02533738,0.02534059,44554.75,150479.6
449.138,-2.23896,-0.02565641,-45307.61,0.1530611,0,3,0.002565641,0.02565641,0.0256597,45307.61,153021.8
449.98,-2.25304,-0.02532143,-46060.17,0.1556034,0,3,0.002532143,0.02532143,0.02532464,46060.17,155564
450.862,-2.26772,-0.02556071,-46812.97,0.1581466,0,3,0.002556071,0.02556071,0.02556397,46812.97,158106.2
451.756,-2.2826,-0.02532143,-47567.02,0.160694,0,3,0.002532143,0.02532143,0.02532464,47567.02,160653.3
452.658,-2.29764,-0.02536926,-48319.94,0.1632375,0,3,0.002536926,0.02536926,0.02537248,48319.94,163196.1
453.576,-2.31288,-0.02541713,-49073.87,0.1657845,0,3,0.002541713,0.02541713,0.02542036,49073.87,165742.4
454.488,-2.32816,-0.02535332,-49825.42,0.1683235,0,3,0.002535332,0.02535332,0.02535653,49825.43,168280.8
455.428,-2.3438,-0.0256883,-50577.3,0.1708635,0,3,0.00256883,0.0256883,0.0256916,50577.3,170819.6
456.382,-2.35972,-0.025784,-51329.16,0.1734035,0,3,0.0025784,0.025784,0.02578733,51329.16,173358.8
457.356,-2.37592,-0.02527356,-52082.2,0.1759475,0,3,0.002527356,0.02527356,0.02527676,52082.2,175903
458.334,-2.39228,-0.02549689,-52834.58,0.1784892,0,3,0.002549689,0.02549689,0.02550014,52834.58,178443.7
459.332,-2.40884,-0.02572019,-53586.69,0.18103,0,3,0.002572019,0.02572019,0.02572349,53586.69,180983.4
460.31,-2.4252,-0.0255926,-54337.78,0.1835674,0,3,0.00255926,0.0255926,0.02559587,54337.78,183520.4
461.31,-2.44184,-0.02541713,-55089.42,0.1861066,0,3,0.002541713,0.02541713,0.02542036,55089.42,186059.3
462.324,-2.458759,-0.02541713,-55840.21,0.188643,0,3,0.002541713,0.02541713,0.02542036,55840.21,188595
463.36,-2.475999,-0.02552878,-56592.84,0.1911856,0,3,0.002552878,0.02552878,0.02553204,56592.84,191136.8
464.408,-2.49352,-0.02554473,-57345.66,0.1937288,0,3,0.002554473,0.02554473,0.02554799,57345.66,193679.3
465.526,-2.51208,-0.02532143,-58098.74,0.1962729,0,3,0.002532143,0.02532143,0.02532464,58098.74,196223.2
466.584,-2.529839,-0.02562448,-58849.54,0.1988093,0,3,0.002562448,0.02562448,0.02562777,58849.54,198758.3
467.622,-2.547039,-0.02533738,-59601.33,0.201349,0,3,0.002533738,0.02533738,0.02534059,59601.33,201298
468.596,-2.56332,-0.02572019,-60354.85,0.2038946,0,3,0.002572019,0.02572019,0.02572349,60354.85,203842.2
469.582,-2.57968,-0.02541713,-61107.02,0.2064357,0,3,0.002541713,0.02541713,0.02542036,61107.02,206383.2
470.568,-2.59616,-0.02583187,-61858.08,0.2089729,0,3,0.002583187,0.02583187,0.02583521,61858.07,208918.9
471.594,-2.61324,-0.02530549,-62610.4,0.2115145,0,3,0.002530549,0.02530549,0.02530869,62610.4,211461
472.624,-2.630439,-0.02572019,-63362.37,0.2140548,0,3,0.002572019,0.02572019,0.02572349,63362.37,213999.8
473.654,-2.6476,-0.02541713,-64114.31,0.2165951,0,3,0.002541713,0.02541713,0.02542036,64114.31,216540
474.708,-2.665239,-0.02549689,-64865.91,0.2191342,0,3,0.002549689,0.02549689,0.02550014,64865.91,219078.3
475.764,-2.682719,-0.02549689,-65618.44,0.2216764,0,3,0.002549689,0.02549689,0.02550014,65618.44,221619.9
476.762,-2.699399,-0.02543308,-66370.14,0.2242159,0,3,0.002543308,0.02543308,0.02543631,66370.13,224158.8
477.782,-2.71636,-0.02538525,-67121.83,0.2267553,0,3,0.002538525,0.02538525,0.02538847,67121.84,226697.7
478.826,-2.733759,-0.02540119,-67873.17,0.2292935,0,3,0.002540119,0.02540119,0.02540442,67873.17,229235.3
479.862,-2.75112,-0.02573617,-68625.12,0.2318338,0,3,0.002573617,0.02573617,0.02573948,68625.13,231774.1
480.936,-2.769,-0.02565641,-69377.2,0.2343745,0,3,0.002565641,0.02565641,0.0256597,69377.2,234314.4
482.008,-2.78684,-0.02517786,-70129.45,0.2369158,0,3,0.002517786,0.02517786,0.02518103,70129.45,236856.2
483.074,-2.804559,-0.0251938,-70881.6,0.2394568,0,3,0.00251938,0.0251938,0.02519698,70881.6,239396.4
484.102,-2.82176,-0.02527356,-71633.87,0.2419981,0,3,0.002527356,0.02527356,0.02527676,71633.87,241937
485.118,-2.83868,-0.0255926,-72385.82,0.2445384,0,3,0.00255926,0.0255926,0.02559587,72385.82,244475.8
486.144,-2.85576,-0.02540119,-73139.1,0.2470832,0,3,0.002540119,0.02540119,0.02540442,73139.1,247020.4
487.204,-2.873399,-0.02536926,-73891.02,0.2496234,0,3,0.002536926,0.02536926,0.02537248,73891.02,249560.1
488.3,-2.89176,-0.02544902,-74642.7,0.2521628,0,3,0.002544902,0.02544902,0.02545226,74642.7,252098.6
489.452,-2.91088,-0.02527356,-75393.87,0.2547004,0,3,0.002527356,0.02527356,0.02527676,75393.87,254636
490.47,-2.92792,-0.02520975,-76146.65,0.2572435,0,3,0.002520975,0.02520975,0.02521293,76146.65,257178.7
491.474,-2.9446,-0.02517786,-76896.87,0.2597779,0,3,0.002517786,0.02517786,0.02518103,76896.87,259712.5
492.474,-2.961319,-0.02524167,-77649.65,0.2623211,0,3,0.002524167,0.02524167,0.02524486,77649.66,262254.9
493.45,-2.977519,-0.02564047,-78402.42,0.2648641,0,3,0.002564047,0.02564047,0.02564375,78402.41,264796.2
494.408,-2.993479,-0.02524167,-79156.17,0.2674105,0,3,0.002524167,0.02524167,0.02524486,79156.17,267343
495.392,-3.00988,-0.02538525,-79909.54,0.2699555,0,3,0.002538525,0.02538525,0.02538847,79909.54,269887
496.352,-3.02596,-0.02535332,-80662.31,0.2724986,0,3,0.002535332,0.02535332,0.02535653,80662.31,272429.5
497.452,-3.0442,-0.0250024,-81414.92,0.2750411,0,3,0.00250024,0.0250024,0.02500552,81414.92,274972.3
498.498,-3.061719,-0.02527356,-82165.61,0.2775771,0,3,0.002527356,0.02527356,0.02527676,82165.61,277507
499.642,-3.080679,-0.02552878,-82917.61,0.2801176,0,3,0.002552878,0.02552878,0.02553204,82917.61,280046.1
500.588,-3.09652,-0.02541713,-83669.99,0.2826593,0,3,0.002541713,0.02541713,0.02542036,83669.99,282587.5
501.524,-3.11208,-0.02536926,-84422.55,0.2852017,0,3,0.002536926,0.02536926,0.02537248,84422.55,285129.3
502.464,-3.127799,-0.02557665,-85176.72,0.2877495,0,3,0.002557665,0.02557665,0.02557992,85176.72,287675.9
503.426,-3.14376,-0.02546497,-85929.51,0.2902926,0,3,0.002546497,0.02546497,0.02546821,85929.51,290218.7
504.354,-3.159319,-0.0255926,-86682.1,0.292835,0,3,0.00255926,0.0255926,0.02559587,86682.1,292760.1
505.328,-3.175439,-0.02556071,-87434.23,0.2953759,0,3,0.002556071,0.02556071,0.02556397,87434.23,295300.4
506.238,-3.19068,-0.02546497,-88185.86,0.2979151,0,3,0.002546497,0.02546497,0.02546821,88185.86,297839.3
507.146,-3.20576,-0.02533738,-88938.39,0.3004574,0,3,0.002533738,0.02533738,0.02534059,88938.38,300381.2
508.074,-3.221279,-0.0255926,-89690.3,0.3029975,0,3,0.00255926,0.0255926,0.02559587,89690.3,302920
508.986,-3.236439,-0.02525762,-90443.63,0.3055425,0,3,0.002525762,0.02525762,0.02526081,90443.63,305465.3
509.89,-3.25152,-0.02536926,-91195.83,0.3080836,0,3,0.002536926,0.02536926,0.02537248,91195.83,308005.4
510.79,-3.266479,-0.02516191,-91947.79,0.3106239,0,3,0.002516191,0.02516191,0.02516508,91947.8,310545.8
511.692,-3.281559,-0.02552878,-92699.84,0.3131646,0,3,0.002552878,0.02552878,0.02553204,92699.84,313084.6
512.616,-3.296999,-0.02576806,-93452.26,0.3157064,0,3,0.002576806,0.02576806,0.02577138,93452.26,315625.1
513.552,-3.312519,-0.02573617,-94204.94,0.3182492,0,3,0.002573617,0.02573617,0.02573948,94204.94,318167.3
514.506,-3.32852,-0.02524167,-94958.62,0.3207953,0,3,0.002524167,0.02524167,0.02524486,94958.63,320714.4
515.474,-3.344599,-0.02516191,-95711.48,0.3233387,0,3,0.002516191,0.02516191,0.02516508,95711.48,323257.3
516.444,-3.36076,-0.02524167,-96463.87,0.3258804,0,3,0.002524167,0.02524167,0.02524486,96463.87,325798.2
517.452,-3.377519,-0.02562448,-97216.43,0.3284228,0,3,0.002562448,0.02562448,0.02562777,97216.43,328338.6
518.064,-3.387759,-0.02573617,-97697.86,0.3300492,0,3,0.002573617,0.02573617,0.02573948,97697.86,329964.2